AST SEEN   TYPE      REASON                            OBJECT                                                              MESSAGE
5m3s        Warning   FailedToRetrieveImagePullSecret   pod/cli-pod-custom-ca                                               Unable to retrieve some image pull secrets (sas-image-pull-secrets-h8k8f47k5c); attempting to pull the image may not succeed.31m         Normal    Scheduled                         pod/prepull-ds-edxepzai-85bwf                                       Successfully assigned viya-dev/prepull-ds-edxepzai-85bwf to ip-100-64-118-176.us-west-2.compute.internal
31m         Normal    Pulled                            pod/prepull-ds-edxepzai-85bwf                                       Container image "668749497752.dkr.ecr.us-west-2.amazonaws.com/sasviya/viya-4-x64_oci_linux_2-docker/sas-certframe:3.51.0-20240313.1710330811841" already present on machine
31m         Normal    Created                           pod/prepull-ds-edxepzai-85bwf                                       Created container prepull-pod-yghfrktk31m         Normal    Started                           pod/prepull-ds-edxepzai-85bwf                                       Started container prepull-pod-yghfrktk
30m         Normal    Killing                           pod/prepull-ds-edxepzai-85bwf                                       Stopping container prepull-pod-yghfrktk31m         Normal    Scheduled                         pod/prepull-ds-edxepzai-96rtq                                       Successfully assigned viya-dev/prepull-ds-edxepzai-96rtq to ip-100-64-88-54.us-west-2.compute.internal31m         Normal    Pulled                            pod/prepull-ds-edxepzai-96rtq                                       Container image "668749497752.dkr.ecr.us-west-2.amazonaws.com/sasviya/viya-4-x64_oci_linux_2-docker/sas-certframe:3.51.0-20240313.1710330811841" already present on machine31m         Normal    Created                           pod/prepull-ds-edxepzai-96rtq                                       Created container prepull-pod-yghfrktk
31m         Normal    Started                           pod/prepull-ds-edxepzai-96rtq                                       Started container prepull-pod-yghfrktk
30m         Normal    Killing                           pod/prepull-ds-edxepzai-96rtq                                       Stopping container prepull-pod-yghfrktk
31m         Normal    Scheduled                         pod/prepull-ds-edxepzai-djbwx                                       Successfully assigned viya-dev/prepull-ds-edxepzai-djbwx to ip-100-64-118-98.us-west-2.compute.internal
31m         Normal    Pulled                            pod/prepull-ds-edxepzai-djbwx                                       Container image "668749497752.dkr.ecr.us-west-2.amazonaws.com/sasviya/viya-4-x64_oci_linux_2-docker/sas-certframe:3.51.0-20240313.1710330811841" already present on machine
31m         Normal    Created                           pod/prepull-ds-edxepzai-djbwx                                       Created container prepull-pod-yghfrktk
31m         Normal    Started                           pod/prepull-ds-edxepzai-djbwx                                       Started container prepull-pod-yghfrktk
30m         Normal    Killing                           pod/prepull-ds-edxepzai-djbwx                                       Stopping container prepull-pod-yghfrktk
31m         Normal    Scheduled                         pod/prepull-ds-edxepzai-grsp6                                       Successfully assigned viya-dev/prepull-ds-edxepzai-grsp6 to ip-100-64-103-52.us-west-2.compute.internal31m         Normal    Pulled                            pod/prepull-ds-edxepzai-grsp6                                       Container image "668749497752.dkr.ecr.us-west-2.amazonaws.com/sasviya/viya-4-x64_oci_linux_2-docker/sas-certframe:3.51.0-20240313.1710330811841" already present on machine
31m         Normal    Created                           pod/prepull-ds-edxepzai-grsp6                                       Created container prepull-pod-yghfrktk31m         Normal    Started                           pod/prepull-ds-edxepzai-grsp6                                       Started container prepull-pod-yghfrktk
30m         Normal    Killing                           pod/prepull-ds-edxepzai-grsp6                                       Stopping container prepull-pod-yghfrktk
31m         Normal    Scheduled                         pod/prepull-ds-edxepzai-mpv9h                                       Successfully assigned viya-dev/prepull-ds-edxepzai-mpv9h to ip-100-64-125-225.us-west-2.compute.internal
31m         Normal    Pulled                            pod/prepull-ds-edxepzai-mpv9h                                       Container image "668749497752.dkr.ecr.us-west-2.amazonaws.com/sasviya/viya-4-x64_oci_linux_2-docker/sas-certframe:3.51.0-20240313.1710330811841" already present on machine
31m         Normal    Created                           pod/prepull-ds-edxepzai-mpv9h                                       Created container prepull-pod-yghfrktk
31m         Normal    Started                           pod/prepull-ds-edxepzai-mpv9h                                       Started container prepull-pod-yghfrktk
30m         Normal    Killing                           pod/prepull-ds-edxepzai-mpv9h                                       Stopping container prepull-pod-yghfrktk
31m         Normal    Scheduled                         pod/prepull-ds-edxepzai-qjhgt                                       Successfully assigned viya-dev/prepull-ds-edxepzai-qjhgt to ip-100-64-98-232.us-west-2.compute.internal
31m         Normal    Pulled                            pod/prepull-ds-edxepzai-qjhgt                                       Container image "668749497752.dkr.ecr.us-west-2.amazonaws.com/sasviya/viya-4-x64_oci_linux_2-docker/sas-certframe:3.51.0-20240313.1710330811841" already present on machine
31m         Normal    Created                           pod/prepull-ds-edxepzai-qjhgt                                       Created container prepull-pod-yghfrktk
31m         Normal    Started                           pod/prepull-ds-edxepzai-qjhgt                                       Started container prepull-pod-yghfrktk
30m         Normal    Killing                           pod/prepull-ds-edxepzai-qjhgt                                       Stopping container prepull-pod-yghfrktk
31m         Normal    Scheduled                         pod/prepull-ds-ficuxfqn-ckjql                                       Successfully assigned viya-dev/prepull-ds-ficuxfqn-ckjql to ip-100-64-88-54.us-west-2.compute.internal
31m         Normal    Pulled                            pod/prepull-ds-ficuxfqn-ckjql                                       Container image "668749497752.dkr.ecr.us-west-2.amazonaws.com/sasviya/viya-4-x64_oci_linux_2-docker/sas-programming-environment:1.53.31-20240613.1718295947845" already present on machine
31m         Normal    Created                           pod/prepull-ds-ficuxfqn-ckjql                                       Created container prepull-pod-aehggbky
31m         Normal    Started                           pod/prepull-ds-ficuxfqn-ckjql                                       Started container prepull-pod-aehggbky
31m         Normal    Killing                           pod/prepull-ds-ficuxfqn-ckjql                                       Stopping container prepull-pod-aehggbky
31m         Normal    Scheduled                         pod/prepull-ds-ficuxfqn-fwfwf                                       Successfully assigned viya-dev/prepull-ds-ficuxfqn-fwfwf to ip-100-64-103-52.us-west-2.compute.internal
31m         Normal    Pulled                            pod/prepull-ds-ficuxfqn-fwfwf                                       Container image "668749497752.dkr.ecr.us-west-2.amazonaws.com/sasviya/viya-4-x64_oci_linux_2-docker/sas-programming-environment:1.53.31-20240613.1718295947845" already present on machine
31m         Normal    Created                           pod/prepull-ds-ficuxfqn-fwfwf                                       Created container prepull-pod-aehggbky
31m         Normal    Started                           pod/prepull-ds-ficuxfqn-fwfwf                                       Started container prepull-pod-aehggbky
31m         Normal    Killing                           pod/prepull-ds-ficuxfqn-fwfwf                                       Stopping container prepull-pod-aehggbky
31m         Normal    Scheduled                         pod/prepull-ds-ficuxfqn-ggfjv                                       Successfully assigned viya-dev/prepull-ds-ficuxfqn-ggfjv to ip-100-64-125-225.us-west-2.compute.internal
31m         Normal    Pulled                            pod/prepull-ds-ficuxfqn-ggfjv                                       Container image "668749497752.dkr.ecr.us-west-2.amazonaws.com/sasviya/viya-4-x64_oci_linux_2-docker/sas-programming-environment:1.53.31-20240613.1718295947845" already present on machine
31m         Normal    Created                           pod/prepull-ds-ficuxfqn-ggfjv                                       Created container prepull-pod-aehggbky
31m         Normal    Started                           pod/prepull-ds-ficuxfqn-ggfjv                                       Started container prepull-pod-aehggbky
31m         Normal    Killing                           pod/prepull-ds-ficuxfqn-ggfjv                                       Stopping container prepull-pod-aehggbky
31m         Normal    Scheduled                         pod/prepull-ds-ficuxfqn-jm67p                                       Successfully assigned viya-dev/prepull-ds-ficuxfqn-jm67p to ip-100-64-118-98.us-west-2.compute.internal
31m         Normal    Pulled                            pod/prepull-ds-ficuxfqn-jm67p                                       Container image "668749497752.dkr.ecr.us-west-2.amazonaws.com/sasviya/viya-4-x64_oci_linux_2-docker/sas-programming-environment:1.53.31-20240613.1718295947845" already present on machine
31m         Normal    Created                           pod/prepull-ds-ficuxfqn-jm67p                                       Created container prepull-pod-aehggbky
31m         Normal    Started                           pod/prepull-ds-ficuxfqn-jm67p                                       Started container prepull-pod-aehggbky
31m         Normal    Killing                           pod/prepull-ds-ficuxfqn-jm67p                                       Stopping container prepull-pod-aehggbky
31m         Normal    Scheduled                         pod/prepull-ds-ficuxfqn-rfb87                                       Successfully assigned viya-dev/prepull-ds-ficuxfqn-rfb87 to ip-100-64-118-176.us-west-2.compute.internal
31m         Normal    Pulled                            pod/prepull-ds-ficuxfqn-rfb87                                       Container image "668749497752.dkr.ecr.us-west-2.amazonaws.com/sasviya/viya-4-x64_oci_linux_2-docker/sas-programming-environment:1.53.31-20240613.1718295947845" already present on machine
31m         Normal    Created                           pod/prepull-ds-ficuxfqn-rfb87                                       Created container prepull-pod-aehggbky
31m         Normal    Started                           pod/prepull-ds-ficuxfqn-rfb87                                       Started container prepull-pod-aehggbky
31m         Normal    Killing                           pod/prepull-ds-ficuxfqn-rfb87                                       Stopping container prepull-pod-aehggbky
31m         Normal    Scheduled                         pod/prepull-ds-ficuxfqn-vph6q                                       Successfully assigned viya-dev/prepull-ds-ficuxfqn-vph6q to ip-100-64-98-232.us-west-2.compute.internal
31m         Normal    Pulled                            pod/prepull-ds-ficuxfqn-vph6q                                       Container image "668749497752.dkr.ecr.us-west-2.amazonaws.com/sasviya/viya-4-x64_oci_linux_2-docker/sas-programming-environment:1.53.31-20240613.1718295947845" already present on machine
31m         Normal    Created                           pod/prepull-ds-ficuxfqn-vph6q                                       Created container prepull-pod-aehggbky
31m         Normal    Started                           pod/prepull-ds-ficuxfqn-vph6q                                       Started container prepull-pod-aehggbky
31m         Normal    Killing                           pod/prepull-ds-ficuxfqn-vph6q                                       Stopping container prepull-pod-aehggbky
30m         Normal    Scheduled                         pod/prepull-ds-rehhypkr-bnhxr                                       Successfully assigned viya-dev/prepull-ds-rehhypkr-bnhxr to ip-100-64-118-176.us-west-2.compute.internal
30m         Normal    Pulled                            pod/prepull-ds-rehhypkr-bnhxr                                       Container image "668749497752.dkr.ecr.us-west-2.amazonaws.com/sasviya/viya-4-x64_oci_linux_2-docker/sas-config-init:1.21.1-20240305.1709656957059" already present on machine
30m         Normal    Created                           pod/prepull-ds-rehhypkr-bnhxr                                       Created container prepull-pod-lcxbhajv
30m         Normal    Started                           pod/prepull-ds-rehhypkr-bnhxr                                       Started container prepull-pod-lcxbhajv
30m         Normal    Killing                           pod/prepull-ds-rehhypkr-bnhxr                                       Stopping container prepull-pod-lcxbhajv
30m         Normal    Scheduled                         pod/prepull-ds-rehhypkr-jfhz4                                       Successfully assigned viya-dev/prepull-ds-rehhypkr-jfhz4 to ip-100-64-125-225.us-west-2.compute.internal
30m         Normal    Pulled                            pod/prepull-ds-rehhypkr-jfhz4                                       Container image "668749497752.dkr.ecr.us-west-2.amazonaws.com/sasviya/viya-4-x64_oci_linux_2-docker/sas-config-init:1.21.1-20240305.1709656957059" already present on machine
30m         Normal    Created                           pod/prepull-ds-rehhypkr-jfhz4                                       Created container prepull-pod-lcxbhajv
30m         Normal    Started                           pod/prepull-ds-rehhypkr-jfhz4                                       Started container prepull-pod-lcxbhajv
30m         Normal    Killing                           pod/prepull-ds-rehhypkr-jfhz4                                       Stopping container prepull-pod-lcxbhajv
30m         Normal    Scheduled                         pod/prepull-ds-rehhypkr-mqqxm                                       Successfully assigned viya-dev/prepull-ds-rehhypkr-mqqxm to ip-100-64-103-52.us-west-2.compute.internal
30m         Normal    Pulled                            pod/prepull-ds-rehhypkr-mqqxm                                       Container image "668749497752.dkr.ecr.us-west-2.amazonaws.com/sasviya/viya-4-x64_oci_linux_2-docker/sas-config-init:1.21.1-20240305.1709656957059" already present on machine
30m         Normal    Created                           pod/prepull-ds-rehhypkr-mqqxm                                       Created container prepull-pod-lcxbhajv
30m         Normal    Started                           pod/prepull-ds-rehhypkr-mqqxm                                       Started container prepull-pod-lcxbhajv
30m         Normal    Killing                           pod/prepull-ds-rehhypkr-mqqxm                                       Stopping container prepull-pod-lcxbhajv
30m         Normal    Scheduled                         pod/prepull-ds-rehhypkr-p44t5                                       Successfully assigned viya-dev/prepull-ds-rehhypkr-p44t5 to ip-100-64-88-54.us-west-2.compute.internal
30m         Normal    Pulled                            pod/prepull-ds-rehhypkr-p44t5                                       Container image "668749497752.dkr.ecr.us-west-2.amazonaws.com/sasviya/viya-4-x64_oci_linux_2-docker/sas-config-init:1.21.1-20240305.1709656957059" already present on machine
30m         Normal    Created                           pod/prepull-ds-rehhypkr-p44t5                                       Created container prepull-pod-lcxbhajv
30m         Normal    Started                           pod/prepull-ds-rehhypkr-p44t5                                       Started container prepull-pod-lcxbhajv
30m         Normal    Killing                           pod/prepull-ds-rehhypkr-p44t5                                       Stopping container prepull-pod-lcxbhajv
30m         Normal    Scheduled                         pod/prepull-ds-rehhypkr-wtvsp                                       Successfully assigned viya-dev/prepull-ds-rehhypkr-wtvsp to ip-100-64-118-98.us-west-2.compute.internal
30m         Normal    Pulled                            pod/prepull-ds-rehhypkr-wtvsp                                       Container image "668749497752.dkr.ecr.us-west-2.amazonaws.com/sasviya/viya-4-x64_oci_linux_2-docker/sas-config-init:1.21.1-20240305.1709656957059" already present on machine
30m         Normal    Created                           pod/prepull-ds-rehhypkr-wtvsp                                       Created container prepull-pod-lcxbhajv
30m         Normal    Started                           pod/prepull-ds-rehhypkr-wtvsp                                       Started container prepull-pod-lcxbhajv
30m         Normal    Killing                           pod/prepull-ds-rehhypkr-wtvsp                                       Stopping container prepull-pod-lcxbhajv
30m         Normal    Scheduled                         pod/prepull-ds-rehhypkr-xsfs2                                       Successfully assigned viya-dev/prepull-ds-rehhypkr-xsfs2 to ip-100-64-98-232.us-west-2.compute.internal
30m         Normal    Pulled                            pod/prepull-ds-rehhypkr-xsfs2                                       Container image "668749497752.dkr.ecr.us-west-2.amazonaws.com/sasviya/viya-4-x64_oci_linux_2-docker/sas-config-init:1.21.1-20240305.1709656957059" already present on machine
30m         Normal    Created                           pod/prepull-ds-rehhypkr-xsfs2                                       Created container prepull-pod-lcxbhajv
30m         Normal    Started                           pod/prepull-ds-rehhypkr-xsfs2                                       Started container prepull-pod-lcxbhajv
30m         Normal    Killing                           pod/prepull-ds-rehhypkr-xsfs2                                       Stopping container prepull-pod-lcxbhajv
46m         Normal    Scheduled                         pod/sas-arke-6c76b56755-l8n5p                                       Successfully assigned viya-dev/sas-arke-6c76b56755-l8n5p to ip-100-64-79-87.us-west-2.compute.internal
46m         Normal    Pulled                            pod/sas-arke-6c76b56755-l8n5p                                       Container image "668749497752.dkr.ecr.us-west-2.amazonaws.com/sasviya/viya-4-x64_oci_linux_2-docker/sas-start-sequencer:2.11.2-20240307.1709824176855" already present on machine
46m         Normal    Created                           pod/sas-arke-6c76b56755-l8n5p                                       Created container sas-start-sequencer
46m         Normal    Started                           pod/sas-arke-6c76b56755-l8n5p                                       Started container sas-start-sequencer
46m         Normal    Pulled                            pod/sas-arke-6c76b56755-l8n5p                                       Container image "668749497752.dkr.ecr.us-west-2.amazonaws.com/sasviya/viya-4-x64_oci_linux_2-docker/sas-certframe:3.51.0-20240313.1710330811841" already present on machine
46m         Normal    Created                           pod/sas-arke-6c76b56755-l8n5p                                       Created container sas-certframe
46m         Normal    Started                           pod/sas-arke-6c76b56755-l8n5p                                       Started container sas-certframe
46m         Normal    Pulled                            pod/sas-arke-6c76b56755-l8n5p                                       Container image "668749497752.dkr.ecr.us-west-2.amazonaws.com/sasviya/viya-4-x64_oci_linux_2-docker/sas-arke:1.30.5-20240308.1709923133954" already present on machine
46m         Normal    Created                           pod/sas-arke-6c76b56755-l8n5p                                       Created container sas-arke
46m         Normal    Started                           pod/sas-arke-6c76b56755-l8n5p                                       Started container sas-arke
40m         Normal    Killing                           pod/sas-arke-6c76b56755-l8n5p                                       Stopping container sas-arke
40m         Warning   Unhealthy                         pod/sas-arke-6c76b56755-l8n5p                                       Readiness probe errored: rpc error: code = Unknown desc = failed to exec in container: container is in CONTAINER_EXITED state
19m         Normal    Scheduled                         pod/sas-arke-6c76b56755-rfjll                                       Successfully assigned viya-dev/sas-arke-6c76b56755-rfjll to ip-100-64-79-87.us-west-2.compute.internal
19m         Normal    Pulled                            pod/sas-arke-6c76b56755-rfjll                                       Container image "668749497752.dkr.ecr.us-west-2.amazonaws.com/sasviya/viya-4-x64_oci_linux_2-docker/sas-start-sequencer:2.11.2-20240307.1709824176855" already present on machine
19m         Normal    Created                           pod/sas-arke-6c76b56755-rfjll                                       Created container sas-start-sequencer
19m         Normal    Started                           pod/sas-arke-6c76b56755-rfjll                                       Started container sas-start-sequencer
19m         Normal    Pulled                            pod/sas-arke-6c76b56755-rfjll                                       Container image "668749497752.dkr.ecr.us-west-2.amazonaws.com/sasviya/viya-4-x64_oci_linux_2-docker/sas-certframe:3.51.0-20240313.1710330811841" already present on machine
19m         Normal    Created                           pod/sas-arke-6c76b56755-rfjll                                       Created container sas-certframe
19m         Normal    Started                           pod/sas-arke-6c76b56755-rfjll                                       Started container sas-certframe
19m         Normal    Pulled                            pod/sas-arke-6c76b56755-rfjll                                       Container image "668749497752.dkr.ecr.us-west-2.amazonaws.com/sasviya/viya-4-x64_oci_linux_2-docker/sas-arke:1.30.5-20240308.1709923133954" already present on machine
19m         Normal    Created                           pod/sas-arke-6c76b56755-rfjll                                       Created container sas-arke
19m         Normal    Started                           pod/sas-arke-6c76b56755-rfjll                                       Started container sas-arke
12m         Normal    Killing                           pod/sas-arke-6c76b56755-rfjll                                       Stopping container sas-arke
3m41s       Warning   FailedMount                       pod/sas-backup-purge-job-28877775-dlcdz                             MountVolume.SetUp failed for volume "oneagent-bin" : kubernetes.io/csi: mounter.SetUpAt failed to get CSI client: driver name csi.oneagent.dynatrace.com not found in the list of registered CSI drivers
20m         Normal    Scheduled                         pod/sas-batch-server-0109d582-ee46-4197-b6c4-16facadf58ef-16695     Successfully assigned viya-dev/sas-batch-server-0109d582-ee46-4197-b6c4-16facadf58ef-16695 to ip-100-64-88-54.us-west-2.compute.internal
20m         Normal    Pulled                            pod/sas-batch-server-0109d582-ee46-4197-b6c4-16facadf58ef-16695     Container image "668749497752.dkr.ecr.us-west-2.amazonaws.com/sasviya/viya-4-x64_oci_linux_2-docker/sas-certframe:3.51.0-20240313.1710330811841" already present on machine
20m         Normal    Created                           pod/sas-batch-server-0109d582-ee46-4197-b6c4-16facadf58ef-16695     Created container sas-certframe
20m         Normal    Started                           pod/sas-batch-server-0109d582-ee46-4197-b6c4-16facadf58ef-16695     Started container sas-certframe
19m         Normal    Pulled                            pod/sas-batch-server-0109d582-ee46-4197-b6c4-16facadf58ef-16695     Container image "668749497752.dkr.ecr.us-west-2.amazonaws.com/sasviya/viya-4-x64_oci_linux_2-docker/sas-config-init:1.21.1-20240305.1709656957059" already present on machine
19m         Normal    Created                           pod/sas-batch-server-0109d582-ee46-4197-b6c4-16facadf58ef-16695     Created container sas-config-init
19m         Normal    Started                           pod/sas-batch-server-0109d582-ee46-4197-b6c4-16facadf58ef-16695     Started container sas-config-init
19m         Normal    Pulled                            pod/sas-batch-server-0109d582-ee46-4197-b6c4-16facadf58ef-16695     Container image "668749497752.dkr.ecr.us-west-2.amazonaws.com/sasviya/viya-4-x64_oci_linux_2-docker/sas-programming-environment:1.53.31-20240613.1718295947845" already present on machine
19m         Normal    Created                           pod/sas-batch-server-0109d582-ee46-4197-b6c4-16facadf58ef-16695     Created container sas-programming-environment
19m         Normal    Started                           pod/sas-batch-server-0109d582-ee46-4197-b6c4-16facadf58ef-16695     Started container sas-programming-environment
19m         Normal    Pulled                            pod/sas-batch-server-0109d582-ee46-4197-b6c4-16facadf58ef-16695     Container image "668749497752.dkr.ecr.us-west-2.amazonaws.com/sasviya/viya-4-x64_oci_linux_2-docker/sas-process-exporter:1.9.1-20240306.1709732097762" already present on machine
19m         Normal    Created                           pod/sas-batch-server-0109d582-ee46-4197-b6c4-16facadf58ef-16695     Created container sas-process-exporter
19m         Normal    Started                           pod/sas-batch-server-0109d582-ee46-4197-b6c4-16facadf58ef-16695     Started container sas-process-exporter
10m         Normal    Killing                           pod/sas-batch-server-0109d582-ee46-4197-b6c4-16facadf58ef-16695     Stopping container sas-process-exporter
58m         Warning   FailedScheduling                  pod/sas-batch-server-025f128d-cb41-4cf5-8222-6110215a30ba-16659     0/9 nodes are available: 1 Insufficient cpu, 1node(s) had untolerated taint {workload.sas.com/class: cas}, 1 node(s) had untolerated taint {workload.sas.com/class: stateful}, 1 node(s) had untolerated taint {workload.sas.com/class: stateless}, 5 node(s) didn't match Pod's node affinity/selector. preemption: 0/9 nodes are available: 1 No preemption victims found for incoming pod, 8 Preemption is not helpful for scheduling..
59m         Normal    NotTriggerScaleUp                 pod/sas-batch-server-025f128d-cb41-4cf5-8222-6110215a30ba-16659     pod didn't trigger scale-up: 2 node(s) didn't match Pod's node affinity/selector, 1 node(s) had untolerated taint {workload.sas.com/class: stateful}, 1 node(s) had untolerated taint {workload.sas.com/class: stateless}, 1 node(s) had untolerated taint {workload.sas.com/class: cas}
53m         Warning   FailedScheduling                  pod/sas-batch-server-025f128d-cb41-4cf5-8222-6110215a30ba-16659     0/10 nodes are available: 1 Insufficient cpu, 1 node(s) had untolerated taint {workload.sas.com/class: cas}, 1 node(s) had untolerated taint {workload.sas.com/class: stateful}, 1 node(s) had untolerated taint {workload.sas.com/class: stateless}, 6 node(s) didn't match Pod's node affinity/selector. preemption: 0/10 nodes are available: 1 No preemption victims found for incoming pod, 9 Preemption is not helpful for scheduling..
53m         Normal    Scheduled                         pod/sas-batch-server-025f128d-cb41-4cf5-8222-6110215a30ba-16659     Successfully assigned viya-dev/sas-batch-server-025f128d-cb41-4cf5-8222-6110215a30ba-16659 to ip-100-64-125-225.us-west-2.compute.internal
52m         Normal    Pulled                            pod/sas-batch-server-025f128d-cb41-4cf5-8222-6110215a30ba-16659     Container image "668749497752.dkr.ecr.us-west-2.amazonaws.com/sasviya/viya-4-x64_oci_linux_2-docker/sas-certframe:3.51.0-20240313.1710330811841" already present on machine
52m         Normal    Created                           pod/sas-batch-server-025f128d-cb41-4cf5-8222-6110215a30ba-16659     Created container sas-certframe
52m         Normal    Started                           pod/sas-batch-server-025f128d-cb41-4cf5-8222-6110215a30ba-16659     Started container sas-certframe
52m         Normal    Pulled                            pod/sas-batch-server-025f128d-cb41-4cf5-8222-6110215a30ba-16659     Container image "668749497752.dkr.ecr.us-west-2.amazonaws.com/sasviya/viya-4-x64_oci_linux_2-docker/sas-config-init:1.21.1-20240305.1709656957059" already present on machine
52m         Normal    Created                           pod/sas-batch-server-025f128d-cb41-4cf5-8222-6110215a30ba-16659     Created container sas-config-init
52m         Normal    Started                           pod/sas-batch-server-025f128d-cb41-4cf5-8222-6110215a30ba-16659     Started container sas-config-init
52m         Normal    Pulled                            pod/sas-batch-server-025f128d-cb41-4cf5-8222-6110215a30ba-16659     Container image "668749497752.dkr.ecr.us-west-2.amazonaws.com/sasviya/viya-4-x64_oci_linux_2-docker/sas-programming-environment:1.53.31-20240613.1718295947845" already present on machine
52m         Normal    Created                           pod/sas-batch-server-025f128d-cb41-4cf5-8222-6110215a30ba-16659     Created container sas-programming-environment
52m         Normal    Started                           pod/sas-batch-server-025f128d-cb41-4cf5-8222-6110215a30ba-16659     Started container sas-programming-environment
52m         Normal    Pulled                            pod/sas-batch-server-025f128d-cb41-4cf5-8222-6110215a30ba-16659     Container image "668749497752.dkr.ecr.us-west-2.amazonaws.com/sasviya/viya-4-x64_oci_linux_2-docker/sas-process-exporter:1.9.1-20240306.1709732097762" already present on machine
52m         Normal    Created                           pod/sas-batch-server-025f128d-cb41-4cf5-8222-6110215a30ba-16659     Created container sas-process-exporter
52m         Normal    Started                           pod/sas-batch-server-025f128d-cb41-4cf5-8222-6110215a30ba-16659     Started container sas-process-exporter
46m         Normal    Killing                           pod/sas-batch-server-025f128d-cb41-4cf5-8222-6110215a30ba-16659     Stopping container sas-process-exporter
59m         Normal    Scheduled                         pod/sas-batch-server-03c1553a-1c54-49b5-954f-c8a9080cf0c6-16655     Successfully assigned viya-dev/sas-batch-server-03c1553a-1c54-49b5-954f-c8a9080cf0c6-16655 to ip-100-64-125-225.us-west-2.compute.internal
59m         Normal    Pulled                            pod/sas-batch-server-03c1553a-1c54-49b5-954f-c8a9080cf0c6-16655     Container image "668749497752.dkr.ecr.us-west-2.amazonaws.com/sasviya/viya-4-x64_oci_linux_2-docker/sas-certframe:3.51.0-20240313.1710330811841" already present on machine
59m         Normal    Created                           pod/sas-batch-server-03c1553a-1c54-49b5-954f-c8a9080cf0c6-16655     Created container sas-certframe
59m         Normal    Started                           pod/sas-batch-server-03c1553a-1c54-49b5-954f-c8a9080cf0c6-16655     Started container sas-certframe
59m         Normal    Pulled                            pod/sas-batch-server-03c1553a-1c54-49b5-954f-c8a9080cf0c6-16655     Container image "668749497752.dkr.ecr.us-west-2.amazonaws.com/sasviya/viya-4-x64_oci_linux_2-docker/sas-config-init:1.21.1-20240305.1709656957059" already present on machine
59m         Normal    Created                           pod/sas-batch-server-03c1553a-1c54-49b5-954f-c8a9080cf0c6-16655     Created container sas-config-init
59m         Normal    Started                           pod/sas-batch-server-03c1553a-1c54-49b5-954f-c8a9080cf0c6-16655     Started container sas-config-init
59m         Normal    Pulled                            pod/sas-batch-server-03c1553a-1c54-49b5-954f-c8a9080cf0c6-16655     Container image "668749497752.dkr.ecr.us-west-2.amazonaws.com/sasviya/viya-4-x64_oci_linux_2-docker/sas-programming-environment:1.53.31-20240613.1718295947845" already present on machine
59m         Normal    Created                           pod/sas-batch-server-03c1553a-1c54-49b5-954f-c8a9080cf0c6-16655     Created container sas-programming-environment
59m         Normal    Started                           pod/sas-batch-server-03c1553a-1c54-49b5-954f-c8a9080cf0c6-16655     Started container sas-programming-environment
59m         Normal    Pulled                            pod/sas-batch-server-03c1553a-1c54-49b5-954f-c8a9080cf0c6-16655     Container image "668749497752.dkr.ecr.us-west-2.amazonaws.com/sasviya/viya-4-x64_oci_linux_2-docker/sas-process-exporter:1.9.1-20240306.1709732097762" already present on machine
59m         Normal    Created                           pod/sas-batch-server-03c1553a-1c54-49b5-954f-c8a9080cf0c6-16655     Created container sas-process-exporter
59m         Normal    Started                           pod/sas-batch-server-03c1553a-1c54-49b5-954f-c8a9080cf0c6-16655     Started container sas-process-exporter
46m         Normal    Killing                           pod/sas-batch-server-03c1553a-1c54-49b5-954f-c8a9080cf0c6-16655     Stopping container sas-process-exporter
57m         Normal    Scheduled                         pod/sas-batch-server-043abfeb-9ceb-424d-b6ec-a545ffb00a9a-16672     Successfully assigned viya-dev/sas-batch-server-043abfeb-9ceb-424d-b6ec-a545ffb00a9a-16672 to ip-100-64-98-232.us-west-2.compute.internal
57m         Normal    Pulled                            pod/sas-batch-server-043abfeb-9ceb-424d-b6ec-a545ffb00a9a-16672     Container image "668749497752.dkr.ecr.us-west-2.amazonaws.com/sasviya/viya-4-x64_oci_linux_2-docker/sas-certframe:3.51.0-20240313.1710330811841" already present on machine
57m         Normal    Created                           pod/sas-batch-server-043abfeb-9ceb-424d-b6ec-a545ffb00a9a-16672     Created container sas-certframe
57m         Normal    Started                           pod/sas-batch-server-043abfeb-9ceb-424d-b6ec-a545ffb00a9a-16672     Started container sas-certframe
57m         Normal    Pulling                           pod/sas-batch-server-043abfeb-9ceb-424d-b6ec-a545ffb00a9a-16672     Pulling image "668749497752.dkr.ecr.us-west-2.amazonaws.com/sasviya/viya-4-x64_oci_linux_2-docker/sas-config-init:1.21.1-20240305.1709656957059"
56m         Normal    Pulled                            pod/sas-batch-server-043abfeb-9ceb-424d-b6ec-a545ffb00a9a-16672     Successfully pulled image "668749497752.dkr.ecr.us-west-2.amazonaws.com/sasviya/viya-4-x64_oci_linux_2-docker/sas-config-init:1.21.1-20240305.1709656957059" in 25.061s (25.061s including waiting)
56m         Normal    Created                           pod/sas-batch-server-043abfeb-9ceb-424d-b6ec-a545ffb00a9a-16672     Created container sas-config-init
56m         Normal    Started                           pod/sas-batch-server-043abfeb-9ceb-424d-b6ec-a545ffb00a9a-16672     Started container sas-config-init
56m         Normal    Pulling                           pod/sas-batch-server-043abfeb-9ceb-424d-b6ec-a545ffb00a9a-16672     Pulling image "668749497752.dkr.ecr.us-west-2.amazonaws.com/sasviya/viya-4-x64_oci_linux_2-docker/sas-programming-environment:1.53.31-20240613.1718295947845"
56m         Warning   Failed                            pod/sas-batch-server-043abfeb-9ceb-424d-b6ec-a545ffb00a9a-16672     Failed to pull image "668749497752.dkr.ecr.us-west-2.amazonaws.com/sasviya/viya-4-x64_oci_linux_2-docker/sas-programming-environment:1.53.31-20240613.1718295947845": pull QPS exceeded
56m         Warning   Failed                            pod/sas-batch-server-043abfeb-9ceb-424d-b6ec-a545ffb00a9a-16672     Error: ErrImagePull
56m         Normal    Pulled                            pod/sas-batch-server-043abfeb-9ceb-424d-b6ec-a545ffb00a9a-16672     Container image "668749497752.dkr.ecr.us-west-2.amazonaws.com/sasviya/viya-4-x64_oci_linux_2-docker/sas-process-exporter:1.9.1-20240306.1709732097762" already present on machine
56m         Normal    Created                           pod/sas-batch-server-043abfeb-9ceb-424d-b6ec-a545ffb00a9a-16672     Created container sas-process-exporter
56m         Normal    Started                           pod/sas-batch-server-043abfeb-9ceb-424d-b6ec-a545ffb00a9a-16672     Started container sas-process-exporter
56m         Normal    BackOff                           pod/sas-batch-server-043abfeb-9ceb-424d-b6ec-a545ffb00a9a-16672     Back-off pulling image "668749497752.dkr.ecr.us-west-2.amazonaws.com/sasviya/viya-4-x64_oci_linux_2-docker/sas-programming-environment:1.53.31-20240613.1718295947845"
56m         Warning   Failed                            pod/sas-batch-server-043abfeb-9ceb-424d-b6ec-a545ffb00a9a-16672     Error: ImagePullBackOff
55m         Normal    Pulled                            pod/sas-batch-server-043abfeb-9ceb-424d-b6ec-a545ffb00a9a-16672     Successfully pulled image "668749497752.dkr.ecr.us-west-2.amazonaws.com/sasviya/viya-4-x64_oci_linux_2-docker/sas-programming-environment:1.53.31-20240613.1718295947845" in 1m3.041s (1m3.041s including waiting)
55m         Normal    Created                           pod/sas-batch-server-043abfeb-9ceb-424d-b6ec-a545ffb00a9a-16672     Created container sas-programming-environment
55m         Normal    Started                           pod/sas-batch-server-043abfeb-9ceb-424d-b6ec-a545ffb00a9a-16672     Started container sas-programming-environment
46m         Normal    Killing                           pod/sas-batch-server-043abfeb-9ceb-424d-b6ec-a545ffb00a9a-16672     Stopping container sas-process-exporter
20m         Normal    Scheduled                         pod/sas-batch-server-06b72b5b-d082-40e8-ab22-0efdaf1aac82-16689     Successfully assigned viya-dev/sas-batch-server-06b72b5b-d082-40e8-ab22-0efdaf1aac82-16689 to ip-100-64-98-232.us-west-2.compute.internal
20m         Normal    Pulled                            pod/sas-batch-server-06b72b5b-d082-40e8-ab22-0efdaf1aac82-16689     Container image "668749497752.dkr.ecr.us-west-2.amazonaws.com/sasviya/viya-4-x64_oci_linux_2-docker/sas-certframe:3.51.0-20240313.1710330811841" already present on machine
20m         Normal    Created                           pod/sas-batch-server-06b72b5b-d082-40e8-ab22-0efdaf1aac82-16689     Created container sas-certframe
20m         Normal    Started                           pod/sas-batch-server-06b72b5b-d082-40e8-ab22-0efdaf1aac82-16689     Started container sas-certframe
20m         Normal    Pulled                            pod/sas-batch-server-06b72b5b-d082-40e8-ab22-0efdaf1aac82-16689     Container image "668749497752.dkr.ecr.us-west-2.amazonaws.com/sasviya/viya-4-x64_oci_linux_2-docker/sas-config-init:1.21.1-20240305.1709656957059" already present on machine
20m         Normal    Created                           pod/sas-batch-server-06b72b5b-d082-40e8-ab22-0efdaf1aac82-16689     Created container sas-config-init
20m         Normal    Started                           pod/sas-batch-server-06b72b5b-d082-40e8-ab22-0efdaf1aac82-16689     Started container sas-config-init
20m         Normal    Pulled                            pod/sas-batch-server-06b72b5b-d082-40e8-ab22-0efdaf1aac82-16689     Container image "668749497752.dkr.ecr.us-west-2.amazonaws.com/sasviya/viya-4-x64_oci_linux_2-docker/sas-programming-environment:1.53.31-20240613.1718295947845" already present on machine
19m         Normal    Created                           pod/sas-batch-server-06b72b5b-d082-40e8-ab22-0efdaf1aac82-16689     Created container sas-programming-environment
19m         Normal    Started                           pod/sas-batch-server-06b72b5b-d082-40e8-ab22-0efdaf1aac82-16689     Started container sas-programming-environment
19m         Normal    Pulled                            pod/sas-batch-server-06b72b5b-d082-40e8-ab22-0efdaf1aac82-16689     Container image "668749497752.dkr.ecr.us-west-2.amazonaws.com/sasviya/viya-4-x64_oci_linux_2-docker/sas-process-exporter:1.9.1-20240306.1709732097762" already present on machine
19m         Normal    Created                           pod/sas-batch-server-06b72b5b-d082-40e8-ab22-0efdaf1aac82-16689     Created container sas-process-exporter
19m         Normal    Started                           pod/sas-batch-server-06b72b5b-d082-40e8-ab22-0efdaf1aac82-16689     Started container sas-process-exporter
13m         Normal    Killing                           pod/sas-batch-server-06b72b5b-d082-40e8-ab22-0efdaf1aac82-16689     Stopping container sas-process-exporter
19m         Normal    Scheduled                         pod/sas-batch-server-07610f95-553d-4602-b4c1-2b7f30e95fa3-16769     Successfully assigned viya-dev/sas-batch-server-07610f95-553d-4602-b4c1-2b7f30e95fa3-16769 to ip-100-64-125-225.us-west-2.compute.internal
19m         Normal    Pulled                            pod/sas-batch-server-07610f95-553d-4602-b4c1-2b7f30e95fa3-16769     Container image "668749497752.dkr.ecr.us-west-2.amazonaws.com/sasviya/viya-4-x64_oci_linux_2-docker/sas-certframe:3.51.0-20240313.1710330811841" already present on machine
19m         Normal    Created                           pod/sas-batch-server-07610f95-553d-4602-b4c1-2b7f30e95fa3-16769     Created container sas-certframe
19m         Normal    Started                           pod/sas-batch-server-07610f95-553d-4602-b4c1-2b7f30e95fa3-16769     Started container sas-certframe
19m         Normal    Pulled                            pod/sas-batch-server-07610f95-553d-4602-b4c1-2b7f30e95fa3-16769     Container image "668749497752.dkr.ecr.us-west-2.amazonaws.com/sasviya/viya-4-x64_oci_linux_2-docker/sas-config-init:1.21.1-20240305.1709656957059" already present on machine
19m         Normal    Created                           pod/sas-batch-server-07610f95-553d-4602-b4c1-2b7f30e95fa3-16769     Created container sas-config-init
19m         Normal    Started                           pod/sas-batch-server-07610f95-553d-4602-b4c1-2b7f30e95fa3-16769     Started container sas-config-init
19m         Normal    Pulled                            pod/sas-batch-server-07610f95-553d-4602-b4c1-2b7f30e95fa3-16769     Container image "668749497752.dkr.ecr.us-west-2.amazonaws.com/sasviya/viya-4-x64_oci_linux_2-docker/sas-programming-environment:1.53.31-20240613.1718295947845" already present on machine
19m         Normal    Created                           pod/sas-batch-server-07610f95-553d-4602-b4c1-2b7f30e95fa3-16769     Created container sas-programming-environment
19m         Normal    Started                           pod/sas-batch-server-07610f95-553d-4602-b4c1-2b7f30e95fa3-16769     Started container sas-programming-environment
19m         Normal    Pulled                            pod/sas-batch-server-07610f95-553d-4602-b4c1-2b7f30e95fa3-16769     Container image "668749497752.dkr.ecr.us-west-2.amazonaws.com/sasviya/viya-4-x64_oci_linux_2-docker/sas-process-exporter:1.9.1-20240306.1709732097762" already present on machine
19m         Normal    Created                           pod/sas-batch-server-07610f95-553d-4602-b4c1-2b7f30e95fa3-16769     Created container sas-process-exporter
19m         Normal    Started                           pod/sas-batch-server-07610f95-553d-4602-b4c1-2b7f30e95fa3-16769     Started container sas-process-exporter
5m22s       Normal    Killing                           pod/sas-batch-server-07610f95-553d-4602-b4c1-2b7f30e95fa3-16769     Stopping container sas-process-exporter
19m         Normal    Scheduled                         pod/sas-batch-server-0961d0c8-d198-45e9-b54f-84c167a0292d-16717     Successfully assigned viya-dev/sas-batch-server-0961d0c8-d198-45e9-b54f-84c167a0292d-16717 to ip-100-64-118-176.us-west-2.compute.internal
19m         Normal    Pulled                            pod/sas-batch-server-0961d0c8-d198-45e9-b54f-84c167a0292d-16717     Container image "668749497752.dkr.ecr.us-west-2.amazonaws.com/sasviya/viya-4-x64_oci_linux_2-docker/sas-certframe:3.51.0-20240313.1710330811841" already present on machine
19m         Normal    Created                           pod/sas-batch-server-0961d0c8-d198-45e9-b54f-84c167a0292d-16717     Created container sas-certframe
19m         Normal    Started                           pod/sas-batch-server-0961d0c8-d198-45e9-b54f-84c167a0292d-16717     Started container sas-certframe
19m         Normal    Pulled                            pod/sas-batch-server-0961d0c8-d198-45e9-b54f-84c167a0292d-16717     Container image "668749497752.dkr.ecr.us-west-2.amazonaws.com/sasviya/viya-4-x64_oci_linux_2-docker/sas-config-init:1.21.1-20240305.1709656957059" already present on machine
19m         Normal    Created                           pod/sas-batch-server-0961d0c8-d198-45e9-b54f-84c167a0292d-16717     Created container sas-config-init
19m         Normal    Started                           pod/sas-batch-server-0961d0c8-d198-45e9-b54f-84c167a0292d-16717     Started container sas-config-init
19m         Normal    Pulled                            pod/sas-batch-server-0961d0c8-d198-45e9-b54f-84c167a0292d-16717     Container image "668749497752.dkr.ecr.us-west-2.amazonaws.com/sasviya/viya-4-x64_oci_linux_2-docker/sas-programming-environment:1.53.31-20240613.1718295947845" already present on machine
19m         Normal    Created                           pod/sas-batch-server-0961d0c8-d198-45e9-b54f-84c167a0292d-16717     Created container sas-programming-environment
19m         Normal    Started                           pod/sas-batch-server-0961d0c8-d198-45e9-b54f-84c167a0292d-16717     Started container sas-programming-environment
19m         Normal    Pulled                            pod/sas-batch-server-0961d0c8-d198-45e9-b54f-84c167a0292d-16717     Container image "668749497752.dkr.ecr.us-west-2.amazonaws.com/sasviya/viya-4-x64_oci_linux_2-docker/sas-process-exporter:1.9.1-20240306.1709732097762" already present on machine
19m         Normal    Created                           pod/sas-batch-server-0961d0c8-d198-45e9-b54f-84c167a0292d-16717     Created container sas-process-exporter
19m         Normal    Started                           pod/sas-batch-server-0961d0c8-d198-45e9-b54f-84c167a0292d-16717     Started container sas-process-exporter
9m27s       Normal    Killing                           pod/sas-batch-server-0961d0c8-d198-45e9-b54f-84c167a0292d-16717     Stopping container sas-process-exporter
59m         Normal    Killing                           pod/sas-batch-server-09d4ac61-9d8e-42f0-b230-b22e4ea49d34-16606     Stopping container sas-process-exporter
20m         Normal    Scheduled                         pod/sas-batch-server-0a86e68c-bbf1-457d-8f44-4ec390edf34f-16694     Successfully assigned viya-dev/sas-batch-server-0a86e68c-bbf1-457d-8f44-4ec390edf34f-16694 to ip-100-64-118-176.us-west-2.compute.internal
20m         Normal    Pulled                            pod/sas-batch-server-0a86e68c-bbf1-457d-8f44-4ec390edf34f-16694     Container image "668749497752.dkr.ecr.us-west-2.amazonaws.com/sasviya/viya-4-x64_oci_linux_2-docker/sas-certframe:3.51.0-20240313.1710330811841" already present on machine
20m         Normal    Created                           pod/sas-batch-server-0a86e68c-bbf1-457d-8f44-4ec390edf34f-16694     Created container sas-certframe
20m         Normal    Started                           pod/sas-batch-server-0a86e68c-bbf1-457d-8f44-4ec390edf34f-16694     Started container sas-certframe
20m         Normal    Pulled                            pod/sas-batch-server-0a86e68c-bbf1-457d-8f44-4ec390edf34f-16694     Container image "668749497752.dkr.ecr.us-west-2.amazonaws.com/sasviya/viya-4-x64_oci_linux_2-docker/sas-config-init:1.21.1-20240305.1709656957059" already present on machine
20m         Normal    Created                           pod/sas-batch-server-0a86e68c-bbf1-457d-8f44-4ec390edf34f-16694     Created container sas-config-init
20m         Normal    Started                           pod/sas-batch-server-0a86e68c-bbf1-457d-8f44-4ec390edf34f-16694     Started container sas-config-init
19m         Normal    Pulled                            pod/sas-batch-server-0a86e68c-bbf1-457d-8f44-4ec390edf34f-16694     Container image "668749497752.dkr.ecr.us-west-2.amazonaws.com/sasviya/viya-4-x64_oci_linux_2-docker/sas-programming-environment:1.53.31-20240613.1718295947845" already present on machine
19m         Normal    Created                           pod/sas-batch-server-0a86e68c-bbf1-457d-8f44-4ec390edf34f-16694     Created container sas-programming-environment
19m         Normal    Started                           pod/sas-batch-server-0a86e68c-bbf1-457d-8f44-4ec390edf34f-16694     Started container sas-programming-environment
19m         Normal    Pulled                            pod/sas-batch-server-0a86e68c-bbf1-457d-8f44-4ec390edf34f-16694     Container image "668749497752.dkr.ecr.us-west-2.amazonaws.com/sasviya/viya-4-x64_oci_linux_2-docker/sas-process-exporter:1.9.1-20240306.1709732097762" already present on machine
19m         Normal    Created                           pod/sas-batch-server-0a86e68c-bbf1-457d-8f44-4ec390edf34f-16694     Created container sas-process-exporter
19m         Normal    Started                           pod/sas-batch-server-0a86e68c-bbf1-457d-8f44-4ec390edf34f-16694     Started container sas-process-exporter
13m         Normal    Killing                           pod/sas-batch-server-0a86e68c-bbf1-457d-8f44-4ec390edf34f-16694     Stopping container sas-process-exporter
19m         Normal    Scheduled                         pod/sas-batch-server-0ae2138c-023b-4320-a2bf-e48ee9983607-16697     Successfully assigned viya-dev/sas-batch-server-0ae2138c-023b-4320-a2bf-e48ee9983607-16697 to ip-100-64-88-54.us-west-2.compute.internal
19m         Normal    Pulled                            pod/sas-batch-server-0ae2138c-023b-4320-a2bf-e48ee9983607-16697     Container image "668749497752.dkr.ecr.us-west-2.amazonaws.com/sasviya/viya-4-x64_oci_linux_2-docker/sas-certframe:3.51.0-20240313.1710330811841" already present on machine
19m         Normal    Created                           pod/sas-batch-server-0ae2138c-023b-4320-a2bf-e48ee9983607-16697     Created container sas-certframe
19m         Normal    Started                           pod/sas-batch-server-0ae2138c-023b-4320-a2bf-e48ee9983607-16697     Started container sas-certframe
19m         Normal    Pulled                            pod/sas-batch-server-0ae2138c-023b-4320-a2bf-e48ee9983607-16697     Container image "668749497752.dkr.ecr.us-west-2.amazonaws.com/sasviya/viya-4-x64_oci_linux_2-docker/sas-config-init:1.21.1-20240305.1709656957059" already present on machine
19m         Normal    Created                           pod/sas-batch-server-0ae2138c-023b-4320-a2bf-e48ee9983607-16697     Created container sas-config-init
19m         Normal    Started                           pod/sas-batch-server-0ae2138c-023b-4320-a2bf-e48ee9983607-16697     Started container sas-config-init
19m         Normal    Pulled                            pod/sas-batch-server-0ae2138c-023b-4320-a2bf-e48ee9983607-16697     Container image "668749497752.dkr.ecr.us-west-2.amazonaws.com/sasviya/viya-4-x64_oci_linux_2-docker/sas-programming-environment:1.53.31-20240613.1718295947845" already present on machine
19m         Normal    Created                           pod/sas-batch-server-0ae2138c-023b-4320-a2bf-e48ee9983607-16697     Created container sas-programming-environment
19m         Normal    Started                           pod/sas-batch-server-0ae2138c-023b-4320-a2bf-e48ee9983607-16697     Started container sas-programming-environment
19m         Normal    Pulled                            pod/sas-batch-server-0ae2138c-023b-4320-a2bf-e48ee9983607-16697     Container image "668749497752.dkr.ecr.us-west-2.amazonaws.com/sasviya/viya-4-x64_oci_linux_2-docker/sas-process-exporter:1.9.1-20240306.1709732097762" already present on machine
19m         Normal    Created                           pod/sas-batch-server-0ae2138c-023b-4320-a2bf-e48ee9983607-16697     Created container sas-process-exporter
19m         Normal    Started                           pod/sas-batch-server-0ae2138c-023b-4320-a2bf-e48ee9983607-16697     Started container sas-process-exporter
9m36s       Normal    Killing                           pod/sas-batch-server-0ae2138c-023b-4320-a2bf-e48ee9983607-16697     Stopping container sas-process-exporter
13m         Warning   FailedScheduling                  pod/sas-batch-server-0b9001df-ceca-426d-893e-711749084e16-16776     0/10 nodes are available: 1 Insufficient cpu, 1 node(s) had untolerated taint {workload.sas.com/class: cas}, 1 node(s) had untolerated taint {workload.sas.com/class: stateful}, 1 node(s) had untolerated taint {workload.sas.com/class: stateless}, 6 node(s) didn't match Pod's node affinity/selector. preemption: 0/10 nodes are available: 1 No preemption victims found for incoming pod, 9 Preemption is not helpful for scheduling..
12m         Normal    Scheduled                         pod/sas-batch-server-0b9001df-ceca-426d-893e-711749084e16-16776     Successfully assigned viya-dev/sas-batch-server-0b9001df-ceca-426d-893e-711749084e16-16776 to ip-100-64-118-98.us-west-2.compute.internal
12m         Normal    Pulled                            pod/sas-batch-server-0b9001df-ceca-426d-893e-711749084e16-16776     Container image "668749497752.dkr.ecr.us-west-2.amazonaws.com/sasviya/viya-4-x64_oci_linux_2-docker/sas-certframe:3.51.0-20240313.1710330811841" already present on machine
12m         Normal    Created                           pod/sas-batch-server-0b9001df-ceca-426d-893e-711749084e16-16776     Created container sas-certframe
12m         Normal    Started                           pod/sas-batch-server-0b9001df-ceca-426d-893e-711749084e16-16776     Started container sas-certframe
12m         Normal    Pulled                            pod/sas-batch-server-0b9001df-ceca-426d-893e-711749084e16-16776     Container image "668749497752.dkr.ecr.us-west-2.amazonaws.com/sasviya/viya-4-x64_oci_linux_2-docker/sas-config-init:1.21.1-20240305.1709656957059" already present on machine
12m         Normal    Created                           pod/sas-batch-server-0b9001df-ceca-426d-893e-711749084e16-16776     Created container sas-config-init
12m         Normal    Started                           pod/sas-batch-server-0b9001df-ceca-426d-893e-711749084e16-16776     Started container sas-config-init
12m         Normal    Pulled                            pod/sas-batch-server-0b9001df-ceca-426d-893e-711749084e16-16776     Container image "668749497752.dkr.ecr.us-west-2.amazonaws.com/sasviya/viya-4-x64_oci_linux_2-docker/sas-programming-environment:1.53.31-20240613.1718295947845" already present on machine
12m         Normal    Created                           pod/sas-batch-server-0b9001df-ceca-426d-893e-711749084e16-16776     Created container sas-programming-environment
12m         Normal    Started                           pod/sas-batch-server-0b9001df-ceca-426d-893e-711749084e16-16776     Started container sas-programming-environment
12m         Normal    Pulled                            pod/sas-batch-server-0b9001df-ceca-426d-893e-711749084e16-16776     Container image "668749497752.dkr.ecr.us-west-2.amazonaws.com/sasviya/viya-4-x64_oci_linux_2-docker/sas-process-exporter:1.9.1-20240306.1709732097762" already present on machine
12m         Normal    Created                           pod/sas-batch-server-0b9001df-ceca-426d-893e-711749084e16-16776     Created container sas-process-exporter
12m         Normal    Started                           pod/sas-batch-server-0b9001df-ceca-426d-893e-711749084e16-16776     Started container sas-process-exporter
4m11s       Normal    Killing                           pod/sas-batch-server-0b9001df-ceca-426d-893e-711749084e16-16776     Stopping container sas-process-exporter
19m         Normal    Scheduled                         pod/sas-batch-server-0e38d861-828e-421b-97c6-0f5ef896603e-16712     Successfully assigned viya-dev/sas-batch-server-0e38d861-828e-421b-97c6-0f5ef896603e-16712 to ip-100-64-118-98.us-west-2.compute.internal
19m         Normal    Pulled                            pod/sas-batch-server-0e38d861-828e-421b-97c6-0f5ef896603e-16712     Container image "668749497752.dkr.ecr.us-west-2.amazonaws.com/sasviya/viya-4-x64_oci_linux_2-docker/sas-certframe:3.51.0-20240313.1710330811841" already present on machine
19m         Normal    Created                           pod/sas-batch-server-0e38d861-828e-421b-97c6-0f5ef896603e-16712     Created container sas-certframe
19m         Normal    Started                           pod/sas-batch-server-0e38d861-828e-421b-97c6-0f5ef896603e-16712     Started container sas-certframe
19m         Normal    Pulled                            pod/sas-batch-server-0e38d861-828e-421b-97c6-0f5ef896603e-16712     Container image "668749497752.dkr.ecr.us-west-2.amazonaws.com/sasviya/viya-4-x64_oci_linux_2-docker/sas-config-init:1.21.1-20240305.1709656957059" already present on machine
19m         Normal    Created                           pod/sas-batch-server-0e38d861-828e-421b-97c6-0f5ef896603e-16712     Created container sas-config-init
19m         Normal    Started                           pod/sas-batch-server-0e38d861-828e-421b-97c6-0f5ef896603e-16712     Started container sas-config-init
19m         Normal    Pulled                            pod/sas-batch-server-0e38d861-828e-421b-97c6-0f5ef896603e-16712     Container image "668749497752.dkr.ecr.us-west-2.amazonaws.com/sasviya/viya-4-x64_oci_linux_2-docker/sas-programming-environment:1.53.31-20240613.1718295947845" already present on machine
19m         Normal    Created                           pod/sas-batch-server-0e38d861-828e-421b-97c6-0f5ef896603e-16712     Created container sas-programming-environment
19m         Normal    Started                           pod/sas-batch-server-0e38d861-828e-421b-97c6-0f5ef896603e-16712     Started container sas-programming-environment
19m         Normal    Pulled                            pod/sas-batch-server-0e38d861-828e-421b-97c6-0f5ef896603e-16712     Container image "668749497752.dkr.ecr.us-west-2.amazonaws.com/sasviya/viya-4-x64_oci_linux_2-docker/sas-process-exporter:1.9.1-20240306.1709732097762" already present on machine
19m         Normal    Created                           pod/sas-batch-server-0e38d861-828e-421b-97c6-0f5ef896603e-16712     Created container sas-process-exporter
19m         Normal    Started                           pod/sas-batch-server-0e38d861-828e-421b-97c6-0f5ef896603e-16712     Started container sas-process-exporter
11m         Normal    Killing                           pod/sas-batch-server-0e38d861-828e-421b-97c6-0f5ef896603e-16712     Stopping container sas-process-exporter
59m         Normal    Scheduled                         pod/sas-batch-server-0e4fc539-394b-4441-a7ff-4bfc814babc4-16650     Successfully assigned viya-dev/sas-batch-server-0e4fc539-394b-4441-a7ff-4bfc814babc4-16650 to ip-100-64-103-52.us-west-2.compute.internal
59m         Normal    Pulled                            pod/sas-batch-server-0e4fc539-394b-4441-a7ff-4bfc814babc4-16650     Container image "668749497752.dkr.ecr.us-west-2.amazonaws.com/sasviya/viya-4-x64_oci_linux_2-docker/sas-certframe:3.51.0-20240313.1710330811841" already present on machine
59m         Normal    Created                           pod/sas-batch-server-0e4fc539-394b-4441-a7ff-4bfc814babc4-16650     Created container sas-certframe
59m         Normal    Started                           pod/sas-batch-server-0e4fc539-394b-4441-a7ff-4bfc814babc4-16650     Started container sas-certframe
59m         Normal    Pulled                            pod/sas-batch-server-0e4fc539-394b-4441-a7ff-4bfc814babc4-16650     Container image "668749497752.dkr.ecr.us-west-2.amazonaws.com/sasviya/viya-4-x64_oci_linux_2-docker/sas-config-init:1.21.1-20240305.1709656957059" already present on machine
59m         Normal    Created                           pod/sas-batch-server-0e4fc539-394b-4441-a7ff-4bfc814babc4-16650     Created container sas-config-init
59m         Normal    Started                           pod/sas-batch-server-0e4fc539-394b-4441-a7ff-4bfc814babc4-16650     Started container sas-config-init
59m         Normal    Pulled                            pod/sas-batch-server-0e4fc539-394b-4441-a7ff-4bfc814babc4-16650     Container image "668749497752.dkr.ecr.us-west-2.amazonaws.com/sasviya/viya-4-x64_oci_linux_2-docker/sas-programming-environment:1.53.31-20240613.1718295947845" already present on machine
59m         Normal    Created                           pod/sas-batch-server-0e4fc539-394b-4441-a7ff-4bfc814babc4-16650     Created container sas-programming-environment
59m         Normal    Started                           pod/sas-batch-server-0e4fc539-394b-4441-a7ff-4bfc814babc4-16650     Started container sas-programming-environment
59m         Normal    Pulled                            pod/sas-batch-server-0e4fc539-394b-4441-a7ff-4bfc814babc4-16650     Container image "668749497752.dkr.ecr.us-west-2.amazonaws.com/sasviya/viya-4-x64_oci_linux_2-docker/sas-process-exporter:1.9.1-20240306.1709732097762" already present on machine
59m         Normal    Created                           pod/sas-batch-server-0e4fc539-394b-4441-a7ff-4bfc814babc4-16650     Created container sas-process-exporter
59m         Normal    Started                           pod/sas-batch-server-0e4fc539-394b-4441-a7ff-4bfc814babc4-16650     Started container sas-process-exporter
48m         Normal    Killing                           pod/sas-batch-server-0e4fc539-394b-4441-a7ff-4bfc814babc4-16650     Stopping container sas-process-exporter
19m         Normal    Scheduled                         pod/sas-batch-server-0ef7e794-70a1-484f-8ec8-44c2c07679ca-16723     Successfully assigned viya-dev/sas-batch-server-0ef7e794-70a1-484f-8ec8-44c2c07679ca-16723 to ip-100-64-118-176.us-west-2.compute.internal
19m         Normal    Pulled                            pod/sas-batch-server-0ef7e794-70a1-484f-8ec8-44c2c07679ca-16723     Container image "668749497752.dkr.ecr.us-west-2.amazonaws.com/sasviya/viya-4-x64_oci_linux_2-docker/sas-certframe:3.51.0-20240313.1710330811841" already present on machine
19m         Normal    Created                           pod/sas-batch-server-0ef7e794-70a1-484f-8ec8-44c2c07679ca-16723     Created container sas-certframe
19m         Normal    Started                           pod/sas-batch-server-0ef7e794-70a1-484f-8ec8-44c2c07679ca-16723     Started container sas-certframe
19m         Normal    Pulled                            pod/sas-batch-server-0ef7e794-70a1-484f-8ec8-44c2c07679ca-16723     Container image "668749497752.dkr.ecr.us-west-2.amazonaws.com/sasviya/viya-4-x64_oci_linux_2-docker/sas-config-init:1.21.1-20240305.1709656957059" already present on machine
19m         Normal    Created                           pod/sas-batch-server-0ef7e794-70a1-484f-8ec8-44c2c07679ca-16723     Created container sas-config-init
19m         Normal    Started                           pod/sas-batch-server-0ef7e794-70a1-484f-8ec8-44c2c07679ca-16723     Started container sas-config-init
19m         Normal    Pulled                            pod/sas-batch-server-0ef7e794-70a1-484f-8ec8-44c2c07679ca-16723     Container image "668749497752.dkr.ecr.us-west-2.amazonaws.com/sasviya/viya-4-x64_oci_linux_2-docker/sas-programming-environment:1.53.31-20240613.1718295947845" already present on machine
19m         Normal    Created                           pod/sas-batch-server-0ef7e794-70a1-484f-8ec8-44c2c07679ca-16723     Created container sas-programming-environment
19m         Normal    Started                           pod/sas-batch-server-0ef7e794-70a1-484f-8ec8-44c2c07679ca-16723     Started container sas-programming-environment
19m         Normal    Pulled                            pod/sas-batch-server-0ef7e794-70a1-484f-8ec8-44c2c07679ca-16723     Container image "668749497752.dkr.ecr.us-west-2.amazonaws.com/sasviya/viya-4-x64_oci_linux_2-docker/sas-process-exporter:1.9.1-20240306.1709732097762" already present on machine
19m         Normal    Created                           pod/sas-batch-server-0ef7e794-70a1-484f-8ec8-44c2c07679ca-16723     Created container sas-process-exporter
19m         Normal    Started                           pod/sas-batch-server-0ef7e794-70a1-484f-8ec8-44c2c07679ca-16723     Started container sas-process-exporter
8m42s       Normal    Killing                           pod/sas-batch-server-0ef7e794-70a1-484f-8ec8-44c2c07679ca-16723     Stopping container sas-process-exporter
59m         Normal    Scheduled                         pod/sas-batch-server-1065e5fc-35e8-4322-8326-844e2792acb5-16661     Successfully assigned viya-dev/sas-batch-server-1065e5fc-35e8-4322-8326-844e2792acb5-16661 to ip-100-64-103-52.us-west-2.compute.internal
59m         Normal    Pulled                            pod/sas-batch-server-1065e5fc-35e8-4322-8326-844e2792acb5-16661     Container image "668749497752.dkr.ecr.us-west-2.amazonaws.com/sasviya/viya-4-x64_oci_linux_2-docker/sas-certframe:3.51.0-20240313.1710330811841" already present on machine
59m         Normal    Created                           pod/sas-batch-server-1065e5fc-35e8-4322-8326-844e2792acb5-16661     Created container sas-certframe
59m         Normal    Started                           pod/sas-batch-server-1065e5fc-35e8-4322-8326-844e2792acb5-16661     Started container sas-certframe
59m         Normal    Pulled                            pod/sas-batch-server-1065e5fc-35e8-4322-8326-844e2792acb5-16661     Container image "668749497752.dkr.ecr.us-west-2.amazonaws.com/sasviya/viya-4-x64_oci_linux_2-docker/sas-config-init:1.21.1-20240305.1709656957059" already present on machine
59m         Normal    Created                           pod/sas-batch-server-1065e5fc-35e8-4322-8326-844e2792acb5-16661     Created container sas-config-init
59m         Normal    Started                           pod/sas-batch-server-1065e5fc-35e8-4322-8326-844e2792acb5-16661     Started container sas-config-init
59m         Normal    Pulled                            pod/sas-batch-server-1065e5fc-35e8-4322-8326-844e2792acb5-16661     Container image "668749497752.dkr.ecr.us-west-2.amazonaws.com/sasviya/viya-4-x64_oci_linux_2-docker/sas-programming-environment:1.53.31-20240613.1718295947845" already present on machine
59m         Normal    Created                           pod/sas-batch-server-1065e5fc-35e8-4322-8326-844e2792acb5-16661     Created container sas-programming-environment
59m         Normal    Started                           pod/sas-batch-server-1065e5fc-35e8-4322-8326-844e2792acb5-16661     Started container sas-programming-environment
59m         Normal    Pulled                            pod/sas-batch-server-1065e5fc-35e8-4322-8326-844e2792acb5-16661     Container image "668749497752.dkr.ecr.us-west-2.amazonaws.com/sasviya/viya-4-x64_oci_linux_2-docker/sas-process-exporter:1.9.1-20240306.1709732097762" already present on machine
59m         Normal    Created                           pod/sas-batch-server-1065e5fc-35e8-4322-8326-844e2792acb5-16661     Created container sas-process-exporter
59m         Normal    Started                           pod/sas-batch-server-1065e5fc-35e8-4322-8326-844e2792acb5-16661     Started container sas-process-exporter
47m         Normal    Killing                           pod/sas-batch-server-1065e5fc-35e8-4322-8326-844e2792acb5-16661     Stopping container sas-process-exporter
59m         Normal    Killing                           pod/sas-batch-server-10a09205-20ec-45ec-9a6e-61959c8b6daf-16588     Stopping container sas-process-exporter
59m         Normal    Scheduled                         pod/sas-batch-server-122ad60f-3196-4c18-8cf1-6b42946b689e-16645     Successfully assigned viya-dev/sas-batch-server-122ad60f-3196-4c18-8cf1-6b42946b689e-16645 to ip-100-64-125-225.us-west-2.compute.internal
59m         Normal    Pulled                            pod/sas-batch-server-122ad60f-3196-4c18-8cf1-6b42946b689e-16645     Container image "668749497752.dkr.ecr.us-west-2.amazonaws.com/sasviya/viya-4-x64_oci_linux_2-docker/sas-certframe:3.51.0-20240313.1710330811841" already present on machine
59m         Normal    Created                           pod/sas-batch-server-122ad60f-3196-4c18-8cf1-6b42946b689e-16645     Created container sas-certframe
59m         Normal    Started                           pod/sas-batch-server-122ad60f-3196-4c18-8cf1-6b42946b689e-16645     Started container sas-certframe
59m         Normal    Pulled                            pod/sas-batch-server-122ad60f-3196-4c18-8cf1-6b42946b689e-16645     Container image "668749497752.dkr.ecr.us-west-2.amazonaws.com/sasviya/viya-4-x64_oci_linux_2-docker/sas-config-init:1.21.1-20240305.1709656957059" already present on machine
59m         Normal    Created                           pod/sas-batch-server-122ad60f-3196-4c18-8cf1-6b42946b689e-16645     Created container sas-config-init
59m         Normal    Started                           pod/sas-batch-server-122ad60f-3196-4c18-8cf1-6b42946b689e-16645     Started container sas-config-init
59m         Normal    Pulled                            pod/sas-batch-server-122ad60f-3196-4c18-8cf1-6b42946b689e-16645     Container image "668749497752.dkr.ecr.us-west-2.amazonaws.com/sasviya/viya-4-x64_oci_linux_2-docker/sas-programming-environment:1.53.31-20240613.1718295947845" already present on machine
59m         Normal    Created                           pod/sas-batch-server-122ad60f-3196-4c18-8cf1-6b42946b689e-16645     Created container sas-programming-environment
59m         Normal    Started                           pod/sas-batch-server-122ad60f-3196-4c18-8cf1-6b42946b689e-16645     Started container sas-programming-environment
59m         Normal    Pulled                            pod/sas-batch-server-122ad60f-3196-4c18-8cf1-6b42946b689e-16645     Container image "668749497752.dkr.ecr.us-west-2.amazonaws.com/sasviya/viya-4-x64_oci_linux_2-docker/sas-process-exporter:1.9.1-20240306.1709732097762" already present on machine
59m         Normal    Created                           pod/sas-batch-server-122ad60f-3196-4c18-8cf1-6b42946b689e-16645     Created container sas-process-exporter
59m         Normal    Started                           pod/sas-batch-server-122ad60f-3196-4c18-8cf1-6b42946b689e-16645     Started container sas-process-exporter
47m         Normal    Killing                           pod/sas-batch-server-122ad60f-3196-4c18-8cf1-6b42946b689e-16645     Stopping container sas-process-exporter
59m         Normal    Scheduled                         pod/sas-batch-server-15069a1c-5805-49aa-89cc-e3e7cfeaf9fa-16620     Successfully assigned viya-dev/sas-batch-server-15069a1c-5805-49aa-89cc-e3e7cfeaf9fa-16620 to ip-100-64-118-98.us-west-2.compute.internal
59m         Normal    Pulled                            pod/sas-batch-server-15069a1c-5805-49aa-89cc-e3e7cfeaf9fa-16620     Container image "668749497752.dkr.ecr.us-west-2.amazonaws.com/sasviya/viya-4-x64_oci_linux_2-docker/sas-certframe:3.51.0-20240313.1710330811841" already present on machine
59m         Normal    Created                           pod/sas-batch-server-15069a1c-5805-49aa-89cc-e3e7cfeaf9fa-16620     Created container sas-certframe
59m         Normal    Started                           pod/sas-batch-server-15069a1c-5805-49aa-89cc-e3e7cfeaf9fa-16620     Started container sas-certframe
59m         Normal    Pulled                            pod/sas-batch-server-15069a1c-5805-49aa-89cc-e3e7cfeaf9fa-16620     Container image "668749497752.dkr.ecr.us-west-2.amazonaws.com/sasviya/viya-4-x64_oci_linux_2-docker/sas-config-init:1.21.1-20240305.1709656957059" already present on machine
59m         Normal    Created                           pod/sas-batch-server-15069a1c-5805-49aa-89cc-e3e7cfeaf9fa-16620     Created container sas-config-init
59m         Normal    Started                           pod/sas-batch-server-15069a1c-5805-49aa-89cc-e3e7cfeaf9fa-16620     Started container sas-config-init
59m         Normal    Pulled                            pod/sas-batch-server-15069a1c-5805-49aa-89cc-e3e7cfeaf9fa-16620     Container image "668749497752.dkr.ecr.us-west-2.amazonaws.com/sasviya/viya-4-x64_oci_linux_2-docker/sas-programming-environment:1.53.31-20240613.1718295947845" already present on machine
59m         Normal    Created                           pod/sas-batch-server-15069a1c-5805-49aa-89cc-e3e7cfeaf9fa-16620     Created container sas-programming-environment
59m         Normal    Started                           pod/sas-batch-server-15069a1c-5805-49aa-89cc-e3e7cfeaf9fa-16620     Started container sas-programming-environment
59m         Normal    Pulled                            pod/sas-batch-server-15069a1c-5805-49aa-89cc-e3e7cfeaf9fa-16620     Container image "668749497752.dkr.ecr.us-west-2.amazonaws.com/sasviya/viya-4-x64_oci_linux_2-docker/sas-process-exporter:1.9.1-20240306.1709732097762" already present on machine
59m         Normal    Created                           pod/sas-batch-server-15069a1c-5805-49aa-89cc-e3e7cfeaf9fa-16620     Created container sas-process-exporter
59m         Normal    Started                           pod/sas-batch-server-15069a1c-5805-49aa-89cc-e3e7cfeaf9fa-16620     Started container sas-process-exporter
47m         Normal    Killing                           pod/sas-batch-server-15069a1c-5805-49aa-89cc-e3e7cfeaf9fa-16620     Stopping container sas-process-exporter
59m         Normal    Scheduled                         pod/sas-batch-server-15246ea0-728a-4353-a02e-2dc756c1deba-16644     Successfully assigned viya-dev/sas-batch-server-15246ea0-728a-4353-a02e-2dc756c1deba-16644 to ip-100-64-103-52.us-west-2.compute.internal
59m         Normal    Pulled                            pod/sas-batch-server-15246ea0-728a-4353-a02e-2dc756c1deba-16644     Container image "668749497752.dkr.ecr.us-west-2.amazonaws.com/sasviya/viya-4-x64_oci_linux_2-docker/sas-certframe:3.51.0-20240313.1710330811841" already present on machine
59m         Normal    Created                           pod/sas-batch-server-15246ea0-728a-4353-a02e-2dc756c1deba-16644     Created container sas-certframe
59m         Normal    Started                           pod/sas-batch-server-15246ea0-728a-4353-a02e-2dc756c1deba-16644     Started container sas-certframe
59m         Normal    Pulled                            pod/sas-batch-server-15246ea0-728a-4353-a02e-2dc756c1deba-16644     Container image "668749497752.dkr.ecr.us-west-2.amazonaws.com/sasviya/viya-4-x64_oci_linux_2-docker/sas-config-init:1.21.1-20240305.1709656957059" already present on machine
59m         Normal    Created                           pod/sas-batch-server-15246ea0-728a-4353-a02e-2dc756c1deba-16644     Created container sas-config-init
59m         Normal    Started                           pod/sas-batch-server-15246ea0-728a-4353-a02e-2dc756c1deba-16644     Started container sas-config-init
59m         Normal    Pulled                            pod/sas-batch-server-15246ea0-728a-4353-a02e-2dc756c1deba-16644     Container image "668749497752.dkr.ecr.us-west-2.amazonaws.com/sasviya/viya-4-x64_oci_linux_2-docker/sas-programming-environment:1.53.31-20240613.1718295947845" already present on machine
59m         Normal    Created                           pod/sas-batch-server-15246ea0-728a-4353-a02e-2dc756c1deba-16644     Created container sas-programming-environment
59m         Normal    Started                           pod/sas-batch-server-15246ea0-728a-4353-a02e-2dc756c1deba-16644     Started container sas-programming-environment
59m         Normal    Pulled                            pod/sas-batch-server-15246ea0-728a-4353-a02e-2dc756c1deba-16644     Container image "668749497752.dkr.ecr.us-west-2.amazonaws.com/sasviya/viya-4-x64_oci_linux_2-docker/sas-process-exporter:1.9.1-20240306.1709732097762" already present on machine
59m         Normal    Created                           pod/sas-batch-server-15246ea0-728a-4353-a02e-2dc756c1deba-16644     Created container sas-process-exporter
59m         Normal    Started                           pod/sas-batch-server-15246ea0-728a-4353-a02e-2dc756c1deba-16644     Started container sas-process-exporter
47m         Normal    Killing                           pod/sas-batch-server-15246ea0-728a-4353-a02e-2dc756c1deba-16644     Stopping container sas-process-exporter
19m         Normal    Scheduled                         pod/sas-batch-server-155cca27-ecb5-4fdf-b289-b5f76def1838-16701     Successfully assigned viya-dev/sas-batch-server-155cca27-ecb5-4fdf-b289-b5f76def1838-16701 to ip-100-64-88-54.us-west-2.compute.internal
19m         Normal    Pulled                            pod/sas-batch-server-155cca27-ecb5-4fdf-b289-b5f76def1838-16701     Container image "668749497752.dkr.ecr.us-west-2.amazonaws.com/sasviya/viya-4-x64_oci_linux_2-docker/sas-certframe:3.51.0-20240313.1710330811841" already present on machine
19m         Normal    Created                           pod/sas-batch-server-155cca27-ecb5-4fdf-b289-b5f76def1838-16701     Created container sas-certframe
19m         Normal    Started                           pod/sas-batch-server-155cca27-ecb5-4fdf-b289-b5f76def1838-16701     Started container sas-certframe
19m         Normal    Pulled                            pod/sas-batch-server-155cca27-ecb5-4fdf-b289-b5f76def1838-16701     Container image "668749497752.dkr.ecr.us-west-2.amazonaws.com/sasviya/viya-4-x64_oci_linux_2-docker/sas-config-init:1.21.1-20240305.1709656957059" already present on machine
19m         Normal    Created                           pod/sas-batch-server-155cca27-ecb5-4fdf-b289-b5f76def1838-16701     Created container sas-config-init
19m         Normal    Started                           pod/sas-batch-server-155cca27-ecb5-4fdf-b289-b5f76def1838-16701     Started container sas-config-init
19m         Normal    Pulled                            pod/sas-batch-server-155cca27-ecb5-4fdf-b289-b5f76def1838-16701     Container image "668749497752.dkr.ecr.us-west-2.amazonaws.com/sasviya/viya-4-x64_oci_linux_2-docker/sas-programming-environment:1.53.31-20240613.1718295947845" already present on machine
19m         Normal    Created                           pod/sas-batch-server-155cca27-ecb5-4fdf-b289-b5f76def1838-16701     Created container sas-programming-environment
19m         Normal    Started                           pod/sas-batch-server-155cca27-ecb5-4fdf-b289-b5f76def1838-16701     Started container sas-programming-environment
19m         Normal    Pulled                            pod/sas-batch-server-155cca27-ecb5-4fdf-b289-b5f76def1838-16701     Container image "668749497752.dkr.ecr.us-west-2.amazonaws.com/sasviya/viya-4-x64_oci_linux_2-docker/sas-process-exporter:1.9.1-20240306.1709732097762" already present on machine
19m         Normal    Created                           pod/sas-batch-server-155cca27-ecb5-4fdf-b289-b5f76def1838-16701     Created container sas-process-exporter
19m         Normal    Started                           pod/sas-batch-server-155cca27-ecb5-4fdf-b289-b5f76def1838-16701     Started container sas-process-exporter
10m         Normal    Killing                           pod/sas-batch-server-155cca27-ecb5-4fdf-b289-b5f76def1838-16701     Stopping container sas-process-exporter
59m         Normal    Scheduled                         pod/sas-batch-server-1573eeed-5659-47ed-9e6b-53b741b5c46e-16621     Successfully assigned viya-dev/sas-batch-server-1573eeed-5659-47ed-9e6b-53b741b5c46e-16621 to ip-100-64-103-52.us-west-2.compute.internal
59m         Normal    Pulled                            pod/sas-batch-server-1573eeed-5659-47ed-9e6b-53b741b5c46e-16621     Container image "668749497752.dkr.ecr.us-west-2.amazonaws.com/sasviya/viya-4-x64_oci_linux_2-docker/sas-certframe:3.51.0-20240313.1710330811841" already present on machine
59m         Normal    Created                           pod/sas-batch-server-1573eeed-5659-47ed-9e6b-53b741b5c46e-16621     Created container sas-certframe
59m         Normal    Started                           pod/sas-batch-server-1573eeed-5659-47ed-9e6b-53b741b5c46e-16621     Started container sas-certframe
59m         Normal    Pulled                            pod/sas-batch-server-1573eeed-5659-47ed-9e6b-53b741b5c46e-16621     Container image "668749497752.dkr.ecr.us-west-2.amazonaws.com/sasviya/viya-4-x64_oci_linux_2-docker/sas-config-init:1.21.1-20240305.1709656957059" already present on machine
59m         Normal    Created                           pod/sas-batch-server-1573eeed-5659-47ed-9e6b-53b741b5c46e-16621     Created container sas-config-init
59m         Normal    Started                           pod/sas-batch-server-1573eeed-5659-47ed-9e6b-53b741b5c46e-16621     Started container sas-config-init
59m         Normal    Pulled                            pod/sas-batch-server-1573eeed-5659-47ed-9e6b-53b741b5c46e-16621     Container image "668749497752.dkr.ecr.us-west-2.amazonaws.com/sasviya/viya-4-x64_oci_linux_2-docker/sas-programming-environment:1.53.31-20240613.1718295947845" already present on machine
59m         Normal    Created                           pod/sas-batch-server-1573eeed-5659-47ed-9e6b-53b741b5c46e-16621     Created container sas-programming-environment
59m         Normal    Started                           pod/sas-batch-server-1573eeed-5659-47ed-9e6b-53b741b5c46e-16621     Started container sas-programming-environment
59m         Normal    Pulled                            pod/sas-batch-server-1573eeed-5659-47ed-9e6b-53b741b5c46e-16621     Container image "668749497752.dkr.ecr.us-west-2.amazonaws.com/sasviya/viya-4-x64_oci_linux_2-docker/sas-process-exporter:1.9.1-20240306.1709732097762" already present on machine
59m         Normal    Created                           pod/sas-batch-server-1573eeed-5659-47ed-9e6b-53b741b5c46e-16621     Created container sas-process-exporter
59m         Normal    Started                           pod/sas-batch-server-1573eeed-5659-47ed-9e6b-53b741b5c46e-16621     Started container sas-process-exporter
48m         Normal    Killing                           pod/sas-batch-server-1573eeed-5659-47ed-9e6b-53b741b5c46e-16621     Stopping container sas-process-exporter
59m         Normal    Scheduled                         pod/sas-batch-server-17b44001-6b9d-4c07-a943-b3ba49925cd5-16638     Successfully assigned viya-dev/sas-batch-server-17b44001-6b9d-4c07-a943-b3ba49925cd5-16638 to ip-100-64-118-176.us-west-2.compute.internal
59m         Normal    Pulled                            pod/sas-batch-server-17b44001-6b9d-4c07-a943-b3ba49925cd5-16638     Container image "668749497752.dkr.ecr.us-west-2.amazonaws.com/sasviya/viya-4-x64_oci_linux_2-docker/sas-certframe:3.51.0-20240313.1710330811841" already present on machine
59m         Normal    Created                           pod/sas-batch-server-17b44001-6b9d-4c07-a943-b3ba49925cd5-16638     Created container sas-certframe
59m         Normal    Started                           pod/sas-batch-server-17b44001-6b9d-4c07-a943-b3ba49925cd5-16638     Started container sas-certframe
59m         Normal    Pulled                            pod/sas-batch-server-17b44001-6b9d-4c07-a943-b3ba49925cd5-16638     Container image "668749497752.dkr.ecr.us-west-2.amazonaws.com/sasviya/viya-4-x64_oci_linux_2-docker/sas-config-init:1.21.1-20240305.1709656957059" already present on machine
59m         Normal    Created                           pod/sas-batch-server-17b44001-6b9d-4c07-a943-b3ba49925cd5-16638     Created container sas-config-init
59m         Normal    Started                           pod/sas-batch-server-17b44001-6b9d-4c07-a943-b3ba49925cd5-16638     Started container sas-config-init
59m         Normal    Pulled                            pod/sas-batch-server-17b44001-6b9d-4c07-a943-b3ba49925cd5-16638     Container image "668749497752.dkr.ecr.us-west-2.amazonaws.com/sasviya/viya-4-x64_oci_linux_2-docker/sas-programming-environment:1.53.31-20240613.1718295947845" already present on machine
59m         Normal    Created                           pod/sas-batch-server-17b44001-6b9d-4c07-a943-b3ba49925cd5-16638     Created container sas-programming-environment
59m         Normal    Started                           pod/sas-batch-server-17b44001-6b9d-4c07-a943-b3ba49925cd5-16638     Started container sas-programming-environment
59m         Normal    Pulled                            pod/sas-batch-server-17b44001-6b9d-4c07-a943-b3ba49925cd5-16638     Container image "668749497752.dkr.ecr.us-west-2.amazonaws.com/sasviya/viya-4-x64_oci_linux_2-docker/sas-process-exporter:1.9.1-20240306.1709732097762" already present on machine
59m         Normal    Created                           pod/sas-batch-server-17b44001-6b9d-4c07-a943-b3ba49925cd5-16638     Created container sas-process-exporter
59m         Normal    Started                           pod/sas-batch-server-17b44001-6b9d-4c07-a943-b3ba49925cd5-16638     Started container sas-process-exporter
48m         Normal    Killing                           pod/sas-batch-server-17b44001-6b9d-4c07-a943-b3ba49925cd5-16638     Stopping container sas-process-exporter
19m         Normal    Scheduled                         pod/sas-batch-server-1a19aa4e-714b-41b4-89f1-6c6dffb7728c-16735     Successfully assigned viya-dev/sas-batch-server-1a19aa4e-714b-41b4-89f1-6c6dffb7728c-16735 to ip-100-64-103-52.us-west-2.compute.internal
19m         Normal    Pulled                            pod/sas-batch-server-1a19aa4e-714b-41b4-89f1-6c6dffb7728c-16735     Container image "668749497752.dkr.ecr.us-west-2.amazonaws.com/sasviya/viya-4-x64_oci_linux_2-docker/sas-certframe:3.51.0-20240313.1710330811841" already present on machine
19m         Normal    Created                           pod/sas-batch-server-1a19aa4e-714b-41b4-89f1-6c6dffb7728c-16735     Created container sas-certframe
19m         Normal    Started                           pod/sas-batch-server-1a19aa4e-714b-41b4-89f1-6c6dffb7728c-16735     Started container sas-certframe
19m         Normal    Pulled                            pod/sas-batch-server-1a19aa4e-714b-41b4-89f1-6c6dffb7728c-16735     Container image "668749497752.dkr.ecr.us-west-2.amazonaws.com/sasviya/viya-4-x64_oci_linux_2-docker/sas-config-init:1.21.1-20240305.1709656957059" already present on machine
19m         Normal    Created                           pod/sas-batch-server-1a19aa4e-714b-41b4-89f1-6c6dffb7728c-16735     Created container sas-config-init
19m         Normal    Started                           pod/sas-batch-server-1a19aa4e-714b-41b4-89f1-6c6dffb7728c-16735     Started container sas-config-init
19m         Normal    Pulled                            pod/sas-batch-server-1a19aa4e-714b-41b4-89f1-6c6dffb7728c-16735     Container image "668749497752.dkr.ecr.us-west-2.amazonaws.com/sasviya/viya-4-x64_oci_linux_2-docker/sas-programming-environment:1.53.31-20240613.1718295947845" already present on machine
19m         Normal    Created                           pod/sas-batch-server-1a19aa4e-714b-41b4-89f1-6c6dffb7728c-16735     Created container sas-programming-environment
19m         Normal    Started                           pod/sas-batch-server-1a19aa4e-714b-41b4-89f1-6c6dffb7728c-16735     Started container sas-programming-environment
19m         Normal    Pulled                            pod/sas-batch-server-1a19aa4e-714b-41b4-89f1-6c6dffb7728c-16735     Container image "668749497752.dkr.ecr.us-west-2.amazonaws.com/sasviya/viya-4-x64_oci_linux_2-docker/sas-process-exporter:1.9.1-20240306.1709732097762" already present on machine
19m         Normal    Created                           pod/sas-batch-server-1a19aa4e-714b-41b4-89f1-6c6dffb7728c-16735     Created container sas-process-exporter
19m         Normal    Started                           pod/sas-batch-server-1a19aa4e-714b-41b4-89f1-6c6dffb7728c-16735     Started container sas-process-exporter
4m36s       Normal    Killing                           pod/sas-batch-server-1a19aa4e-714b-41b4-89f1-6c6dffb7728c-16735     Stopping container sas-process-exporter
20m         Normal    Scheduled                         pod/sas-batch-server-1b533658-236d-4dc9-9156-7e3e7be7cb79-16688     Successfully assigned viya-dev/sas-batch-server-1b533658-236d-4dc9-9156-7e3e7be7cb79-16688 to ip-100-64-118-176.us-west-2.compute.internal
20m         Normal    Pulled                            pod/sas-batch-server-1b533658-236d-4dc9-9156-7e3e7be7cb79-16688     Container image "668749497752.dkr.ecr.us-west-2.amazonaws.com/sasviya/viya-4-x64_oci_linux_2-docker/sas-certframe:3.51.0-20240313.1710330811841" already present on machine
20m         Normal    Created                           pod/sas-batch-server-1b533658-236d-4dc9-9156-7e3e7be7cb79-16688     Created container sas-certframe
20m         Normal    Started                           pod/sas-batch-server-1b533658-236d-4dc9-9156-7e3e7be7cb79-16688     Started container sas-certframe
20m         Normal    Pulled                            pod/sas-batch-server-1b533658-236d-4dc9-9156-7e3e7be7cb79-16688     Container image "668749497752.dkr.ecr.us-west-2.amazonaws.com/sasviya/viya-4-x64_oci_linux_2-docker/sas-config-init:1.21.1-20240305.1709656957059" already present on machine
20m         Normal    Created                           pod/sas-batch-server-1b533658-236d-4dc9-9156-7e3e7be7cb79-16688     Created container sas-config-init
20m         Normal    Started                           pod/sas-batch-server-1b533658-236d-4dc9-9156-7e3e7be7cb79-16688     Started container sas-config-init
19m         Normal    Pulled                            pod/sas-batch-server-1b533658-236d-4dc9-9156-7e3e7be7cb79-16688     Container image "668749497752.dkr.ecr.us-west-2.amazonaws.com/sasviya/viya-4-x64_oci_linux_2-docker/sas-programming-environment:1.53.31-20240613.1718295947845" already present on machine
19m         Normal    Created                           pod/sas-batch-server-1b533658-236d-4dc9-9156-7e3e7be7cb79-16688     Created container sas-programming-environment
19m         Normal    Started                           pod/sas-batch-server-1b533658-236d-4dc9-9156-7e3e7be7cb79-16688     Started container sas-programming-environment
19m         Normal    Pulled                            pod/sas-batch-server-1b533658-236d-4dc9-9156-7e3e7be7cb79-16688     Container image "668749497752.dkr.ecr.us-west-2.amazonaws.com/sasviya/viya-4-x64_oci_linux_2-docker/sas-process-exporter:1.9.1-20240306.1709732097762" already present on machine
19m         Normal    Created                           pod/sas-batch-server-1b533658-236d-4dc9-9156-7e3e7be7cb79-16688     Created container sas-process-exporter
19m         Normal    Started                           pod/sas-batch-server-1b533658-236d-4dc9-9156-7e3e7be7cb79-16688     Started container sas-process-exporter
14m         Normal    Killing                           pod/sas-batch-server-1b533658-236d-4dc9-9156-7e3e7be7cb79-16688     Stopping container sas-process-exporter
59m         Normal    Killing                           pod/sas-batch-server-1cab50bd-d722-4cb0-926f-6dd6be62bc17-16597     Stopping container sas-process-exporter
59m         Normal    Scheduled                         pod/sas-batch-server-216502ee-5feb-4e6d-8076-e0e08a198258-16613     Successfully assigned viya-dev/sas-batch-server-216502ee-5feb-4e6d-8076-e0e08a198258-16613 to ip-100-64-125-225.us-west-2.compute.internal
59m         Normal    Pulled                            pod/sas-batch-server-216502ee-5feb-4e6d-8076-e0e08a198258-16613     Container image "668749497752.dkr.ecr.us-west-2.amazonaws.com/sasviya/viya-4-x64_oci_linux_2-docker/sas-certframe:3.51.0-20240313.1710330811841" already present on machine
59m         Normal    Created                           pod/sas-batch-server-216502ee-5feb-4e6d-8076-e0e08a198258-16613     Created container sas-certframe
59m         Normal    Started                           pod/sas-batch-server-216502ee-5feb-4e6d-8076-e0e08a198258-16613     Started container sas-certframe
59m         Normal    Pulled                            pod/sas-batch-server-216502ee-5feb-4e6d-8076-e0e08a198258-16613     Container image "668749497752.dkr.ecr.us-west-2.amazonaws.com/sasviya/viya-4-x64_oci_linux_2-docker/sas-config-init:1.21.1-20240305.1709656957059" already present on machine
59m         Normal    Created                           pod/sas-batch-server-216502ee-5feb-4e6d-8076-e0e08a198258-16613     Created container sas-config-init
59m         Normal    Started                           pod/sas-batch-server-216502ee-5feb-4e6d-8076-e0e08a198258-16613     Started container sas-config-init
59m         Normal    Pulled                            pod/sas-batch-server-216502ee-5feb-4e6d-8076-e0e08a198258-16613     Container image "668749497752.dkr.ecr.us-west-2.amazonaws.com/sasviya/viya-4-x64_oci_linux_2-docker/sas-programming-environment:1.53.31-20240613.1718295947845" already present on machine
59m         Normal    Created                           pod/sas-batch-server-216502ee-5feb-4e6d-8076-e0e08a198258-16613     Created container sas-programming-environment
59m         Normal    Started                           pod/sas-batch-server-216502ee-5feb-4e6d-8076-e0e08a198258-16613     Started container sas-programming-environment
59m         Normal    Pulled                            pod/sas-batch-server-216502ee-5feb-4e6d-8076-e0e08a198258-16613     Container image "668749497752.dkr.ecr.us-west-2.amazonaws.com/sasviya/viya-4-x64_oci_linux_2-docker/sas-process-exporter:1.9.1-20240306.1709732097762" already present on machine
59m         Normal    Created                           pod/sas-batch-server-216502ee-5feb-4e6d-8076-e0e08a198258-16613     Created container sas-process-exporter
59m         Normal    Started                           pod/sas-batch-server-216502ee-5feb-4e6d-8076-e0e08a198258-16613     Started container sas-process-exporter
53m         Normal    Killing                           pod/sas-batch-server-216502ee-5feb-4e6d-8076-e0e08a198258-16613     Stopping container sas-process-exporter
10m         Warning   FailedScheduling                  pod/sas-batch-server-21d45100-7064-4946-81f0-727f721e496c-16785     0/10 nodes are available: 1 Insufficient cpu, 1 node(s) had untolerated taint {workload.sas.com/class: cas}, 1 node(s) had untolerated taint {workload.sas.com/class: stateful}, 1 node(s) had untolerated taint {workload.sas.com/class: stateless}, 6 node(s) didn't match Pod's node affinity/selector. preemption: 0/10 nodes are available: 1 No preemption victims found for incoming pod, 9 Preemption is not helpful for scheduling..
9m38s       Normal    NotTriggerScaleUp                 pod/sas-batch-server-21d45100-7064-4946-81f0-727f721e496c-16785     pod didn't trigger scale-up: 1 node(s) had untolerated taint {workload.sas.com/class: cas}, 2 node(s) didn't match Pod's node affinity/selector, 1 node(s) had untolerated taint {workload.sas.com/class: stateful}, 1 node(s) had untolerated taint {workload.sas.com/class: stateless}
9m36s       Normal    Scheduled                         pod/sas-batch-server-21d45100-7064-4946-81f0-727f721e496c-16785     Successfully assigned viya-dev/sas-batch-server-21d45100-7064-4946-81f0-727f721e496c-16785 to ip-100-64-88-54.us-west-2.compute.internal
9m34s       Normal    Pulled                            pod/sas-batch-server-21d45100-7064-4946-81f0-727f721e496c-16785     Container image "668749497752.dkr.ecr.us-west-2.amazonaws.com/sasviya/viya-4-x64_oci_linux_2-docker/sas-certframe:3.51.0-20240313.1710330811841" already present on machine
9m34s       Normal    Created                           pod/sas-batch-server-21d45100-7064-4946-81f0-727f721e496c-16785     Created container sas-certframe
9m34s       Normal    Started                           pod/sas-batch-server-21d45100-7064-4946-81f0-727f721e496c-16785     Started container sas-certframe
9m33s       Normal    Pulled                            pod/sas-batch-server-21d45100-7064-4946-81f0-727f721e496c-16785     Container image "668749497752.dkr.ecr.us-west-2.amazonaws.com/sasviya/viya-4-x64_oci_linux_2-docker/sas-config-init:1.21.1-20240305.1709656957059" already present on machine
9m33s       Normal    Created                           pod/sas-batch-server-21d45100-7064-4946-81f0-727f721e496c-16785     Created container sas-config-init
9m33s       Normal    Started                           pod/sas-batch-server-21d45100-7064-4946-81f0-727f721e496c-16785     Started container sas-config-init
9m31s       Normal    Pulled                            pod/sas-batch-server-21d45100-7064-4946-81f0-727f721e496c-16785     Container image "668749497752.dkr.ecr.us-west-2.amazonaws.com/sasviya/viya-4-x64_oci_linux_2-docker/sas-programming-environment:1.53.31-20240613.1718295947845" already present on machine
9m31s       Normal    Created                           pod/sas-batch-server-21d45100-7064-4946-81f0-727f721e496c-16785     Created container sas-programming-environment
9m31s       Normal    Started                           pod/sas-batch-server-21d45100-7064-4946-81f0-727f721e496c-16785     Started container sas-programming-environment
9m31s       Normal    Pulled                            pod/sas-batch-server-21d45100-7064-4946-81f0-727f721e496c-16785     Container image "668749497752.dkr.ecr.us-west-2.amazonaws.com/sasviya/viya-4-x64_oci_linux_2-docker/sas-process-exporter:1.9.1-20240306.1709732097762" already present on machine
9m31s       Normal    Created                           pod/sas-batch-server-21d45100-7064-4946-81f0-727f721e496c-16785     Created container sas-process-exporter
9m31s       Normal    Started                           pod/sas-batch-server-21d45100-7064-4946-81f0-727f721e496c-16785     Started container sas-process-exporter
3m10s       Normal    Killing                           pod/sas-batch-server-21d45100-7064-4946-81f0-727f721e496c-16785     Stopping container sas-process-exporter
55m         Normal    Killing                           pod/sas-batch-server-22394bf0-2d2f-43f5-bb06-d9e5e28280ca-16592     Stopping container sas-process-exporter
9m34s       Warning   FailedScheduling                  pod/sas-batch-server-2495e73d-6cfc-4c5c-a382-4602be91fc1d-16787     0/10 nodes are available: 1 Insufficient cpu, 1 node(s) had untolerated taint {workload.sas.com/class: cas}, 1 node(s) had untolerated taint {workload.sas.com/class: stateful}, 1 node(s) had untolerated taint {workload.sas.com/class: stateless}, 6 node(s) didn't match Pod's node affinity/selector. preemption: 0/10 nodes are available: 1 No preemption victims found for incoming pod, 9 Preemption is not helpful for scheduling..
9m32s       Normal    Scheduled                         pod/sas-batch-server-2495e73d-6cfc-4c5c-a382-4602be91fc1d-16787     Successfully assigned viya-dev/sas-batch-server-2495e73d-6cfc-4c5c-a382-4602be91fc1d-16787 to ip-100-64-125-225.us-west-2.compute.internal
9m30s       Normal    Pulled                            pod/sas-batch-server-2495e73d-6cfc-4c5c-a382-4602be91fc1d-16787     Container image "668749497752.dkr.ecr.us-west-2.amazonaws.com/sasviya/viya-4-x64_oci_linux_2-docker/sas-certframe:3.51.0-20240313.1710330811841" already present on machine
9m30s       Normal    Created                           pod/sas-batch-server-2495e73d-6cfc-4c5c-a382-4602be91fc1d-16787     Created container sas-certframe
9m30s       Normal    Started                           pod/sas-batch-server-2495e73d-6cfc-4c5c-a382-4602be91fc1d-16787     Started container sas-certframe
9m28s       Normal    Pulled                            pod/sas-batch-server-2495e73d-6cfc-4c5c-a382-4602be91fc1d-16787     Container image "668749497752.dkr.ecr.us-west-2.amazonaws.com/sasviya/viya-4-x64_oci_linux_2-docker/sas-config-init:1.21.1-20240305.1709656957059" already present on machine
9m28s       Normal    Created                           pod/sas-batch-server-2495e73d-6cfc-4c5c-a382-4602be91fc1d-16787     Created container sas-config-init
9m28s       Normal    Started                           pod/sas-batch-server-2495e73d-6cfc-4c5c-a382-4602be91fc1d-16787     Started container sas-config-init
9m26s       Normal    Pulled                            pod/sas-batch-server-2495e73d-6cfc-4c5c-a382-4602be91fc1d-16787     Container image "668749497752.dkr.ecr.us-west-2.amazonaws.com/sasviya/viya-4-x64_oci_linux_2-docker/sas-programming-environment:1.53.31-20240613.1718295947845" already present on machine
9m26s       Normal    Created                           pod/sas-batch-server-2495e73d-6cfc-4c5c-a382-4602be91fc1d-16787     Created container sas-programming-environment
9m26s       Normal    Started                           pod/sas-batch-server-2495e73d-6cfc-4c5c-a382-4602be91fc1d-16787     Started container sas-programming-environment
9m26s       Normal    Pulled                            pod/sas-batch-server-2495e73d-6cfc-4c5c-a382-4602be91fc1d-16787     Container image "668749497752.dkr.ecr.us-west-2.amazonaws.com/sasviya/viya-4-x64_oci_linux_2-docker/sas-process-exporter:1.9.1-20240306.1709732097762" already present on machine
9m26s       Normal    Created                           pod/sas-batch-server-2495e73d-6cfc-4c5c-a382-4602be91fc1d-16787     Created container sas-process-exporter
9m26s       Normal    Started                           pod/sas-batch-server-2495e73d-6cfc-4c5c-a382-4602be91fc1d-16787     Started container sas-process-exporter
3m14s       Normal    Killing                           pod/sas-batch-server-2495e73d-6cfc-4c5c-a382-4602be91fc1d-16787     Stopping container sas-process-exporter
19m         Normal    Scheduled                         pod/sas-batch-server-2704dcc7-b5da-4f85-b14c-219a881970ec-16719     Successfully assigned viya-dev/sas-batch-server-2704dcc7-b5da-4f85-b14c-219a881970ec-16719 to ip-100-64-88-54.us-west-2.compute.internal
19m         Normal    Pulled                            pod/sas-batch-server-2704dcc7-b5da-4f85-b14c-219a881970ec-16719     Container image "668749497752.dkr.ecr.us-west-2.amazonaws.com/sasviya/viya-4-x64_oci_linux_2-docker/sas-certframe:3.51.0-20240313.1710330811841" already present on machine
19m         Normal    Created                           pod/sas-batch-server-2704dcc7-b5da-4f85-b14c-219a881970ec-16719     Created container sas-certframe
19m         Normal    Started                           pod/sas-batch-server-2704dcc7-b5da-4f85-b14c-219a881970ec-16719     Started container sas-certframe
19m         Normal    Pulled                            pod/sas-batch-server-2704dcc7-b5da-4f85-b14c-219a881970ec-16719     Container image "668749497752.dkr.ecr.us-west-2.amazonaws.com/sasviya/viya-4-x64_oci_linux_2-docker/sas-config-init:1.21.1-20240305.1709656957059" already present on machine
19m         Normal    Created                           pod/sas-batch-server-2704dcc7-b5da-4f85-b14c-219a881970ec-16719     Created container sas-config-init
19m         Normal    Started                           pod/sas-batch-server-2704dcc7-b5da-4f85-b14c-219a881970ec-16719     Started container sas-config-init
19m         Normal    Pulled                            pod/sas-batch-server-2704dcc7-b5da-4f85-b14c-219a881970ec-16719     Container image "668749497752.dkr.ecr.us-west-2.amazonaws.com/sasviya/viya-4-x64_oci_linux_2-docker/sas-programming-environment:1.53.31-20240613.1718295947845" already present on machine
19m         Normal    Created                           pod/sas-batch-server-2704dcc7-b5da-4f85-b14c-219a881970ec-16719     Created container sas-programming-environment
19m         Normal    Started                           pod/sas-batch-server-2704dcc7-b5da-4f85-b14c-219a881970ec-16719     Started container sas-programming-environment
19m         Normal    Pulled                            pod/sas-batch-server-2704dcc7-b5da-4f85-b14c-219a881970ec-16719     Container image "668749497752.dkr.ecr.us-west-2.amazonaws.com/sasviya/viya-4-x64_oci_linux_2-docker/sas-process-exporter:1.9.1-20240306.1709732097762" already present on machine
19m         Normal    Created                           pod/sas-batch-server-2704dcc7-b5da-4f85-b14c-219a881970ec-16719     Created container sas-process-exporter
19m         Normal    Started                           pod/sas-batch-server-2704dcc7-b5da-4f85-b14c-219a881970ec-16719     Started container sas-process-exporter
5m9s        Normal    Killing                           pod/sas-batch-server-2704dcc7-b5da-4f85-b14c-219a881970ec-16719     Stopping container sas-process-exporter
8m43s       Warning   FailedScheduling                  pod/sas-batch-server-273f7c99-7d98-4a5c-89e9-245d88b5fb1f-16774     0/10 nodes are available: 1 Insufficient cpu, 1 node(s) had untolerated taint {workload.sas.com/class: cas}, 1 node(s) had untolerated taint {workload.sas.com/class: stateful}, 1 node(s) had untolerated taint {workload.sas.com/class: stateless}, 6 node(s) didn't match Pod's node affinity/selector. preemption: 0/10 nodes are available: 1 No preemption victims found for incoming pod, 9 Preemption is not helpful for scheduling..
9m38s       Normal    NotTriggerScaleUp                 pod/sas-batch-server-273f7c99-7d98-4a5c-89e9-245d88b5fb1f-16774     pod didn't trigger scale-up: 1 node(s) had untolerated taint {workload.sas.com/class: cas}, 2 node(s) didn't match Pod's node affinity/selector, 1 node(s) had untolerated taint {workload.sas.com/class: stateful}, 1 node(s) had untolerated taint {workload.sas.com/class: stateless}
8m32s       Warning   FailedScheduling                  pod/sas-batch-server-273f7c99-7d98-4a5c-89e9-245d88b5fb1f-16774     0/11 nodes are available: 1 Insufficient cpu, 1 node(s) had untolerated taint {node.kubernetes.io/not-ready: }, 1 node(s) had untolerated taint {workload.sas.com/class: cas}, 1 node(s) had untolerated taint {workload.sas.com/class: stateful}, 1 node(s) had untolerated taint {workload.sas.com/class: stateless}, 6 node(s) didn't match Pod's node affinity/selector. preemption: 0/11 nodes are available: 1 No preemption victims found for incoming pod, 10 Preemption is not helpful for scheduling..
6m57s       Warning   FailedScheduling                  pod/sas-batch-server-273f7c99-7d98-4a5c-89e9-245d88b5fb1f-16774     0/11 nodes are available: 1 Insufficient cpu, 1 node(s) had untolerated taint {workload.sas.com/class: cas}, 1 node(s) had untolerated taint {workload.sas.com/class: stateful}, 1 node(s) had untolerated taint {workload.sas.com/class: stateless}, 7 node(s) didn't match Pod's node affinity/selector. preemption: 0/11 nodes are available: 1 No preemption victims found for incoming pod, 10 Preemption is not helpful for scheduling..
6m47s       Normal    Scheduled                         pod/sas-batch-server-273f7c99-7d98-4a5c-89e9-245d88b5fb1f-16774     Successfully assigned viya-dev/sas-batch-server-273f7c99-7d98-4a5c-89e9-245d88b5fb1f-16774 to ip-100-64-98-232.us-west-2.compute.internal
6m44s       Normal    Pulled                            pod/sas-batch-server-273f7c99-7d98-4a5c-89e9-245d88b5fb1f-16774     Container image "668749497752.dkr.ecr.us-west-2.amazonaws.com/sasviya/viya-4-x64_oci_linux_2-docker/sas-certframe:3.51.0-20240313.1710330811841" already present on machine
6m44s       Normal    Created                           pod/sas-batch-server-273f7c99-7d98-4a5c-89e9-245d88b5fb1f-16774     Created container sas-certframe
6m44s       Normal    Started                           pod/sas-batch-server-273f7c99-7d98-4a5c-89e9-245d88b5fb1f-16774     Started container sas-certframe
6m42s       Normal    Pulled                            pod/sas-batch-server-273f7c99-7d98-4a5c-89e9-245d88b5fb1f-16774     Container image "668749497752.dkr.ecr.us-west-2.amazonaws.com/sasviya/viya-4-x64_oci_linux_2-docker/sas-config-init:1.21.1-20240305.1709656957059" already present on machine
6m42s       Normal    Created                           pod/sas-batch-server-273f7c99-7d98-4a5c-89e9-245d88b5fb1f-16774     Created container sas-config-init
6m41s       Normal    Started                           pod/sas-batch-server-273f7c99-7d98-4a5c-89e9-245d88b5fb1f-16774     Started container sas-config-init
6m40s       Normal    Pulled                            pod/sas-batch-server-273f7c99-7d98-4a5c-89e9-245d88b5fb1f-16774     Container image "668749497752.dkr.ecr.us-west-2.amazonaws.com/sasviya/viya-4-x64_oci_linux_2-docker/sas-programming-environment:1.53.31-20240613.1718295947845" already present on machine
6m40s       Normal    Created                           pod/sas-batch-server-273f7c99-7d98-4a5c-89e9-245d88b5fb1f-16774     Created container sas-programming-environment
6m39s       Normal    Started                           pod/sas-batch-server-273f7c99-7d98-4a5c-89e9-245d88b5fb1f-16774     Started container sas-programming-environment
6m39s       Normal    Pulled                            pod/sas-batch-server-273f7c99-7d98-4a5c-89e9-245d88b5fb1f-16774     Container image "668749497752.dkr.ecr.us-west-2.amazonaws.com/sasviya/viya-4-x64_oci_linux_2-docker/sas-process-exporter:1.9.1-20240306.1709732097762" already present on machine
6m39s       Normal    Created                           pod/sas-batch-server-273f7c99-7d98-4a5c-89e9-245d88b5fb1f-16774     Created container sas-process-exporter
6m39s       Normal    Started                           pod/sas-batch-server-273f7c99-7d98-4a5c-89e9-245d88b5fb1f-16774     Started container sas-process-exporter
3m24s       Normal    Killing                           pod/sas-batch-server-273f7c99-7d98-4a5c-89e9-245d88b5fb1f-16774     Stopping container sas-process-exporter
19m         Normal    Scheduled                         pod/sas-batch-server-27bc72af-1eaa-4769-b879-fe66ba0a1eed-16716     Successfully assigned viya-dev/sas-batch-server-27bc72af-1eaa-4769-b879-fe66ba0a1eed-16716 to ip-100-64-98-232.us-west-2.compute.internal
19m         Normal    Pulled                            pod/sas-batch-server-27bc72af-1eaa-4769-b879-fe66ba0a1eed-16716     Container image "668749497752.dkr.ecr.us-west-2.amazonaws.com/sasviya/viya-4-x64_oci_linux_2-docker/sas-certframe:3.51.0-20240313.1710330811841" already present on machine
19m         Normal    Created                           pod/sas-batch-server-27bc72af-1eaa-4769-b879-fe66ba0a1eed-16716     Created container sas-certframe
19m         Normal    Started                           pod/sas-batch-server-27bc72af-1eaa-4769-b879-fe66ba0a1eed-16716     Started container sas-certframe
19m         Normal    Pulled                            pod/sas-batch-server-27bc72af-1eaa-4769-b879-fe66ba0a1eed-16716     Container image "668749497752.dkr.ecr.us-west-2.amazonaws.com/sasviya/viya-4-x64_oci_linux_2-docker/sas-config-init:1.21.1-20240305.1709656957059" already present on machine
19m         Normal    Created                           pod/sas-batch-server-27bc72af-1eaa-4769-b879-fe66ba0a1eed-16716     Created container sas-config-init
19m         Normal    Started                           pod/sas-batch-server-27bc72af-1eaa-4769-b879-fe66ba0a1eed-16716     Started container sas-config-init
19m         Normal    Pulled                            pod/sas-batch-server-27bc72af-1eaa-4769-b879-fe66ba0a1eed-16716     Container image "668749497752.dkr.ecr.us-west-2.amazonaws.com/sasviya/viya-4-x64_oci_linux_2-docker/sas-programming-environment:1.53.31-20240613.1718295947845" already present on machine
19m         Normal    Created                           pod/sas-batch-server-27bc72af-1eaa-4769-b879-fe66ba0a1eed-16716     Created container sas-programming-environment
19m         Normal    Started                           pod/sas-batch-server-27bc72af-1eaa-4769-b879-fe66ba0a1eed-16716     Started container sas-programming-environment
19m         Normal    Pulled                            pod/sas-batch-server-27bc72af-1eaa-4769-b879-fe66ba0a1eed-16716     Container image "668749497752.dkr.ecr.us-west-2.amazonaws.com/sasviya/viya-4-x64_oci_linux_2-docker/sas-process-exporter:1.9.1-20240306.1709732097762" already present on machine
19m         Normal    Created                           pod/sas-batch-server-27bc72af-1eaa-4769-b879-fe66ba0a1eed-16716     Created container sas-process-exporter
19m         Normal    Started                           pod/sas-batch-server-27bc72af-1eaa-4769-b879-fe66ba0a1eed-16716     Started container sas-process-exporter
3m42s       Normal    Killing                           pod/sas-batch-server-27bc72af-1eaa-4769-b879-fe66ba0a1eed-16716     Stopping container sas-process-exporter
59m         Normal    Scheduled                         pod/sas-batch-server-287b7993-f374-4132-818d-f708d74c4260-16647     Successfully assigned viya-dev/sas-batch-server-287b7993-f374-4132-818d-f708d74c4260-16647 to ip-100-64-103-52.us-west-2.compute.internal
59m         Normal    Pulled                            pod/sas-batch-server-287b7993-f374-4132-818d-f708d74c4260-16647     Container image "668749497752.dkr.ecr.us-west-2.amazonaws.com/sasviya/viya-4-x64_oci_linux_2-docker/sas-certframe:3.51.0-20240313.1710330811841" already present on machine
59m         Normal    Created                           pod/sas-batch-server-287b7993-f374-4132-818d-f708d74c4260-16647     Created container sas-certframe
59m         Normal    Started                           pod/sas-batch-server-287b7993-f374-4132-818d-f708d74c4260-16647     Started container sas-certframe
59m         Normal    Pulled                            pod/sas-batch-server-287b7993-f374-4132-818d-f708d74c4260-16647     Container image "668749497752.dkr.ecr.us-west-2.amazonaws.com/sasviya/viya-4-x64_oci_linux_2-docker/sas-config-init:1.21.1-20240305.1709656957059" already present on machine
59m         Normal    Created                           pod/sas-batch-server-287b7993-f374-4132-818d-f708d74c4260-16647     Created container sas-config-init
59m         Normal    Started                           pod/sas-batch-server-287b7993-f374-4132-818d-f708d74c4260-16647     Started container sas-config-init
59m         Normal    Pulled                            pod/sas-batch-server-287b7993-f374-4132-818d-f708d74c4260-16647     Container image "668749497752.dkr.ecr.us-west-2.amazonaws.com/sasviya/viya-4-x64_oci_linux_2-docker/sas-programming-environment:1.53.31-20240613.1718295947845" already present on machine
59m         Normal    Created                           pod/sas-batch-server-287b7993-f374-4132-818d-f708d74c4260-16647     Created container sas-programming-environment
59m         Normal    Started                           pod/sas-batch-server-287b7993-f374-4132-818d-f708d74c4260-16647     Started container sas-programming-environment
59m         Normal    Pulled                            pod/sas-batch-server-287b7993-f374-4132-818d-f708d74c4260-16647     Container image "668749497752.dkr.ecr.us-west-2.amazonaws.com/sasviya/viya-4-x64_oci_linux_2-docker/sas-process-exporter:1.9.1-20240306.1709732097762" already present on machine
59m         Normal    Created                           pod/sas-batch-server-287b7993-f374-4132-818d-f708d74c4260-16647     Created container sas-process-exporter
59m         Normal    Started                           pod/sas-batch-server-287b7993-f374-4132-818d-f708d74c4260-16647     Started container sas-process-exporter
47m         Normal    Killing                           pod/sas-batch-server-287b7993-f374-4132-818d-f708d74c4260-16647     Stopping container sas-process-exporter
57m         Normal    Scheduled                         pod/sas-batch-server-2b7e710f-c211-4a68-9d5f-f553484b67aa-16670     Successfully assigned viya-dev/sas-batch-server-2b7e710f-c211-4a68-9d5f-f553484b67aa-16670 to ip-100-64-98-232.us-west-2.compute.internal
57m         Normal    Pulled                            pod/sas-batch-server-2b7e710f-c211-4a68-9d5f-f553484b67aa-16670     Container image "668749497752.dkr.ecr.us-west-2.amazonaws.com/sasviya/viya-4-x64_oci_linux_2-docker/sas-certframe:3.51.0-20240313.1710330811841" already present on machine
57m         Normal    Created                           pod/sas-batch-server-2b7e710f-c211-4a68-9d5f-f553484b67aa-16670     Created container sas-certframe
57m         Normal    Started                           pod/sas-batch-server-2b7e710f-c211-4a68-9d5f-f553484b67aa-16670     Started container sas-certframe
57m         Normal    Pulling                           pod/sas-batch-server-2b7e710f-c211-4a68-9d5f-f553484b67aa-16670     Pulling image "668749497752.dkr.ecr.us-west-2.amazonaws.com/sasviya/viya-4-x64_oci_linux_2-docker/sas-config-init:1.21.1-20240305.1709656957059"
57m         Warning   Failed                            pod/sas-batch-server-2b7e710f-c211-4a68-9d5f-f553484b67aa-16670     Failed to pull image "668749497752.dkr.ecr.us-west-2.amazonaws.com/sasviya/viya-4-x64_oci_linux_2-docker/sas-config-init:1.21.1-20240305.1709656957059": pull QPS exceeded
57m         Warning   Failed                            pod/sas-batch-server-2b7e710f-c211-4a68-9d5f-f553484b67aa-16670     Error: ErrImagePull
56m         Normal    Pulled                            pod/sas-batch-server-2b7e710f-c211-4a68-9d5f-f553484b67aa-16670     Successfully pulled image "668749497752.dkr.ecr.us-west-2.amazonaws.com/sasviya/viya-4-x64_oci_linux_2-docker/sas-config-init:1.21.1-20240305.1709656957059" in 13.265s (13.265s including waiting)
56m         Normal    Created                           pod/sas-batch-server-2b7e710f-c211-4a68-9d5f-f553484b67aa-16670     Created container sas-config-init
56m         Normal    Started                           pod/sas-batch-server-2b7e710f-c211-4a68-9d5f-f553484b67aa-16670     Started container sas-config-init
56m         Normal    Pulling                           pod/sas-batch-server-2b7e710f-c211-4a68-9d5f-f553484b67aa-16670     Pulling image "668749497752.dkr.ecr.us-west-2.amazonaws.com/sasviya/viya-4-x64_oci_linux_2-docker/sas-programming-environment:1.53.31-20240613.1718295947845"
55m         Normal    Pulled                            pod/sas-batch-server-2b7e710f-c211-4a68-9d5f-f553484b67aa-16670     Successfully pulled image "668749497752.dkr.ecr.us-west-2.amazonaws.com/sasviya/viya-4-x64_oci_linux_2-docker/sas-programming-environment:1.53.31-20240613.1718295947845" in 1m15.723s (1m15.723s including waiting)
55m         Normal    Created                           pod/sas-batch-server-2b7e710f-c211-4a68-9d5f-f553484b67aa-16670     Created container sas-programming-environment
55m         Normal    Started                           pod/sas-batch-server-2b7e710f-c211-4a68-9d5f-f553484b67aa-16670     Started container sas-programming-environment
55m         Normal    Pulled                            pod/sas-batch-server-2b7e710f-c211-4a68-9d5f-f553484b67aa-16670     Container image "668749497752.dkr.ecr.us-west-2.amazonaws.com/sasviya/viya-4-x64_oci_linux_2-docker/sas-process-exporter:1.9.1-20240306.1709732097762" already present on machine
55m         Normal    Created                           pod/sas-batch-server-2b7e710f-c211-4a68-9d5f-f553484b67aa-16670     Created container sas-process-exporter
55m         Normal    Started                           pod/sas-batch-server-2b7e710f-c211-4a68-9d5f-f553484b67aa-16670     Started container sas-process-exporter
46m         Normal    Killing                           pod/sas-batch-server-2b7e710f-c211-4a68-9d5f-f553484b67aa-16670     Stopping container sas-process-exporter
19m         Normal    Scheduled                         pod/sas-batch-server-2c37f7c5-a03a-41f1-bd67-19d1675a2ff0-16743     Successfully assigned viya-dev/sas-batch-server-2c37f7c5-a03a-41f1-bd67-19d1675a2ff0-16743 to ip-100-64-88-54.us-west-2.compute.internal
19m         Normal    Pulled                            pod/sas-batch-server-2c37f7c5-a03a-41f1-bd67-19d1675a2ff0-16743     Container image "668749497752.dkr.ecr.us-west-2.amazonaws.com/sasviya/viya-4-x64_oci_linux_2-docker/sas-certframe:3.51.0-20240313.1710330811841" already present on machine
19m         Normal    Created                           pod/sas-batch-server-2c37f7c5-a03a-41f1-bd67-19d1675a2ff0-16743     Created container sas-certframe
19m         Normal    Started                           pod/sas-batch-server-2c37f7c5-a03a-41f1-bd67-19d1675a2ff0-16743     Started container sas-certframe
19m         Normal    Pulled                            pod/sas-batch-server-2c37f7c5-a03a-41f1-bd67-19d1675a2ff0-16743     Container image "668749497752.dkr.ecr.us-west-2.amazonaws.com/sasviya/viya-4-x64_oci_linux_2-docker/sas-config-init:1.21.1-20240305.1709656957059" already present on machine
19m         Normal    Created                           pod/sas-batch-server-2c37f7c5-a03a-41f1-bd67-19d1675a2ff0-16743     Created container sas-config-init
19m         Normal    Started                           pod/sas-batch-server-2c37f7c5-a03a-41f1-bd67-19d1675a2ff0-16743     Started container sas-config-init
19m         Normal    Pulled                            pod/sas-batch-server-2c37f7c5-a03a-41f1-bd67-19d1675a2ff0-16743     Container image "668749497752.dkr.ecr.us-west-2.amazonaws.com/sasviya/viya-4-x64_oci_linux_2-docker/sas-programming-environment:1.53.31-20240613.1718295947845" already present on machine
19m         Normal    Created                           pod/sas-batch-server-2c37f7c5-a03a-41f1-bd67-19d1675a2ff0-16743     Created container sas-programming-environment
19m         Normal    Started                           pod/sas-batch-server-2c37f7c5-a03a-41f1-bd67-19d1675a2ff0-16743     Started container sas-programming-environment
19m         Normal    Pulled                            pod/sas-batch-server-2c37f7c5-a03a-41f1-bd67-19d1675a2ff0-16743     Container image "668749497752.dkr.ecr.us-west-2.amazonaws.com/sasviya/viya-4-x64_oci_linux_2-docker/sas-process-exporter:1.9.1-20240306.1709732097762" already present on machine
19m         Normal    Created                           pod/sas-batch-server-2c37f7c5-a03a-41f1-bd67-19d1675a2ff0-16743     Created container sas-process-exporter
19m         Normal    Started                           pod/sas-batch-server-2c37f7c5-a03a-41f1-bd67-19d1675a2ff0-16743     Started container sas-process-exporter
7m10s       Normal    Killing                           pod/sas-batch-server-2c37f7c5-a03a-41f1-bd67-19d1675a2ff0-16743     Stopping container sas-process-exporter
59m         Warning   FailedScheduling                  pod/sas-batch-server-2d685ec4-8d7a-4806-91f1-5efc865b42a8-16660     0/9 nodes are available: 1 Insufficient cpu, 1node(s) had untolerated taint {workload.sas.com/class: cas}, 1 node(s) had untolerated taint {workload.sas.com/class: stateful}, 1 node(s) had untolerated taint {workload.sas.com/class: stateless}, 5 node(s) didn't match Pod's node affinity/selector. preemption: 0/9 nodes are available: 1 No preemption victims found for incoming pod, 8 Preemption is not helpful for scheduling..
59m         Normal    Scheduled                         pod/sas-batch-server-2d685ec4-8d7a-4806-91f1-5efc865b42a8-16660     Successfully assigned viya-dev/sas-batch-server-2d685ec4-8d7a-4806-91f1-5efc865b42a8-16660 to ip-100-64-118-176.us-west-2.compute.internal
59m         Normal    Pulled                            pod/sas-batch-server-2d685ec4-8d7a-4806-91f1-5efc865b42a8-16660     Container image "668749497752.dkr.ecr.us-west-2.amazonaws.com/sasviya/viya-4-x64_oci_linux_2-docker/sas-certframe:3.51.0-20240313.1710330811841" already present on machine
59m         Normal    Created                           pod/sas-batch-server-2d685ec4-8d7a-4806-91f1-5efc865b42a8-16660     Created container sas-certframe
59m         Normal    Started                           pod/sas-batch-server-2d685ec4-8d7a-4806-91f1-5efc865b42a8-16660     Started container sas-certframe
59m         Normal    Pulled                            pod/sas-batch-server-2d685ec4-8d7a-4806-91f1-5efc865b42a8-16660     Container image "668749497752.dkr.ecr.us-west-2.amazonaws.com/sasviya/viya-4-x64_oci_linux_2-docker/sas-config-init:1.21.1-20240305.1709656957059" already present on machine
59m         Normal    Created                           pod/sas-batch-server-2d685ec4-8d7a-4806-91f1-5efc865b42a8-16660     Created container sas-config-init
59m         Normal    Started                           pod/sas-batch-server-2d685ec4-8d7a-4806-91f1-5efc865b42a8-16660     Started container sas-config-init
59m         Normal    Pulled                            pod/sas-batch-server-2d685ec4-8d7a-4806-91f1-5efc865b42a8-16660     Container image "668749497752.dkr.ecr.us-west-2.amazonaws.com/sasviya/viya-4-x64_oci_linux_2-docker/sas-programming-environment:1.53.31-20240613.1718295947845" already present on machine
59m         Normal    Created                           pod/sas-batch-server-2d685ec4-8d7a-4806-91f1-5efc865b42a8-16660     Created container sas-programming-environment
59m         Normal    Started                           pod/sas-batch-server-2d685ec4-8d7a-4806-91f1-5efc865b42a8-16660     Started container sas-programming-environment
59m         Normal    Pulled                            pod/sas-batch-server-2d685ec4-8d7a-4806-91f1-5efc865b42a8-16660     Container image "668749497752.dkr.ecr.us-west-2.amazonaws.com/sasviya/viya-4-x64_oci_linux_2-docker/sas-process-exporter:1.9.1-20240306.1709732097762" already present on machine
59m         Normal    Created                           pod/sas-batch-server-2d685ec4-8d7a-4806-91f1-5efc865b42a8-16660     Created container sas-process-exporter
59m         Normal    Started                           pod/sas-batch-server-2d685ec4-8d7a-4806-91f1-5efc865b42a8-16660     Started container sas-process-exporter
47m         Normal    Killing                           pod/sas-batch-server-2d685ec4-8d7a-4806-91f1-5efc865b42a8-16660     Stopping container sas-process-exporter
19m         Normal    Scheduled                         pod/sas-batch-server-2f7bc580-391b-4052-a196-56f8327db377-16739     Successfully assigned viya-dev/sas-batch-server-2f7bc580-391b-4052-a196-56f8327db377-16739 to ip-100-64-125-225.us-west-2.compute.internal
19m         Normal    Pulled                            pod/sas-batch-server-2f7bc580-391b-4052-a196-56f8327db377-16739     Container image "668749497752.dkr.ecr.us-west-2.amazonaws.com/sasviya/viya-4-x64_oci_linux_2-docker/sas-certframe:3.51.0-20240313.1710330811841" already present on machine
19m         Normal    Created                           pod/sas-batch-server-2f7bc580-391b-4052-a196-56f8327db377-16739     Created container sas-certframe
19m         Normal    Started                           pod/sas-batch-server-2f7bc580-391b-4052-a196-56f8327db377-16739     Started container sas-certframe
19m         Normal    Pulled                            pod/sas-batch-server-2f7bc580-391b-4052-a196-56f8327db377-16739     Container image "668749497752.dkr.ecr.us-west-2.amazonaws.com/sasviya/viya-4-x64_oci_linux_2-docker/sas-config-init:1.21.1-20240305.1709656957059" already present on machine
19m         Normal    Created                           pod/sas-batch-server-2f7bc580-391b-4052-a196-56f8327db377-16739     Created container sas-config-init
19m         Normal    Started                           pod/sas-batch-server-2f7bc580-391b-4052-a196-56f8327db377-16739     Started container sas-config-init
19m         Normal    Pulled                            pod/sas-batch-server-2f7bc580-391b-4052-a196-56f8327db377-16739     Container image "668749497752.dkr.ecr.us-west-2.amazonaws.com/sasviya/viya-4-x64_oci_linux_2-docker/sas-programming-environment:1.53.31-20240613.1718295947845" already present on machine
19m         Normal    Created                           pod/sas-batch-server-2f7bc580-391b-4052-a196-56f8327db377-16739     Created container sas-programming-environment
19m         Normal    Started                           pod/sas-batch-server-2f7bc580-391b-4052-a196-56f8327db377-16739     Started container sas-programming-environment
19m         Normal    Pulled                            pod/sas-batch-server-2f7bc580-391b-4052-a196-56f8327db377-16739     Container image "668749497752.dkr.ecr.us-west-2.amazonaws.com/sasviya/viya-4-x64_oci_linux_2-docker/sas-process-exporter:1.9.1-20240306.1709732097762" already present on machine
19m         Normal    Created                           pod/sas-batch-server-2f7bc580-391b-4052-a196-56f8327db377-16739     Created container sas-process-exporter
19m         Normal    Started                           pod/sas-batch-server-2f7bc580-391b-4052-a196-56f8327db377-16739     Started container sas-process-exporter
6m14s       Normal    Killing                           pod/sas-batch-server-2f7bc580-391b-4052-a196-56f8327db377-16739     Stopping container sas-process-exporter
19m         Normal    Scheduled                         pod/sas-batch-server-3163d751-378f-4b3c-a67a-41ccf6a8710f-16727     Successfully assigned viya-dev/sas-batch-server-3163d751-378f-4b3c-a67a-41ccf6a8710f-16727 to ip-100-64-125-225.us-west-2.compute.internal
19m         Normal    Pulled                            pod/sas-batch-server-3163d751-378f-4b3c-a67a-41ccf6a8710f-16727     Container image "668749497752.dkr.ecr.us-west-2.amazonaws.com/sasviya/viya-4-x64_oci_linux_2-docker/sas-certframe:3.51.0-20240313.1710330811841" already present on machine
19m         Normal    Created                           pod/sas-batch-server-3163d751-378f-4b3c-a67a-41ccf6a8710f-16727     Created container sas-certframe
19m         Normal    Started                           pod/sas-batch-server-3163d751-378f-4b3c-a67a-41ccf6a8710f-16727     Started container sas-certframe
19m         Normal    Pulled                            pod/sas-batch-server-3163d751-378f-4b3c-a67a-41ccf6a8710f-16727     Container image "668749497752.dkr.ecr.us-west-2.amazonaws.com/sasviya/viya-4-x64_oci_linux_2-docker/sas-config-init:1.21.1-20240305.1709656957059" already present on machine
19m         Normal    Created                           pod/sas-batch-server-3163d751-378f-4b3c-a67a-41ccf6a8710f-16727     Created container sas-config-init
19m         Normal    Started                           pod/sas-batch-server-3163d751-378f-4b3c-a67a-41ccf6a8710f-16727     Started container sas-config-init
19m         Normal    Pulled                            pod/sas-batch-server-3163d751-378f-4b3c-a67a-41ccf6a8710f-16727     Container image "668749497752.dkr.ecr.us-west-2.amazonaws.com/sasviya/viya-4-x64_oci_linux_2-docker/sas-programming-environment:1.53.31-20240613.1718295947845" already present on machine
19m         Normal    Created                           pod/sas-batch-server-3163d751-378f-4b3c-a67a-41ccf6a8710f-16727     Created container sas-programming-environment
19m         Normal    Started                           pod/sas-batch-server-3163d751-378f-4b3c-a67a-41ccf6a8710f-16727     Started container sas-programming-environment
19m         Normal    Pulled                            pod/sas-batch-server-3163d751-378f-4b3c-a67a-41ccf6a8710f-16727     Container image "668749497752.dkr.ecr.us-west-2.amazonaws.com/sasviya/viya-4-x64_oci_linux_2-docker/sas-process-exporter:1.9.1-20240306.1709732097762" already present on machine
19m         Normal    Created                           pod/sas-batch-server-3163d751-378f-4b3c-a67a-41ccf6a8710f-16727     Created container sas-process-exporter
19m         Normal    Started                           pod/sas-batch-server-3163d751-378f-4b3c-a67a-41ccf6a8710f-16727     Started container sas-process-exporter
9m33s       Normal    Killing                           pod/sas-batch-server-3163d751-378f-4b3c-a67a-41ccf6a8710f-16727     Stopping container sas-process-exporter
14m         Warning   FailedScheduling                  pod/sas-batch-server-3314bbe4-a9d1-44be-a3d7-17b0fb411b07-16747     0/10 nodes are available: 1 Insufficient cpu, 1 node(s) had untolerated taint {workload.sas.com/class: cas}, 1 node(s) had untolerated taint {workload.sas.com/class: stateful}, 1 node(s) had untolerated taint {workload.sas.com/class: stateless}, 6 node(s) didn't match Pod's node affinity/selector. preemption: 0/10 nodes are available: 1 No preemption victims found for incoming pod, 9 Preemption is not helpful for scheduling..
13m         Normal    Scheduled                         pod/sas-batch-server-3314bbe4-a9d1-44be-a3d7-17b0fb411b07-16747     Successfully assigned viya-dev/sas-batch-server-3314bbe4-a9d1-44be-a3d7-17b0fb411b07-16747 to ip-100-64-103-52.us-west-2.compute.internal
13m         Normal    Pulled                            pod/sas-batch-server-3314bbe4-a9d1-44be-a3d7-17b0fb411b07-16747     Container image "668749497752.dkr.ecr.us-west-2.amazonaws.com/sasviya/viya-4-x64_oci_linux_2-docker/sas-certframe:3.51.0-20240313.1710330811841" already present on machine
13m         Normal    Created                           pod/sas-batch-server-3314bbe4-a9d1-44be-a3d7-17b0fb411b07-16747     Created container sas-certframe
13m         Normal    Started                           pod/sas-batch-server-3314bbe4-a9d1-44be-a3d7-17b0fb411b07-16747     Started container sas-certframe
13m         Normal    Pulled                            pod/sas-batch-server-3314bbe4-a9d1-44be-a3d7-17b0fb411b07-16747     Container image "668749497752.dkr.ecr.us-west-2.amazonaws.com/sasviya/viya-4-x64_oci_linux_2-docker/sas-config-init:1.21.1-20240305.1709656957059" already present on machine
13m         Normal    Created                           pod/sas-batch-server-3314bbe4-a9d1-44be-a3d7-17b0fb411b07-16747     Created container sas-config-init
13m         Normal    Started                           pod/sas-batch-server-3314bbe4-a9d1-44be-a3d7-17b0fb411b07-16747     Started container sas-config-init
13m         Normal    Pulled                            pod/sas-batch-server-3314bbe4-a9d1-44be-a3d7-17b0fb411b07-16747     Container image "668749497752.dkr.ecr.us-west-2.amazonaws.com/sasviya/viya-4-x64_oci_linux_2-docker/sas-programming-environment:1.53.31-20240613.1718295947845" already present on machine
13m         Normal    Created                           pod/sas-batch-server-3314bbe4-a9d1-44be-a3d7-17b0fb411b07-16747     Created container sas-programming-environment
13m         Normal    Started                           pod/sas-batch-server-3314bbe4-a9d1-44be-a3d7-17b0fb411b07-16747     Started container sas-programming-environment
13m         Normal    Pulled                            pod/sas-batch-server-3314bbe4-a9d1-44be-a3d7-17b0fb411b07-16747     Container image "668749497752.dkr.ecr.us-west-2.amazonaws.com/sasviya/viya-4-x64_oci_linux_2-docker/sas-process-exporter:1.9.1-20240306.1709732097762" already present on machine
13m         Normal    Created                           pod/sas-batch-server-3314bbe4-a9d1-44be-a3d7-17b0fb411b07-16747     Created container sas-process-exporter
13m         Normal    Started                           pod/sas-batch-server-3314bbe4-a9d1-44be-a3d7-17b0fb411b07-16747     Started container sas-process-exporter
4m11s       Normal    Killing                           pod/sas-batch-server-3314bbe4-a9d1-44be-a3d7-17b0fb411b07-16747     Stopping container sas-process-exporter
59m         Normal    Scheduled                         pod/sas-batch-server-34eba98b-7c4c-4e2d-8449-2bcc17a9be01-16612     Successfully assigned viya-dev/sas-batch-server-34eba98b-7c4c-4e2d-8449-2bcc17a9be01-16612 to ip-100-64-103-52.us-west-2.compute.internal
59m         Normal    Pulled                            pod/sas-batch-server-34eba98b-7c4c-4e2d-8449-2bcc17a9be01-16612     Container image "668749497752.dkr.ecr.us-west-2.amazonaws.com/sasviya/viya-4-x64_oci_linux_2-docker/sas-certframe:3.51.0-20240313.1710330811841" already present on machine
59m         Normal    Created                           pod/sas-batch-server-34eba98b-7c4c-4e2d-8449-2bcc17a9be01-16612     Created container sas-certframe
59m         Normal    Started                           pod/sas-batch-server-34eba98b-7c4c-4e2d-8449-2bcc17a9be01-16612     Started container sas-certframe
59m         Normal    Pulled                            pod/sas-batch-server-34eba98b-7c4c-4e2d-8449-2bcc17a9be01-16612     Container image "668749497752.dkr.ecr.us-west-2.amazonaws.com/sasviya/viya-4-x64_oci_linux_2-docker/sas-config-init:1.21.1-20240305.1709656957059" already present on machine
59m         Normal    Created                           pod/sas-batch-server-34eba98b-7c4c-4e2d-8449-2bcc17a9be01-16612     Created container sas-config-init
59m         Normal    Started                           pod/sas-batch-server-34eba98b-7c4c-4e2d-8449-2bcc17a9be01-16612     Started container sas-config-init
59m         Normal    Pulled                            pod/sas-batch-server-34eba98b-7c4c-4e2d-8449-2bcc17a9be01-16612     Container image "668749497752.dkr.ecr.us-west-2.amazonaws.com/sasviya/viya-4-x64_oci_linux_2-docker/sas-programming-environment:1.53.31-20240613.1718295947845" already present on machine
59m         Normal    Created                           pod/sas-batch-server-34eba98b-7c4c-4e2d-8449-2bcc17a9be01-16612     Created container sas-programming-environment
59m         Normal    Started                           pod/sas-batch-server-34eba98b-7c4c-4e2d-8449-2bcc17a9be01-16612     Started container sas-programming-environment
59m         Normal    Pulled                            pod/sas-batch-server-34eba98b-7c4c-4e2d-8449-2bcc17a9be01-16612     Container image "668749497752.dkr.ecr.us-west-2.amazonaws.com/sasviya/viya-4-x64_oci_linux_2-docker/sas-process-exporter:1.9.1-20240306.1709732097762" already present on machine
59m         Normal    Created                           pod/sas-batch-server-34eba98b-7c4c-4e2d-8449-2bcc17a9be01-16612     Created container sas-process-exporter
59m         Normal    Started                           pod/sas-batch-server-34eba98b-7c4c-4e2d-8449-2bcc17a9be01-16612     Started container sas-process-exporter
48m         Normal    Killing                           pod/sas-batch-server-34eba98b-7c4c-4e2d-8449-2bcc17a9be01-16612     Stopping container sas-process-exporter
10m         Warning   FailedScheduling                  pod/sas-batch-server-3567055d-f2e2-4dc3-b788-1ca3bde69674-16782     0/10 nodes are available: 1 Insufficient cpu, 1 node(s) had untolerated taint {workload.sas.com/class: cas}, 1 node(s) had untolerated taint {workload.sas.com/class: stateful}, 1 node(s) had untolerated taint {workload.sas.com/class: stateless}, 6 node(s) didn't match Pod's node affinity/selector. preemption: 0/10 nodes are available: 1 No preemption victims found for incoming pod, 9 Preemption is not helpful for scheduling..
10m         Normal    Scheduled                         pod/sas-batch-server-3567055d-f2e2-4dc3-b788-1ca3bde69674-16782     Successfully assigned viya-dev/sas-batch-server-3567055d-f2e2-4dc3-b788-1ca3bde69674-16782 to ip-100-64-88-54.us-west-2.compute.internal
10m         Normal    Pulled                            pod/sas-batch-server-3567055d-f2e2-4dc3-b788-1ca3bde69674-16782     Container image "668749497752.dkr.ecr.us-west-2.amazonaws.com/sasviya/viya-4-x64_oci_linux_2-docker/sas-certframe:3.51.0-20240313.1710330811841" already present on machine
10m         Normal    Created                           pod/sas-batch-server-3567055d-f2e2-4dc3-b788-1ca3bde69674-16782     Created container sas-certframe
10m         Normal    Started                           pod/sas-batch-server-3567055d-f2e2-4dc3-b788-1ca3bde69674-16782     Started container sas-certframe
10m         Normal    Pulled                            pod/sas-batch-server-3567055d-f2e2-4dc3-b788-1ca3bde69674-16782     Container image "668749497752.dkr.ecr.us-west-2.amazonaws.com/sasviya/viya-4-x64_oci_linux_2-docker/sas-config-init:1.21.1-20240305.1709656957059" already present on machine
10m         Normal    Created                           pod/sas-batch-server-3567055d-f2e2-4dc3-b788-1ca3bde69674-16782     Created container sas-config-init
10m         Normal    Started                           pod/sas-batch-server-3567055d-f2e2-4dc3-b788-1ca3bde69674-16782     Started container sas-config-init
10m         Normal    Pulled                            pod/sas-batch-server-3567055d-f2e2-4dc3-b788-1ca3bde69674-16782     Container image "668749497752.dkr.ecr.us-west-2.amazonaws.com/sasviya/viya-4-x64_oci_linux_2-docker/sas-programming-environment:1.53.31-20240613.1718295947845" already present on machine
10m         Normal    Created                           pod/sas-batch-server-3567055d-f2e2-4dc3-b788-1ca3bde69674-16782     Created container sas-programming-environment
10m         Normal    Started                           pod/sas-batch-server-3567055d-f2e2-4dc3-b788-1ca3bde69674-16782     Started container sas-programming-environment
10m         Normal    Pulled                            pod/sas-batch-server-3567055d-f2e2-4dc3-b788-1ca3bde69674-16782     Container image "668749497752.dkr.ecr.us-west-2.amazonaws.com/sasviya/viya-4-x64_oci_linux_2-docker/sas-process-exporter:1.9.1-20240306.1709732097762" already present on machine
10m         Normal    Created                           pod/sas-batch-server-3567055d-f2e2-4dc3-b788-1ca3bde69674-16782     Created container sas-process-exporter
10m         Normal    Started                           pod/sas-batch-server-3567055d-f2e2-4dc3-b788-1ca3bde69674-16782     Started container sas-process-exporter
3m31s       Normal    Killing                           pod/sas-batch-server-3567055d-f2e2-4dc3-b788-1ca3bde69674-16782     Stopping container sas-process-exporter
19m         Normal    Scheduled                         pod/sas-batch-server-3593e98c-b45f-4d4a-b53a-e1133a3900d0-16708     Successfully assigned viya-dev/sas-batch-server-3593e98c-b45f-4d4a-b53a-e1133a3900d0-16708 to ip-100-64-118-98.us-west-2.compute.internal
19m         Normal    Pulled                            pod/sas-batch-server-3593e98c-b45f-4d4a-b53a-e1133a3900d0-16708     Container image "668749497752.dkr.ecr.us-west-2.amazonaws.com/sasviya/viya-4-x64_oci_linux_2-docker/sas-certframe:3.51.0-20240313.1710330811841" already present on machine
19m         Normal    Created                           pod/sas-batch-server-3593e98c-b45f-4d4a-b53a-e1133a3900d0-16708     Created container sas-certframe
19m         Normal    Started                           pod/sas-batch-server-3593e98c-b45f-4d4a-b53a-e1133a3900d0-16708     Started container sas-certframe
19m         Normal    Pulled                            pod/sas-batch-server-3593e98c-b45f-4d4a-b53a-e1133a3900d0-16708     Container image "668749497752.dkr.ecr.us-west-2.amazonaws.com/sasviya/viya-4-x64_oci_linux_2-docker/sas-config-init:1.21.1-20240305.1709656957059" already present on machine
19m         Normal    Created                           pod/sas-batch-server-3593e98c-b45f-4d4a-b53a-e1133a3900d0-16708     Created container sas-config-init
19m         Normal    Started                           pod/sas-batch-server-3593e98c-b45f-4d4a-b53a-e1133a3900d0-16708     Started container sas-config-init
19m         Normal    Pulled                            pod/sas-batch-server-3593e98c-b45f-4d4a-b53a-e1133a3900d0-16708     Container image "668749497752.dkr.ecr.us-west-2.amazonaws.com/sasviya/viya-4-x64_oci_linux_2-docker/sas-programming-environment:1.53.31-20240613.1718295947845" already present on machine
19m         Normal    Created                           pod/sas-batch-server-3593e98c-b45f-4d4a-b53a-e1133a3900d0-16708     Created container sas-programming-environment
19m         Normal    Started                           pod/sas-batch-server-3593e98c-b45f-4d4a-b53a-e1133a3900d0-16708     Started container sas-programming-environment
19m         Normal    Pulled                            pod/sas-batch-server-3593e98c-b45f-4d4a-b53a-e1133a3900d0-16708     Container image "668749497752.dkr.ecr.us-west-2.amazonaws.com/sasviya/viya-4-x64_oci_linux_2-docker/sas-process-exporter:1.9.1-20240306.1709732097762" already present on machine
19m         Normal    Created                           pod/sas-batch-server-3593e98c-b45f-4d4a-b53a-e1133a3900d0-16708     Created container sas-process-exporter
19m         Normal    Started                           pod/sas-batch-server-3593e98c-b45f-4d4a-b53a-e1133a3900d0-16708     Started container sas-process-exporter
11m         Normal    Killing                           pod/sas-batch-server-3593e98c-b45f-4d4a-b53a-e1133a3900d0-16708     Stopping container sas-process-exporter
11m         Warning   FailedScheduling                  pod/sas-batch-server-35e04db4-fd74-489e-8669-38e2a5fefe5c-16779     0/10 nodes are available: 1 Insufficient cpu, 1 node(s) had untolerated taint {workload.sas.com/class: cas}, 1 node(s) had untolerated taint {workload.sas.com/class: stateful}, 1 node(s) had untolerated taint {workload.sas.com/class: stateless}, 6 node(s) didn't match Pod's node affinity/selector. preemption: 0/10 nodes are available: 1 No preemption victims found for incoming pod, 9 Preemption is not helpful for scheduling..
11m         Normal    Scheduled                         pod/sas-batch-server-35e04db4-fd74-489e-8669-38e2a5fefe5c-16779     Successfully assigned viya-dev/sas-batch-server-35e04db4-fd74-489e-8669-38e2a5fefe5c-16779 to ip-100-64-118-98.us-west-2.compute.internal
11m         Normal    Pulled                            pod/sas-batch-server-35e04db4-fd74-489e-8669-38e2a5fefe5c-16779     Container image "668749497752.dkr.ecr.us-west-2.amazonaws.com/sasviya/viya-4-x64_oci_linux_2-docker/sas-certframe:3.51.0-20240313.1710330811841" already present on machine
11m         Normal    Created                           pod/sas-batch-server-35e04db4-fd74-489e-8669-38e2a5fefe5c-16779     Created container sas-certframe
11m         Normal    Started                           pod/sas-batch-server-35e04db4-fd74-489e-8669-38e2a5fefe5c-16779     Started container sas-certframe
11m         Normal    Pulled                            pod/sas-batch-server-35e04db4-fd74-489e-8669-38e2a5fefe5c-16779     Container image "668749497752.dkr.ecr.us-west-2.amazonaws.com/sasviya/viya-4-x64_oci_linux_2-docker/sas-config-init:1.21.1-20240305.1709656957059" already present on machine
11m         Normal    Created                           pod/sas-batch-server-35e04db4-fd74-489e-8669-38e2a5fefe5c-16779     Created container sas-config-init
11m         Normal    Started                           pod/sas-batch-server-35e04db4-fd74-489e-8669-38e2a5fefe5c-16779     Started container sas-config-init
11m         Normal    Pulled                            pod/sas-batch-server-35e04db4-fd74-489e-8669-38e2a5fefe5c-16779     Container image "668749497752.dkr.ecr.us-west-2.amazonaws.com/sasviya/viya-4-x64_oci_linux_2-docker/sas-programming-environment:1.53.31-20240613.1718295947845" already present on machine
11m         Normal    Created                           pod/sas-batch-server-35e04db4-fd74-489e-8669-38e2a5fefe5c-16779     Created container sas-programming-environment
11m         Normal    Started                           pod/sas-batch-server-35e04db4-fd74-489e-8669-38e2a5fefe5c-16779     Started container sas-programming-environment
11m         Normal    Pulled                            pod/sas-batch-server-35e04db4-fd74-489e-8669-38e2a5fefe5c-16779     Container image "668749497752.dkr.ecr.us-west-2.amazonaws.com/sasviya/viya-4-x64_oci_linux_2-docker/sas-process-exporter:1.9.1-20240306.1709732097762" already present on machine
11m         Normal    Created                           pod/sas-batch-server-35e04db4-fd74-489e-8669-38e2a5fefe5c-16779     Created container sas-process-exporter
11m         Normal    Started                           pod/sas-batch-server-35e04db4-fd74-489e-8669-38e2a5fefe5c-16779     Started container sas-process-exporter
3m55s       Normal    Killing                           pod/sas-batch-server-35e04db4-fd74-489e-8669-38e2a5fefe5c-16779     Stopping container sas-process-exporter
19m         Normal    Scheduled                         pod/sas-batch-server-38a3efd6-b9a7-43c2-aeae-8b2f5f51975d-16704     Successfully assigned viya-dev/sas-batch-server-38a3efd6-b9a7-43c2-aeae-8b2f5f51975d-16704 to ip-100-64-118-98.us-west-2.compute.internal
19m         Normal    Pulled                            pod/sas-batch-server-38a3efd6-b9a7-43c2-aeae-8b2f5f51975d-16704     Container image "668749497752.dkr.ecr.us-west-2.amazonaws.com/sasviya/viya-4-x64_oci_linux_2-docker/sas-certframe:3.51.0-20240313.1710330811841" already present on machine
19m         Normal    Created                           pod/sas-batch-server-38a3efd6-b9a7-43c2-aeae-8b2f5f51975d-16704     Created container sas-certframe
19m         Normal    Started                           pod/sas-batch-server-38a3efd6-b9a7-43c2-aeae-8b2f5f51975d-16704     Started container sas-certframe
19m         Normal    Pulled                            pod/sas-batch-server-38a3efd6-b9a7-43c2-aeae-8b2f5f51975d-16704     Container image "668749497752.dkr.ecr.us-west-2.amazonaws.com/sasviya/viya-4-x64_oci_linux_2-docker/sas-config-init:1.21.1-20240305.1709656957059" already present on machine
19m         Normal    Created                           pod/sas-batch-server-38a3efd6-b9a7-43c2-aeae-8b2f5f51975d-16704     Created container sas-config-init
19m         Normal    Started                           pod/sas-batch-server-38a3efd6-b9a7-43c2-aeae-8b2f5f51975d-16704     Started container sas-config-init
19m         Normal    Pulled                            pod/sas-batch-server-38a3efd6-b9a7-43c2-aeae-8b2f5f51975d-16704     Container image "668749497752.dkr.ecr.us-west-2.amazonaws.com/sasviya/viya-4-x64_oci_linux_2-docker/sas-programming-environment:1.53.31-20240613.1718295947845" already present on machine
19m         Normal    Created                           pod/sas-batch-server-38a3efd6-b9a7-43c2-aeae-8b2f5f51975d-16704     Created container sas-programming-environment
19m         Normal    Started                           pod/sas-batch-server-38a3efd6-b9a7-43c2-aeae-8b2f5f51975d-16704     Started container sas-programming-environment
19m         Normal    Pulled                            pod/sas-batch-server-38a3efd6-b9a7-43c2-aeae-8b2f5f51975d-16704     Container image "668749497752.dkr.ecr.us-west-2.amazonaws.com/sasviya/viya-4-x64_oci_linux_2-docker/sas-process-exporter:1.9.1-20240306.1709732097762" already present on machine
19m         Normal    Created                           pod/sas-batch-server-38a3efd6-b9a7-43c2-aeae-8b2f5f51975d-16704     Created container sas-process-exporter
19m         Normal    Started                           pod/sas-batch-server-38a3efd6-b9a7-43c2-aeae-8b2f5f51975d-16704     Started container sas-process-exporter
13m         Normal    Killing                           pod/sas-batch-server-38a3efd6-b9a7-43c2-aeae-8b2f5f51975d-16704     Stopping container sas-process-exporter
58m         Warning   FailedScheduling                  pod/sas-batch-server-38ada97d-213e-41e8-81ba-d880000b3291-16649     0/9 nodes are available: 1 Insufficient cpu, 1node(s) had untolerated taint {workload.sas.com/class: cas}, 1 node(s) had untolerated taint {workload.sas.com/class: stateful}, 1 node(s) had untolerated taint {workload.sas.com/class: stateless}, 5 node(s) didn't match Pod's node affinity/selector. preemption: 0/9 nodes are available: 1 No preemption victims found for incoming pod, 8 Preemption is not helpful for scheduling..
59m         Normal    NotTriggerScaleUp                 pod/sas-batch-server-38ada97d-213e-41e8-81ba-d880000b3291-16649     pod didn't trigger scale-up: 1 node(s) had untolerated taint {workload.sas.com/class: cas}, 2 node(s) didn't match Pod's node affinity/selector, 1 node(s) had untolerated taint {workload.sas.com/class: stateful}, 1 node(s) had untolerated taint {workload.sas.com/class: stateless}
49m         Warning   FailedScheduling                  pod/sas-batch-server-38ada97d-213e-41e8-81ba-d880000b3291-16649     0/10 nodes are available: 1 Insufficient cpu, 1 node(s) had untolerated taint {workload.sas.com/class: cas}, 1 node(s) had untolerated taint {workload.sas.com/class: stateful}, 1 node(s) had untolerated taint {workload.sas.com/class: stateless}, 6 node(s) didn't match Pod's node affinity/selector. preemption: 0/10 nodes are available: 1 No preemption victims found for incoming pod, 9 Preemption is not helpful for scheduling..
48m         Normal    Scheduled                         pod/sas-batch-server-38ada97d-213e-41e8-81ba-d880000b3291-16649     Successfully assigned viya-dev/sas-batch-server-38ada97d-213e-41e8-81ba-d880000b3291-16649 to ip-100-64-118-176.us-west-2.compute.internal
48m         Normal    Pulled                            pod/sas-batch-server-38ada97d-213e-41e8-81ba-d880000b3291-16649     Container image "668749497752.dkr.ecr.us-west-2.amazonaws.com/sasviya/viya-4-x64_oci_linux_2-docker/sas-certframe:3.51.0-20240313.1710330811841" already present on machine
48m         Normal    Created                           pod/sas-batch-server-38ada97d-213e-41e8-81ba-d880000b3291-16649     Created container sas-certframe
48m         Normal    Started                           pod/sas-batch-server-38ada97d-213e-41e8-81ba-d880000b3291-16649     Started container sas-certframe
48m         Normal    Pulled                            pod/sas-batch-server-38ada97d-213e-41e8-81ba-d880000b3291-16649     Container image "668749497752.dkr.ecr.us-west-2.amazonaws.com/sasviya/viya-4-x64_oci_linux_2-docker/sas-config-init:1.21.1-20240305.1709656957059" already present on machine
48m         Normal    Created                           pod/sas-batch-server-38ada97d-213e-41e8-81ba-d880000b3291-16649     Created container sas-config-init
48m         Normal    Started                           pod/sas-batch-server-38ada97d-213e-41e8-81ba-d880000b3291-16649     Started container sas-config-init
48m         Normal    Pulled                            pod/sas-batch-server-38ada97d-213e-41e8-81ba-d880000b3291-16649     Container image "668749497752.dkr.ecr.us-west-2.amazonaws.com/sasviya/viya-4-x64_oci_linux_2-docker/sas-programming-environment:1.53.31-20240613.1718295947845" already present on machine
48m         Normal    Created                           pod/sas-batch-server-38ada97d-213e-41e8-81ba-d880000b3291-16649     Created container sas-programming-environment
48m         Normal    Started                           pod/sas-batch-server-38ada97d-213e-41e8-81ba-d880000b3291-16649     Started container sas-programming-environment
48m         Normal    Pulled                            pod/sas-batch-server-38ada97d-213e-41e8-81ba-d880000b3291-16649     Container image "668749497752.dkr.ecr.us-west-2.amazonaws.com/sasviya/viya-4-x64_oci_linux_2-docker/sas-process-exporter:1.9.1-20240306.1709732097762" already present on machine
48m         Normal    Created                           pod/sas-batch-server-38ada97d-213e-41e8-81ba-d880000b3291-16649     Created container sas-process-exporter
48m         Normal    Started                           pod/sas-batch-server-38ada97d-213e-41e8-81ba-d880000b3291-16649     Started container sas-process-exporter
46m         Normal    Killing                           pod/sas-batch-server-38ada97d-213e-41e8-81ba-d880000b3291-16649     Stopping container sas-process-exporter
55m         Normal    Killing                           pod/sas-batch-server-3b3d13fb-9e29-46e1-b0a7-a65a2df99a56-16599     Stopping container sas-process-exporter
58m         Normal    Killing                           pod/sas-batch-server-3e957f6d-a3bf-4866-8949-7b3295d8a986-16587     Stopping container sas-process-exporter
59m         Normal    Scheduled                         pod/sas-batch-server-3ece5439-8bcf-4d18-b736-79d1a7594979-16626     Successfully assigned viya-dev/sas-batch-server-3ece5439-8bcf-4d18-b736-79d1a7594979-16626 to ip-100-64-118-98.us-west-2.compute.internal
59m         Normal    Pulled                            pod/sas-batch-server-3ece5439-8bcf-4d18-b736-79d1a7594979-16626     Container image "668749497752.dkr.ecr.us-west-2.amazonaws.com/sasviya/viya-4-x64_oci_linux_2-docker/sas-certframe:3.51.0-20240313.1710330811841" already present on machine
59m         Normal    Created                           pod/sas-batch-server-3ece5439-8bcf-4d18-b736-79d1a7594979-16626     Created container sas-certframe
59m         Normal    Started                           pod/sas-batch-server-3ece5439-8bcf-4d18-b736-79d1a7594979-16626     Started container sas-certframe
59m         Normal    Pulled                            pod/sas-batch-server-3ece5439-8bcf-4d18-b736-79d1a7594979-16626     Container image "668749497752.dkr.ecr.us-west-2.amazonaws.com/sasviya/viya-4-x64_oci_linux_2-docker/sas-config-init:1.21.1-20240305.1709656957059" already present on machine
59m         Normal    Created                           pod/sas-batch-server-3ece5439-8bcf-4d18-b736-79d1a7594979-16626     Created container sas-config-init
59m         Normal    Started                           pod/sas-batch-server-3ece5439-8bcf-4d18-b736-79d1a7594979-16626     Started container sas-config-init
59m         Normal    Pulled                            pod/sas-batch-server-3ece5439-8bcf-4d18-b736-79d1a7594979-16626     Container image "668749497752.dkr.ecr.us-west-2.amazonaws.com/sasviya/viya-4-x64_oci_linux_2-docker/sas-programming-environment:1.53.31-20240613.1718295947845" already present on machine
59m         Normal    Created                           pod/sas-batch-server-3ece5439-8bcf-4d18-b736-79d1a7594979-16626     Created container sas-programming-environment
59m         Normal    Started                           pod/sas-batch-server-3ece5439-8bcf-4d18-b736-79d1a7594979-16626     Started container sas-programming-environment
59m         Normal    Pulled                            pod/sas-batch-server-3ece5439-8bcf-4d18-b736-79d1a7594979-16626     Container image "668749497752.dkr.ecr.us-west-2.amazonaws.com/sasviya/viya-4-x64_oci_linux_2-docker/sas-process-exporter:1.9.1-20240306.1709732097762" already present on machine
59m         Normal    Created                           pod/sas-batch-server-3ece5439-8bcf-4d18-b736-79d1a7594979-16626     Created container sas-process-exporter
59m         Normal    Started                           pod/sas-batch-server-3ece5439-8bcf-4d18-b736-79d1a7594979-16626     Started container sas-process-exporter
49m         Normal    Killing                           pod/sas-batch-server-3ece5439-8bcf-4d18-b736-79d1a7594979-16626     Stopping container sas-process-exporter
59m         Normal    Scheduled                         pod/sas-batch-server-425f6b16-5dc9-4a41-9e84-febe0b4b18c6-16610     Successfully assigned viya-dev/sas-batch-server-425f6b16-5dc9-4a41-9e84-febe0b4b18c6-16610 to ip-100-64-88-54.us-west-2.compute.internal
59m         Normal    Pulled                            pod/sas-batch-server-425f6b16-5dc9-4a41-9e84-febe0b4b18c6-16610     Container image "668749497752.dkr.ecr.us-west-2.amazonaws.com/sasviya/viya-4-x64_oci_linux_2-docker/sas-certframe:3.51.0-20240313.1710330811841" already present on machine
59m         Normal    Created                           pod/sas-batch-server-425f6b16-5dc9-4a41-9e84-febe0b4b18c6-16610     Created container sas-certframe
59m         Normal    Started                           pod/sas-batch-server-425f6b16-5dc9-4a41-9e84-febe0b4b18c6-16610     Started container sas-certframe
59m         Normal    Pulled                            pod/sas-batch-server-425f6b16-5dc9-4a41-9e84-febe0b4b18c6-16610     Container image "668749497752.dkr.ecr.us-west-2.amazonaws.com/sasviya/viya-4-x64_oci_linux_2-docker/sas-config-init:1.21.1-20240305.1709656957059" already present on machine
59m         Normal    Created                           pod/sas-batch-server-425f6b16-5dc9-4a41-9e84-febe0b4b18c6-16610     Created container sas-config-init
59m         Normal    Started                           pod/sas-batch-server-425f6b16-5dc9-4a41-9e84-febe0b4b18c6-16610     Started container sas-config-init
59m         Normal    Pulled                            pod/sas-batch-server-425f6b16-5dc9-4a41-9e84-febe0b4b18c6-16610     Container image "668749497752.dkr.ecr.us-west-2.amazonaws.com/sasviya/viya-4-x64_oci_linux_2-docker/sas-programming-environment:1.53.31-20240613.1718295947845" already present on machine
59m         Normal    Created                           pod/sas-batch-server-425f6b16-5dc9-4a41-9e84-febe0b4b18c6-16610     Created container sas-programming-environment
59m         Normal    Started                           pod/sas-batch-server-425f6b16-5dc9-4a41-9e84-febe0b4b18c6-16610     Started container sas-programming-environment
59m         Normal    Pulled                            pod/sas-batch-server-425f6b16-5dc9-4a41-9e84-febe0b4b18c6-16610     Container image "668749497752.dkr.ecr.us-west-2.amazonaws.com/sasviya/viya-4-x64_oci_linux_2-docker/sas-process-exporter:1.9.1-20240306.1709732097762" already present on machine
59m         Normal    Created                           pod/sas-batch-server-425f6b16-5dc9-4a41-9e84-febe0b4b18c6-16610     Created container sas-process-exporter
59m         Normal    Started                           pod/sas-batch-server-425f6b16-5dc9-4a41-9e84-febe0b4b18c6-16610     Started container sas-process-exporter
54m         Normal    Killing                           pod/sas-batch-server-425f6b16-5dc9-4a41-9e84-febe0b4b18c6-16610     Stopping container sas-process-exporter
22m         Normal    Scheduled                         pod/sas-batch-server-42634161-f878-4eac-a666-80f730a050b8-16686     Successfully assigned viya-dev/sas-batch-server-42634161-f878-4eac-a666-80f730a050b8-16686 to ip-100-64-118-176.us-west-2.compute.internal
22m         Normal    Pulled                            pod/sas-batch-server-42634161-f878-4eac-a666-80f730a050b8-16686     Container image "668749497752.dkr.ecr.us-west-2.amazonaws.com/sasviya/viya-4-x64_oci_linux_2-docker/sas-certframe:3.51.0-20240313.1710330811841" already present on machine
22m         Normal    Created                           pod/sas-batch-server-42634161-f878-4eac-a666-80f730a050b8-16686     Created container sas-certframe
22m         Normal    Started                           pod/sas-batch-server-42634161-f878-4eac-a666-80f730a050b8-16686     Started container sas-certframe
22m         Normal    Pulled                            pod/sas-batch-server-42634161-f878-4eac-a666-80f730a050b8-16686     Container image "668749497752.dkr.ecr.us-west-2.amazonaws.com/sasviya/viya-4-x64_oci_linux_2-docker/sas-config-init:1.21.1-20240305.1709656957059" already present on machine
22m         Normal    Created                           pod/sas-batch-server-42634161-f878-4eac-a666-80f730a050b8-16686     Created container sas-config-init
22m         Normal    Started                           pod/sas-batch-server-42634161-f878-4eac-a666-80f730a050b8-16686     Started container sas-config-init
22m         Normal    Pulled                            pod/sas-batch-server-42634161-f878-4eac-a666-80f730a050b8-16686     Container image "668749497752.dkr.ecr.us-west-2.amazonaws.com/sasviya/viya-4-x64_oci_linux_2-docker/sas-programming-environment:1.53.31-20240613.1718295947845" already present on machine
22m         Normal    Created                           pod/sas-batch-server-42634161-f878-4eac-a666-80f730a050b8-16686     Created container sas-programming-environment
22m         Normal    Started                           pod/sas-batch-server-42634161-f878-4eac-a666-80f730a050b8-16686     Started container sas-programming-environment
22m         Normal    Pulled                            pod/sas-batch-server-42634161-f878-4eac-a666-80f730a050b8-16686     Container image "668749497752.dkr.ecr.us-west-2.amazonaws.com/sasviya/viya-4-x64_oci_linux_2-docker/sas-process-exporter:1.9.1-20240306.1709732097762" already present on machine
22m         Normal    Created                           pod/sas-batch-server-42634161-f878-4eac-a666-80f730a050b8-16686     Created container sas-process-exporter
22m         Normal    Started                           pod/sas-batch-server-42634161-f878-4eac-a666-80f730a050b8-16686     Started container sas-process-exporter
22m         Normal    Killing                           pod/sas-batch-server-42634161-f878-4eac-a666-80f730a050b8-16686     Stopping container sas-process-exporter
20m         Normal    Scheduled                         pod/sas-batch-server-43720649-8c40-4b3a-aea0-30591eeab46b-16692     Successfully assigned viya-dev/sas-batch-server-43720649-8c40-4b3a-aea0-30591eeab46b-16692 to ip-100-64-103-52.us-west-2.compute.internal
20m         Normal    Pulled                            pod/sas-batch-server-43720649-8c40-4b3a-aea0-30591eeab46b-16692     Container image "668749497752.dkr.ecr.us-west-2.amazonaws.com/sasviya/viya-4-x64_oci_linux_2-docker/sas-certframe:3.51.0-20240313.1710330811841" already present on machine
20m         Normal    Created                           pod/sas-batch-server-43720649-8c40-4b3a-aea0-30591eeab46b-16692     Created container sas-certframe
20m         Normal    Started                           pod/sas-batch-server-43720649-8c40-4b3a-aea0-30591eeab46b-16692     Started container sas-certframe
20m         Normal    Pulled                            pod/sas-batch-server-43720649-8c40-4b3a-aea0-30591eeab46b-16692     Container image "668749497752.dkr.ecr.us-west-2.amazonaws.com/sasviya/viya-4-x64_oci_linux_2-docker/sas-config-init:1.21.1-20240305.1709656957059" already present on machine
20m         Normal    Created                           pod/sas-batch-server-43720649-8c40-4b3a-aea0-30591eeab46b-16692     Created container sas-config-init
20m         Normal    Started                           pod/sas-batch-server-43720649-8c40-4b3a-aea0-30591eeab46b-16692     Started container sas-config-init
20m         Normal    Pulled                            pod/sas-batch-server-43720649-8c40-4b3a-aea0-30591eeab46b-16692     Container image "668749497752.dkr.ecr.us-west-2.amazonaws.com/sasviya/viya-4-x64_oci_linux_2-docker/sas-programming-environment:1.53.31-20240613.1718295947845" already present on machine
20m         Normal    Created                           pod/sas-batch-server-43720649-8c40-4b3a-aea0-30591eeab46b-16692     Created container sas-programming-environment
20m         Normal    Started                           pod/sas-batch-server-43720649-8c40-4b3a-aea0-30591eeab46b-16692     Started container sas-programming-environment
20m         Normal    Pulled                            pod/sas-batch-server-43720649-8c40-4b3a-aea0-30591eeab46b-16692     Container image "668749497752.dkr.ecr.us-west-2.amazonaws.com/sasviya/viya-4-x64_oci_linux_2-docker/sas-process-exporter:1.9.1-20240306.1709732097762" already present on machine
20m         Normal    Created                           pod/sas-batch-server-43720649-8c40-4b3a-aea0-30591eeab46b-16692     Created container sas-process-exporter
20m         Normal    Started                           pod/sas-batch-server-43720649-8c40-4b3a-aea0-30591eeab46b-16692     Started container sas-process-exporter
13m         Normal    Killing                           pod/sas-batch-server-43720649-8c40-4b3a-aea0-30591eeab46b-16692     Stopping container sas-process-exporter
19m         Normal    Scheduled                         pod/sas-batch-server-44467b76-6bea-49bd-8496-528a60bf6210-16767     Successfully assigned viya-dev/sas-batch-server-44467b76-6bea-49bd-8496-528a60bf6210-16767 to ip-100-64-125-225.us-west-2.compute.internal
19m         Normal    Pulled                            pod/sas-batch-server-44467b76-6bea-49bd-8496-528a60bf6210-16767     Container image "668749497752.dkr.ecr.us-west-2.amazonaws.com/sasviya/viya-4-x64_oci_linux_2-docker/sas-certframe:3.51.0-20240313.1710330811841" already present on machine
19m         Normal    Created                           pod/sas-batch-server-44467b76-6bea-49bd-8496-528a60bf6210-16767     Created container sas-certframe
19m         Normal    Started                           pod/sas-batch-server-44467b76-6bea-49bd-8496-528a60bf6210-16767     Started container sas-certframe
19m         Normal    Pulled                            pod/sas-batch-server-44467b76-6bea-49bd-8496-528a60bf6210-16767     Container image "668749497752.dkr.ecr.us-west-2.amazonaws.com/sasviya/viya-4-x64_oci_linux_2-docker/sas-config-init:1.21.1-20240305.1709656957059" already present on machine
19m         Normal    Created                           pod/sas-batch-server-44467b76-6bea-49bd-8496-528a60bf6210-16767     Created container sas-config-init
19m         Normal    Started                           pod/sas-batch-server-44467b76-6bea-49bd-8496-528a60bf6210-16767     Started container sas-config-init
19m         Normal    Pulled                            pod/sas-batch-server-44467b76-6bea-49bd-8496-528a60bf6210-16767     Container image "668749497752.dkr.ecr.us-west-2.amazonaws.com/sasviya/viya-4-x64_oci_linux_2-docker/sas-programming-environment:1.53.31-20240613.1718295947845" already present on machine
19m         Normal    Created                           pod/sas-batch-server-44467b76-6bea-49bd-8496-528a60bf6210-16767     Created container sas-programming-environment
19m         Normal    Started                           pod/sas-batch-server-44467b76-6bea-49bd-8496-528a60bf6210-16767     Started container sas-programming-environment
19m         Normal    Pulled                            pod/sas-batch-server-44467b76-6bea-49bd-8496-528a60bf6210-16767     Container image "668749497752.dkr.ecr.us-west-2.amazonaws.com/sasviya/viya-4-x64_oci_linux_2-docker/sas-process-exporter:1.9.1-20240306.1709732097762" already present on machine
19m         Normal    Created                           pod/sas-batch-server-44467b76-6bea-49bd-8496-528a60bf6210-16767     Created container sas-process-exporter
19m         Normal    Started                           pod/sas-batch-server-44467b76-6bea-49bd-8496-528a60bf6210-16767     Started container sas-process-exporter
5m55s       Normal    Killing                           pod/sas-batch-server-44467b76-6bea-49bd-8496-528a60bf6210-16767     Stopping container sas-process-exporter
19m         Normal    Scheduled                         pod/sas-batch-server-47e8e88b-afd1-48f0-b0fb-90058f606732-16700     Successfully assigned viya-dev/sas-batch-server-47e8e88b-afd1-48f0-b0fb-90058f606732-16700 to ip-100-64-88-54.us-west-2.compute.internal
19m         Normal    Pulled                            pod/sas-batch-server-47e8e88b-afd1-48f0-b0fb-90058f606732-16700     Container image "668749497752.dkr.ecr.us-west-2.amazonaws.com/sasviya/viya-4-x64_oci_linux_2-docker/sas-certframe:3.51.0-20240313.1710330811841" already present on machine
19m         Normal    Created                           pod/sas-batch-server-47e8e88b-afd1-48f0-b0fb-90058f606732-16700     Created container sas-certframe
19m         Normal    Started                           pod/sas-batch-server-47e8e88b-afd1-48f0-b0fb-90058f606732-16700     Started container sas-certframe
19m         Normal    Pulled                            pod/sas-batch-server-47e8e88b-afd1-48f0-b0fb-90058f606732-16700     Container image "668749497752.dkr.ecr.us-west-2.amazonaws.com/sasviya/viya-4-x64_oci_linux_2-docker/sas-config-init:1.21.1-20240305.1709656957059" already present on machine
19m         Normal    Created                           pod/sas-batch-server-47e8e88b-afd1-48f0-b0fb-90058f606732-16700     Created container sas-config-init
19m         Normal    Started                           pod/sas-batch-server-47e8e88b-afd1-48f0-b0fb-90058f606732-16700     Started container sas-config-init
19m         Normal    Pulled                            pod/sas-batch-server-47e8e88b-afd1-48f0-b0fb-90058f606732-16700     Container image "668749497752.dkr.ecr.us-west-2.amazonaws.com/sasviya/viya-4-x64_oci_linux_2-docker/sas-programming-environment:1.53.31-20240613.1718295947845" already present on machine
19m         Normal    Created                           pod/sas-batch-server-47e8e88b-afd1-48f0-b0fb-90058f606732-16700     Created container sas-programming-environment
19m         Normal    Started                           pod/sas-batch-server-47e8e88b-afd1-48f0-b0fb-90058f606732-16700     Started container sas-programming-environment
19m         Normal    Pulled                            pod/sas-batch-server-47e8e88b-afd1-48f0-b0fb-90058f606732-16700     Container image "668749497752.dkr.ecr.us-west-2.amazonaws.com/sasviya/viya-4-x64_oci_linux_2-docker/sas-process-exporter:1.9.1-20240306.1709732097762" already present on machine
19m         Normal    Created                           pod/sas-batch-server-47e8e88b-afd1-48f0-b0fb-90058f606732-16700     Created container sas-process-exporter
19m         Normal    Started                           pod/sas-batch-server-47e8e88b-afd1-48f0-b0fb-90058f606732-16700     Started container sas-process-exporter
11m         Normal    Killing                           pod/sas-batch-server-47e8e88b-afd1-48f0-b0fb-90058f606732-16700     Stopping container sas-process-exporter
59m         Normal    Scheduled                         pod/sas-batch-server-49ba7e71-3362-4142-81fe-3f31948730ce-16652     Successfully assigned viya-dev/sas-batch-server-49ba7e71-3362-4142-81fe-3f31948730ce-16652 to ip-100-64-103-52.us-west-2.compute.internal
59m         Normal    Pulled                            pod/sas-batch-server-49ba7e71-3362-4142-81fe-3f31948730ce-16652     Container image "668749497752.dkr.ecr.us-west-2.amazonaws.com/sasviya/viya-4-x64_oci_linux_2-docker/sas-certframe:3.51.0-20240313.1710330811841" already present on machine
59m         Normal    Created                           pod/sas-batch-server-49ba7e71-3362-4142-81fe-3f31948730ce-16652     Created container sas-certframe
59m         Normal    Started                           pod/sas-batch-server-49ba7e71-3362-4142-81fe-3f31948730ce-16652     Started container sas-certframe
59m         Normal    Pulled                            pod/sas-batch-server-49ba7e71-3362-4142-81fe-3f31948730ce-16652     Container image "668749497752.dkr.ecr.us-west-2.amazonaws.com/sasviya/viya-4-x64_oci_linux_2-docker/sas-config-init:1.21.1-20240305.1709656957059" already present on machine
59m         Normal    Created                           pod/sas-batch-server-49ba7e71-3362-4142-81fe-3f31948730ce-16652     Created container sas-config-init
59m         Normal    Started                           pod/sas-batch-server-49ba7e71-3362-4142-81fe-3f31948730ce-16652     Started container sas-config-init
59m         Normal    Pulled                            pod/sas-batch-server-49ba7e71-3362-4142-81fe-3f31948730ce-16652     Container image "668749497752.dkr.ecr.us-west-2.amazonaws.com/sasviya/viya-4-x64_oci_linux_2-docker/sas-programming-environment:1.53.31-20240613.1718295947845" already present on machine
59m         Normal    Created                           pod/sas-batch-server-49ba7e71-3362-4142-81fe-3f31948730ce-16652     Created container sas-programming-environment
59m         Normal    Started                           pod/sas-batch-server-49ba7e71-3362-4142-81fe-3f31948730ce-16652     Started container sas-programming-environment
59m         Normal    Pulled                            pod/sas-batch-server-49ba7e71-3362-4142-81fe-3f31948730ce-16652     Container image "668749497752.dkr.ecr.us-west-2.amazonaws.com/sasviya/viya-4-x64_oci_linux_2-docker/sas-process-exporter:1.9.1-20240306.1709732097762" already present on machine
59m         Normal    Created                           pod/sas-batch-server-49ba7e71-3362-4142-81fe-3f31948730ce-16652     Created container sas-process-exporter
59m         Normal    Started                           pod/sas-batch-server-49ba7e71-3362-4142-81fe-3f31948730ce-16652     Started container sas-process-exporter
47m         Normal    Killing                           pod/sas-batch-server-49ba7e71-3362-4142-81fe-3f31948730ce-16652     Stopping container sas-process-exporter
55m         Normal    Killing                           pod/sas-batch-server-4a9111e2-dd07-403b-8b2d-7abdbe473020-16603     Stopping container sas-process-exporter
59m         Normal    Scheduled                         pod/sas-batch-server-4adaa90b-ec17-492f-999c-c727c4491ff4-16654     Successfully assigned viya-dev/sas-batch-server-4adaa90b-ec17-492f-999c-c727c4491ff4-16654 to ip-100-64-103-52.us-west-2.compute.internal
59m         Normal    Pulled                            pod/sas-batch-server-4adaa90b-ec17-492f-999c-c727c4491ff4-16654     Container image "668749497752.dkr.ecr.us-west-2.amazonaws.com/sasviya/viya-4-x64_oci_linux_2-docker/sas-certframe:3.51.0-20240313.1710330811841" already present on machine
59m         Normal    Created                           pod/sas-batch-server-4adaa90b-ec17-492f-999c-c727c4491ff4-16654     Created container sas-certframe
59m         Normal    Started                           pod/sas-batch-server-4adaa90b-ec17-492f-999c-c727c4491ff4-16654     Started container sas-certframe
59m         Normal    Pulled                            pod/sas-batch-server-4adaa90b-ec17-492f-999c-c727c4491ff4-16654     Container image "668749497752.dkr.ecr.us-west-2.amazonaws.com/sasviya/viya-4-x64_oci_linux_2-docker/sas-config-init:1.21.1-20240305.1709656957059" already present on machine
59m         Normal    Created                           pod/sas-batch-server-4adaa90b-ec17-492f-999c-c727c4491ff4-16654     Created container sas-config-init
59m         Normal    Started                           pod/sas-batch-server-4adaa90b-ec17-492f-999c-c727c4491ff4-16654     Started container sas-config-init
59m         Normal    Pulled                            pod/sas-batch-server-4adaa90b-ec17-492f-999c-c727c4491ff4-16654     Container image "668749497752.dkr.ecr.us-west-2.amazonaws.com/sasviya/viya-4-x64_oci_linux_2-docker/sas-programming-environment:1.53.31-20240613.1718295947845" already present on machine
59m         Normal    Created                           pod/sas-batch-server-4adaa90b-ec17-492f-999c-c727c4491ff4-16654     Created container sas-programming-environment
59m         Normal    Started                           pod/sas-batch-server-4adaa90b-ec17-492f-999c-c727c4491ff4-16654     Started container sas-programming-environment
59m         Normal    Pulled                            pod/sas-batch-server-4adaa90b-ec17-492f-999c-c727c4491ff4-16654     Container image "668749497752.dkr.ecr.us-west-2.amazonaws.com/sasviya/viya-4-x64_oci_linux_2-docker/sas-process-exporter:1.9.1-20240306.1709732097762" already present on machine
59m         Normal    Created                           pod/sas-batch-server-4adaa90b-ec17-492f-999c-c727c4491ff4-16654     Created container sas-process-exporter
59m         Normal    Started                           pod/sas-batch-server-4adaa90b-ec17-492f-999c-c727c4491ff4-16654     Started container sas-process-exporter
47m         Normal    Killing                           pod/sas-batch-server-4adaa90b-ec17-492f-999c-c727c4491ff4-16654     Stopping container sas-process-exporter
19m         Normal    Scheduled                         pod/sas-batch-server-4bad4d9f-67f2-4709-b152-30e8ae17d268-16714     Successfully assigned viya-dev/sas-batch-server-4bad4d9f-67f2-4709-b152-30e8ae17d268-16714 to ip-100-64-103-52.us-west-2.compute.internal
19m         Normal    Pulled                            pod/sas-batch-server-4bad4d9f-67f2-4709-b152-30e8ae17d268-16714     Container image "668749497752.dkr.ecr.us-west-2.amazonaws.com/sasviya/viya-4-x64_oci_linux_2-docker/sas-certframe:3.51.0-20240313.1710330811841" already present on machine
19m         Normal    Created                           pod/sas-batch-server-4bad4d9f-67f2-4709-b152-30e8ae17d268-16714     Created container sas-certframe
19m         Normal    Started                           pod/sas-batch-server-4bad4d9f-67f2-4709-b152-30e8ae17d268-16714     Started container sas-certframe
19m         Normal    Pulled                            pod/sas-batch-server-4bad4d9f-67f2-4709-b152-30e8ae17d268-16714     Container image "668749497752.dkr.ecr.us-west-2.amazonaws.com/sasviya/viya-4-x64_oci_linux_2-docker/sas-config-init:1.21.1-20240305.1709656957059" already present on machine
19m         Normal    Created                           pod/sas-batch-server-4bad4d9f-67f2-4709-b152-30e8ae17d268-16714     Created container sas-config-init
19m         Normal    Started                           pod/sas-batch-server-4bad4d9f-67f2-4709-b152-30e8ae17d268-16714     Started container sas-config-init
19m         Normal    Pulled                            pod/sas-batch-server-4bad4d9f-67f2-4709-b152-30e8ae17d268-16714     Container image "668749497752.dkr.ecr.us-west-2.amazonaws.com/sasviya/viya-4-x64_oci_linux_2-docker/sas-programming-environment:1.53.31-20240613.1718295947845" already present on machine
19m         Normal    Created                           pod/sas-batch-server-4bad4d9f-67f2-4709-b152-30e8ae17d268-16714     Created container sas-programming-environment
19m         Normal    Started                           pod/sas-batch-server-4bad4d9f-67f2-4709-b152-30e8ae17d268-16714     Started container sas-programming-environment
19m         Normal    Pulled                            pod/sas-batch-server-4bad4d9f-67f2-4709-b152-30e8ae17d268-16714     Container image "668749497752.dkr.ecr.us-west-2.amazonaws.com/sasviya/viya-4-x64_oci_linux_2-docker/sas-process-exporter:1.9.1-20240306.1709732097762" already present on machine
19m         Normal    Created                           pod/sas-batch-server-4bad4d9f-67f2-4709-b152-30e8ae17d268-16714     Created container sas-process-exporter
19m         Normal    Started                           pod/sas-batch-server-4bad4d9f-67f2-4709-b152-30e8ae17d268-16714     Started container sas-process-exporter
6m46s       Normal    Killing                           pod/sas-batch-server-4bad4d9f-67f2-4709-b152-30e8ae17d268-16714     Stopping container sas-process-exporter
59m         Normal    Scheduled                         pod/sas-batch-server-4ce7dc4c-3b93-49a0-b00d-2cf66fe54076-16642     Successfully assigned viya-dev/sas-batch-server-4ce7dc4c-3b93-49a0-b00d-2cf66fe54076-16642 to ip-100-64-118-176.us-west-2.compute.internal
59m         Normal    Pulled                            pod/sas-batch-server-4ce7dc4c-3b93-49a0-b00d-2cf66fe54076-16642     Container image "668749497752.dkr.ecr.us-west-2.amazonaws.com/sasviya/viya-4-x64_oci_linux_2-docker/sas-certframe:3.51.0-20240313.1710330811841" already present on machine
59m         Normal    Created                           pod/sas-batch-server-4ce7dc4c-3b93-49a0-b00d-2cf66fe54076-16642     Created container sas-certframe
59m         Normal    Started                           pod/sas-batch-server-4ce7dc4c-3b93-49a0-b00d-2cf66fe54076-16642     Started container sas-certframe
59m         Normal    Pulled                            pod/sas-batch-server-4ce7dc4c-3b93-49a0-b00d-2cf66fe54076-16642     Container image "668749497752.dkr.ecr.us-west-2.amazonaws.com/sasviya/viya-4-x64_oci_linux_2-docker/sas-config-init:1.21.1-20240305.1709656957059" already present on machine
59m         Normal    Created                           pod/sas-batch-server-4ce7dc4c-3b93-49a0-b00d-2cf66fe54076-16642     Created container sas-config-init
59m         Normal    Started                           pod/sas-batch-server-4ce7dc4c-3b93-49a0-b00d-2cf66fe54076-16642     Started container sas-config-init
59m         Normal    Pulled                            pod/sas-batch-server-4ce7dc4c-3b93-49a0-b00d-2cf66fe54076-16642     Container image "668749497752.dkr.ecr.us-west-2.amazonaws.com/sasviya/viya-4-x64_oci_linux_2-docker/sas-programming-environment:1.53.31-20240613.1718295947845" already present on machine
59m         Normal    Created                           pod/sas-batch-server-4ce7dc4c-3b93-49a0-b00d-2cf66fe54076-16642     Created container sas-programming-environment
59m         Normal    Started                           pod/sas-batch-server-4ce7dc4c-3b93-49a0-b00d-2cf66fe54076-16642     Started container sas-programming-environment
59m         Normal    Pulled                            pod/sas-batch-server-4ce7dc4c-3b93-49a0-b00d-2cf66fe54076-16642     Container image "668749497752.dkr.ecr.us-west-2.amazonaws.com/sasviya/viya-4-x64_oci_linux_2-docker/sas-process-exporter:1.9.1-20240306.1709732097762" already present on machine
59m         Normal    Created                           pod/sas-batch-server-4ce7dc4c-3b93-49a0-b00d-2cf66fe54076-16642     Created container sas-process-exporter
59m         Normal    Started                           pod/sas-batch-server-4ce7dc4c-3b93-49a0-b00d-2cf66fe54076-16642     Started container sas-process-exporter
46m         Normal    Killing                           pod/sas-batch-server-4ce7dc4c-3b93-49a0-b00d-2cf66fe54076-16642     Stopping container sas-process-exporter
11m         Warning   FailedScheduling                  pod/sas-batch-server-4dee94a6-d416-4240-bc25-01db789c6c2a-16778     0/10 nodes are available: 1 Insufficient cpu, 1 node(s) had untolerated taint {workload.sas.com/class: cas}, 1 node(s) had untolerated taint {workload.sas.com/class: stateful}, 1 node(s) had untolerated taint {workload.sas.com/class: stateless}, 6 node(s) didn't match Pod's node affinity/selector. preemption: 0/10 nodes are available: 1 No preemption victims found for incoming pod, 9 Preemption is not helpful for scheduling..
11m         Normal    Scheduled                         pod/sas-batch-server-4dee94a6-d416-4240-bc25-01db789c6c2a-16778     Successfully assigned viya-dev/sas-batch-server-4dee94a6-d416-4240-bc25-01db789c6c2a-16778 to ip-100-64-88-54.us-west-2.compute.internal
11m         Normal    Pulled                            pod/sas-batch-server-4dee94a6-d416-4240-bc25-01db789c6c2a-16778     Container image "668749497752.dkr.ecr.us-west-2.amazonaws.com/sasviya/viya-4-x64_oci_linux_2-docker/sas-certframe:3.51.0-20240313.1710330811841" already present on machine
11m         Normal    Created                           pod/sas-batch-server-4dee94a6-d416-4240-bc25-01db789c6c2a-16778     Created container sas-certframe
11m         Normal    Started                           pod/sas-batch-server-4dee94a6-d416-4240-bc25-01db789c6c2a-16778     Started container sas-certframe
11m         Normal    Pulled                            pod/sas-batch-server-4dee94a6-d416-4240-bc25-01db789c6c2a-16778     Container image "668749497752.dkr.ecr.us-west-2.amazonaws.com/sasviya/viya-4-x64_oci_linux_2-docker/sas-config-init:1.21.1-20240305.1709656957059" already present on machine
11m         Normal    Created                           pod/sas-batch-server-4dee94a6-d416-4240-bc25-01db789c6c2a-16778     Created container sas-config-init
11m         Normal    Started                           pod/sas-batch-server-4dee94a6-d416-4240-bc25-01db789c6c2a-16778     Started container sas-config-init
11m         Normal    Pulled                            pod/sas-batch-server-4dee94a6-d416-4240-bc25-01db789c6c2a-16778     Container image "668749497752.dkr.ecr.us-west-2.amazonaws.com/sasviya/viya-4-x64_oci_linux_2-docker/sas-programming-environment:1.53.31-20240613.1718295947845" already present on machine
11m         Normal    Created                           pod/sas-batch-server-4dee94a6-d416-4240-bc25-01db789c6c2a-16778     Created container sas-programming-environment
11m         Normal    Started                           pod/sas-batch-server-4dee94a6-d416-4240-bc25-01db789c6c2a-16778     Started container sas-programming-environment
11m         Normal    Pulled                            pod/sas-batch-server-4dee94a6-d416-4240-bc25-01db789c6c2a-16778     Container image "668749497752.dkr.ecr.us-west-2.amazonaws.com/sasviya/viya-4-x64_oci_linux_2-docker/sas-process-exporter:1.9.1-20240306.1709732097762" already present on machine
11m         Normal    Created                           pod/sas-batch-server-4dee94a6-d416-4240-bc25-01db789c6c2a-16778     Created container sas-process-exporter
11m         Normal    Started                           pod/sas-batch-server-4dee94a6-d416-4240-bc25-01db789c6c2a-16778     Started container sas-process-exporter
4m11s       Normal    Killing                           pod/sas-batch-server-4dee94a6-d416-4240-bc25-01db789c6c2a-16778     Stopping container sas-process-exporter
11m         Warning   FailedScheduling                  pod/sas-batch-server-4df2c02f-2591-4e39-bded-05dbf7d74039-16781     0/10 nodes are available: 1 Insufficient cpu, 1 node(s) had untolerated taint {workload.sas.com/class: cas}, 1 node(s) had untolerated taint {workload.sas.com/class: stateful}, 1 node(s) had untolerated taint {workload.sas.com/class: stateless}, 6 node(s) didn't match Pod's node affinity/selector. preemption: 0/10 nodes are available: 1 No preemption victims found for incoming pod, 9 Preemption is not helpful for scheduling..
11m         Normal    Scheduled                         pod/sas-batch-server-4df2c02f-2591-4e39-bded-05dbf7d74039-16781     Successfully assigned viya-dev/sas-batch-server-4df2c02f-2591-4e39-bded-05dbf7d74039-16781 to ip-100-64-118-98.us-west-2.compute.internal
11m         Normal    Pulled                            pod/sas-batch-server-4df2c02f-2591-4e39-bded-05dbf7d74039-16781     Container image "668749497752.dkr.ecr.us-west-2.amazonaws.com/sasviya/viya-4-x64_oci_linux_2-docker/sas-certframe:3.51.0-20240313.1710330811841" already present on machine
11m         Normal    Created                           pod/sas-batch-server-4df2c02f-2591-4e39-bded-05dbf7d74039-16781     Created container sas-certframe
11m         Normal    Started                           pod/sas-batch-server-4df2c02f-2591-4e39-bded-05dbf7d74039-16781     Started container sas-certframe
11m         Normal    Pulled                            pod/sas-batch-server-4df2c02f-2591-4e39-bded-05dbf7d74039-16781     Container image "668749497752.dkr.ecr.us-west-2.amazonaws.com/sasviya/viya-4-x64_oci_linux_2-docker/sas-config-init:1.21.1-20240305.1709656957059" already present on machine
11m         Normal    Created                           pod/sas-batch-server-4df2c02f-2591-4e39-bded-05dbf7d74039-16781     Created container sas-config-init
11m         Normal    Started                           pod/sas-batch-server-4df2c02f-2591-4e39-bded-05dbf7d74039-16781     Started container sas-config-init
10m         Normal    Pulled                            pod/sas-batch-server-4df2c02f-2591-4e39-bded-05dbf7d74039-16781     Container image "668749497752.dkr.ecr.us-west-2.amazonaws.com/sasviya/viya-4-x64_oci_linux_2-docker/sas-programming-environment:1.53.31-20240613.1718295947845" already present on machine
10m         Normal    Created                           pod/sas-batch-server-4df2c02f-2591-4e39-bded-05dbf7d74039-16781     Created container sas-programming-environment
10m         Normal    Started                           pod/sas-batch-server-4df2c02f-2591-4e39-bded-05dbf7d74039-16781     Started container sas-programming-environment
10m         Normal    Pulled                            pod/sas-batch-server-4df2c02f-2591-4e39-bded-05dbf7d74039-16781     Container image "668749497752.dkr.ecr.us-west-2.amazonaws.com/sasviya/viya-4-x64_oci_linux_2-docker/sas-process-exporter:1.9.1-20240306.1709732097762" already present on machine
10m         Normal    Created                           pod/sas-batch-server-4df2c02f-2591-4e39-bded-05dbf7d74039-16781     Created container sas-process-exporter
10m         Normal    Started                           pod/sas-batch-server-4df2c02f-2591-4e39-bded-05dbf7d74039-16781     Started container sas-process-exporter
3m54s       Normal    Killing                           pod/sas-batch-server-4df2c02f-2591-4e39-bded-05dbf7d74039-16781     Stopping container sas-process-exporter
59m         Normal    Scheduled                         pod/sas-batch-server-4f06b6a7-81d5-4a51-82aa-bcd4adba4246-16629     Successfully assigned viya-dev/sas-batch-server-4f06b6a7-81d5-4a51-82aa-bcd4adba4246-16629 to ip-100-64-118-176.us-west-2.compute.internal
59m         Normal    Pulled                            pod/sas-batch-server-4f06b6a7-81d5-4a51-82aa-bcd4adba4246-16629     Container image "668749497752.dkr.ecr.us-west-2.amazonaws.com/sasviya/viya-4-x64_oci_linux_2-docker/sas-certframe:3.51.0-20240313.1710330811841" already present on machine
59m         Normal    Created                           pod/sas-batch-server-4f06b6a7-81d5-4a51-82aa-bcd4adba4246-16629     Created container sas-certframe
59m         Normal    Started                           pod/sas-batch-server-4f06b6a7-81d5-4a51-82aa-bcd4adba4246-16629     Started container sas-certframe
59m         Normal    Pulled                            pod/sas-batch-server-4f06b6a7-81d5-4a51-82aa-bcd4adba4246-16629     Container image "668749497752.dkr.ecr.us-west-2.amazonaws.com/sasviya/viya-4-x64_oci_linux_2-docker/sas-config-init:1.21.1-20240305.1709656957059" already present on machine
59m         Normal    Created                           pod/sas-batch-server-4f06b6a7-81d5-4a51-82aa-bcd4adba4246-16629     Created container sas-config-init
59m         Normal    Started                           pod/sas-batch-server-4f06b6a7-81d5-4a51-82aa-bcd4adba4246-16629     Started container sas-config-init
59m         Normal    Pulled                            pod/sas-batch-server-4f06b6a7-81d5-4a51-82aa-bcd4adba4246-16629     Container image "668749497752.dkr.ecr.us-west-2.amazonaws.com/sasviya/viya-4-x64_oci_linux_2-docker/sas-programming-environment:1.53.31-20240613.1718295947845" already present on machine
59m         Normal    Created                           pod/sas-batch-server-4f06b6a7-81d5-4a51-82aa-bcd4adba4246-16629     Created container sas-programming-environment
59m         Normal    Started                           pod/sas-batch-server-4f06b6a7-81d5-4a51-82aa-bcd4adba4246-16629     Started container sas-programming-environment
59m         Normal    Pulled                            pod/sas-batch-server-4f06b6a7-81d5-4a51-82aa-bcd4adba4246-16629     Container image "668749497752.dkr.ecr.us-west-2.amazonaws.com/sasviya/viya-4-x64_oci_linux_2-docker/sas-process-exporter:1.9.1-20240306.1709732097762" already present on machine
59m         Normal    Created                           pod/sas-batch-server-4f06b6a7-81d5-4a51-82aa-bcd4adba4246-16629     Created container sas-process-exporter
59m         Normal    Started                           pod/sas-batch-server-4f06b6a7-81d5-4a51-82aa-bcd4adba4246-16629     Started container sas-process-exporter
47m         Normal    Killing                           pod/sas-batch-server-4f06b6a7-81d5-4a51-82aa-bcd4adba4246-16629     Stopping container sas-process-exporter
19m         Normal    Scheduled                         pod/sas-batch-server-51334031-58f5-413b-9ce0-35eb5493174d-16706     Successfully assigned viya-dev/sas-batch-server-51334031-58f5-413b-9ce0-35eb5493174d-16706 to ip-100-64-98-232.us-west-2.compute.internal
19m         Normal    Pulled                            pod/sas-batch-server-51334031-58f5-413b-9ce0-35eb5493174d-16706     Container image "668749497752.dkr.ecr.us-west-2.amazonaws.com/sasviya/viya-4-x64_oci_linux_2-docker/sas-certframe:3.51.0-20240313.1710330811841" already present on machine
19m         Normal    Created                           pod/sas-batch-server-51334031-58f5-413b-9ce0-35eb5493174d-16706     Created container sas-certframe
19m         Normal    Started                           pod/sas-batch-server-51334031-58f5-413b-9ce0-35eb5493174d-16706     Started container sas-certframe
19m         Normal    Pulled                            pod/sas-batch-server-51334031-58f5-413b-9ce0-35eb5493174d-16706     Container image "668749497752.dkr.ecr.us-west-2.amazonaws.com/sasviya/viya-4-x64_oci_linux_2-docker/sas-config-init:1.21.1-20240305.1709656957059" already present on machine
19m         Normal    Created                           pod/sas-batch-server-51334031-58f5-413b-9ce0-35eb5493174d-16706     Created container sas-config-init
19m         Normal    Started                           pod/sas-batch-server-51334031-58f5-413b-9ce0-35eb5493174d-16706     Started container sas-config-init
19m         Normal    Pulled                            pod/sas-batch-server-51334031-58f5-413b-9ce0-35eb5493174d-16706     Container image "668749497752.dkr.ecr.us-west-2.amazonaws.com/sasviya/viya-4-x64_oci_linux_2-docker/sas-programming-environment:1.53.31-20240613.1718295947845" already present on machine
19m         Normal    Created                           pod/sas-batch-server-51334031-58f5-413b-9ce0-35eb5493174d-16706     Created container sas-programming-environment
19m         Normal    Started                           pod/sas-batch-server-51334031-58f5-413b-9ce0-35eb5493174d-16706     Started container sas-programming-environment
19m         Normal    Pulled                            pod/sas-batch-server-51334031-58f5-413b-9ce0-35eb5493174d-16706     Container image "668749497752.dkr.ecr.us-west-2.amazonaws.com/sasviya/viya-4-x64_oci_linux_2-docker/sas-process-exporter:1.9.1-20240306.1709732097762" already present on machine
19m         Normal    Created                           pod/sas-batch-server-51334031-58f5-413b-9ce0-35eb5493174d-16706     Created container sas-process-exporter
19m         Normal    Started                           pod/sas-batch-server-51334031-58f5-413b-9ce0-35eb5493174d-16706     Started container sas-process-exporter
6m43s       Normal    Killing                           pod/sas-batch-server-51334031-58f5-413b-9ce0-35eb5493174d-16706     Stopping container sas-process-exporter
19m         Normal    Scheduled                         pod/sas-batch-server-53c0604b-373a-4e36-87fb-364195f43eee-16726     Successfully assigned viya-dev/sas-batch-server-53c0604b-373a-4e36-87fb-364195f43eee-16726 to ip-100-64-118-98.us-west-2.compute.internal
19m         Normal    Pulled                            pod/sas-batch-server-53c0604b-373a-4e36-87fb-364195f43eee-16726     Container image "668749497752.dkr.ecr.us-west-2.amazonaws.com/sasviya/viya-4-x64_oci_linux_2-docker/sas-certframe:3.51.0-20240313.1710330811841" already present on machine
19m         Normal    Created                           pod/sas-batch-server-53c0604b-373a-4e36-87fb-364195f43eee-16726     Created container sas-certframe
19m         Normal    Started                           pod/sas-batch-server-53c0604b-373a-4e36-87fb-364195f43eee-16726     Started container sas-certframe
19m         Normal    Pulled                            pod/sas-batch-server-53c0604b-373a-4e36-87fb-364195f43eee-16726     Container image "668749497752.dkr.ecr.us-west-2.amazonaws.com/sasviya/viya-4-x64_oci_linux_2-docker/sas-config-init:1.21.1-20240305.1709656957059" already present on machine
19m         Normal    Created                           pod/sas-batch-server-53c0604b-373a-4e36-87fb-364195f43eee-16726     Created container sas-config-init
19m         Normal    Started                           pod/sas-batch-server-53c0604b-373a-4e36-87fb-364195f43eee-16726     Started container sas-config-init
19m         Normal    Pulled                            pod/sas-batch-server-53c0604b-373a-4e36-87fb-364195f43eee-16726     Container image "668749497752.dkr.ecr.us-west-2.amazonaws.com/sasviya/viya-4-x64_oci_linux_2-docker/sas-programming-environment:1.53.31-20240613.1718295947845" already present on machine
19m         Normal    Created                           pod/sas-batch-server-53c0604b-373a-4e36-87fb-364195f43eee-16726     Created container sas-programming-environment
19m         Normal    Started                           pod/sas-batch-server-53c0604b-373a-4e36-87fb-364195f43eee-16726     Started container sas-programming-environment
19m         Normal    Pulled                            pod/sas-batch-server-53c0604b-373a-4e36-87fb-364195f43eee-16726     Container image "668749497752.dkr.ecr.us-west-2.amazonaws.com/sasviya/viya-4-x64_oci_linux_2-docker/sas-process-exporter:1.9.1-20240306.1709732097762" already present on machine
19m         Normal    Created                           pod/sas-batch-server-53c0604b-373a-4e36-87fb-364195f43eee-16726     Created container sas-process-exporter
19m         Normal    Started                           pod/sas-batch-server-53c0604b-373a-4e36-87fb-364195f43eee-16726     Started container sas-process-exporter
7m29s       Normal    Killing                           pod/sas-batch-server-53c0604b-373a-4e36-87fb-364195f43eee-16726     Stopping container sas-process-exporter
59m         Normal    Scheduled                         pod/sas-batch-server-55f429e2-99db-4747-b544-9373b6713993-16623     Successfully assigned viya-dev/sas-batch-server-55f429e2-99db-4747-b544-9373b6713993-16623 to ip-100-64-118-176.us-west-2.compute.internal
59m         Normal    Pulled                            pod/sas-batch-server-55f429e2-99db-4747-b544-9373b6713993-16623     Container image "668749497752.dkr.ecr.us-west-2.amazonaws.com/sasviya/viya-4-x64_oci_linux_2-docker/sas-certframe:3.51.0-20240313.1710330811841" already present on machine
59m         Normal    Created                           pod/sas-batch-server-55f429e2-99db-4747-b544-9373b6713993-16623     Created container sas-certframe
59m         Normal    Started                           pod/sas-batch-server-55f429e2-99db-4747-b544-9373b6713993-16623     Started container sas-certframe
59m         Normal    Pulled                            pod/sas-batch-server-55f429e2-99db-4747-b544-9373b6713993-16623     Container image "668749497752.dkr.ecr.us-west-2.amazonaws.com/sasviya/viya-4-x64_oci_linux_2-docker/sas-config-init:1.21.1-20240305.1709656957059" already present on machine
59m         Normal    Created                           pod/sas-batch-server-55f429e2-99db-4747-b544-9373b6713993-16623     Created container sas-config-init
59m         Normal    Started                           pod/sas-batch-server-55f429e2-99db-4747-b544-9373b6713993-16623     Started container sas-config-init
59m         Normal    Pulled                            pod/sas-batch-server-55f429e2-99db-4747-b544-9373b6713993-16623     Container image "668749497752.dkr.ecr.us-west-2.amazonaws.com/sasviya/viya-4-x64_oci_linux_2-docker/sas-programming-environment:1.53.31-20240613.1718295947845" already present on machine
59m         Normal    Created                           pod/sas-batch-server-55f429e2-99db-4747-b544-9373b6713993-16623     Created container sas-programming-environment
59m         Normal    Started                           pod/sas-batch-server-55f429e2-99db-4747-b544-9373b6713993-16623     Started container sas-programming-environment
59m         Normal    Pulled                            pod/sas-batch-server-55f429e2-99db-4747-b544-9373b6713993-16623     Container image "668749497752.dkr.ecr.us-west-2.amazonaws.com/sasviya/viya-4-x64_oci_linux_2-docker/sas-process-exporter:1.9.1-20240306.1709732097762" already present on machine
59m         Normal    Created                           pod/sas-batch-server-55f429e2-99db-4747-b544-9373b6713993-16623     Created container sas-process-exporter
59m         Normal    Started                           pod/sas-batch-server-55f429e2-99db-4747-b544-9373b6713993-16623     Started container sas-process-exporter
46m         Normal    Killing                           pod/sas-batch-server-55f429e2-99db-4747-b544-9373b6713993-16623     Stopping container sas-process-exporter
59m         Normal    Killing                           pod/sas-batch-server-56028099-b267-4b85-8202-849407561b24-16607     Stopping container sas-process-exporter
19m         Normal    Scheduled                         pod/sas-batch-server-578a51dc-aa6b-4df6-bd4c-d379bd0b5d52-16741     Successfully assigned viya-dev/sas-batch-server-578a51dc-aa6b-4df6-bd4c-d379bd0b5d52-16741 to ip-100-64-103-52.us-west-2.compute.internal
19m         Normal    Pulled                            pod/sas-batch-server-578a51dc-aa6b-4df6-bd4c-d379bd0b5d52-16741     Container image "668749497752.dkr.ecr.us-west-2.amazonaws.com/sasviya/viya-4-x64_oci_linux_2-docker/sas-certframe:3.51.0-20240313.1710330811841" already present on machine
19m         Normal    Created                           pod/sas-batch-server-578a51dc-aa6b-4df6-bd4c-d379bd0b5d52-16741     Created container sas-certframe
19m         Normal    Started                           pod/sas-batch-server-578a51dc-aa6b-4df6-bd4c-d379bd0b5d52-16741     Started container sas-certframe
19m         Normal    Pulled                            pod/sas-batch-server-578a51dc-aa6b-4df6-bd4c-d379bd0b5d52-16741     Container image "668749497752.dkr.ecr.us-west-2.amazonaws.com/sasviya/viya-4-x64_oci_linux_2-docker/sas-config-init:1.21.1-20240305.1709656957059" already present on machine
19m         Normal    Created                           pod/sas-batch-server-578a51dc-aa6b-4df6-bd4c-d379bd0b5d52-16741     Created container sas-config-init
19m         Normal    Started                           pod/sas-batch-server-578a51dc-aa6b-4df6-bd4c-d379bd0b5d52-16741     Started container sas-config-init
19m         Normal    Pulled                            pod/sas-batch-server-578a51dc-aa6b-4df6-bd4c-d379bd0b5d52-16741     Container image "668749497752.dkr.ecr.us-west-2.amazonaws.com/sasviya/viya-4-x64_oci_linux_2-docker/sas-programming-environment:1.53.31-20240613.1718295947845" already present on machine
19m         Normal    Created                           pod/sas-batch-server-578a51dc-aa6b-4df6-bd4c-d379bd0b5d52-16741     Created container sas-programming-environment
19m         Normal    Started                           pod/sas-batch-server-578a51dc-aa6b-4df6-bd4c-d379bd0b5d52-16741     Started container sas-programming-environment
19m         Normal    Pulled                            pod/sas-batch-server-578a51dc-aa6b-4df6-bd4c-d379bd0b5d52-16741     Container image "668749497752.dkr.ecr.us-west-2.amazonaws.com/sasviya/viya-4-x64_oci_linux_2-docker/sas-process-exporter:1.9.1-20240306.1709732097762" already present on machine
19m         Normal    Created                           pod/sas-batch-server-578a51dc-aa6b-4df6-bd4c-d379bd0b5d52-16741     Created container sas-process-exporter
19m         Normal    Started                           pod/sas-batch-server-578a51dc-aa6b-4df6-bd4c-d379bd0b5d52-16741     Started container sas-process-exporter
6m45s       Normal    Killing                           pod/sas-batch-server-578a51dc-aa6b-4df6-bd4c-d379bd0b5d52-16741     Stopping container sas-process-exporter
19m         Normal    Scheduled                         pod/sas-batch-server-58b803ad-d4d5-4c64-9097-608c12347be3-16718     Successfully assigned viya-dev/sas-batch-server-58b803ad-d4d5-4c64-9097-608c12347be3-16718 to ip-100-64-103-52.us-west-2.compute.internal
19m         Normal    Pulled                            pod/sas-batch-server-58b803ad-d4d5-4c64-9097-608c12347be3-16718     Container image "668749497752.dkr.ecr.us-west-2.amazonaws.com/sasviya/viya-4-x64_oci_linux_2-docker/sas-certframe:3.51.0-20240313.1710330811841" already present on machine
19m         Normal    Created                           pod/sas-batch-server-58b803ad-d4d5-4c64-9097-608c12347be3-16718     Created container sas-certframe
19m         Normal    Started                           pod/sas-batch-server-58b803ad-d4d5-4c64-9097-608c12347be3-16718     Started container sas-certframe
19m         Normal    Pulled                            pod/sas-batch-server-58b803ad-d4d5-4c64-9097-608c12347be3-16718     Container image "668749497752.dkr.ecr.us-west-2.amazonaws.com/sasviya/viya-4-x64_oci_linux_2-docker/sas-config-init:1.21.1-20240305.1709656957059" already present on machine
19m         Normal    Created                           pod/sas-batch-server-58b803ad-d4d5-4c64-9097-608c12347be3-16718     Created container sas-config-init
19m         Normal    Started                           pod/sas-batch-server-58b803ad-d4d5-4c64-9097-608c12347be3-16718     Started container sas-config-init
19m         Normal    Pulled                            pod/sas-batch-server-58b803ad-d4d5-4c64-9097-608c12347be3-16718     Container image "668749497752.dkr.ecr.us-west-2.amazonaws.com/sasviya/viya-4-x64_oci_linux_2-docker/sas-programming-environment:1.53.31-20240613.1718295947845" already present on machine
19m         Normal    Created                           pod/sas-batch-server-58b803ad-d4d5-4c64-9097-608c12347be3-16718     Created container sas-programming-environment
19m         Normal    Started                           pod/sas-batch-server-58b803ad-d4d5-4c64-9097-608c12347be3-16718     Started container sas-programming-environment
19m         Normal    Pulled                            pod/sas-batch-server-58b803ad-d4d5-4c64-9097-608c12347be3-16718     Container image "668749497752.dkr.ecr.us-west-2.amazonaws.com/sasviya/viya-4-x64_oci_linux_2-docker/sas-process-exporter:1.9.1-20240306.1709732097762" already present on machine
19m         Normal    Created                           pod/sas-batch-server-58b803ad-d4d5-4c64-9097-608c12347be3-16718     Created container sas-process-exporter
19m         Normal    Started                           pod/sas-batch-server-58b803ad-d4d5-4c64-9097-608c12347be3-16718     Started container sas-process-exporter
6m2s        Normal    Killing                           pod/sas-batch-server-58b803ad-d4d5-4c64-9097-608c12347be3-16718     Stopping container sas-process-exporter
59m         Normal    Scheduled                         pod/sas-batch-server-5981be76-a08a-40d2-8162-ec030ae74d08-16627     Successfully assigned viya-dev/sas-batch-server-5981be76-a08a-40d2-8162-ec030ae74d08-16627 to ip-100-64-103-52.us-west-2.compute.internal
59m         Normal    Pulled                            pod/sas-batch-server-5981be76-a08a-40d2-8162-ec030ae74d08-16627     Container image "668749497752.dkr.ecr.us-west-2.amazonaws.com/sasviya/viya-4-x64_oci_linux_2-docker/sas-certframe:3.51.0-20240313.1710330811841" already present on machine
59m         Normal    Created                           pod/sas-batch-server-5981be76-a08a-40d2-8162-ec030ae74d08-16627     Created container sas-certframe
59m         Normal    Started                           pod/sas-batch-server-5981be76-a08a-40d2-8162-ec030ae74d08-16627     Started container sas-certframe
59m         Normal    Pulled                            pod/sas-batch-server-5981be76-a08a-40d2-8162-ec030ae74d08-16627     Container image "668749497752.dkr.ecr.us-west-2.amazonaws.com/sasviya/viya-4-x64_oci_linux_2-docker/sas-config-init:1.21.1-20240305.1709656957059" already present on machine
59m         Normal    Created                           pod/sas-batch-server-5981be76-a08a-40d2-8162-ec030ae74d08-16627     Created container sas-config-init
59m         Normal    Started                           pod/sas-batch-server-5981be76-a08a-40d2-8162-ec030ae74d08-16627     Started container sas-config-init
59m         Normal    Pulled                            pod/sas-batch-server-5981be76-a08a-40d2-8162-ec030ae74d08-16627     Container image "668749497752.dkr.ecr.us-west-2.amazonaws.com/sasviya/viya-4-x64_oci_linux_2-docker/sas-programming-environment:1.53.31-20240613.1718295947845" already present on machine
59m         Normal    Created                           pod/sas-batch-server-5981be76-a08a-40d2-8162-ec030ae74d08-16627     Created container sas-programming-environment
59m         Normal    Started                           pod/sas-batch-server-5981be76-a08a-40d2-8162-ec030ae74d08-16627     Started container sas-programming-environment
59m         Normal    Pulled                            pod/sas-batch-server-5981be76-a08a-40d2-8162-ec030ae74d08-16627     Container image "668749497752.dkr.ecr.us-west-2.amazonaws.com/sasviya/viya-4-x64_oci_linux_2-docker/sas-process-exporter:1.9.1-20240306.1709732097762" already present on machine
59m         Normal    Created                           pod/sas-batch-server-5981be76-a08a-40d2-8162-ec030ae74d08-16627     Created container sas-process-exporter
59m         Normal    Started                           pod/sas-batch-server-5981be76-a08a-40d2-8162-ec030ae74d08-16627     Started container sas-process-exporter
48m         Normal    Killing                           pod/sas-batch-server-5981be76-a08a-40d2-8162-ec030ae74d08-16627     Stopping container sas-process-exporter
59m         Normal    Scheduled                         pod/sas-batch-server-5b0b6879-d20a-4938-8a8f-4a50ad20e225-16617     Successfully assigned viya-dev/sas-batch-server-5b0b6879-d20a-4938-8a8f-4a50ad20e225-16617 to ip-100-64-103-52.us-west-2.compute.internal
59m         Normal    Pulled                            pod/sas-batch-server-5b0b6879-d20a-4938-8a8f-4a50ad20e225-16617     Container image "668749497752.dkr.ecr.us-west-2.amazonaws.com/sasviya/viya-4-x64_oci_linux_2-docker/sas-certframe:3.51.0-20240313.1710330811841" already present on machine
59m         Normal    Created                           pod/sas-batch-server-5b0b6879-d20a-4938-8a8f-4a50ad20e225-16617     Created container sas-certframe
59m         Normal    Started                           pod/sas-batch-server-5b0b6879-d20a-4938-8a8f-4a50ad20e225-16617     Started container sas-certframe
59m         Normal    Pulled                            pod/sas-batch-server-5b0b6879-d20a-4938-8a8f-4a50ad20e225-16617     Container image "668749497752.dkr.ecr.us-west-2.amazonaws.com/sasviya/viya-4-x64_oci_linux_2-docker/sas-config-init:1.21.1-20240305.1709656957059" already present on machine
59m         Normal    Created                           pod/sas-batch-server-5b0b6879-d20a-4938-8a8f-4a50ad20e225-16617     Created container sas-config-init
59m         Normal    Started                           pod/sas-batch-server-5b0b6879-d20a-4938-8a8f-4a50ad20e225-16617     Started container sas-config-init
59m         Normal    Pulled                            pod/sas-batch-server-5b0b6879-d20a-4938-8a8f-4a50ad20e225-16617     Container image "668749497752.dkr.ecr.us-west-2.amazonaws.com/sasviya/viya-4-x64_oci_linux_2-docker/sas-programming-environment:1.53.31-20240613.1718295947845" already present on machine
59m         Normal    Created                           pod/sas-batch-server-5b0b6879-d20a-4938-8a8f-4a50ad20e225-16617     Created container sas-programming-environment
59m         Normal    Started                           pod/sas-batch-server-5b0b6879-d20a-4938-8a8f-4a50ad20e225-16617     Started container sas-programming-environment
59m         Normal    Pulled                            pod/sas-batch-server-5b0b6879-d20a-4938-8a8f-4a50ad20e225-16617     Container image "668749497752.dkr.ecr.us-west-2.amazonaws.com/sasviya/viya-4-x64_oci_linux_2-docker/sas-process-exporter:1.9.1-20240306.1709732097762" already present on machine
59m         Normal    Created                           pod/sas-batch-server-5b0b6879-d20a-4938-8a8f-4a50ad20e225-16617     Created container sas-process-exporter
59m         Normal    Started                           pod/sas-batch-server-5b0b6879-d20a-4938-8a8f-4a50ad20e225-16617     Started container sas-process-exporter
47m         Normal    Killing                           pod/sas-batch-server-5b0b6879-d20a-4938-8a8f-4a50ad20e225-16617     Stopping container sas-process-exporter
9m36s       Warning   FailedScheduling                  pod/sas-batch-server-5b614289-9cd5-497a-bc60-2b907c4a197b-16771     0/10 nodes are available: 1 Insufficient cpu, 1 node(s) had untolerated taint {workload.sas.com/class: cas}, 1 node(s) had untolerated taint {workload.sas.com/class: stateful}, 1 node(s) had untolerated taint {workload.sas.com/class: stateless}, 6 node(s) didn't match Pod's node affinity/selector. preemption: 0/10 nodes are available: 1 No preemption victims found for incoming pod, 9 Preemption is not helpful for scheduling..
9m38s       Normal    NotTriggerScaleUp                 pod/sas-batch-server-5b614289-9cd5-497a-bc60-2b907c4a197b-16771     pod didn't trigger scale-up: 1 node(s) had untolerated taint {workload.sas.com/class: stateless}, 1 node(s) had untolerated taint {workload.sas.com/class: cas}, 2 node(s) didn't match Pod's node affinity/selector, 1 node(s) had untolerated taint {workload.sas.com/class: stateful}
9m25s       Normal    Scheduled                         pod/sas-batch-server-5b614289-9cd5-497a-bc60-2b907c4a197b-16771     Successfully assigned viya-dev/sas-batch-server-5b614289-9cd5-497a-bc60-2b907c4a197b-16771 to ip-100-64-118-176.us-west-2.compute.internal
9m23s       Normal    Pulled                            pod/sas-batch-server-5b614289-9cd5-497a-bc60-2b907c4a197b-16771     Container image "668749497752.dkr.ecr.us-west-2.amazonaws.com/sasviya/viya-4-x64_oci_linux_2-docker/sas-certframe:3.51.0-20240313.1710330811841" already present on machine
9m23s       Normal    Created                           pod/sas-batch-server-5b614289-9cd5-497a-bc60-2b907c4a197b-16771     Created container sas-certframe
9m23s       Normal    Started                           pod/sas-batch-server-5b614289-9cd5-497a-bc60-2b907c4a197b-16771     Started container sas-certframe
9m22s       Normal    Pulled                            pod/sas-batch-server-5b614289-9cd5-497a-bc60-2b907c4a197b-16771     Container image "668749497752.dkr.ecr.us-west-2.amazonaws.com/sasviya/viya-4-x64_oci_linux_2-docker/sas-config-init:1.21.1-20240305.1709656957059" already present on machine
9m22s       Normal    Created                           pod/sas-batch-server-5b614289-9cd5-497a-bc60-2b907c4a197b-16771     Created container sas-config-init
9m22s       Normal    Started                           pod/sas-batch-server-5b614289-9cd5-497a-bc60-2b907c4a197b-16771     Started container sas-config-init
9m20s       Normal    Pulled                            pod/sas-batch-server-5b614289-9cd5-497a-bc60-2b907c4a197b-16771     Container image "668749497752.dkr.ecr.us-west-2.amazonaws.com/sasviya/viya-4-x64_oci_linux_2-docker/sas-programming-environment:1.53.31-20240613.1718295947845" already present on machine
9m20s       Normal    Created                           pod/sas-batch-server-5b614289-9cd5-497a-bc60-2b907c4a197b-16771     Created container sas-programming-environment
9m20s       Normal    Started                           pod/sas-batch-server-5b614289-9cd5-497a-bc60-2b907c4a197b-16771     Started container sas-programming-environment
9m20s       Normal    Pulled                            pod/sas-batch-server-5b614289-9cd5-497a-bc60-2b907c4a197b-16771     Container image "668749497752.dkr.ecr.us-west-2.amazonaws.com/sasviya/viya-4-x64_oci_linux_2-docker/sas-process-exporter:1.9.1-20240306.1709732097762" already present on machine
9m20s       Normal    Created                           pod/sas-batch-server-5b614289-9cd5-497a-bc60-2b907c4a197b-16771     Created container sas-process-exporter
9m20s       Normal    Started                           pod/sas-batch-server-5b614289-9cd5-497a-bc60-2b907c4a197b-16771     Started container sas-process-exporter
4m48s       Normal    Killing                           pod/sas-batch-server-5b614289-9cd5-497a-bc60-2b907c4a197b-16771     Stopping container sas-process-exporter
19m         Normal    Scheduled                         pod/sas-batch-server-5d119cc6-ac1c-441f-9441-854ee5f59ae9-16707     Successfully assigned viya-dev/sas-batch-server-5d119cc6-ac1c-441f-9441-854ee5f59ae9-16707 to ip-100-64-118-176.us-west-2.compute.internal
19m         Normal    Pulled                            pod/sas-batch-server-5d119cc6-ac1c-441f-9441-854ee5f59ae9-16707     Container image "668749497752.dkr.ecr.us-west-2.amazonaws.com/sasviya/viya-4-x64_oci_linux_2-docker/sas-certframe:3.51.0-20240313.1710330811841" already present on machine
19m         Normal    Created                           pod/sas-batch-server-5d119cc6-ac1c-441f-9441-854ee5f59ae9-16707     Created container sas-certframe
19m         Normal    Started                           pod/sas-batch-server-5d119cc6-ac1c-441f-9441-854ee5f59ae9-16707     Started container sas-certframe
19m         Normal    Pulled                            pod/sas-batch-server-5d119cc6-ac1c-441f-9441-854ee5f59ae9-16707     Container image "668749497752.dkr.ecr.us-west-2.amazonaws.com/sasviya/viya-4-x64_oci_linux_2-docker/sas-config-init:1.21.1-20240305.1709656957059" already present on machine
19m         Normal    Created                           pod/sas-batch-server-5d119cc6-ac1c-441f-9441-854ee5f59ae9-16707     Created container sas-config-init
19m         Normal    Started                           pod/sas-batch-server-5d119cc6-ac1c-441f-9441-854ee5f59ae9-16707     Started container sas-config-init
19m         Normal    Pulled                            pod/sas-batch-server-5d119cc6-ac1c-441f-9441-854ee5f59ae9-16707     Container image "668749497752.dkr.ecr.us-west-2.amazonaws.com/sasviya/viya-4-x64_oci_linux_2-docker/sas-programming-environment:1.53.31-20240613.1718295947845" already present on machine
19m         Normal    Created                           pod/sas-batch-server-5d119cc6-ac1c-441f-9441-854ee5f59ae9-16707     Created container sas-programming-environment
19m         Normal    Started                           pod/sas-batch-server-5d119cc6-ac1c-441f-9441-854ee5f59ae9-16707     Started container sas-programming-environment
19m         Normal    Pulled                            pod/sas-batch-server-5d119cc6-ac1c-441f-9441-854ee5f59ae9-16707     Container image "668749497752.dkr.ecr.us-west-2.amazonaws.com/sasviya/viya-4-x64_oci_linux_2-docker/sas-process-exporter:1.9.1-20240306.1709732097762" already present on machine
19m         Normal    Created                           pod/sas-batch-server-5d119cc6-ac1c-441f-9441-854ee5f59ae9-16707     Created container sas-process-exporter
19m         Normal    Started                           pod/sas-batch-server-5d119cc6-ac1c-441f-9441-854ee5f59ae9-16707     Started container sas-process-exporter
8m42s       Normal    Killing                           pod/sas-batch-server-5d119cc6-ac1c-441f-9441-854ee5f59ae9-16707     Stopping container sas-process-exporter
13m         Warning   FailedScheduling                  pod/sas-batch-server-5e5ff0de-d0de-4c54-bfc9-197598464277-16773     0/10 nodes are available: 1 Insufficient cpu, 1 node(s) had untolerated taint {workload.sas.com/class: cas}, 1 node(s) had untolerated taint {workload.sas.com/class: stateful}, 1 node(s) had untolerated taint {workload.sas.com/class: stateless}, 6 node(s) didn't match Pod's node affinity/selector. preemption: 0/10 nodes are available: 1 No preemption victims found for incoming pod, 9 Preemption is not helpful for scheduling..
13m         Normal    Scheduled                         pod/sas-batch-server-5e5ff0de-d0de-4c54-bfc9-197598464277-16773     Successfully assigned viya-dev/sas-batch-server-5e5ff0de-d0de-4c54-bfc9-197598464277-16773 to ip-100-64-118-176.us-west-2.compute.internal
13m         Normal    Pulled                            pod/sas-batch-server-5e5ff0de-d0de-4c54-bfc9-197598464277-16773     Container image "668749497752.dkr.ecr.us-west-2.amazonaws.com/sasviya/viya-4-x64_oci_linux_2-docker/sas-certframe:3.51.0-20240313.1710330811841" already present on machine
13m         Normal    Created                           pod/sas-batch-server-5e5ff0de-d0de-4c54-bfc9-197598464277-16773     Created container sas-certframe
13m         Normal    Started                           pod/sas-batch-server-5e5ff0de-d0de-4c54-bfc9-197598464277-16773     Started container sas-certframe
13m         Normal    Pulled                            pod/sas-batch-server-5e5ff0de-d0de-4c54-bfc9-197598464277-16773     Container image "668749497752.dkr.ecr.us-west-2.amazonaws.com/sasviya/viya-4-x64_oci_linux_2-docker/sas-config-init:1.21.1-20240305.1709656957059" already present on machine
13m         Normal    Created                           pod/sas-batch-server-5e5ff0de-d0de-4c54-bfc9-197598464277-16773     Created container sas-config-init
13m         Normal    Started                           pod/sas-batch-server-5e5ff0de-d0de-4c54-bfc9-197598464277-16773     Started container sas-config-init
13m         Normal    Pulled                            pod/sas-batch-server-5e5ff0de-d0de-4c54-bfc9-197598464277-16773     Container image "668749497752.dkr.ecr.us-west-2.amazonaws.com/sasviya/viya-4-x64_oci_linux_2-docker/sas-programming-environment:1.53.31-20240613.1718295947845" already present on machine
13m         Normal    Created                           pod/sas-batch-server-5e5ff0de-d0de-4c54-bfc9-197598464277-16773     Created container sas-programming-environment
13m         Normal    Started                           pod/sas-batch-server-5e5ff0de-d0de-4c54-bfc9-197598464277-16773     Started container sas-programming-environment
13m         Normal    Pulled                            pod/sas-batch-server-5e5ff0de-d0de-4c54-bfc9-197598464277-16773     Container image "668749497752.dkr.ecr.us-west-2.amazonaws.com/sasviya/viya-4-x64_oci_linux_2-docker/sas-process-exporter:1.9.1-20240306.1709732097762" already present on machine
13m         Normal    Created                           pod/sas-batch-server-5e5ff0de-d0de-4c54-bfc9-197598464277-16773     Created container sas-process-exporter
13m         Normal    Started                           pod/sas-batch-server-5e5ff0de-d0de-4c54-bfc9-197598464277-16773     Started container sas-process-exporter
5m43s       Normal    Killing                           pod/sas-batch-server-5e5ff0de-d0de-4c54-bfc9-197598464277-16773     Stopping container sas-process-exporter
8m43s       Warning   FailedScheduling                  pod/sas-batch-server-5e74495b-c9b2-473e-b6eb-e6a79567327c-16777     0/10 nodes are available: 1 Insufficient cpu, 1 node(s) had untolerated taint {workload.sas.com/class: cas}, 1 node(s) had untolerated taint {workload.sas.com/class: stateful}, 1 node(s) had untolerated taint {workload.sas.com/class: stateless}, 6 node(s) didn't match Pod's node affinity/selector. preemption: 0/10 nodes are available: 1 No preemption victims found for incoming pod, 9 Preemption is not helpful for scheduling..
9m38s       Normal    NotTriggerScaleUp                 pod/sas-batch-server-5e74495b-c9b2-473e-b6eb-e6a79567327c-16777     pod didn't trigger scale-up: 1 node(s) had untolerated taint {workload.sas.com/class: cas}, 2 node(s) didn't match Pod's node affinity/selector, 1 node(s) had untolerated taint {workload.sas.com/class: stateful}, 1 node(s) had untolerated taint {workload.sas.com/class: stateless}
8m32s       Warning   FailedScheduling                  pod/sas-batch-server-5e74495b-c9b2-473e-b6eb-e6a79567327c-16777     0/11 nodes are available: 1 Insufficient cpu, 1 node(s) had untolerated taint {node.kubernetes.io/not-ready: }, 1 node(s) had untolerated taint {workload.sas.com/class: cas}, 1 node(s) had untolerated taint {workload.sas.com/class: stateful}, 1 node(s) had untolerated taint {workload.sas.com/class: stateless}, 6 node(s) didn't match Pod's node affinity/selector. preemption: 0/11 nodes are available: 1 No preemption victims found for incoming pod, 10 Preemption is not helpful for scheduling..
8m20s       Warning   FailedScheduling                  pod/sas-batch-server-5e74495b-c9b2-473e-b6eb-e6a79567327c-16777     0/11 nodes are available: 1 Insufficient cpu, 1 node(s) had untolerated taint {workload.sas.com/class: cas}, 1 node(s) had untolerated taint {workload.sas.com/class: stateful}, 1 node(s) had untolerated taint {workload.sas.com/class: stateless}, 7 node(s) didn't match Pod's node affinity/selector. preemption: 0/11 nodes are available: 1 No preemption victims found for incoming pod, 10 Preemption is not helpful for scheduling..
8m9s        Normal    Scheduled                         pod/sas-batch-server-5e74495b-c9b2-473e-b6eb-e6a79567327c-16777     Successfully assigned viya-dev/sas-batch-server-5e74495b-c9b2-473e-b6eb-e6a79567327c-16777 to ip-100-64-118-98.us-west-2.compute.internal
8m6s        Normal    Pulled                            pod/sas-batch-server-5e74495b-c9b2-473e-b6eb-e6a79567327c-16777     Container image "668749497752.dkr.ecr.us-west-2.amazonaws.com/sasviya/viya-4-x64_oci_linux_2-docker/sas-certframe:3.51.0-20240313.1710330811841" already present on machine
8m6s        Normal    Created                           pod/sas-batch-server-5e74495b-c9b2-473e-b6eb-e6a79567327c-16777     Created container sas-certframe
8m6s        Normal    Started                           pod/sas-batch-server-5e74495b-c9b2-473e-b6eb-e6a79567327c-16777     Started container sas-certframe
8m5s        Normal    Pulled                            pod/sas-batch-server-5e74495b-c9b2-473e-b6eb-e6a79567327c-16777     Container image "668749497752.dkr.ecr.us-west-2.amazonaws.com/sasviya/viya-4-x64_oci_linux_2-docker/sas-config-init:1.21.1-20240305.1709656957059" already present on machine
8m5s        Normal    Created                           pod/sas-batch-server-5e74495b-c9b2-473e-b6eb-e6a79567327c-16777     Created container sas-config-init
8m5s        Normal    Started                           pod/sas-batch-server-5e74495b-c9b2-473e-b6eb-e6a79567327c-16777     Started container sas-config-init
8m3s        Normal    Pulled                            pod/sas-batch-server-5e74495b-c9b2-473e-b6eb-e6a79567327c-16777     Container image "668749497752.dkr.ecr.us-west-2.amazonaws.com/sasviya/viya-4-x64_oci_linux_2-docker/sas-programming-environment:1.53.31-20240613.1718295947845" already present on machine
8m3s        Normal    Created                           pod/sas-batch-server-5e74495b-c9b2-473e-b6eb-e6a79567327c-16777     Created container sas-programming-environment
8m3s        Normal    Started                           pod/sas-batch-server-5e74495b-c9b2-473e-b6eb-e6a79567327c-16777     Started container sas-programming-environment
8m3s        Normal    Pulled                            pod/sas-batch-server-5e74495b-c9b2-473e-b6eb-e6a79567327c-16777     Container image "668749497752.dkr.ecr.us-west-2.amazonaws.com/sasviya/viya-4-x64_oci_linux_2-docker/sas-process-exporter:1.9.1-20240306.1709732097762" already present on machine
8m3s        Normal    Created                           pod/sas-batch-server-5e74495b-c9b2-473e-b6eb-e6a79567327c-16777     Created container sas-process-exporter
8m3s        Normal    Started                           pod/sas-batch-server-5e74495b-c9b2-473e-b6eb-e6a79567327c-16777     Started container sas-process-exporter
3m34s       Normal    Killing                           pod/sas-batch-server-5e74495b-c9b2-473e-b6eb-e6a79567327c-16777     Stopping container sas-process-exporter
19m         Normal    Scheduled                         pod/sas-batch-server-5f6656f2-68c7-4627-a8ac-75339955114c-16760     Successfully assigned viya-dev/sas-batch-server-5f6656f2-68c7-4627-a8ac-75339955114c-16760 to ip-100-64-125-225.us-west-2.compute.internal
19m         Normal    Pulled                            pod/sas-batch-server-5f6656f2-68c7-4627-a8ac-75339955114c-16760     Container image "668749497752.dkr.ecr.us-west-2.amazonaws.com/sasviya/viya-4-x64_oci_linux_2-docker/sas-certframe:3.51.0-20240313.1710330811841" already present on machine
19m         Normal    Created                           pod/sas-batch-server-5f6656f2-68c7-4627-a8ac-75339955114c-16760     Created container sas-certframe
19m         Normal    Started                           pod/sas-batch-server-5f6656f2-68c7-4627-a8ac-75339955114c-16760     Started container sas-certframe
19m         Normal    Pulled                            pod/sas-batch-server-5f6656f2-68c7-4627-a8ac-75339955114c-16760     Container image "668749497752.dkr.ecr.us-west-2.amazonaws.com/sasviya/viya-4-x64_oci_linux_2-docker/sas-config-init:1.21.1-20240305.1709656957059" already present on machine
19m         Normal    Created                           pod/sas-batch-server-5f6656f2-68c7-4627-a8ac-75339955114c-16760     Created container sas-config-init
19m         Normal    Started                           pod/sas-batch-server-5f6656f2-68c7-4627-a8ac-75339955114c-16760     Started container sas-config-init
19m         Normal    Pulled                            pod/sas-batch-server-5f6656f2-68c7-4627-a8ac-75339955114c-16760     Container image "668749497752.dkr.ecr.us-west-2.amazonaws.com/sasviya/viya-4-x64_oci_linux_2-docker/sas-programming-environment:1.53.31-20240613.1718295947845" already present on machine
19m         Normal    Created                           pod/sas-batch-server-5f6656f2-68c7-4627-a8ac-75339955114c-16760     Created container sas-programming-environment
19m         Normal    Started                           pod/sas-batch-server-5f6656f2-68c7-4627-a8ac-75339955114c-16760     Started container sas-programming-environment
19m         Normal    Pulled                            pod/sas-batch-server-5f6656f2-68c7-4627-a8ac-75339955114c-16760     Container image "668749497752.dkr.ecr.us-west-2.amazonaws.com/sasviya/viya-4-x64_oci_linux_2-docker/sas-process-exporter:1.9.1-20240306.1709732097762" already present on machine
19m         Normal    Created                           pod/sas-batch-server-5f6656f2-68c7-4627-a8ac-75339955114c-16760     Created container sas-process-exporter
19m         Normal    Started                           pod/sas-batch-server-5f6656f2-68c7-4627-a8ac-75339955114c-16760     Started container sas-process-exporter
5m36s       Normal    Killing                           pod/sas-batch-server-5f6656f2-68c7-4627-a8ac-75339955114c-16760     Stopping container sas-process-exporter
19m         Normal    Scheduled                         pod/sas-batch-server-5fc13e97-34f0-47b2-b1e6-c6851ca4c45c-16720     Successfully assigned viya-dev/sas-batch-server-5fc13e97-34f0-47b2-b1e6-c6851ca4c45c-16720 to ip-100-64-118-98.us-west-2.compute.internal
19m         Normal    Pulled                            pod/sas-batch-server-5fc13e97-34f0-47b2-b1e6-c6851ca4c45c-16720     Container image "668749497752.dkr.ecr.us-west-2.amazonaws.com/sasviya/viya-4-x64_oci_linux_2-docker/sas-certframe:3.51.0-20240313.1710330811841" already present on machine
19m         Normal    Created                           pod/sas-batch-server-5fc13e97-34f0-47b2-b1e6-c6851ca4c45c-16720     Created container sas-certframe
19m         Normal    Started                           pod/sas-batch-server-5fc13e97-34f0-47b2-b1e6-c6851ca4c45c-16720     Started container sas-certframe
19m         Normal    Pulled                            pod/sas-batch-server-5fc13e97-34f0-47b2-b1e6-c6851ca4c45c-16720     Container image "668749497752.dkr.ecr.us-west-2.amazonaws.com/sasviya/viya-4-x64_oci_linux_2-docker/sas-config-init:1.21.1-20240305.1709656957059" already present on machine
19m         Normal    Created                           pod/sas-batch-server-5fc13e97-34f0-47b2-b1e6-c6851ca4c45c-16720     Created container sas-config-init
19m         Normal    Started                           pod/sas-batch-server-5fc13e97-34f0-47b2-b1e6-c6851ca4c45c-16720     Started container sas-config-init
19m         Normal    Pulled                            pod/sas-batch-server-5fc13e97-34f0-47b2-b1e6-c6851ca4c45c-16720     Container image "668749497752.dkr.ecr.us-west-2.amazonaws.com/sasviya/viya-4-x64_oci_linux_2-docker/sas-programming-environment:1.53.31-20240613.1718295947845" already present on machine
19m         Normal    Created                           pod/sas-batch-server-5fc13e97-34f0-47b2-b1e6-c6851ca4c45c-16720     Created container sas-programming-environment
19m         Normal    Started                           pod/sas-batch-server-5fc13e97-34f0-47b2-b1e6-c6851ca4c45c-16720     Started container sas-programming-environment
19m         Normal    Pulled                            pod/sas-batch-server-5fc13e97-34f0-47b2-b1e6-c6851ca4c45c-16720     Container image "668749497752.dkr.ecr.us-west-2.amazonaws.com/sasviya/viya-4-x64_oci_linux_2-docker/sas-process-exporter:1.9.1-20240306.1709732097762" already present on machine
19m         Normal    Created                           pod/sas-batch-server-5fc13e97-34f0-47b2-b1e6-c6851ca4c45c-16720     Created container sas-process-exporter
19m         Normal    Started                           pod/sas-batch-server-5fc13e97-34f0-47b2-b1e6-c6851ca4c45c-16720     Started container sas-process-exporter
7m58s       Normal    Killing                           pod/sas-batch-server-5fc13e97-34f0-47b2-b1e6-c6851ca4c45c-16720     Stopping container sas-process-exporter
19m         Normal    Scheduled                         pod/sas-batch-server-60ff06f7-fb6e-4d2c-a8c6-66ded718283b-16698     Successfully assigned viya-dev/sas-batch-server-60ff06f7-fb6e-4d2c-a8c6-66ded718283b-16698 to ip-100-64-98-232.us-west-2.compute.internal
19m         Normal    Pulled                            pod/sas-batch-server-60ff06f7-fb6e-4d2c-a8c6-66ded718283b-16698     Container image "668749497752.dkr.ecr.us-west-2.amazonaws.com/sasviya/viya-4-x64_oci_linux_2-docker/sas-certframe:3.51.0-20240313.1710330811841" already present on machine
19m         Normal    Created                           pod/sas-batch-server-60ff06f7-fb6e-4d2c-a8c6-66ded718283b-16698     Created container sas-certframe
19m         Normal    Started                           pod/sas-batch-server-60ff06f7-fb6e-4d2c-a8c6-66ded718283b-16698     Started container sas-certframe
19m         Normal    Pulled                            pod/sas-batch-server-60ff06f7-fb6e-4d2c-a8c6-66ded718283b-16698     Container image "668749497752.dkr.ecr.us-west-2.amazonaws.com/sasviya/viya-4-x64_oci_linux_2-docker/sas-config-init:1.21.1-20240305.1709656957059" already present on machine
19m         Normal    Created                           pod/sas-batch-server-60ff06f7-fb6e-4d2c-a8c6-66ded718283b-16698     Created container sas-config-init
19m         Normal    Started                           pod/sas-batch-server-60ff06f7-fb6e-4d2c-a8c6-66ded718283b-16698     Started container sas-config-init
19m         Normal    Pulled                            pod/sas-batch-server-60ff06f7-fb6e-4d2c-a8c6-66ded718283b-16698     Container image "668749497752.dkr.ecr.us-west-2.amazonaws.com/sasviya/viya-4-x64_oci_linux_2-docker/sas-programming-environment:1.53.31-20240613.1718295947845" already present on machine
19m         Normal    Created                           pod/sas-batch-server-60ff06f7-fb6e-4d2c-a8c6-66ded718283b-16698     Created container sas-programming-environment
19m         Normal    Started                           pod/sas-batch-server-60ff06f7-fb6e-4d2c-a8c6-66ded718283b-16698     Started container sas-programming-environment
19m         Normal    Pulled                            pod/sas-batch-server-60ff06f7-fb6e-4d2c-a8c6-66ded718283b-16698     Container image "668749497752.dkr.ecr.us-west-2.amazonaws.com/sasviya/viya-4-x64_oci_linux_2-docker/sas-process-exporter:1.9.1-20240306.1709732097762" already present on machine
19m         Normal    Created                           pod/sas-batch-server-60ff06f7-fb6e-4d2c-a8c6-66ded718283b-16698     Created container sas-process-exporter
19m         Normal    Started                           pod/sas-batch-server-60ff06f7-fb6e-4d2c-a8c6-66ded718283b-16698     Started container sas-process-exporter
10m         Normal    Killing                           pod/sas-batch-server-60ff06f7-fb6e-4d2c-a8c6-66ded718283b-16698     Stopping container sas-process-exporter
19m         Warning   FailedScheduling                  pod/sas-batch-server-6194069e-f1eb-4ea3-9a74-d522f1ae564e-16763     0/10 nodes are available: 1 Insufficient cpu, 1 node(s) had untolerated taint {workload.sas.com/class: cas}, 1 node(s) had untolerated taint {workload.sas.com/class: stateful}, 1 node(s) had untolerated taint {workload.sas.com/class: stateless}, 6 node(s) didn't match Pod's node affinity/selector. preemption: 0/10 nodes are available: 1 No preemption victims found for incoming pod, 9 Preemption is not helpful for scheduling..
14m         Normal    Scheduled                         pod/sas-batch-server-6194069e-f1eb-4ea3-9a74-d522f1ae564e-16763     Successfully assigned viya-dev/sas-batch-server-6194069e-f1eb-4ea3-9a74-d522f1ae564e-16763 to ip-100-64-118-176.us-west-2.compute.internal
14m         Normal    Pulled                            pod/sas-batch-server-6194069e-f1eb-4ea3-9a74-d522f1ae564e-16763     Container image "668749497752.dkr.ecr.us-west-2.amazonaws.com/sasviya/viya-4-x64_oci_linux_2-docker/sas-certframe:3.51.0-20240313.1710330811841" already present on machine
14m         Normal    Created                           pod/sas-batch-server-6194069e-f1eb-4ea3-9a74-d522f1ae564e-16763     Created container sas-certframe
14m         Normal    Started                           pod/sas-batch-server-6194069e-f1eb-4ea3-9a74-d522f1ae564e-16763     Started container sas-certframe
14m         Normal    Pulled                            pod/sas-batch-server-6194069e-f1eb-4ea3-9a74-d522f1ae564e-16763     Container image "668749497752.dkr.ecr.us-west-2.amazonaws.com/sasviya/viya-4-x64_oci_linux_2-docker/sas-config-init:1.21.1-20240305.1709656957059" already present on machine
14m         Normal    Created                           pod/sas-batch-server-6194069e-f1eb-4ea3-9a74-d522f1ae564e-16763     Created container sas-config-init
14m         Normal    Started                           pod/sas-batch-server-6194069e-f1eb-4ea3-9a74-d522f1ae564e-16763     Started container sas-config-init
14m         Normal    Pulled                            pod/sas-batch-server-6194069e-f1eb-4ea3-9a74-d522f1ae564e-16763     Container image "668749497752.dkr.ecr.us-west-2.amazonaws.com/sasviya/viya-4-x64_oci_linux_2-docker/sas-programming-environment:1.53.31-20240613.1718295947845" already present on machine
14m         Normal    Created                           pod/sas-batch-server-6194069e-f1eb-4ea3-9a74-d522f1ae564e-16763     Created container sas-programming-environment
14m         Normal    Started                           pod/sas-batch-server-6194069e-f1eb-4ea3-9a74-d522f1ae564e-16763     Started container sas-programming-environment
14m         Normal    Pulled                            pod/sas-batch-server-6194069e-f1eb-4ea3-9a74-d522f1ae564e-16763     Container image "668749497752.dkr.ecr.us-west-2.amazonaws.com/sasviya/viya-4-x64_oci_linux_2-docker/sas-process-exporter:1.9.1-20240306.1709732097762" already present on machine
14m         Normal    Created                           pod/sas-batch-server-6194069e-f1eb-4ea3-9a74-d522f1ae564e-16763     Created container sas-process-exporter
14m         Normal    Started                           pod/sas-batch-server-6194069e-f1eb-4ea3-9a74-d522f1ae564e-16763     Started container sas-process-exporter
5m34s       Normal    Killing                           pod/sas-batch-server-6194069e-f1eb-4ea3-9a74-d522f1ae564e-16763     Stopping container sas-process-exporter
59m         Normal    Scheduled                         pod/sas-batch-server-62683403-d383-45a9-ab09-23fe02ed1695-16625     Successfully assigned viya-dev/sas-batch-server-62683403-d383-45a9-ab09-23fe02ed1695-16625 to ip-100-64-118-176.us-west-2.compute.internal
59m         Normal    Pulled                            pod/sas-batch-server-62683403-d383-45a9-ab09-23fe02ed1695-16625     Container image "668749497752.dkr.ecr.us-west-2.amazonaws.com/sasviya/viya-4-x64_oci_linux_2-docker/sas-certframe:3.51.0-20240313.1710330811841" already present on machine
59m         Normal    Created                           pod/sas-batch-server-62683403-d383-45a9-ab09-23fe02ed1695-16625     Created container sas-certframe
59m         Normal    Started                           pod/sas-batch-server-62683403-d383-45a9-ab09-23fe02ed1695-16625     Started container sas-certframe
59m         Normal    Pulled                            pod/sas-batch-server-62683403-d383-45a9-ab09-23fe02ed1695-16625     Container image "668749497752.dkr.ecr.us-west-2.amazonaws.com/sasviya/viya-4-x64_oci_linux_2-docker/sas-config-init:1.21.1-20240305.1709656957059" already present on machine
59m         Normal    Created                           pod/sas-batch-server-62683403-d383-45a9-ab09-23fe02ed1695-16625     Created container sas-config-init
59m         Normal    Started                           pod/sas-batch-server-62683403-d383-45a9-ab09-23fe02ed1695-16625     Started container sas-config-init
59m         Normal    Pulled                            pod/sas-batch-server-62683403-d383-45a9-ab09-23fe02ed1695-16625     Container image "668749497752.dkr.ecr.us-west-2.amazonaws.com/sasviya/viya-4-x64_oci_linux_2-docker/sas-programming-environment:1.53.31-20240613.1718295947845" already present on machine
59m         Normal    Created                           pod/sas-batch-server-62683403-d383-45a9-ab09-23fe02ed1695-16625     Created container sas-programming-environment
59m         Normal    Started                           pod/sas-batch-server-62683403-d383-45a9-ab09-23fe02ed1695-16625     Started container sas-programming-environment
59m         Normal    Pulled                            pod/sas-batch-server-62683403-d383-45a9-ab09-23fe02ed1695-16625     Container image "668749497752.dkr.ecr.us-west-2.amazonaws.com/sasviya/viya-4-x64_oci_linux_2-docker/sas-process-exporter:1.9.1-20240306.1709732097762" already present on machine
59m         Normal    Created                           pod/sas-batch-server-62683403-d383-45a9-ab09-23fe02ed1695-16625     Created container sas-process-exporter
59m         Normal    Started                           pod/sas-batch-server-62683403-d383-45a9-ab09-23fe02ed1695-16625     Started container sas-process-exporter
48m         Normal    Killing                           pod/sas-batch-server-62683403-d383-45a9-ab09-23fe02ed1695-16625     Stopping container sas-process-exporter
58m         Warning   FailedScheduling                  pod/sas-batch-server-6477a07c-3ba2-45d8-a24a-74795fa3278a-16656     0/9 nodes are available: 1 Insufficient cpu, 1node(s) had untolerated taint {workload.sas.com/class: cas}, 1 node(s) had untolerated taint {workload.sas.com/class: stateful}, 1 node(s) had untolerated taint {workload.sas.com/class: stateless}, 5 node(s) didn't match Pod's node affinity/selector. preemption: 0/9 nodes are available: 1 No preemption victims found for incoming pod, 8 Preemption is not helpful for scheduling..
59m         Normal    NotTriggerScaleUp                 pod/sas-batch-server-6477a07c-3ba2-45d8-a24a-74795fa3278a-16656     pod didn't trigger scale-up: 1 node(s) had untolerated taint {workload.sas.com/class: stateful}, 1 node(s) had untolerated taint {workload.sas.com/class: stateless}, 1 node(s) had untolerated taint {workload.sas.com/class: cas}, 2 node(s) didn't match Pod's node affinity/selector
54m         Warning   FailedScheduling                  pod/sas-batch-server-6477a07c-3ba2-45d8-a24a-74795fa3278a-16656     0/10 nodes are available: 1 Insufficient cpu, 1 node(s) had untolerated taint {workload.sas.com/class: cas}, 1 node(s) had untolerated taint {workload.sas.com/class: stateful}, 1 node(s) had untolerated taint {workload.sas.com/class: stateless}, 6 node(s) didn't match Pod's node affinity/selector. preemption: 0/10 nodes are available: 1 No preemption victims found for incoming pod, 9 Preemption is not helpful for scheduling..
53m         Normal    Scheduled                         pod/sas-batch-server-6477a07c-3ba2-45d8-a24a-74795fa3278a-16656     Successfully assigned viya-dev/sas-batch-server-6477a07c-3ba2-45d8-a24a-74795fa3278a-16656 to ip-100-64-103-52.us-west-2.compute.internal
53m         Normal    Pulled                            pod/sas-batch-server-6477a07c-3ba2-45d8-a24a-74795fa3278a-16656     Container image "668749497752.dkr.ecr.us-west-2.amazonaws.com/sasviya/viya-4-x64_oci_linux_2-docker/sas-certframe:3.51.0-20240313.1710330811841" already present on machine
53m         Normal    Created                           pod/sas-batch-server-6477a07c-3ba2-45d8-a24a-74795fa3278a-16656     Created container sas-certframe
53m         Normal    Started                           pod/sas-batch-server-6477a07c-3ba2-45d8-a24a-74795fa3278a-16656     Started container sas-certframe
53m         Normal    Pulled                            pod/sas-batch-server-6477a07c-3ba2-45d8-a24a-74795fa3278a-16656     Container image "668749497752.dkr.ecr.us-west-2.amazonaws.com/sasviya/viya-4-x64_oci_linux_2-docker/sas-config-init:1.21.1-20240305.1709656957059" already present on machine
53m         Normal    Created                           pod/sas-batch-server-6477a07c-3ba2-45d8-a24a-74795fa3278a-16656     Created container sas-config-init
53m         Normal    Started                           pod/sas-batch-server-6477a07c-3ba2-45d8-a24a-74795fa3278a-16656     Started container sas-config-init
53m         Normal    Pulled                            pod/sas-batch-server-6477a07c-3ba2-45d8-a24a-74795fa3278a-16656     Container image "668749497752.dkr.ecr.us-west-2.amazonaws.com/sasviya/viya-4-x64_oci_linux_2-docker/sas-programming-environment:1.53.31-20240613.1718295947845" already present on machine
53m         Normal    Created                           pod/sas-batch-server-6477a07c-3ba2-45d8-a24a-74795fa3278a-16656     Created container sas-programming-environment
53m         Normal    Started                           pod/sas-batch-server-6477a07c-3ba2-45d8-a24a-74795fa3278a-16656     Started container sas-programming-environment
53m         Normal    Pulled                            pod/sas-batch-server-6477a07c-3ba2-45d8-a24a-74795fa3278a-16656     Container image "668749497752.dkr.ecr.us-west-2.amazonaws.com/sasviya/viya-4-x64_oci_linux_2-docker/sas-process-exporter:1.9.1-20240306.1709732097762" already present on machine
53m         Normal    Created                           pod/sas-batch-server-6477a07c-3ba2-45d8-a24a-74795fa3278a-16656     Created container sas-process-exporter
53m         Normal    Started                           pod/sas-batch-server-6477a07c-3ba2-45d8-a24a-74795fa3278a-16656     Started container sas-process-exporter
46m         Normal    Killing                           pod/sas-batch-server-6477a07c-3ba2-45d8-a24a-74795fa3278a-16656     Stopping container sas-process-exporter
57m         Normal    Scheduled                         pod/sas-batch-server-651afb79-e247-45d0-bb64-0e8db17de017-16675     Successfully assigned viya-dev/sas-batch-server-651afb79-e247-45d0-bb64-0e8db17de017-16675 to ip-100-64-98-232.us-west-2.compute.internal
57m         Normal    Pulled                            pod/sas-batch-server-651afb79-e247-45d0-bb64-0e8db17de017-16675     Container image "668749497752.dkr.ecr.us-west-2.amazonaws.com/sasviya/viya-4-x64_oci_linux_2-docker/sas-certframe:3.51.0-20240313.1710330811841" already present on machine
57m         Normal    Created                           pod/sas-batch-server-651afb79-e247-45d0-bb64-0e8db17de017-16675     Created container sas-certframe
57m         Normal    Started                           pod/sas-batch-server-651afb79-e247-45d0-bb64-0e8db17de017-16675     Started container sas-certframe
57m         Normal    Pulling                           pod/sas-batch-server-651afb79-e247-45d0-bb64-0e8db17de017-16675     Pulling image "668749497752.dkr.ecr.us-west-2.amazonaws.com/sasviya/viya-4-x64_oci_linux_2-docker/sas-config-init:1.21.1-20240305.1709656957059"
56m         Normal    Pulled                            pod/sas-batch-server-651afb79-e247-45d0-bb64-0e8db17de017-16675     Successfully pulled image "668749497752.dkr.ecr.us-west-2.amazonaws.com/sasviya/viya-4-x64_oci_linux_2-docker/sas-config-init:1.21.1-20240305.1709656957059" in 25.015s (25.015s including waiting)
56m         Normal    Created                           pod/sas-batch-server-651afb79-e247-45d0-bb64-0e8db17de017-16675     Created container sas-config-init
56m         Normal    Started                           pod/sas-batch-server-651afb79-e247-45d0-bb64-0e8db17de017-16675     Started container sas-config-init
56m         Normal    Pulling                           pod/sas-batch-server-651afb79-e247-45d0-bb64-0e8db17de017-16675     Pulling image "668749497752.dkr.ecr.us-west-2.amazonaws.com/sasviya/viya-4-x64_oci_linux_2-docker/sas-programming-environment:1.53.31-20240613.1718295947845"
56m         Warning   Failed                            pod/sas-batch-server-651afb79-e247-45d0-bb64-0e8db17de017-16675     Failed to pull image "668749497752.dkr.ecr.us-west-2.amazonaws.com/sasviya/viya-4-x64_oci_linux_2-docker/sas-programming-environment:1.53.31-20240613.1718295947845": pull QPS exceeded
56m         Warning   Failed                            pod/sas-batch-server-651afb79-e247-45d0-bb64-0e8db17de017-16675     Error: ErrImagePull
56m         Normal    Pulled                            pod/sas-batch-server-651afb79-e247-45d0-bb64-0e8db17de017-16675     Container image "668749497752.dkr.ecr.us-west-2.amazonaws.com/sasviya/viya-4-x64_oci_linux_2-docker/sas-process-exporter:1.9.1-20240306.1709732097762" already present on machine
56m         Normal    Created                           pod/sas-batch-server-651afb79-e247-45d0-bb64-0e8db17de017-16675     Created container sas-process-exporter
56m         Normal    Started                           pod/sas-batch-server-651afb79-e247-45d0-bb64-0e8db17de017-16675     Started container sas-process-exporter
56m         Normal    BackOff                           pod/sas-batch-server-651afb79-e247-45d0-bb64-0e8db17de017-16675     Back-off pulling image "668749497752.dkr.ecr.us-west-2.amazonaws.com/sasviya/viya-4-x64_oci_linux_2-docker/sas-programming-environment:1.53.31-20240613.1718295947845"
56m         Warning   Failed                            pod/sas-batch-server-651afb79-e247-45d0-bb64-0e8db17de017-16675     Error: ImagePullBackOff
55m         Normal    Pulled                            pod/sas-batch-server-651afb79-e247-45d0-bb64-0e8db17de017-16675     Successfully pulled image "668749497752.dkr.ecr.us-west-2.amazonaws.com/sasviya/viya-4-x64_oci_linux_2-docker/sas-programming-environment:1.53.31-20240613.1718295947845" in 1m3.034s (1m3.034s including waiting)
55m         Normal    Created                           pod/sas-batch-server-651afb79-e247-45d0-bb64-0e8db17de017-16675     Created container sas-programming-environment
55m         Normal    Started                           pod/sas-batch-server-651afb79-e247-45d0-bb64-0e8db17de017-16675     Started container sas-programming-environment
46m         Normal    Killing                           pod/sas-batch-server-651afb79-e247-45d0-bb64-0e8db17de017-16675     Stopping container sas-process-exporter
19m         Normal    Scheduled                         pod/sas-batch-server-65f5a8a2-ee3b-474b-ba2a-938f82535497-16710     Successfully assigned viya-dev/sas-batch-server-65f5a8a2-ee3b-474b-ba2a-938f82535497-16710 to ip-100-64-98-232.us-west-2.compute.internal
19m         Normal    Pulled                            pod/sas-batch-server-65f5a8a2-ee3b-474b-ba2a-938f82535497-16710     Container image "668749497752.dkr.ecr.us-west-2.amazonaws.com/sasviya/viya-4-x64_oci_linux_2-docker/sas-certframe:3.51.0-20240313.1710330811841" already present on machine
19m         Normal    Created                           pod/sas-batch-server-65f5a8a2-ee3b-474b-ba2a-938f82535497-16710     Created container sas-certframe
19m         Normal    Started                           pod/sas-batch-server-65f5a8a2-ee3b-474b-ba2a-938f82535497-16710     Started container sas-certframe
19m         Normal    Pulled                            pod/sas-batch-server-65f5a8a2-ee3b-474b-ba2a-938f82535497-16710     Container image "668749497752.dkr.ecr.us-west-2.amazonaws.com/sasviya/viya-4-x64_oci_linux_2-docker/sas-config-init:1.21.1-20240305.1709656957059" already present on machine
19m         Normal    Created                           pod/sas-batch-server-65f5a8a2-ee3b-474b-ba2a-938f82535497-16710     Created container sas-config-init
19m         Normal    Started                           pod/sas-batch-server-65f5a8a2-ee3b-474b-ba2a-938f82535497-16710     Started container sas-config-init
19m         Normal    Pulled                            pod/sas-batch-server-65f5a8a2-ee3b-474b-ba2a-938f82535497-16710     Container image "668749497752.dkr.ecr.us-west-2.amazonaws.com/sasviya/viya-4-x64_oci_linux_2-docker/sas-programming-environment:1.53.31-20240613.1718295947845" already present on machine
19m         Normal    Created                           pod/sas-batch-server-65f5a8a2-ee3b-474b-ba2a-938f82535497-16710     Created container sas-programming-environment
19m         Normal    Started                           pod/sas-batch-server-65f5a8a2-ee3b-474b-ba2a-938f82535497-16710     Started container sas-programming-environment
19m         Normal    Pulled                            pod/sas-batch-server-65f5a8a2-ee3b-474b-ba2a-938f82535497-16710     Container image "668749497752.dkr.ecr.us-west-2.amazonaws.com/sasviya/viya-4-x64_oci_linux_2-docker/sas-process-exporter:1.9.1-20240306.1709732097762" already present on machine
19m         Normal    Created                           pod/sas-batch-server-65f5a8a2-ee3b-474b-ba2a-938f82535497-16710     Created container sas-process-exporter
19m         Normal    Started                           pod/sas-batch-server-65f5a8a2-ee3b-474b-ba2a-938f82535497-16710     Started container sas-process-exporter
6m          Normal    Killing                           pod/sas-batch-server-65f5a8a2-ee3b-474b-ba2a-938f82535497-16710     Stopping container sas-process-exporter
59m         Normal    Scheduled                         pod/sas-batch-server-66119b30-0e96-4413-987a-b83f47870c6e-16611     Successfully assigned viya-dev/sas-batch-server-66119b30-0e96-4413-987a-b83f47870c6e-16611 to ip-100-64-118-98.us-west-2.compute.internal
59m         Normal    Pulled                            pod/sas-batch-server-66119b30-0e96-4413-987a-b83f47870c6e-16611     Container image "668749497752.dkr.ecr.us-west-2.amazonaws.com/sasviya/viya-4-x64_oci_linux_2-docker/sas-certframe:3.51.0-20240313.1710330811841" already present on machine
59m         Normal    Created                           pod/sas-batch-server-66119b30-0e96-4413-987a-b83f47870c6e-16611     Created container sas-certframe
59m         Normal    Started                           pod/sas-batch-server-66119b30-0e96-4413-987a-b83f47870c6e-16611     Started container sas-certframe
59m         Normal    Pulled                            pod/sas-batch-server-66119b30-0e96-4413-987a-b83f47870c6e-16611     Container image "668749497752.dkr.ecr.us-west-2.amazonaws.com/sasviya/viya-4-x64_oci_linux_2-docker/sas-config-init:1.21.1-20240305.1709656957059" already present on machine
59m         Normal    Created                           pod/sas-batch-server-66119b30-0e96-4413-987a-b83f47870c6e-16611     Created container sas-config-init
59m         Normal    Started                           pod/sas-batch-server-66119b30-0e96-4413-987a-b83f47870c6e-16611     Started container sas-config-init
59m         Normal    Pulled                            pod/sas-batch-server-66119b30-0e96-4413-987a-b83f47870c6e-16611     Container image "668749497752.dkr.ecr.us-west-2.amazonaws.com/sasviya/viya-4-x64_oci_linux_2-docker/sas-programming-environment:1.53.31-20240613.1718295947845" already present on machine
59m         Normal    Created                           pod/sas-batch-server-66119b30-0e96-4413-987a-b83f47870c6e-16611     Created container sas-programming-environment
59m         Normal    Started                           pod/sas-batch-server-66119b30-0e96-4413-987a-b83f47870c6e-16611     Started container sas-programming-environment
59m         Normal    Pulled                            pod/sas-batch-server-66119b30-0e96-4413-987a-b83f47870c6e-16611     Container image "668749497752.dkr.ecr.us-west-2.amazonaws.com/sasviya/viya-4-x64_oci_linux_2-docker/sas-process-exporter:1.9.1-20240306.1709732097762" already present on machine
59m         Normal    Created                           pod/sas-batch-server-66119b30-0e96-4413-987a-b83f47870c6e-16611     Created container sas-process-exporter
59m         Normal    Started                           pod/sas-batch-server-66119b30-0e96-4413-987a-b83f47870c6e-16611     Started container sas-process-exporter
48m         Normal    Killing                           pod/sas-batch-server-66119b30-0e96-4413-987a-b83f47870c6e-16611     Stopping container sas-process-exporter
59m         Normal    Scheduled                         pod/sas-batch-server-67da8639-1e70-41ac-82ea-1ed1d9fcd815-16614     Successfully assigned viya-dev/sas-batch-server-67da8639-1e70-41ac-82ea-1ed1d9fcd815-16614 to ip-100-64-118-176.us-west-2.compute.internal
59m         Normal    Pulled                            pod/sas-batch-server-67da8639-1e70-41ac-82ea-1ed1d9fcd815-16614     Container image "668749497752.dkr.ecr.us-west-2.amazonaws.com/sasviya/viya-4-x64_oci_linux_2-docker/sas-certframe:3.51.0-20240313.1710330811841" already present on machine
59m         Normal    Created                           pod/sas-batch-server-67da8639-1e70-41ac-82ea-1ed1d9fcd815-16614     Created container sas-certframe
59m         Normal    Started                           pod/sas-batch-server-67da8639-1e70-41ac-82ea-1ed1d9fcd815-16614     Started container sas-certframe
59m         Normal    Pulled                            pod/sas-batch-server-67da8639-1e70-41ac-82ea-1ed1d9fcd815-16614     Container image "668749497752.dkr.ecr.us-west-2.amazonaws.com/sasviya/viya-4-x64_oci_linux_2-docker/sas-config-init:1.21.1-20240305.1709656957059" already present on machine
59m         Normal    Created                           pod/sas-batch-server-67da8639-1e70-41ac-82ea-1ed1d9fcd815-16614     Created container sas-config-init
59m         Normal    Started                           pod/sas-batch-server-67da8639-1e70-41ac-82ea-1ed1d9fcd815-16614     Started container sas-config-init
59m         Normal    Pulled                            pod/sas-batch-server-67da8639-1e70-41ac-82ea-1ed1d9fcd815-16614     Container image "668749497752.dkr.ecr.us-west-2.amazonaws.com/sasviya/viya-4-x64_oci_linux_2-docker/sas-programming-environment:1.53.31-20240613.1718295947845" already present on machine
59m         Normal    Created                           pod/sas-batch-server-67da8639-1e70-41ac-82ea-1ed1d9fcd815-16614     Created container sas-programming-environment
59m         Normal    Started                           pod/sas-batch-server-67da8639-1e70-41ac-82ea-1ed1d9fcd815-16614     Started container sas-programming-environment
59m         Normal    Pulled                            pod/sas-batch-server-67da8639-1e70-41ac-82ea-1ed1d9fcd815-16614     Container image "668749497752.dkr.ecr.us-west-2.amazonaws.com/sasviya/viya-4-x64_oci_linux_2-docker/sas-process-exporter:1.9.1-20240306.1709732097762" already present on machine
59m         Normal    Created                           pod/sas-batch-server-67da8639-1e70-41ac-82ea-1ed1d9fcd815-16614     Created container sas-process-exporter
59m         Normal    Started                           pod/sas-batch-server-67da8639-1e70-41ac-82ea-1ed1d9fcd815-16614     Started container sas-process-exporter
46m         Normal    Killing                           pod/sas-batch-server-67da8639-1e70-41ac-82ea-1ed1d9fcd815-16614     Stopping container sas-process-exporter
59m         Normal    Scheduled                         pod/sas-batch-server-68395ee8-14b4-4015-b2b4-1153e246973a-16628     Successfully assigned viya-dev/sas-batch-server-68395ee8-14b4-4015-b2b4-1153e246973a-16628 to ip-100-64-125-225.us-west-2.compute.internal
59m         Normal    Pulled                            pod/sas-batch-server-68395ee8-14b4-4015-b2b4-1153e246973a-16628     Container image "668749497752.dkr.ecr.us-west-2.amazonaws.com/sasviya/viya-4-x64_oci_linux_2-docker/sas-certframe:3.51.0-20240313.1710330811841" already present on machine
59m         Normal    Created                           pod/sas-batch-server-68395ee8-14b4-4015-b2b4-1153e246973a-16628     Created container sas-certframe
59m         Normal    Started                           pod/sas-batch-server-68395ee8-14b4-4015-b2b4-1153e246973a-16628     Started container sas-certframe
59m         Normal    Pulled                            pod/sas-batch-server-68395ee8-14b4-4015-b2b4-1153e246973a-16628     Container image "668749497752.dkr.ecr.us-west-2.amazonaws.com/sasviya/viya-4-x64_oci_linux_2-docker/sas-config-init:1.21.1-20240305.1709656957059" already present on machine
59m         Normal    Created                           pod/sas-batch-server-68395ee8-14b4-4015-b2b4-1153e246973a-16628     Created container sas-config-init
59m         Normal    Started                           pod/sas-batch-server-68395ee8-14b4-4015-b2b4-1153e246973a-16628     Started container sas-config-init
59m         Normal    Pulled                            pod/sas-batch-server-68395ee8-14b4-4015-b2b4-1153e246973a-16628     Container image "668749497752.dkr.ecr.us-west-2.amazonaws.com/sasviya/viya-4-x64_oci_linux_2-docker/sas-programming-environment:1.53.31-20240613.1718295947845" already present on machine
59m         Normal    Created                           pod/sas-batch-server-68395ee8-14b4-4015-b2b4-1153e246973a-16628     Created container sas-programming-environment
59m         Normal    Started                           pod/sas-batch-server-68395ee8-14b4-4015-b2b4-1153e246973a-16628     Started container sas-programming-environment
59m         Normal    Pulled                            pod/sas-batch-server-68395ee8-14b4-4015-b2b4-1153e246973a-16628     Container image "668749497752.dkr.ecr.us-west-2.amazonaws.com/sasviya/viya-4-x64_oci_linux_2-docker/sas-process-exporter:1.9.1-20240306.1709732097762" already present on machine
59m         Normal    Created                           pod/sas-batch-server-68395ee8-14b4-4015-b2b4-1153e246973a-16628     Created container sas-process-exporter
59m         Normal    Started                           pod/sas-batch-server-68395ee8-14b4-4015-b2b4-1153e246973a-16628     Started container sas-process-exporter
46m         Normal    Killing                           pod/sas-batch-server-68395ee8-14b4-4015-b2b4-1153e246973a-16628     Stopping container sas-process-exporter
8m43s       Warning   FailedScheduling                  pod/sas-batch-server-6a1a807e-f7a6-427f-a114-0278a8d9350f-16775     0/10 nodes are available: 1 Insufficient cpu, 1 node(s) had untolerated taint {workload.sas.com/class: cas}, 1 node(s) had untolerated taint {workload.sas.com/class: stateful}, 1 node(s) had untolerated taint {workload.sas.com/class: stateless}, 6 node(s) didn't match Pod's node affinity/selector. preemption: 0/10 nodes are available: 1 No preemption victims found for incoming pod, 9 Preemption is not helpful for scheduling..
9m38s       Normal    NotTriggerScaleUp                 pod/sas-batch-server-6a1a807e-f7a6-427f-a114-0278a8d9350f-16775     pod didn't trigger scale-up: 2 node(s) didn't match Pod's node affinity/selector, 1 node(s) had untolerated taint {workload.sas.com/class: stateful}, 1 node(s) had untolerated taint {workload.sas.com/class: stateless}, 1 node(s) had untolerated taint {workload.sas.com/class: cas}
8m32s       Warning   FailedScheduling                  pod/sas-batch-server-6a1a807e-f7a6-427f-a114-0278a8d9350f-16775     0/11 nodes are available: 1 Insufficient cpu, 1 node(s) had untolerated taint {node.kubernetes.io/not-ready: }, 1 node(s) had untolerated taint {workload.sas.com/class: cas}, 1 node(s) had untolerated taint {workload.sas.com/class: stateful}, 1 node(s) had untolerated taint {workload.sas.com/class: stateless}, 6 node(s) didn't match Pod's node affinity/selector. preemption: 0/11 nodes are available: 1 No preemption victims found for incoming pod, 10 Preemption is not helpful for scheduling..
6m25s       Warning   FailedScheduling                  pod/sas-batch-server-6a1a807e-f7a6-427f-a114-0278a8d9350f-16775     0/11 nodes are available: 1 Insufficient cpu, 1 node(s) had untolerated taint {workload.sas.com/class: cas}, 1 node(s) had untolerated taint {workload.sas.com/class: stateful}, 1 node(s) had untolerated taint {workload.sas.com/class: stateless}, 7 node(s) didn't match Pod's node affinity/selector. preemption: 0/11 nodes are available: 1 No preemption victims found for incoming pod, 10 Preemption is not helpful for scheduling..
6m1s        Normal    Pulled                            pod/sas-batch-server-6a1a807e-f7a6-427f-a114-0278a8d9350f-16775     Container image "668749497752.dkr.ecr.us-west-2.amazonaws.com/sasviya/viya-4-x64_oci_linux_2-docker/sas-certframe:3.51.0-20240313.1710330811841" already present on machine
6m1s        Normal    Created                           pod/sas-batch-server-6a1a807e-f7a6-427f-a114-0278a8d9350f-16775     Created container sas-certframe
6m1s        Normal    Started                           pod/sas-batch-server-6a1a807e-f7a6-427f-a114-0278a8d9350f-16775     Started container sas-certframe
5m59s       Normal    Pulled                            pod/sas-batch-server-6a1a807e-f7a6-427f-a114-0278a8d9350f-16775     Container image "668749497752.dkr.ecr.us-west-2.amazonaws.com/sasviya/viya-4-x64_oci_linux_2-docker/sas-config-init:1.21.1-20240305.1709656957059" already present on machine
5m59s       Normal    Created                           pod/sas-batch-server-6a1a807e-f7a6-427f-a114-0278a8d9350f-16775     Created container sas-config-init
5m59s       Normal    Started                           pod/sas-batch-server-6a1a807e-f7a6-427f-a114-0278a8d9350f-16775     Started container sas-config-init
5m57s       Normal    Pulled                            pod/sas-batch-server-6a1a807e-f7a6-427f-a114-0278a8d9350f-16775     Container image "668749497752.dkr.ecr.us-west-2.amazonaws.com/sasviya/viya-4-x64_oci_linux_2-docker/sas-programming-environment:1.53.31-20240613.1718295947845" already present on machine
5m57s       Normal    Created                           pod/sas-batch-server-6a1a807e-f7a6-427f-a114-0278a8d9350f-16775     Created container sas-programming-environment
5m57s       Normal    Started                           pod/sas-batch-server-6a1a807e-f7a6-427f-a114-0278a8d9350f-16775     Started container sas-programming-environment
5m57s       Normal    Pulled                            pod/sas-batch-server-6a1a807e-f7a6-427f-a114-0278a8d9350f-16775     Container image "668749497752.dkr.ecr.us-west-2.amazonaws.com/sasviya/viya-4-x64_oci_linux_2-docker/sas-process-exporter:1.9.1-20240306.1709732097762" already present on machine
5m56s       Normal    Created                           pod/sas-batch-server-6a1a807e-f7a6-427f-a114-0278a8d9350f-16775     Created container sas-process-exporter
5m56s       Normal    Started                           pod/sas-batch-server-6a1a807e-f7a6-427f-a114-0278a8d9350f-16775     Started container sas-process-exporter
3m16s       Normal    Killing                           pod/sas-batch-server-6a1a807e-f7a6-427f-a114-0278a8d9350f-16775     Stopping container sas-process-exporter
59m         Normal    Scheduled                         pod/sas-batch-server-6a34282c-0198-42e1-a8a3-5a231f39e429-16636     Successfully assigned viya-dev/sas-batch-server-6a34282c-0198-42e1-a8a3-5a231f39e429-16636 to ip-100-64-125-225.us-west-2.compute.internal
59m         Normal    Pulled                            pod/sas-batch-server-6a34282c-0198-42e1-a8a3-5a231f39e429-16636     Container image "668749497752.dkr.ecr.us-west-2.amazonaws.com/sasviya/viya-4-x64_oci_linux_2-docker/sas-certframe:3.51.0-20240313.1710330811841" already present on machine
59m         Normal    Created                           pod/sas-batch-server-6a34282c-0198-42e1-a8a3-5a231f39e429-16636     Created container sas-certframe
59m         Normal    Started                           pod/sas-batch-server-6a34282c-0198-42e1-a8a3-5a231f39e429-16636     Started container sas-certframe
59m         Normal    Pulled                            pod/sas-batch-server-6a34282c-0198-42e1-a8a3-5a231f39e429-16636     Container image "668749497752.dkr.ecr.us-west-2.amazonaws.com/sasviya/viya-4-x64_oci_linux_2-docker/sas-config-init:1.21.1-20240305.1709656957059" already present on machine
59m         Normal    Created                           pod/sas-batch-server-6a34282c-0198-42e1-a8a3-5a231f39e429-16636     Created container sas-config-init
59m         Normal    Started                           pod/sas-batch-server-6a34282c-0198-42e1-a8a3-5a231f39e429-16636     Started container sas-config-init
59m         Normal    Pulled                            pod/sas-batch-server-6a34282c-0198-42e1-a8a3-5a231f39e429-16636     Container image "668749497752.dkr.ecr.us-west-2.amazonaws.com/sasviya/viya-4-x64_oci_linux_2-docker/sas-programming-environment:1.53.31-20240613.1718295947845" already present on machine
59m         Normal    Created                           pod/sas-batch-server-6a34282c-0198-42e1-a8a3-5a231f39e429-16636     Created container sas-programming-environment
59m         Normal    Started                           pod/sas-batch-server-6a34282c-0198-42e1-a8a3-5a231f39e429-16636     Started container sas-programming-environment
59m         Normal    Pulled                            pod/sas-batch-server-6a34282c-0198-42e1-a8a3-5a231f39e429-16636     Container image "668749497752.dkr.ecr.us-west-2.amazonaws.com/sasviya/viya-4-x64_oci_linux_2-docker/sas-process-exporter:1.9.1-20240306.1709732097762" already present on machine
59m         Normal    Created                           pod/sas-batch-server-6a34282c-0198-42e1-a8a3-5a231f39e429-16636     Created container sas-process-exporter
59m         Normal    Started                           pod/sas-batch-server-6a34282c-0198-42e1-a8a3-5a231f39e429-16636     Started container sas-process-exporter
46m         Normal    Killing                           pod/sas-batch-server-6a34282c-0198-42e1-a8a3-5a231f39e429-16636     Stopping container sas-process-exporter
59m         Normal    Killing                           pod/sas-batch-server-6c799f4e-3544-4ac6-b92e-840c39fbd62b-16604     Stopping container sas-process-exporter
59m         Normal    Scheduled                         pod/sas-batch-server-6ce1b641-1671-48bd-b64f-f15d7a5812a4-16639     Successfully assigned viya-dev/sas-batch-server-6ce1b641-1671-48bd-b64f-f15d7a5812a4-16639 to ip-100-64-118-98.us-west-2.compute.internal
59m         Normal    Pulled                            pod/sas-batch-server-6ce1b641-1671-48bd-b64f-f15d7a5812a4-16639     Container image "668749497752.dkr.ecr.us-west-2.amazonaws.com/sasviya/viya-4-x64_oci_linux_2-docker/sas-certframe:3.51.0-20240313.1710330811841" already present on machine
59m         Normal    Created                           pod/sas-batch-server-6ce1b641-1671-48bd-b64f-f15d7a5812a4-16639     Created container sas-certframe
59m         Normal    Started                           pod/sas-batch-server-6ce1b641-1671-48bd-b64f-f15d7a5812a4-16639     Started container sas-certframe
59m         Normal    Pulled                            pod/sas-batch-server-6ce1b641-1671-48bd-b64f-f15d7a5812a4-16639     Container image "668749497752.dkr.ecr.us-west-2.amazonaws.com/sasviya/viya-4-x64_oci_linux_2-docker/sas-config-init:1.21.1-20240305.1709656957059" already present on machine
59m         Normal    Created                           pod/sas-batch-server-6ce1b641-1671-48bd-b64f-f15d7a5812a4-16639     Created container sas-config-init
59m         Normal    Started                           pod/sas-batch-server-6ce1b641-1671-48bd-b64f-f15d7a5812a4-16639     Started container sas-config-init
59m         Normal    Pulled                            pod/sas-batch-server-6ce1b641-1671-48bd-b64f-f15d7a5812a4-16639     Container image "668749497752.dkr.ecr.us-west-2.amazonaws.com/sasviya/viya-4-x64_oci_linux_2-docker/sas-programming-environment:1.53.31-20240613.1718295947845" already present on machine
59m         Normal    Created                           pod/sas-batch-server-6ce1b641-1671-48bd-b64f-f15d7a5812a4-16639     Created container sas-programming-environment
59m         Normal    Started                           pod/sas-batch-server-6ce1b641-1671-48bd-b64f-f15d7a5812a4-16639     Started container sas-programming-environment
59m         Normal    Pulled                            pod/sas-batch-server-6ce1b641-1671-48bd-b64f-f15d7a5812a4-16639     Container image "668749497752.dkr.ecr.us-west-2.amazonaws.com/sasviya/viya-4-x64_oci_linux_2-docker/sas-process-exporter:1.9.1-20240306.1709732097762" already present on machine
59m         Normal    Created                           pod/sas-batch-server-6ce1b641-1671-48bd-b64f-f15d7a5812a4-16639     Created container sas-process-exporter
59m         Normal    Started                           pod/sas-batch-server-6ce1b641-1671-48bd-b64f-f15d7a5812a4-16639     Started container sas-process-exporter
47m         Normal    Killing                           pod/sas-batch-server-6ce1b641-1671-48bd-b64f-f15d7a5812a4-16639     Stopping container sas-process-exporter
19m         Normal    Scheduled                         pod/sas-batch-server-6dc7ae29-bef1-4f7b-ad73-be2c51c57ac9-16746     Successfully assigned viya-dev/sas-batch-server-6dc7ae29-bef1-4f7b-ad73-be2c51c57ac9-16746 to ip-100-64-98-232.us-west-2.compute.internal
19m         Normal    Pulled                            pod/sas-batch-server-6dc7ae29-bef1-4f7b-ad73-be2c51c57ac9-16746     Container image "668749497752.dkr.ecr.us-west-2.amazonaws.com/sasviya/viya-4-x64_oci_linux_2-docker/sas-certframe:3.51.0-20240313.1710330811841" already present on machine
19m         Normal    Created                           pod/sas-batch-server-6dc7ae29-bef1-4f7b-ad73-be2c51c57ac9-16746     Created container sas-certframe
19m         Normal    Started                           pod/sas-batch-server-6dc7ae29-bef1-4f7b-ad73-be2c51c57ac9-16746     Started container sas-certframe
19m         Normal    Pulled                            pod/sas-batch-server-6dc7ae29-bef1-4f7b-ad73-be2c51c57ac9-16746     Container image "668749497752.dkr.ecr.us-west-2.amazonaws.com/sasviya/viya-4-x64_oci_linux_2-docker/sas-config-init:1.21.1-20240305.1709656957059" already present on machine
19m         Normal    Created                           pod/sas-batch-server-6dc7ae29-bef1-4f7b-ad73-be2c51c57ac9-16746     Created container sas-config-init
19m         Normal    Started                           pod/sas-batch-server-6dc7ae29-bef1-4f7b-ad73-be2c51c57ac9-16746     Started container sas-config-init
19m         Normal    Pulled                            pod/sas-batch-server-6dc7ae29-bef1-4f7b-ad73-be2c51c57ac9-16746     Container image "668749497752.dkr.ecr.us-west-2.amazonaws.com/sasviya/viya-4-x64_oci_linux_2-docker/sas-programming-environment:1.53.31-20240613.1718295947845" already present on machine
19m         Normal    Created                           pod/sas-batch-server-6dc7ae29-bef1-4f7b-ad73-be2c51c57ac9-16746     Created container sas-programming-environment
19m         Normal    Started                           pod/sas-batch-server-6dc7ae29-bef1-4f7b-ad73-be2c51c57ac9-16746     Started container sas-programming-environment
19m         Normal    Pulled                            pod/sas-batch-server-6dc7ae29-bef1-4f7b-ad73-be2c51c57ac9-16746     Container image "668749497752.dkr.ecr.us-west-2.amazonaws.com/sasviya/viya-4-x64_oci_linux_2-docker/sas-process-exporter:1.9.1-20240306.1709732097762" already present on machine
19m         Normal    Created                           pod/sas-batch-server-6dc7ae29-bef1-4f7b-ad73-be2c51c57ac9-16746     Created container sas-process-exporter
19m         Normal    Started                           pod/sas-batch-server-6dc7ae29-bef1-4f7b-ad73-be2c51c57ac9-16746     Started container sas-process-exporter
6m56s       Normal    Killing                           pod/sas-batch-server-6dc7ae29-bef1-4f7b-ad73-be2c51c57ac9-16746     Stopping container sas-process-exporter
59m         Normal    Scheduled                         pod/sas-batch-server-6f55db7f-0907-4d76-a901-41ca64bc8109-16619     Successfully assigned viya-dev/sas-batch-server-6f55db7f-0907-4d76-a901-41ca64bc8109-16619 to ip-100-64-118-176.us-west-2.compute.internal
59m         Normal    Pulled                            pod/sas-batch-server-6f55db7f-0907-4d76-a901-41ca64bc8109-16619     Container image "668749497752.dkr.ecr.us-west-2.amazonaws.com/sasviya/viya-4-x64_oci_linux_2-docker/sas-certframe:3.51.0-20240313.1710330811841" already present on machine
59m         Normal    Created                           pod/sas-batch-server-6f55db7f-0907-4d76-a901-41ca64bc8109-16619     Created container sas-certframe
59m         Normal    Started                           pod/sas-batch-server-6f55db7f-0907-4d76-a901-41ca64bc8109-16619     Started container sas-certframe
59m         Normal    Pulled                            pod/sas-batch-server-6f55db7f-0907-4d76-a901-41ca64bc8109-16619     Container image "668749497752.dkr.ecr.us-west-2.amazonaws.com/sasviya/viya-4-x64_oci_linux_2-docker/sas-config-init:1.21.1-20240305.1709656957059" already present on machine
59m         Normal    Created                           pod/sas-batch-server-6f55db7f-0907-4d76-a901-41ca64bc8109-16619     Created container sas-config-init
59m         Normal    Started                           pod/sas-batch-server-6f55db7f-0907-4d76-a901-41ca64bc8109-16619     Started container sas-config-init
59m         Normal    Pulled                            pod/sas-batch-server-6f55db7f-0907-4d76-a901-41ca64bc8109-16619     Container image "668749497752.dkr.ecr.us-west-2.amazonaws.com/sasviya/viya-4-x64_oci_linux_2-docker/sas-programming-environment:1.53.31-20240613.1718295947845" already present on machine
59m         Normal    Created                           pod/sas-batch-server-6f55db7f-0907-4d76-a901-41ca64bc8109-16619     Created container sas-programming-environment
59m         Normal    Started                           pod/sas-batch-server-6f55db7f-0907-4d76-a901-41ca64bc8109-16619     Started container sas-programming-environment
59m         Normal    Pulled                            pod/sas-batch-server-6f55db7f-0907-4d76-a901-41ca64bc8109-16619     Container image "668749497752.dkr.ecr.us-west-2.amazonaws.com/sasviya/viya-4-x64_oci_linux_2-docker/sas-process-exporter:1.9.1-20240306.1709732097762" already present on machine
59m         Normal    Created                           pod/sas-batch-server-6f55db7f-0907-4d76-a901-41ca64bc8109-16619     Created container sas-process-exporter
59m         Normal    Started                           pod/sas-batch-server-6f55db7f-0907-4d76-a901-41ca64bc8109-16619     Started container sas-process-exporter
47m         Normal    Killing                           pod/sas-batch-server-6f55db7f-0907-4d76-a901-41ca64bc8109-16619     Stopping container sas-process-exporter
19m         Normal    Scheduled                         pod/sas-batch-server-6fa1080e-8e78-4804-b0d2-1dd8a80f8bbe-16730     Successfully assigned viya-dev/sas-batch-server-6fa1080e-8e78-4804-b0d2-1dd8a80f8bbe-16730 to ip-100-64-103-52.us-west-2.compute.internal
19m         Normal    Pulled                            pod/sas-batch-server-6fa1080e-8e78-4804-b0d2-1dd8a80f8bbe-16730     Container image "668749497752.dkr.ecr.us-west-2.amazonaws.com/sasviya/viya-4-x64_oci_linux_2-docker/sas-certframe:3.51.0-20240313.1710330811841" already present on machine
19m         Normal    Created                           pod/sas-batch-server-6fa1080e-8e78-4804-b0d2-1dd8a80f8bbe-16730     Created container sas-certframe
19m         Normal    Started                           pod/sas-batch-server-6fa1080e-8e78-4804-b0d2-1dd8a80f8bbe-16730     Started container sas-certframe
19m         Normal    Pulled                            pod/sas-batch-server-6fa1080e-8e78-4804-b0d2-1dd8a80f8bbe-16730     Container image "668749497752.dkr.ecr.us-west-2.amazonaws.com/sasviya/viya-4-x64_oci_linux_2-docker/sas-config-init:1.21.1-20240305.1709656957059" already present on machine
19m         Normal    Created                           pod/sas-batch-server-6fa1080e-8e78-4804-b0d2-1dd8a80f8bbe-16730     Created container sas-config-init
19m         Normal    Started                           pod/sas-batch-server-6fa1080e-8e78-4804-b0d2-1dd8a80f8bbe-16730     Started container sas-config-init
19m         Normal    Pulled                            pod/sas-batch-server-6fa1080e-8e78-4804-b0d2-1dd8a80f8bbe-16730     Container image "668749497752.dkr.ecr.us-west-2.amazonaws.com/sasviya/viya-4-x64_oci_linux_2-docker/sas-programming-environment:1.53.31-20240613.1718295947845" already present on machine
19m         Normal    Created                           pod/sas-batch-server-6fa1080e-8e78-4804-b0d2-1dd8a80f8bbe-16730     Created container sas-programming-environment
19m         Normal    Started                           pod/sas-batch-server-6fa1080e-8e78-4804-b0d2-1dd8a80f8bbe-16730     Started container sas-programming-environment
19m         Normal    Pulled                            pod/sas-batch-server-6fa1080e-8e78-4804-b0d2-1dd8a80f8bbe-16730     Container image "668749497752.dkr.ecr.us-west-2.amazonaws.com/sasviya/viya-4-x64_oci_linux_2-docker/sas-process-exporter:1.9.1-20240306.1709732097762" already present on machine
19m         Normal    Created                           pod/sas-batch-server-6fa1080e-8e78-4804-b0d2-1dd8a80f8bbe-16730     Created container sas-process-exporter
19m         Normal    Started                           pod/sas-batch-server-6fa1080e-8e78-4804-b0d2-1dd8a80f8bbe-16730     Started container sas-process-exporter
4m9s        Normal    Killing                           pod/sas-batch-server-6fa1080e-8e78-4804-b0d2-1dd8a80f8bbe-16730     Stopping container sas-process-exporter
59m         Normal    Scheduled                         pod/sas-batch-server-6fe5d516-b828-4ae6-a89e-c1926a84722b-16618     Successfully assigned viya-dev/sas-batch-server-6fe5d516-b828-4ae6-a89e-c1926a84722b-16618 to ip-100-64-125-225.us-west-2.compute.internal
59m         Normal    Pulled                            pod/sas-batch-server-6fe5d516-b828-4ae6-a89e-c1926a84722b-16618     Container image "668749497752.dkr.ecr.us-west-2.amazonaws.com/sasviya/viya-4-x64_oci_linux_2-docker/sas-certframe:3.51.0-20240313.1710330811841" already present on machine
59m         Normal    Created                           pod/sas-batch-server-6fe5d516-b828-4ae6-a89e-c1926a84722b-16618     Created container sas-certframe
59m         Normal    Started                           pod/sas-batch-server-6fe5d516-b828-4ae6-a89e-c1926a84722b-16618     Started container sas-certframe
59m         Normal    Pulled                            pod/sas-batch-server-6fe5d516-b828-4ae6-a89e-c1926a84722b-16618     Container image "668749497752.dkr.ecr.us-west-2.amazonaws.com/sasviya/viya-4-x64_oci_linux_2-docker/sas-config-init:1.21.1-20240305.1709656957059" already present on machine
59m         Normal    Created                           pod/sas-batch-server-6fe5d516-b828-4ae6-a89e-c1926a84722b-16618     Created container sas-config-init
59m         Normal    Started                           pod/sas-batch-server-6fe5d516-b828-4ae6-a89e-c1926a84722b-16618     Started container sas-config-init
59m         Normal    Pulled                            pod/sas-batch-server-6fe5d516-b828-4ae6-a89e-c1926a84722b-16618     Container image "668749497752.dkr.ecr.us-west-2.amazonaws.com/sasviya/viya-4-x64_oci_linux_2-docker/sas-programming-environment:1.53.31-20240613.1718295947845" already present on machine
59m         Normal    Created                           pod/sas-batch-server-6fe5d516-b828-4ae6-a89e-c1926a84722b-16618     Created container sas-programming-environment
59m         Normal    Started                           pod/sas-batch-server-6fe5d516-b828-4ae6-a89e-c1926a84722b-16618     Started container sas-programming-environment
59m         Normal    Pulled                            pod/sas-batch-server-6fe5d516-b828-4ae6-a89e-c1926a84722b-16618     Container image "668749497752.dkr.ecr.us-west-2.amazonaws.com/sasviya/viya-4-x64_oci_linux_2-docker/sas-process-exporter:1.9.1-20240306.1709732097762" already present on machine
59m         Normal    Created                           pod/sas-batch-server-6fe5d516-b828-4ae6-a89e-c1926a84722b-16618     Created container sas-process-exporter
59m         Normal    Started                           pod/sas-batch-server-6fe5d516-b828-4ae6-a89e-c1926a84722b-16618     Started container sas-process-exporter
48m         Normal    Killing                           pod/sas-batch-server-6fe5d516-b828-4ae6-a89e-c1926a84722b-16618     Stopping container sas-process-exporter
59m         Normal    Scheduled                         pod/sas-batch-server-715962b8-d79f-4ca1-8464-deb7aeec35dc-16648     Successfully assigned viya-dev/sas-batch-server-715962b8-d79f-4ca1-8464-deb7aeec35dc-16648 to ip-100-64-125-225.us-west-2.compute.internal
59m         Normal    Pulled                            pod/sas-batch-server-715962b8-d79f-4ca1-8464-deb7aeec35dc-16648     Container image "668749497752.dkr.ecr.us-west-2.amazonaws.com/sasviya/viya-4-x64_oci_linux_2-docker/sas-certframe:3.51.0-20240313.1710330811841" already present on machine
59m         Normal    Created                           pod/sas-batch-server-715962b8-d79f-4ca1-8464-deb7aeec35dc-16648     Created container sas-certframe
59m         Normal    Started                           pod/sas-batch-server-715962b8-d79f-4ca1-8464-deb7aeec35dc-16648     Started container sas-certframe
59m         Normal    Pulled                            pod/sas-batch-server-715962b8-d79f-4ca1-8464-deb7aeec35dc-16648     Container image "668749497752.dkr.ecr.us-west-2.amazonaws.com/sasviya/viya-4-x64_oci_linux_2-docker/sas-config-init:1.21.1-20240305.1709656957059" already present on machine
59m         Normal    Created                           pod/sas-batch-server-715962b8-d79f-4ca1-8464-deb7aeec35dc-16648     Created container sas-config-init
59m         Normal    Started                           pod/sas-batch-server-715962b8-d79f-4ca1-8464-deb7aeec35dc-16648     Started container sas-config-init
59m         Normal    Pulled                            pod/sas-batch-server-715962b8-d79f-4ca1-8464-deb7aeec35dc-16648     Container image "668749497752.dkr.ecr.us-west-2.amazonaws.com/sasviya/viya-4-x64_oci_linux_2-docker/sas-programming-environment:1.53.31-20240613.1718295947845" already present on machine
59m         Normal    Created                           pod/sas-batch-server-715962b8-d79f-4ca1-8464-deb7aeec35dc-16648     Created container sas-programming-environment
59m         Normal    Started                           pod/sas-batch-server-715962b8-d79f-4ca1-8464-deb7aeec35dc-16648     Started container sas-programming-environment
59m         Normal    Pulled                            pod/sas-batch-server-715962b8-d79f-4ca1-8464-deb7aeec35dc-16648     Container image "668749497752.dkr.ecr.us-west-2.amazonaws.com/sasviya/viya-4-x64_oci_linux_2-docker/sas-process-exporter:1.9.1-20240306.1709732097762" already present on machine
59m         Normal    Created                           pod/sas-batch-server-715962b8-d79f-4ca1-8464-deb7aeec35dc-16648     Created container sas-process-exporter
59m         Normal    Started                           pod/sas-batch-server-715962b8-d79f-4ca1-8464-deb7aeec35dc-16648     Started container sas-process-exporter
46m         Normal    Killing                           pod/sas-batch-server-715962b8-d79f-4ca1-8464-deb7aeec35dc-16648     Stopping container sas-process-exporter
19m         Normal    Scheduled                         pod/sas-batch-server-72bce2d6-5a56-4db7-91bf-0b4335527b52-16737     Successfully assigned viya-dev/sas-batch-server-72bce2d6-5a56-4db7-91bf-0b4335527b52-16737 to ip-100-64-88-54.us-west-2.compute.internal
19m         Normal    Pulled                            pod/sas-batch-server-72bce2d6-5a56-4db7-91bf-0b4335527b52-16737     Container image "668749497752.dkr.ecr.us-west-2.amazonaws.com/sasviya/viya-4-x64_oci_linux_2-docker/sas-certframe:3.51.0-20240313.1710330811841" already present on machine
19m         Normal    Created                           pod/sas-batch-server-72bce2d6-5a56-4db7-91bf-0b4335527b52-16737     Created container sas-certframe
19m         Normal    Started                           pod/sas-batch-server-72bce2d6-5a56-4db7-91bf-0b4335527b52-16737     Started container sas-certframe
19m         Normal    Pulled                            pod/sas-batch-server-72bce2d6-5a56-4db7-91bf-0b4335527b52-16737     Container image "668749497752.dkr.ecr.us-west-2.amazonaws.com/sasviya/viya-4-x64_oci_linux_2-docker/sas-config-init:1.21.1-20240305.1709656957059" already present on machine
19m         Normal    Created                           pod/sas-batch-server-72bce2d6-5a56-4db7-91bf-0b4335527b52-16737     Created container sas-config-init
19m         Normal    Started                           pod/sas-batch-server-72bce2d6-5a56-4db7-91bf-0b4335527b52-16737     Started container sas-config-init
19m         Normal    Pulled                            pod/sas-batch-server-72bce2d6-5a56-4db7-91bf-0b4335527b52-16737     Container image "668749497752.dkr.ecr.us-west-2.amazonaws.com/sasviya/viya-4-x64_oci_linux_2-docker/sas-programming-environment:1.53.31-20240613.1718295947845" already present on machine
19m         Normal    Created                           pod/sas-batch-server-72bce2d6-5a56-4db7-91bf-0b4335527b52-16737     Created container sas-programming-environment
19m         Normal    Started                           pod/sas-batch-server-72bce2d6-5a56-4db7-91bf-0b4335527b52-16737     Started container sas-programming-environment
19m         Normal    Pulled                            pod/sas-batch-server-72bce2d6-5a56-4db7-91bf-0b4335527b52-16737     Container image "668749497752.dkr.ecr.us-west-2.amazonaws.com/sasviya/viya-4-x64_oci_linux_2-docker/sas-process-exporter:1.9.1-20240306.1709732097762" already present on machine
19m         Normal    Created                           pod/sas-batch-server-72bce2d6-5a56-4db7-91bf-0b4335527b52-16737     Created container sas-process-exporter
19m         Normal    Started                           pod/sas-batch-server-72bce2d6-5a56-4db7-91bf-0b4335527b52-16737     Started container sas-process-exporter
5m31s       Normal    Killing                           pod/sas-batch-server-72bce2d6-5a56-4db7-91bf-0b4335527b52-16737     Stopping container sas-process-exporter
59m         Normal    Scheduled                         pod/sas-batch-server-72d25173-9edb-4412-8094-ef737d65101b-16646     Successfully assigned viya-dev/sas-batch-server-72d25173-9edb-4412-8094-ef737d65101b-16646 to ip-100-64-118-176.us-west-2.compute.internal
59m         Normal    Pulled                            pod/sas-batch-server-72d25173-9edb-4412-8094-ef737d65101b-16646     Container image "668749497752.dkr.ecr.us-west-2.amazonaws.com/sasviya/viya-4-x64_oci_linux_2-docker/sas-certframe:3.51.0-20240313.1710330811841" already present on machine
59m         Normal    Created                           pod/sas-batch-server-72d25173-9edb-4412-8094-ef737d65101b-16646     Created container sas-certframe
59m         Normal    Started                           pod/sas-batch-server-72d25173-9edb-4412-8094-ef737d65101b-16646     Started container sas-certframe
59m         Normal    Pulled                            pod/sas-batch-server-72d25173-9edb-4412-8094-ef737d65101b-16646     Container image "668749497752.dkr.ecr.us-west-2.amazonaws.com/sasviya/viya-4-x64_oci_linux_2-docker/sas-config-init:1.21.1-20240305.1709656957059" already present on machine
59m         Normal    Created                           pod/sas-batch-server-72d25173-9edb-4412-8094-ef737d65101b-16646     Created container sas-config-init
59m         Normal    Started                           pod/sas-batch-server-72d25173-9edb-4412-8094-ef737d65101b-16646     Started container sas-config-init
59m         Normal    Pulled                            pod/sas-batch-server-72d25173-9edb-4412-8094-ef737d65101b-16646     Container image "668749497752.dkr.ecr.us-west-2.amazonaws.com/sasviya/viya-4-x64_oci_linux_2-docker/sas-programming-environment:1.53.31-20240613.1718295947845" already present on machine
59m         Normal    Created                           pod/sas-batch-server-72d25173-9edb-4412-8094-ef737d65101b-16646     Created container sas-programming-environment
59m         Normal    Started                           pod/sas-batch-server-72d25173-9edb-4412-8094-ef737d65101b-16646     Started container sas-programming-environment
59m         Normal    Pulled                            pod/sas-batch-server-72d25173-9edb-4412-8094-ef737d65101b-16646     Container image "668749497752.dkr.ecr.us-west-2.amazonaws.com/sasviya/viya-4-x64_oci_linux_2-docker/sas-process-exporter:1.9.1-20240306.1709732097762" already present on machine
59m         Normal    Created                           pod/sas-batch-server-72d25173-9edb-4412-8094-ef737d65101b-16646     Created container sas-process-exporter
59m         Normal    Started                           pod/sas-batch-server-72d25173-9edb-4412-8094-ef737d65101b-16646     Started container sas-process-exporter
46m         Normal    Killing                           pod/sas-batch-server-72d25173-9edb-4412-8094-ef737d65101b-16646     Stopping container sas-process-exporter
59m         Warning   FailedScheduling                  pod/sas-batch-server-73eb5bc6-462b-41b2-b76b-c163a5ba85c7-16662     0/9 nodes are available: 1 Insufficient cpu, 1node(s) had untolerated taint {workload.sas.com/class: cas}, 1 node(s) had untolerated taint {workload.sas.com/class: stateful}, 1 node(s) had untolerated taint {workload.sas.com/class: stateless}, 5 node(s) didn't match Pod's node affinity/selector. preemption: 0/9 nodes are available: 1 No preemption victims found for incoming pod, 8 Preemption is not helpful for scheduling..
59m         Normal    Scheduled                         pod/sas-batch-server-73eb5bc6-462b-41b2-b76b-c163a5ba85c7-16662     Successfully assigned viya-dev/sas-batch-server-73eb5bc6-462b-41b2-b76b-c163a5ba85c7-16662 to ip-100-64-118-176.us-west-2.compute.internal
59m         Normal    Pulled                            pod/sas-batch-server-73eb5bc6-462b-41b2-b76b-c163a5ba85c7-16662     Container image "668749497752.dkr.ecr.us-west-2.amazonaws.com/sasviya/viya-4-x64_oci_linux_2-docker/sas-certframe:3.51.0-20240313.1710330811841" already present on machine
59m         Normal    Created                           pod/sas-batch-server-73eb5bc6-462b-41b2-b76b-c163a5ba85c7-16662     Created container sas-certframe
59m         Normal    Started                           pod/sas-batch-server-73eb5bc6-462b-41b2-b76b-c163a5ba85c7-16662     Started container sas-certframe
59m         Normal    Pulled                            pod/sas-batch-server-73eb5bc6-462b-41b2-b76b-c163a5ba85c7-16662     Container image "668749497752.dkr.ecr.us-west-2.amazonaws.com/sasviya/viya-4-x64_oci_linux_2-docker/sas-config-init:1.21.1-20240305.1709656957059" already present on machine
59m         Normal    Created                           pod/sas-batch-server-73eb5bc6-462b-41b2-b76b-c163a5ba85c7-16662     Created container sas-config-init
59m         Normal    Started                           pod/sas-batch-server-73eb5bc6-462b-41b2-b76b-c163a5ba85c7-16662     Started container sas-config-init
59m         Normal    Pulled                            pod/sas-batch-server-73eb5bc6-462b-41b2-b76b-c163a5ba85c7-16662     Container image "668749497752.dkr.ecr.us-west-2.amazonaws.com/sasviya/viya-4-x64_oci_linux_2-docker/sas-programming-environment:1.53.31-20240613.1718295947845" already present on machine
59m         Normal    Created                           pod/sas-batch-server-73eb5bc6-462b-41b2-b76b-c163a5ba85c7-16662     Created container sas-programming-environment
59m         Normal    Started                           pod/sas-batch-server-73eb5bc6-462b-41b2-b76b-c163a5ba85c7-16662     Started container sas-programming-environment
59m         Normal    Pulled                            pod/sas-batch-server-73eb5bc6-462b-41b2-b76b-c163a5ba85c7-16662     Container image "668749497752.dkr.ecr.us-west-2.amazonaws.com/sasviya/viya-4-x64_oci_linux_2-docker/sas-process-exporter:1.9.1-20240306.1709732097762" already present on machine
59m         Normal    Created                           pod/sas-batch-server-73eb5bc6-462b-41b2-b76b-c163a5ba85c7-16662     Created container sas-process-exporter
59m         Normal    Started                           pod/sas-batch-server-73eb5bc6-462b-41b2-b76b-c163a5ba85c7-16662     Started container sas-process-exporter
46m         Normal    Killing                           pod/sas-batch-server-73eb5bc6-462b-41b2-b76b-c163a5ba85c7-16662     Stopping container sas-process-exporter
58m         Warning   FailedScheduling                  pod/sas-batch-server-74612bc6-8e88-4eeb-b36a-1a212a61d719-16667     0/9 nodes are available: 1 Insufficient cpu, 1node(s) had untolerated taint {workload.sas.com/class: cas}, 1 node(s) had untolerated taint {workload.sas.com/class: stateful}, 1 node(s) had untolerated taint {workload.sas.com/class: stateless}, 5 node(s) didn't match Pod's node affinity/selector. preemption: 0/9 nodes are available: 1 No preemption victims found for incoming pod, 8 Preemption is not helpful for scheduling..
58m         Normal    NotTriggerScaleUp                 pod/sas-batch-server-74612bc6-8e88-4eeb-b36a-1a212a61d719-16667     pod didn't trigger scale-up: 2 node(s) didn't match Pod's node affinity/selector, 1 node(s) had untolerated taint {workload.sas.com/class: stateful}, 1 node(s) had untolerated taint {workload.sas.com/class: stateless}, 1 node(s) had untolerated taint {workload.sas.com/class: cas}
57m         Warning   FailedScheduling                  pod/sas-batch-server-74612bc6-8e88-4eeb-b36a-1a212a61d719-16667     0/10 nodes are available: 1 Insufficient cpu, 1 node(s) had untolerated taint {workload.sas.com/class: cas}, 1 node(s) had untolerated taint {workload.sas.com/class: stateful}, 1 node(s) had untolerated taint {workload.sas.com/class: stateless}, 6 node(s) didn't match Pod's node affinity/selector. preemption: 0/10 nodes are available: 1 No preemption victims found for incoming pod, 9 Preemption is not helpful for scheduling..
56m         Normal    Scheduled                         pod/sas-batch-server-74612bc6-8e88-4eeb-b36a-1a212a61d719-16667     Successfully assigned viya-dev/sas-batch-server-74612bc6-8e88-4eeb-b36a-1a212a61d719-16667 to ip-100-64-88-54.us-west-2.compute.internal
56m         Normal    Pulled                            pod/sas-batch-server-74612bc6-8e88-4eeb-b36a-1a212a61d719-16667     Container image "668749497752.dkr.ecr.us-west-2.amazonaws.com/sasviya/viya-4-x64_oci_linux_2-docker/sas-certframe:3.51.0-20240313.1710330811841" already present on machine
56m         Normal    Created                           pod/sas-batch-server-74612bc6-8e88-4eeb-b36a-1a212a61d719-16667     Created container sas-certframe
56m         Normal    Started                           pod/sas-batch-server-74612bc6-8e88-4eeb-b36a-1a212a61d719-16667     Started container sas-certframe
56m         Normal    Pulled                            pod/sas-batch-server-74612bc6-8e88-4eeb-b36a-1a212a61d719-16667     Container image "668749497752.dkr.ecr.us-west-2.amazonaws.com/sasviya/viya-4-x64_oci_linux_2-docker/sas-config-init:1.21.1-20240305.1709656957059" already present on machine
56m         Normal    Created                           pod/sas-batch-server-74612bc6-8e88-4eeb-b36a-1a212a61d719-16667     Created container sas-config-init
56m         Normal    Started                           pod/sas-batch-server-74612bc6-8e88-4eeb-b36a-1a212a61d719-16667     Started container sas-config-init
56m         Normal    Pulled                            pod/sas-batch-server-74612bc6-8e88-4eeb-b36a-1a212a61d719-16667     Container image "668749497752.dkr.ecr.us-west-2.amazonaws.com/sasviya/viya-4-x64_oci_linux_2-docker/sas-programming-environment:1.53.31-20240613.1718295947845" already present on machine
56m         Normal    Created                           pod/sas-batch-server-74612bc6-8e88-4eeb-b36a-1a212a61d719-16667     Created container sas-programming-environment
56m         Normal    Started                           pod/sas-batch-server-74612bc6-8e88-4eeb-b36a-1a212a61d719-16667     Started container sas-programming-environment
56m         Normal    Pulled                            pod/sas-batch-server-74612bc6-8e88-4eeb-b36a-1a212a61d719-16667     Container image "668749497752.dkr.ecr.us-west-2.amazonaws.com/sasviya/viya-4-x64_oci_linux_2-docker/sas-process-exporter:1.9.1-20240306.1709732097762" already present on machine
56m         Normal    Created                           pod/sas-batch-server-74612bc6-8e88-4eeb-b36a-1a212a61d719-16667     Created container sas-process-exporter
56m         Normal    Started                           pod/sas-batch-server-74612bc6-8e88-4eeb-b36a-1a212a61d719-16667     Started container sas-process-exporter
53m         Normal    Killing                           pod/sas-batch-server-74612bc6-8e88-4eeb-b36a-1a212a61d719-16667     Stopping container sas-process-exporter
19m         Normal    Scheduled                         pod/sas-batch-server-753cfd9f-3d29-41b4-8232-bd173edc04b4-16766     Successfully assigned viya-dev/sas-batch-server-753cfd9f-3d29-41b4-8232-bd173edc04b4-16766 to ip-100-64-125-225.us-west-2.compute.internal
19m         Normal    Pulled                            pod/sas-batch-server-753cfd9f-3d29-41b4-8232-bd173edc04b4-16766     Container image "668749497752.dkr.ecr.us-west-2.amazonaws.com/sasviya/viya-4-x64_oci_linux_2-docker/sas-certframe:3.51.0-20240313.1710330811841" already present on machine
19m         Normal    Created                           pod/sas-batch-server-753cfd9f-3d29-41b4-8232-bd173edc04b4-16766     Created container sas-certframe
19m         Normal    Started                           pod/sas-batch-server-753cfd9f-3d29-41b4-8232-bd173edc04b4-16766     Started container sas-certframe
19m         Normal    Pulled                            pod/sas-batch-server-753cfd9f-3d29-41b4-8232-bd173edc04b4-16766     Container image "668749497752.dkr.ecr.us-west-2.amazonaws.com/sasviya/viya-4-x64_oci_linux_2-docker/sas-config-init:1.21.1-20240305.1709656957059" already present on machine
19m         Normal    Created                           pod/sas-batch-server-753cfd9f-3d29-41b4-8232-bd173edc04b4-16766     Created container sas-config-init
19m         Normal    Started                           pod/sas-batch-server-753cfd9f-3d29-41b4-8232-bd173edc04b4-16766     Started container sas-config-init
19m         Normal    Pulled                            pod/sas-batch-server-753cfd9f-3d29-41b4-8232-bd173edc04b4-16766     Container image "668749497752.dkr.ecr.us-west-2.amazonaws.com/sasviya/viya-4-x64_oci_linux_2-docker/sas-programming-environment:1.53.31-20240613.1718295947845" already present on machine
19m         Normal    Created                           pod/sas-batch-server-753cfd9f-3d29-41b4-8232-bd173edc04b4-16766     Created container sas-programming-environment
19m         Normal    Started                           pod/sas-batch-server-753cfd9f-3d29-41b4-8232-bd173edc04b4-16766     Started container sas-programming-environment
19m         Normal    Pulled                            pod/sas-batch-server-753cfd9f-3d29-41b4-8232-bd173edc04b4-16766     Container image "668749497752.dkr.ecr.us-west-2.amazonaws.com/sasviya/viya-4-x64_oci_linux_2-docker/sas-process-exporter:1.9.1-20240306.1709732097762" already present on machine
19m         Normal    Created                           pod/sas-batch-server-753cfd9f-3d29-41b4-8232-bd173edc04b4-16766     Created container sas-process-exporter
19m         Normal    Started                           pod/sas-batch-server-753cfd9f-3d29-41b4-8232-bd173edc04b4-16766     Started container sas-process-exporter
4m          Normal    Killing                           pod/sas-batch-server-753cfd9f-3d29-41b4-8232-bd173edc04b4-16766     Stopping container sas-process-exporter
55m         Normal    Killing                           pod/sas-batch-server-77a6d980-83c0-4232-bb13-a9e96cc4307b-16608     Stopping container sas-process-exporter
19m         Normal    Scheduled                         pod/sas-batch-server-7853a087-7cbc-4e03-823d-4404ae45b1f3-16699     Successfully assigned viya-dev/sas-batch-server-7853a087-7cbc-4e03-823d-4404ae45b1f3-16699 to ip-100-64-103-52.us-west-2.compute.internal
19m         Normal    Pulled                            pod/sas-batch-server-7853a087-7cbc-4e03-823d-4404ae45b1f3-16699     Container image "668749497752.dkr.ecr.us-west-2.amazonaws.com/sasviya/viya-4-x64_oci_linux_2-docker/sas-certframe:3.51.0-20240313.1710330811841" already present on machine
19m         Normal    Created                           pod/sas-batch-server-7853a087-7cbc-4e03-823d-4404ae45b1f3-16699     Created container sas-certframe
19m         Normal    Started                           pod/sas-batch-server-7853a087-7cbc-4e03-823d-4404ae45b1f3-16699     Started container sas-certframe
19m         Normal    Pulled                            pod/sas-batch-server-7853a087-7cbc-4e03-823d-4404ae45b1f3-16699     Container image "668749497752.dkr.ecr.us-west-2.amazonaws.com/sasviya/viya-4-x64_oci_linux_2-docker/sas-config-init:1.21.1-20240305.1709656957059" already present on machine
19m         Normal    Created                           pod/sas-batch-server-7853a087-7cbc-4e03-823d-4404ae45b1f3-16699     Created container sas-config-init
19m         Normal    Started                           pod/sas-batch-server-7853a087-7cbc-4e03-823d-4404ae45b1f3-16699     Started container sas-config-init
19m         Normal    Pulled                            pod/sas-batch-server-7853a087-7cbc-4e03-823d-4404ae45b1f3-16699     Container image "668749497752.dkr.ecr.us-west-2.amazonaws.com/sasviya/viya-4-x64_oci_linux_2-docker/sas-programming-environment:1.53.31-20240613.1718295947845" already present on machine
19m         Normal    Created                           pod/sas-batch-server-7853a087-7cbc-4e03-823d-4404ae45b1f3-16699     Created container sas-programming-environment
19m         Normal    Started                           pod/sas-batch-server-7853a087-7cbc-4e03-823d-4404ae45b1f3-16699     Started container sas-programming-environment
19m         Normal    Pulled                            pod/sas-batch-server-7853a087-7cbc-4e03-823d-4404ae45b1f3-16699     Container image "668749497752.dkr.ecr.us-west-2.amazonaws.com/sasviya/viya-4-x64_oci_linux_2-docker/sas-process-exporter:1.9.1-20240306.1709732097762" already present on machine
19m         Normal    Created                           pod/sas-batch-server-7853a087-7cbc-4e03-823d-4404ae45b1f3-16699     Created container sas-process-exporter
19m         Normal    Started                           pod/sas-batch-server-7853a087-7cbc-4e03-823d-4404ae45b1f3-16699     Started container sas-process-exporter
4m36s       Normal    Killing                           pod/sas-batch-server-7853a087-7cbc-4e03-823d-4404ae45b1f3-16699     Stopping container sas-process-exporter
59m         Normal    Scheduled                         pod/sas-batch-server-78ef6194-bf85-43dc-bbcf-6f088eb13712-16631     Successfully assigned viya-dev/sas-batch-server-78ef6194-bf85-43dc-bbcf-6f088eb13712-16631 to ip-100-64-103-52.us-west-2.compute.internal
59m         Normal    Pulled                            pod/sas-batch-server-78ef6194-bf85-43dc-bbcf-6f088eb13712-16631     Container image "668749497752.dkr.ecr.us-west-2.amazonaws.com/sasviya/viya-4-x64_oci_linux_2-docker/sas-certframe:3.51.0-20240313.1710330811841" already present on machine
59m         Normal    Created                           pod/sas-batch-server-78ef6194-bf85-43dc-bbcf-6f088eb13712-16631     Created container sas-certframe
59m         Normal    Started                           pod/sas-batch-server-78ef6194-bf85-43dc-bbcf-6f088eb13712-16631     Started container sas-certframe
59m         Normal    Pulled                            pod/sas-batch-server-78ef6194-bf85-43dc-bbcf-6f088eb13712-16631     Container image "668749497752.dkr.ecr.us-west-2.amazonaws.com/sasviya/viya-4-x64_oci_linux_2-docker/sas-config-init:1.21.1-20240305.1709656957059" already present on machine
59m         Normal    Created                           pod/sas-batch-server-78ef6194-bf85-43dc-bbcf-6f088eb13712-16631     Created container sas-config-init
59m         Normal    Started                           pod/sas-batch-server-78ef6194-bf85-43dc-bbcf-6f088eb13712-16631     Started container sas-config-init
59m         Normal    Pulled                            pod/sas-batch-server-78ef6194-bf85-43dc-bbcf-6f088eb13712-16631     Container image "668749497752.dkr.ecr.us-west-2.amazonaws.com/sasviya/viya-4-x64_oci_linux_2-docker/sas-programming-environment:1.53.31-20240613.1718295947845" already present on machine
59m         Normal    Created                           pod/sas-batch-server-78ef6194-bf85-43dc-bbcf-6f088eb13712-16631     Created container sas-programming-environment
59m         Normal    Started                           pod/sas-batch-server-78ef6194-bf85-43dc-bbcf-6f088eb13712-16631     Started container sas-programming-environment
59m         Normal    Pulled                            pod/sas-batch-server-78ef6194-bf85-43dc-bbcf-6f088eb13712-16631     Container image "668749497752.dkr.ecr.us-west-2.amazonaws.com/sasviya/viya-4-x64_oci_linux_2-docker/sas-process-exporter:1.9.1-20240306.1709732097762" already present on machine
59m         Normal    Created                           pod/sas-batch-server-78ef6194-bf85-43dc-bbcf-6f088eb13712-16631     Created container sas-process-exporter
59m         Normal    Started                           pod/sas-batch-server-78ef6194-bf85-43dc-bbcf-6f088eb13712-16631     Started container sas-process-exporter
47m         Normal    Killing                           pod/sas-batch-server-78ef6194-bf85-43dc-bbcf-6f088eb13712-16631     Stopping container sas-process-exporter
59m         Normal    Scheduled                         pod/sas-batch-server-79515b0b-1c64-43d9-837b-09a14eef5c46-16632     Successfully assigned viya-dev/sas-batch-server-79515b0b-1c64-43d9-837b-09a14eef5c46-16632 to ip-100-64-125-225.us-west-2.compute.internal
59m         Normal    Pulled                            pod/sas-batch-server-79515b0b-1c64-43d9-837b-09a14eef5c46-16632     Container image "668749497752.dkr.ecr.us-west-2.amazonaws.com/sasviya/viya-4-x64_oci_linux_2-docker/sas-certframe:3.51.0-20240313.1710330811841" already present on machine
59m         Normal    Created                           pod/sas-batch-server-79515b0b-1c64-43d9-837b-09a14eef5c46-16632     Created container sas-certframe
59m         Normal    Started                           pod/sas-batch-server-79515b0b-1c64-43d9-837b-09a14eef5c46-16632     Started container sas-certframe
59m         Normal    Pulled                            pod/sas-batch-server-79515b0b-1c64-43d9-837b-09a14eef5c46-16632     Container image "668749497752.dkr.ecr.us-west-2.amazonaws.com/sasviya/viya-4-x64_oci_linux_2-docker/sas-config-init:1.21.1-20240305.1709656957059" already present on machine
59m         Normal    Created                           pod/sas-batch-server-79515b0b-1c64-43d9-837b-09a14eef5c46-16632     Created container sas-config-init
59m         Normal    Started                           pod/sas-batch-server-79515b0b-1c64-43d9-837b-09a14eef5c46-16632     Started container sas-config-init
59m         Normal    Pulled                            pod/sas-batch-server-79515b0b-1c64-43d9-837b-09a14eef5c46-16632     Container image "668749497752.dkr.ecr.us-west-2.amazonaws.com/sasviya/viya-4-x64_oci_linux_2-docker/sas-programming-environment:1.53.31-20240613.1718295947845" already present on machine
59m         Normal    Created                           pod/sas-batch-server-79515b0b-1c64-43d9-837b-09a14eef5c46-16632     Created container sas-programming-environment
59m         Normal    Started                           pod/sas-batch-server-79515b0b-1c64-43d9-837b-09a14eef5c46-16632     Started container sas-programming-environment
59m         Normal    Pulled                            pod/sas-batch-server-79515b0b-1c64-43d9-837b-09a14eef5c46-16632     Container image "668749497752.dkr.ecr.us-west-2.amazonaws.com/sasviya/viya-4-x64_oci_linux_2-docker/sas-process-exporter:1.9.1-20240306.1709732097762" already present on machine
59m         Normal    Created                           pod/sas-batch-server-79515b0b-1c64-43d9-837b-09a14eef5c46-16632     Created container sas-process-exporter
59m         Normal    Started                           pod/sas-batch-server-79515b0b-1c64-43d9-837b-09a14eef5c46-16632     Started container sas-process-exporter
50m         Normal    Killing                           pod/sas-batch-server-79515b0b-1c64-43d9-837b-09a14eef5c46-16632     Stopping container sas-process-exporter
19m         Normal    Scheduled                         pod/sas-batch-server-79e48edb-8723-4a34-8560-317da738af4c-16724     Successfully assigned viya-dev/sas-batch-server-79e48edb-8723-4a34-8560-317da738af4c-16724 to ip-100-64-103-52.us-west-2.compute.internal
19m         Normal    Pulled                            pod/sas-batch-server-79e48edb-8723-4a34-8560-317da738af4c-16724     Container image "668749497752.dkr.ecr.us-west-2.amazonaws.com/sasviya/viya-4-x64_oci_linux_2-docker/sas-certframe:3.51.0-20240313.1710330811841" already present on machine
19m         Normal    Created                           pod/sas-batch-server-79e48edb-8723-4a34-8560-317da738af4c-16724     Created container sas-certframe
19m         Normal    Started                           pod/sas-batch-server-79e48edb-8723-4a34-8560-317da738af4c-16724     Started container sas-certframe
19m         Normal    Pulled                            pod/sas-batch-server-79e48edb-8723-4a34-8560-317da738af4c-16724     Container image "668749497752.dkr.ecr.us-west-2.amazonaws.com/sasviya/viya-4-x64_oci_linux_2-docker/sas-config-init:1.21.1-20240305.1709656957059" already present on machine
19m         Normal    Created                           pod/sas-batch-server-79e48edb-8723-4a34-8560-317da738af4c-16724     Created container sas-config-init
19m         Normal    Started                           pod/sas-batch-server-79e48edb-8723-4a34-8560-317da738af4c-16724     Started container sas-config-init
19m         Normal    Pulled                            pod/sas-batch-server-79e48edb-8723-4a34-8560-317da738af4c-16724     Container image "668749497752.dkr.ecr.us-west-2.amazonaws.com/sasviya/viya-4-x64_oci_linux_2-docker/sas-programming-environment:1.53.31-20240613.1718295947845" already present on machine
19m         Normal    Created                           pod/sas-batch-server-79e48edb-8723-4a34-8560-317da738af4c-16724     Created container sas-programming-environment
19m         Normal    Started                           pod/sas-batch-server-79e48edb-8723-4a34-8560-317da738af4c-16724     Started container sas-programming-environment
19m         Normal    Pulled                            pod/sas-batch-server-79e48edb-8723-4a34-8560-317da738af4c-16724     Container image "668749497752.dkr.ecr.us-west-2.amazonaws.com/sasviya/viya-4-x64_oci_linux_2-docker/sas-process-exporter:1.9.1-20240306.1709732097762" already present on machine
19m         Normal    Created                           pod/sas-batch-server-79e48edb-8723-4a34-8560-317da738af4c-16724     Created container sas-process-exporter
19m         Normal    Started                           pod/sas-batch-server-79e48edb-8723-4a34-8560-317da738af4c-16724     Started container sas-process-exporter
5m47s       Normal    Killing                           pod/sas-batch-server-79e48edb-8723-4a34-8560-317da738af4c-16724     Stopping container sas-process-exporter
10m         Warning   FailedScheduling                  pod/sas-batch-server-7ba56d5b-fa4a-45ef-955c-5d0b4b9202ca-16784     0/10 nodes are available: 1 Insufficient cpu, 1 node(s) had untolerated taint {workload.sas.com/class: cas}, 1 node(s) had untolerated taint {workload.sas.com/class: stateful}, 1 node(s) had untolerated taint {workload.sas.com/class: stateless}, 6 node(s) didn't match Pod's node affinity/selector. preemption: 0/10 nodes are available: 1 No preemption victims found for incoming pod, 9 Preemption is not helpful for scheduling..
10m         Normal    Scheduled                         pod/sas-batch-server-7ba56d5b-fa4a-45ef-955c-5d0b4b9202ca-16784     Successfully assigned viya-dev/sas-batch-server-7ba56d5b-fa4a-45ef-955c-5d0b4b9202ca-16784 to ip-100-64-88-54.us-west-2.compute.internal
10m         Normal    Pulled                            pod/sas-batch-server-7ba56d5b-fa4a-45ef-955c-5d0b4b9202ca-16784     Container image "668749497752.dkr.ecr.us-west-2.amazonaws.com/sasviya/viya-4-x64_oci_linux_2-docker/sas-certframe:3.51.0-20240313.1710330811841" already present on machine
10m         Normal    Created                           pod/sas-batch-server-7ba56d5b-fa4a-45ef-955c-5d0b4b9202ca-16784     Created container sas-certframe
10m         Normal    Started                           pod/sas-batch-server-7ba56d5b-fa4a-45ef-955c-5d0b4b9202ca-16784     Started container sas-certframe
10m         Normal    Pulled                            pod/sas-batch-server-7ba56d5b-fa4a-45ef-955c-5d0b4b9202ca-16784     Container image "668749497752.dkr.ecr.us-west-2.amazonaws.com/sasviya/viya-4-x64_oci_linux_2-docker/sas-config-init:1.21.1-20240305.1709656957059" already present on machine
10m         Normal    Created                           pod/sas-batch-server-7ba56d5b-fa4a-45ef-955c-5d0b4b9202ca-16784     Created container sas-config-init
10m         Normal    Started                           pod/sas-batch-server-7ba56d5b-fa4a-45ef-955c-5d0b4b9202ca-16784     Started container sas-config-init
10m         Normal    Pulled                            pod/sas-batch-server-7ba56d5b-fa4a-45ef-955c-5d0b4b9202ca-16784     Container image "668749497752.dkr.ecr.us-west-2.amazonaws.com/sasviya/viya-4-x64_oci_linux_2-docker/sas-programming-environment:1.53.31-20240613.1718295947845" already present on machine
10m         Normal    Created                           pod/sas-batch-server-7ba56d5b-fa4a-45ef-955c-5d0b4b9202ca-16784     Created container sas-programming-environment
10m         Normal    Started                           pod/sas-batch-server-7ba56d5b-fa4a-45ef-955c-5d0b4b9202ca-16784     Started container sas-programming-environment
10m         Normal    Pulled                            pod/sas-batch-server-7ba56d5b-fa4a-45ef-955c-5d0b4b9202ca-16784     Container image "668749497752.dkr.ecr.us-west-2.amazonaws.com/sasviya/viya-4-x64_oci_linux_2-docker/sas-process-exporter:1.9.1-20240306.1709732097762" already present on machine
10m         Normal    Created                           pod/sas-batch-server-7ba56d5b-fa4a-45ef-955c-5d0b4b9202ca-16784     Created container sas-process-exporter
10m         Normal    Started                           pod/sas-batch-server-7ba56d5b-fa4a-45ef-955c-5d0b4b9202ca-16784     Started container sas-process-exporter
3m10s       Normal    Killing                           pod/sas-batch-server-7ba56d5b-fa4a-45ef-955c-5d0b4b9202ca-16784     Stopping container sas-process-exporter
59m         Warning   FailedScheduling                  pod/sas-batch-server-7bf628fa-28a0-4fc9-92ff-a54f6e607dc4-16664     0/9 nodes are available: 1 Insufficient cpu, 1node(s) had untolerated taint {workload.sas.com/class: cas}, 1 node(s) had untolerated taint {workload.sas.com/class: stateful}, 1 node(s) had untolerated taint {workload.sas.com/class: stateless}, 5 node(s) didn't match Pod's node affinity/selector. preemption: 0/9 nodes are available: 1 No preemption victims found for incoming pod, 8 Preemption is not helpful for scheduling..
59m         Normal    Scheduled                         pod/sas-batch-server-7bf628fa-28a0-4fc9-92ff-a54f6e607dc4-16664     Successfully assigned viya-dev/sas-batch-server-7bf628fa-28a0-4fc9-92ff-a54f6e607dc4-16664 to ip-100-64-118-98.us-west-2.compute.internal
59m         Normal    Pulled                            pod/sas-batch-server-7bf628fa-28a0-4fc9-92ff-a54f6e607dc4-16664     Container image "668749497752.dkr.ecr.us-west-2.amazonaws.com/sasviya/viya-4-x64_oci_linux_2-docker/sas-certframe:3.51.0-20240313.1710330811841" already present on machine
59m         Normal    Created                           pod/sas-batch-server-7bf628fa-28a0-4fc9-92ff-a54f6e607dc4-16664     Created container sas-certframe
59m         Normal    Started                           pod/sas-batch-server-7bf628fa-28a0-4fc9-92ff-a54f6e607dc4-16664     Started container sas-certframe
59m         Normal    Pulled                            pod/sas-batch-server-7bf628fa-28a0-4fc9-92ff-a54f6e607dc4-16664     Container image "668749497752.dkr.ecr.us-west-2.amazonaws.com/sasviya/viya-4-x64_oci_linux_2-docker/sas-config-init:1.21.1-20240305.1709656957059" already present on machine
59m         Normal    Created                           pod/sas-batch-server-7bf628fa-28a0-4fc9-92ff-a54f6e607dc4-16664     Created container sas-config-init
59m         Normal    Started                           pod/sas-batch-server-7bf628fa-28a0-4fc9-92ff-a54f6e607dc4-16664     Started container sas-config-init
59m         Normal    Pulled                            pod/sas-batch-server-7bf628fa-28a0-4fc9-92ff-a54f6e607dc4-16664     Container image "668749497752.dkr.ecr.us-west-2.amazonaws.com/sasviya/viya-4-x64_oci_linux_2-docker/sas-programming-environment:1.53.31-20240613.1718295947845" already present on machine
59m         Normal    Created                           pod/sas-batch-server-7bf628fa-28a0-4fc9-92ff-a54f6e607dc4-16664     Created container sas-programming-environment
59m         Normal    Started                           pod/sas-batch-server-7bf628fa-28a0-4fc9-92ff-a54f6e607dc4-16664     Started container sas-programming-environment
59m         Normal    Pulled                            pod/sas-batch-server-7bf628fa-28a0-4fc9-92ff-a54f6e607dc4-16664     Container image "668749497752.dkr.ecr.us-west-2.amazonaws.com/sasviya/viya-4-x64_oci_linux_2-docker/sas-process-exporter:1.9.1-20240306.1709732097762" already present on machine
59m         Normal    Created                           pod/sas-batch-server-7bf628fa-28a0-4fc9-92ff-a54f6e607dc4-16664     Created container sas-process-exporter
59m         Normal    Started                           pod/sas-batch-server-7bf628fa-28a0-4fc9-92ff-a54f6e607dc4-16664     Started container sas-process-exporter
48m         Normal    Killing                           pod/sas-batch-server-7bf628fa-28a0-4fc9-92ff-a54f6e607dc4-16664     Stopping container sas-process-exporter
19m         Normal    Scheduled                         pod/sas-batch-server-7cfd1a23-b84b-4345-adb9-88b1c1948d9c-16749     Successfully assigned viya-dev/sas-batch-server-7cfd1a23-b84b-4345-adb9-88b1c1948d9c-16749 to ip-100-64-118-176.us-west-2.compute.internal
19m         Normal    Pulled                            pod/sas-batch-server-7cfd1a23-b84b-4345-adb9-88b1c1948d9c-16749     Container image "668749497752.dkr.ecr.us-west-2.amazonaws.com/sasviya/viya-4-x64_oci_linux_2-docker/sas-certframe:3.51.0-20240313.1710330811841" already present on machine
19m         Normal    Created                           pod/sas-batch-server-7cfd1a23-b84b-4345-adb9-88b1c1948d9c-16749     Created container sas-certframe
19m         Normal    Started                           pod/sas-batch-server-7cfd1a23-b84b-4345-adb9-88b1c1948d9c-16749     Started container sas-certframe
19m         Normal    Pulled                            pod/sas-batch-server-7cfd1a23-b84b-4345-adb9-88b1c1948d9c-16749     Container image "668749497752.dkr.ecr.us-west-2.amazonaws.com/sasviya/viya-4-x64_oci_linux_2-docker/sas-config-init:1.21.1-20240305.1709656957059" already present on machine
19m         Normal    Created                           pod/sas-batch-server-7cfd1a23-b84b-4345-adb9-88b1c1948d9c-16749     Created container sas-config-init
19m         Normal    Started                           pod/sas-batch-server-7cfd1a23-b84b-4345-adb9-88b1c1948d9c-16749     Started container sas-config-init
19m         Normal    Pulled                            pod/sas-batch-server-7cfd1a23-b84b-4345-adb9-88b1c1948d9c-16749     Container image "668749497752.dkr.ecr.us-west-2.amazonaws.com/sasviya/viya-4-x64_oci_linux_2-docker/sas-programming-environment:1.53.31-20240613.1718295947845" already present on machine
19m         Normal    Created                           pod/sas-batch-server-7cfd1a23-b84b-4345-adb9-88b1c1948d9c-16749     Created container sas-programming-environment
19m         Normal    Started                           pod/sas-batch-server-7cfd1a23-b84b-4345-adb9-88b1c1948d9c-16749     Started container sas-programming-environment
19m         Normal    Pulled                            pod/sas-batch-server-7cfd1a23-b84b-4345-adb9-88b1c1948d9c-16749     Container image "668749497752.dkr.ecr.us-west-2.amazonaws.com/sasviya/viya-4-x64_oci_linux_2-docker/sas-process-exporter:1.9.1-20240306.1709732097762" already present on machine
19m         Normal    Created                           pod/sas-batch-server-7cfd1a23-b84b-4345-adb9-88b1c1948d9c-16749     Created container sas-process-exporter
19m         Normal    Started                           pod/sas-batch-server-7cfd1a23-b84b-4345-adb9-88b1c1948d9c-16749     Started container sas-process-exporter
6m27s       Normal    Killing                           pod/sas-batch-server-7cfd1a23-b84b-4345-adb9-88b1c1948d9c-16749     Stopping container sas-process-exporter
56m         Normal    Killing                           pod/sas-batch-server-7e2c2525-9be0-49b8-8f2b-f5f4cc3862a8-16586     Stopping container sas-process-exporter
60m         Normal    Killing                           pod/sas-batch-server-82492ba0-4386-4fd7-95c9-9e3aac020163-16598     Stopping container sas-process-exporter
19m         Normal    Scheduled                         pod/sas-batch-server-8365fdec-b70c-445c-9f4b-ca2af9134e03-16705     Successfully assigned viya-dev/sas-batch-server-8365fdec-b70c-445c-9f4b-ca2af9134e03-16705 to ip-100-64-103-52.us-west-2.compute.internal
19m         Normal    Pulled                            pod/sas-batch-server-8365fdec-b70c-445c-9f4b-ca2af9134e03-16705     Container image "668749497752.dkr.ecr.us-west-2.amazonaws.com/sasviya/viya-4-x64_oci_linux_2-docker/sas-certframe:3.51.0-20240313.1710330811841" already present on machine
19m         Normal    Created                           pod/sas-batch-server-8365fdec-b70c-445c-9f4b-ca2af9134e03-16705     Created container sas-certframe
19m         Normal    Started                           pod/sas-batch-server-8365fdec-b70c-445c-9f4b-ca2af9134e03-16705     Started container sas-certframe
19m         Normal    Pulled                            pod/sas-batch-server-8365fdec-b70c-445c-9f4b-ca2af9134e03-16705     Container image "668749497752.dkr.ecr.us-west-2.amazonaws.com/sasviya/viya-4-x64_oci_linux_2-docker/sas-config-init:1.21.1-20240305.1709656957059" already present on machine
19m         Normal    Created                           pod/sas-batch-server-8365fdec-b70c-445c-9f4b-ca2af9134e03-16705     Created container sas-config-init
19m         Normal    Started                           pod/sas-batch-server-8365fdec-b70c-445c-9f4b-ca2af9134e03-16705     Started container sas-config-init
19m         Normal    Pulled                            pod/sas-batch-server-8365fdec-b70c-445c-9f4b-ca2af9134e03-16705     Container image "668749497752.dkr.ecr.us-west-2.amazonaws.com/sasviya/viya-4-x64_oci_linux_2-docker/sas-programming-environment:1.53.31-20240613.1718295947845" already present on machine
19m         Normal    Created                           pod/sas-batch-server-8365fdec-b70c-445c-9f4b-ca2af9134e03-16705     Created container sas-programming-environment
19m         Normal    Started                           pod/sas-batch-server-8365fdec-b70c-445c-9f4b-ca2af9134e03-16705     Started container sas-programming-environment
19m         Normal    Pulled                            pod/sas-batch-server-8365fdec-b70c-445c-9f4b-ca2af9134e03-16705     Container image "668749497752.dkr.ecr.us-west-2.amazonaws.com/sasviya/viya-4-x64_oci_linux_2-docker/sas-process-exporter:1.9.1-20240306.1709732097762" already present on machine
19m         Normal    Created                           pod/sas-batch-server-8365fdec-b70c-445c-9f4b-ca2af9134e03-16705     Created container sas-process-exporter
19m         Normal    Started                           pod/sas-batch-server-8365fdec-b70c-445c-9f4b-ca2af9134e03-16705     Started container sas-process-exporter
6m10s       Normal    Killing                           pod/sas-batch-server-8365fdec-b70c-445c-9f4b-ca2af9134e03-16705     Stopping container sas-process-exporter
20m         Normal    Scheduled                         pod/sas-batch-server-84d387ad-035f-487c-b142-2b912ac8728d-16691     Successfully assigned viya-dev/sas-batch-server-84d387ad-035f-487c-b142-2b912ac8728d-16691 to ip-100-64-125-225.us-west-2.compute.internal
20m         Normal    Pulled                            pod/sas-batch-server-84d387ad-035f-487c-b142-2b912ac8728d-16691     Container image "668749497752.dkr.ecr.us-west-2.amazonaws.com/sasviya/viya-4-x64_oci_linux_2-docker/sas-certframe:3.51.0-20240313.1710330811841" already present on machine
20m         Normal    Created                           pod/sas-batch-server-84d387ad-035f-487c-b142-2b912ac8728d-16691     Created container sas-certframe
20m         Normal    Started                           pod/sas-batch-server-84d387ad-035f-487c-b142-2b912ac8728d-16691     Started container sas-certframe
20m         Normal    Pulled                            pod/sas-batch-server-84d387ad-035f-487c-b142-2b912ac8728d-16691     Container image "668749497752.dkr.ecr.us-west-2.amazonaws.com/sasviya/viya-4-x64_oci_linux_2-docker/sas-config-init:1.21.1-20240305.1709656957059" already present on machine
20m         Normal    Created                           pod/sas-batch-server-84d387ad-035f-487c-b142-2b912ac8728d-16691     Created container sas-config-init
20m         Normal    Started                           pod/sas-batch-server-84d387ad-035f-487c-b142-2b912ac8728d-16691     Started container sas-config-init
20m         Normal    Pulled                            pod/sas-batch-server-84d387ad-035f-487c-b142-2b912ac8728d-16691     Container image "668749497752.dkr.ecr.us-west-2.amazonaws.com/sasviya/viya-4-x64_oci_linux_2-docker/sas-programming-environment:1.53.31-20240613.1718295947845" already present on machine
20m         Normal    Created                           pod/sas-batch-server-84d387ad-035f-487c-b142-2b912ac8728d-16691     Created container sas-programming-environment
20m         Normal    Started                           pod/sas-batch-server-84d387ad-035f-487c-b142-2b912ac8728d-16691     Started container sas-programming-environment
20m         Normal    Pulled                            pod/sas-batch-server-84d387ad-035f-487c-b142-2b912ac8728d-16691     Container image "668749497752.dkr.ecr.us-west-2.amazonaws.com/sasviya/viya-4-x64_oci_linux_2-docker/sas-process-exporter:1.9.1-20240306.1709732097762" already present on machine
20m         Normal    Created                           pod/sas-batch-server-84d387ad-035f-487c-b142-2b912ac8728d-16691     Created container sas-process-exporter
20m         Normal    Started                           pod/sas-batch-server-84d387ad-035f-487c-b142-2b912ac8728d-16691     Started container sas-process-exporter
13m         Normal    Killing                           pod/sas-batch-server-84d387ad-035f-487c-b142-2b912ac8728d-16691     Stopping container sas-process-exporter
57m         Normal    Scheduled                         pod/sas-batch-server-87a4655a-3cb6-4a81-9b57-48a15a9edb46-16674     Successfully assigned viya-dev/sas-batch-server-87a4655a-3cb6-4a81-9b57-48a15a9edb46-16674 to ip-100-64-98-232.us-west-2.compute.internal
57m         Normal    Pulled                            pod/sas-batch-server-87a4655a-3cb6-4a81-9b57-48a15a9edb46-16674     Container image "668749497752.dkr.ecr.us-west-2.amazonaws.com/sasviya/viya-4-x64_oci_linux_2-docker/sas-certframe:3.51.0-20240313.1710330811841" already present on machine
57m         Normal    Created                           pod/sas-batch-server-87a4655a-3cb6-4a81-9b57-48a15a9edb46-16674     Created container sas-certframe
57m         Normal    Started                           pod/sas-batch-server-87a4655a-3cb6-4a81-9b57-48a15a9edb46-16674     Started container sas-certframe
57m         Normal    Pulling                           pod/sas-batch-server-87a4655a-3cb6-4a81-9b57-48a15a9edb46-16674     Pulling image "668749497752.dkr.ecr.us-west-2.amazonaws.com/sasviya/viya-4-x64_oci_linux_2-docker/sas-config-init:1.21.1-20240305.1709656957059"
56m         Normal    Pulled                            pod/sas-batch-server-87a4655a-3cb6-4a81-9b57-48a15a9edb46-16674     Successfully pulled image "668749497752.dkr.ecr.us-west-2.amazonaws.com/sasviya/viya-4-x64_oci_linux_2-docker/sas-config-init:1.21.1-20240305.1709656957059" in 25.022s (25.022s including waiting)
56m         Normal    Created                           pod/sas-batch-server-87a4655a-3cb6-4a81-9b57-48a15a9edb46-16674     Created container sas-config-init
56m         Normal    Started                           pod/sas-batch-server-87a4655a-3cb6-4a81-9b57-48a15a9edb46-16674     Started container sas-config-init
56m         Normal    Pulling                           pod/sas-batch-server-87a4655a-3cb6-4a81-9b57-48a15a9edb46-16674     Pulling image "668749497752.dkr.ecr.us-west-2.amazonaws.com/sasviya/viya-4-x64_oci_linux_2-docker/sas-programming-environment:1.53.31-20240613.1718295947845"
55m         Normal    Pulled                            pod/sas-batch-server-87a4655a-3cb6-4a81-9b57-48a15a9edb46-16674     Successfully pulled image "668749497752.dkr.ecr.us-west-2.amazonaws.com/sasviya/viya-4-x64_oci_linux_2-docker/sas-programming-environment:1.53.31-20240613.1718295947845" in 1m15.715s (1m15.715s including waiting)
55m         Normal    Created                           pod/sas-batch-server-87a4655a-3cb6-4a81-9b57-48a15a9edb46-16674     Created container sas-programming-environment
55m         Normal    Started                           pod/sas-batch-server-87a4655a-3cb6-4a81-9b57-48a15a9edb46-16674     Started container sas-programming-environment
55m         Normal    Pulled                            pod/sas-batch-server-87a4655a-3cb6-4a81-9b57-48a15a9edb46-16674     Container image "668749497752.dkr.ecr.us-west-2.amazonaws.com/sasviya/viya-4-x64_oci_linux_2-docker/sas-process-exporter:1.9.1-20240306.1709732097762" already present on machine
55m         Normal    Created                           pod/sas-batch-server-87a4655a-3cb6-4a81-9b57-48a15a9edb46-16674     Created container sas-process-exporter
55m         Normal    Started                           pod/sas-batch-server-87a4655a-3cb6-4a81-9b57-48a15a9edb46-16674     Started container sas-process-exporter
47m         Normal    Killing                           pod/sas-batch-server-87a4655a-3cb6-4a81-9b57-48a15a9edb46-16674     Stopping container sas-process-exporter
55m         Normal    Killing                           pod/sas-batch-server-8867fa65-306f-4478-91e4-d8bf03d49df4-16589     Stopping container sas-process-exporter
19m         Normal    Scheduled                         pod/sas-batch-server-8c314c88-ee35-4675-86d8-261b87cd15d9-16731     Successfully assigned viya-dev/sas-batch-server-8c314c88-ee35-4675-86d8-261b87cd15d9-16731 to ip-100-64-98-232.us-west-2.compute.internal
19m         Normal    Pulled                            pod/sas-batch-server-8c314c88-ee35-4675-86d8-261b87cd15d9-16731     Container image "668749497752.dkr.ecr.us-west-2.amazonaws.com/sasviya/viya-4-x64_oci_linux_2-docker/sas-certframe:3.51.0-20240313.1710330811841" already present on machine
19m         Normal    Created                           pod/sas-batch-server-8c314c88-ee35-4675-86d8-261b87cd15d9-16731     Created container sas-certframe
19m         Normal    Started                           pod/sas-batch-server-8c314c88-ee35-4675-86d8-261b87cd15d9-16731     Started container sas-certframe
19m         Normal    Pulled                            pod/sas-batch-server-8c314c88-ee35-4675-86d8-261b87cd15d9-16731     Container image "668749497752.dkr.ecr.us-west-2.amazonaws.com/sasviya/viya-4-x64_oci_linux_2-docker/sas-config-init:1.21.1-20240305.1709656957059" already present on machine
19m         Normal    Created                           pod/sas-batch-server-8c314c88-ee35-4675-86d8-261b87cd15d9-16731     Created container sas-config-init
19m         Normal    Started                           pod/sas-batch-server-8c314c88-ee35-4675-86d8-261b87cd15d9-16731     Started container sas-config-init
19m         Normal    Pulled                            pod/sas-batch-server-8c314c88-ee35-4675-86d8-261b87cd15d9-16731     Container image "668749497752.dkr.ecr.us-west-2.amazonaws.com/sasviya/viya-4-x64_oci_linux_2-docker/sas-programming-environment:1.53.31-20240613.1718295947845" already present on machine
19m         Normal    Created                           pod/sas-batch-server-8c314c88-ee35-4675-86d8-261b87cd15d9-16731     Created container sas-programming-environment
19m         Normal    Started                           pod/sas-batch-server-8c314c88-ee35-4675-86d8-261b87cd15d9-16731     Started container sas-programming-environment
19m         Normal    Pulled                            pod/sas-batch-server-8c314c88-ee35-4675-86d8-261b87cd15d9-16731     Container image "668749497752.dkr.ecr.us-west-2.amazonaws.com/sasviya/viya-4-x64_oci_linux_2-docker/sas-process-exporter:1.9.1-20240306.1709732097762" already present on machine
19m         Normal    Created                           pod/sas-batch-server-8c314c88-ee35-4675-86d8-261b87cd15d9-16731     Created container sas-process-exporter
19m         Normal    Started                           pod/sas-batch-server-8c314c88-ee35-4675-86d8-261b87cd15d9-16731     Started container sas-process-exporter
3m42s       Normal    Killing                           pod/sas-batch-server-8c314c88-ee35-4675-86d8-261b87cd15d9-16731     Stopping container sas-process-exporter
59m         Normal    Killing                           pod/sas-batch-server-8e437dec-3bd3-4964-80fb-e994ad49fb78-16601     Stopping container sas-process-exporter
8m44s       Warning   FailedScheduling                  pod/sas-batch-server-8f33f191-219e-403b-8d72-c6fe0c8a0cae-16772     0/10 nodes are available: 1 Insufficient cpu, 1 node(s) had untolerated taint {workload.sas.com/class: cas}, 1 node(s) had untolerated taint {workload.sas.com/class: stateful}, 1 node(s) had untolerated taint {workload.sas.com/class: stateless}, 6 node(s) didn't match Pod's node affinity/selector. preemption: 0/10 nodes are available: 1 No preemption victims found for incoming pod, 9 Preemption is not helpful for scheduling..
9m39s       Normal    NotTriggerScaleUp                 pod/sas-batch-server-8f33f191-219e-403b-8d72-c6fe0c8a0cae-16772     pod didn't trigger scale-up: 1 node(s) had untolerated taint {workload.sas.com/class: stateless}, 1 node(s) had untolerated taint {workload.sas.com/class: cas}, 2 node(s) didn't match Pod's node affinity/selector, 1 node(s) had untolerated taint {workload.sas.com/class: stateful}
8m33s       Warning   FailedScheduling                  pod/sas-batch-server-8f33f191-219e-403b-8d72-c6fe0c8a0cae-16772     0/11 nodes are available: 1 Insufficient cpu, 1 node(s) had untolerated taint {node.kubernetes.io/not-ready: }, 1 node(s) had untolerated taint {workload.sas.com/class: cas}, 1 node(s) had untolerated taint {workload.sas.com/class: stateful}, 1 node(s) had untolerated taint {workload.sas.com/class: stateless}, 6 node(s) didn't match Pod's node affinity/selector. preemption: 0/11 nodes are available: 1 No preemption victims found for incoming pod, 10 Preemption is not helpful for scheduling..
8m21s       Normal    Scheduled                         pod/sas-batch-server-8f33f191-219e-403b-8d72-c6fe0c8a0cae-16772     Successfully assigned viya-dev/sas-batch-server-8f33f191-219e-403b-8d72-c6fe0c8a0cae-16772 to ip-100-64-103-52.us-west-2.compute.internal
8m18s       Normal    Pulled                            pod/sas-batch-server-8f33f191-219e-403b-8d72-c6fe0c8a0cae-16772     Container image "668749497752.dkr.ecr.us-west-2.amazonaws.com/sasviya/viya-4-x64_oci_linux_2-docker/sas-certframe:3.51.0-20240313.1710330811841" already present on machine
8m18s       Normal    Created                           pod/sas-batch-server-8f33f191-219e-403b-8d72-c6fe0c8a0cae-16772     Created container sas-certframe
8m17s       Normal    Started                           pod/sas-batch-server-8f33f191-219e-403b-8d72-c6fe0c8a0cae-16772     Started container sas-certframe
8m16s       Normal    Pulled                            pod/sas-batch-server-8f33f191-219e-403b-8d72-c6fe0c8a0cae-16772     Container image "668749497752.dkr.ecr.us-west-2.amazonaws.com/sasviya/viya-4-x64_oci_linux_2-docker/sas-config-init:1.21.1-20240305.1709656957059" already present on machine
8m16s       Normal    Created                           pod/sas-batch-server-8f33f191-219e-403b-8d72-c6fe0c8a0cae-16772     Created container sas-config-init
8m16s       Normal    Started                           pod/sas-batch-server-8f33f191-219e-403b-8d72-c6fe0c8a0cae-16772     Started container sas-config-init
8m14s       Normal    Pulled                            pod/sas-batch-server-8f33f191-219e-403b-8d72-c6fe0c8a0cae-16772     Container image "668749497752.dkr.ecr.us-west-2.amazonaws.com/sasviya/viya-4-x64_oci_linux_2-docker/sas-programming-environment:1.53.31-20240613.1718295947845" already present on machine
8m14s       Normal    Created                           pod/sas-batch-server-8f33f191-219e-403b-8d72-c6fe0c8a0cae-16772     Created container sas-programming-environment
8m14s       Normal    Started                           pod/sas-batch-server-8f33f191-219e-403b-8d72-c6fe0c8a0cae-16772     Started container sas-programming-environment
8m14s       Normal    Pulled                            pod/sas-batch-server-8f33f191-219e-403b-8d72-c6fe0c8a0cae-16772     Container image "668749497752.dkr.ecr.us-west-2.amazonaws.com/sasviya/viya-4-x64_oci_linux_2-docker/sas-process-exporter:1.9.1-20240306.1709732097762" already present on machine
8m14s       Normal    Created                           pod/sas-batch-server-8f33f191-219e-403b-8d72-c6fe0c8a0cae-16772     Created container sas-process-exporter
8m14s       Normal    Started                           pod/sas-batch-server-8f33f191-219e-403b-8d72-c6fe0c8a0cae-16772     Started container sas-process-exporter
3m47s       Normal    Killing                           pod/sas-batch-server-8f33f191-219e-403b-8d72-c6fe0c8a0cae-16772     Stopping container sas-process-exporter
60m         Normal    Killing                           pod/sas-batch-server-901e21ee-acf7-4d8d-bfcd-9c95b4ca7db0-16595     Stopping container sas-process-exporter
59m         Normal    Killing                           pod/sas-batch-server-90812143-0c66-44f7-a601-51a9b55073b8-16602     Stopping container sas-process-exporter
59m         Normal    Scheduled                         pod/sas-batch-server-914e8647-db02-4c4b-95fc-f898fa95e59d-16630     Successfully assigned viya-dev/sas-batch-server-914e8647-db02-4c4b-95fc-f898fa95e59d-16630 to ip-100-64-118-98.us-west-2.compute.internal
59m         Normal    Pulled                            pod/sas-batch-server-914e8647-db02-4c4b-95fc-f898fa95e59d-16630     Container image "668749497752.dkr.ecr.us-west-2.amazonaws.com/sasviya/viya-4-x64_oci_linux_2-docker/sas-certframe:3.51.0-20240313.1710330811841" already present on machine
59m         Normal    Created                           pod/sas-batch-server-914e8647-db02-4c4b-95fc-f898fa95e59d-16630     Created container sas-certframe
59m         Normal    Started                           pod/sas-batch-server-914e8647-db02-4c4b-95fc-f898fa95e59d-16630     Started container sas-certframe
59m         Normal    Pulled                            pod/sas-batch-server-914e8647-db02-4c4b-95fc-f898fa95e59d-16630     Container image "668749497752.dkr.ecr.us-west-2.amazonaws.com/sasviya/viya-4-x64_oci_linux_2-docker/sas-config-init:1.21.1-20240305.1709656957059" already present on machine
59m         Normal    Created                           pod/sas-batch-server-914e8647-db02-4c4b-95fc-f898fa95e59d-16630     Created container sas-config-init
59m         Normal    Started                           pod/sas-batch-server-914e8647-db02-4c4b-95fc-f898fa95e59d-16630     Started container sas-config-init
59m         Normal    Pulled                            pod/sas-batch-server-914e8647-db02-4c4b-95fc-f898fa95e59d-16630     Container image "668749497752.dkr.ecr.us-west-2.amazonaws.com/sasviya/viya-4-x64_oci_linux_2-docker/sas-programming-environment:1.53.31-20240613.1718295947845" already present on machine
59m         Normal    Created                           pod/sas-batch-server-914e8647-db02-4c4b-95fc-f898fa95e59d-16630     Created container sas-programming-environment
59m         Normal    Started                           pod/sas-batch-server-914e8647-db02-4c4b-95fc-f898fa95e59d-16630     Started container sas-programming-environment
59m         Normal    Pulled                            pod/sas-batch-server-914e8647-db02-4c4b-95fc-f898fa95e59d-16630     Container image "668749497752.dkr.ecr.us-west-2.amazonaws.com/sasviya/viya-4-x64_oci_linux_2-docker/sas-process-exporter:1.9.1-20240306.1709732097762" already present on machine
59m         Normal    Created                           pod/sas-batch-server-914e8647-db02-4c4b-95fc-f898fa95e59d-16630     Created container sas-process-exporter
59m         Normal    Started                           pod/sas-batch-server-914e8647-db02-4c4b-95fc-f898fa95e59d-16630     Started container sas-process-exporter
49m         Normal    Killing                           pod/sas-batch-server-914e8647-db02-4c4b-95fc-f898fa95e59d-16630     Stopping container sas-process-exporter
19m         Normal    Scheduled                         pod/sas-batch-server-9239fe98-263a-49fc-b7e5-ae703578e3d0-16752     Successfully assigned viya-dev/sas-batch-server-9239fe98-263a-49fc-b7e5-ae703578e3d0-16752 to ip-100-64-118-176.us-west-2.compute.internal
19m         Normal    Pulled                            pod/sas-batch-server-9239fe98-263a-49fc-b7e5-ae703578e3d0-16752     Container image "668749497752.dkr.ecr.us-west-2.amazonaws.com/sasviya/viya-4-x64_oci_linux_2-docker/sas-certframe:3.51.0-20240313.1710330811841" already present on machine
19m         Normal    Created                           pod/sas-batch-server-9239fe98-263a-49fc-b7e5-ae703578e3d0-16752     Created container sas-certframe
19m         Normal    Started                           pod/sas-batch-server-9239fe98-263a-49fc-b7e5-ae703578e3d0-16752     Started container sas-certframe
19m         Normal    Pulled                            pod/sas-batch-server-9239fe98-263a-49fc-b7e5-ae703578e3d0-16752     Container image "668749497752.dkr.ecr.us-west-2.amazonaws.com/sasviya/viya-4-x64_oci_linux_2-docker/sas-config-init:1.21.1-20240305.1709656957059" already present on machine
19m         Normal    Created                           pod/sas-batch-server-9239fe98-263a-49fc-b7e5-ae703578e3d0-16752     Created container sas-config-init
19m         Normal    Started                           pod/sas-batch-server-9239fe98-263a-49fc-b7e5-ae703578e3d0-16752     Started container sas-config-init
19m         Normal    Pulled                            pod/sas-batch-server-9239fe98-263a-49fc-b7e5-ae703578e3d0-16752     Container image "668749497752.dkr.ecr.us-west-2.amazonaws.com/sasviya/viya-4-x64_oci_linux_2-docker/sas-programming-environment:1.53.31-20240613.1718295947845" already present on machine
19m         Normal    Created                           pod/sas-batch-server-9239fe98-263a-49fc-b7e5-ae703578e3d0-16752     Created container sas-programming-environment
19m         Normal    Started                           pod/sas-batch-server-9239fe98-263a-49fc-b7e5-ae703578e3d0-16752     Started container sas-programming-environment
19m         Normal    Pulled                            pod/sas-batch-server-9239fe98-263a-49fc-b7e5-ae703578e3d0-16752     Container image "668749497752.dkr.ecr.us-west-2.amazonaws.com/sasviya/viya-4-x64_oci_linux_2-docker/sas-process-exporter:1.9.1-20240306.1709732097762" already present on machine
19m         Normal    Created                           pod/sas-batch-server-9239fe98-263a-49fc-b7e5-ae703578e3d0-16752     Created container sas-process-exporter
19m         Normal    Started                           pod/sas-batch-server-9239fe98-263a-49fc-b7e5-ae703578e3d0-16752     Started container sas-process-exporter
6m25s       Normal    Killing                           pod/sas-batch-server-9239fe98-263a-49fc-b7e5-ae703578e3d0-16752     Stopping container sas-process-exporter
59m         Normal    Scheduled                         pod/sas-batch-server-9319e3b9-8b0a-4e08-b91f-6eecd94a7591-16640     Successfully assigned viya-dev/sas-batch-server-9319e3b9-8b0a-4e08-b91f-6eecd94a7591-16640 to ip-100-64-103-52.us-west-2.compute.internal
59m         Normal    Pulled                            pod/sas-batch-server-9319e3b9-8b0a-4e08-b91f-6eecd94a7591-16640     Container image "668749497752.dkr.ecr.us-west-2.amazonaws.com/sasviya/viya-4-x64_oci_linux_2-docker/sas-certframe:3.51.0-20240313.1710330811841" already present on machine
59m         Normal    Created                           pod/sas-batch-server-9319e3b9-8b0a-4e08-b91f-6eecd94a7591-16640     Created container sas-certframe
59m         Normal    Started                           pod/sas-batch-server-9319e3b9-8b0a-4e08-b91f-6eecd94a7591-16640     Started container sas-certframe
59m         Normal    Pulled                            pod/sas-batch-server-9319e3b9-8b0a-4e08-b91f-6eecd94a7591-16640     Container image "668749497752.dkr.ecr.us-west-2.amazonaws.com/sasviya/viya-4-x64_oci_linux_2-docker/sas-config-init:1.21.1-20240305.1709656957059" already present on machine
59m         Normal    Created                           pod/sas-batch-server-9319e3b9-8b0a-4e08-b91f-6eecd94a7591-16640     Created container sas-config-init
59m         Normal    Started                           pod/sas-batch-server-9319e3b9-8b0a-4e08-b91f-6eecd94a7591-16640     Started container sas-config-init
59m         Normal    Pulled                            pod/sas-batch-server-9319e3b9-8b0a-4e08-b91f-6eecd94a7591-16640     Container image "668749497752.dkr.ecr.us-west-2.amazonaws.com/sasviya/viya-4-x64_oci_linux_2-docker/sas-programming-environment:1.53.31-20240613.1718295947845" already present on machine
59m         Normal    Created                           pod/sas-batch-server-9319e3b9-8b0a-4e08-b91f-6eecd94a7591-16640     Created container sas-programming-environment
59m         Normal    Started                           pod/sas-batch-server-9319e3b9-8b0a-4e08-b91f-6eecd94a7591-16640     Started container sas-programming-environment
59m         Normal    Pulled                            pod/sas-batch-server-9319e3b9-8b0a-4e08-b91f-6eecd94a7591-16640     Container image "668749497752.dkr.ecr.us-west-2.amazonaws.com/sasviya/viya-4-x64_oci_linux_2-docker/sas-process-exporter:1.9.1-20240306.1709732097762" already present on machine
59m         Normal    Created                           pod/sas-batch-server-9319e3b9-8b0a-4e08-b91f-6eecd94a7591-16640     Created container sas-process-exporter
59m         Normal    Started                           pod/sas-batch-server-9319e3b9-8b0a-4e08-b91f-6eecd94a7591-16640     Started container sas-process-exporter
53m         Normal    Killing                           pod/sas-batch-server-9319e3b9-8b0a-4e08-b91f-6eecd94a7591-16640     Stopping container sas-process-exporter
59m         Normal    Scheduled                         pod/sas-batch-server-93780ed8-67e0-493f-824b-e6bfb38130f4-16641     Successfully assigned viya-dev/sas-batch-server-93780ed8-67e0-493f-824b-e6bfb38130f4-16641 to ip-100-64-125-225.us-west-2.compute.internal
59m         Normal    Pulled                            pod/sas-batch-server-93780ed8-67e0-493f-824b-e6bfb38130f4-16641     Container image "668749497752.dkr.ecr.us-west-2.amazonaws.com/sasviya/viya-4-x64_oci_linux_2-docker/sas-certframe:3.51.0-20240313.1710330811841" already present on machine
59m         Normal    Created                           pod/sas-batch-server-93780ed8-67e0-493f-824b-e6bfb38130f4-16641     Created container sas-certframe
59m         Normal    Started                           pod/sas-batch-server-93780ed8-67e0-493f-824b-e6bfb38130f4-16641     Started container sas-certframe
59m         Normal    Pulled                            pod/sas-batch-server-93780ed8-67e0-493f-824b-e6bfb38130f4-16641     Container image "668749497752.dkr.ecr.us-west-2.amazonaws.com/sasviya/viya-4-x64_oci_linux_2-docker/sas-config-init:1.21.1-20240305.1709656957059" already present on machine
59m         Normal    Created                           pod/sas-batch-server-93780ed8-67e0-493f-824b-e6bfb38130f4-16641     Created container sas-config-init
59m         Normal    Started                           pod/sas-batch-server-93780ed8-67e0-493f-824b-e6bfb38130f4-16641     Started container sas-config-init
59m         Normal    Pulled                            pod/sas-batch-server-93780ed8-67e0-493f-824b-e6bfb38130f4-16641     Container image "668749497752.dkr.ecr.us-west-2.amazonaws.com/sasviya/viya-4-x64_oci_linux_2-docker/sas-programming-environment:1.53.31-20240613.1718295947845" already present on machine
59m         Normal    Created                           pod/sas-batch-server-93780ed8-67e0-493f-824b-e6bfb38130f4-16641     Created container sas-programming-environment
59m         Normal    Started                           pod/sas-batch-server-93780ed8-67e0-493f-824b-e6bfb38130f4-16641     Started container sas-programming-environment
59m         Normal    Pulled                            pod/sas-batch-server-93780ed8-67e0-493f-824b-e6bfb38130f4-16641     Container image "668749497752.dkr.ecr.us-west-2.amazonaws.com/sasviya/viya-4-x64_oci_linux_2-docker/sas-process-exporter:1.9.1-20240306.1709732097762" already present on machine
59m         Normal    Created                           pod/sas-batch-server-93780ed8-67e0-493f-824b-e6bfb38130f4-16641     Created container sas-process-exporter
59m         Normal    Started                           pod/sas-batch-server-93780ed8-67e0-493f-824b-e6bfb38130f4-16641     Started container sas-process-exporter
49m         Normal    Killing                           pod/sas-batch-server-93780ed8-67e0-493f-824b-e6bfb38130f4-16641     Stopping container sas-process-exporter
19m         Normal    Scheduled                         pod/sas-batch-server-93800272-a464-40de-a04c-26f6f92794fa-16761     Successfully assigned viya-dev/sas-batch-server-93800272-a464-40de-a04c-26f6f92794fa-16761 to ip-100-64-118-176.us-west-2.compute.internal
19m         Normal    Pulled                            pod/sas-batch-server-93800272-a464-40de-a04c-26f6f92794fa-16761     Container image "668749497752.dkr.ecr.us-west-2.amazonaws.com/sasviya/viya-4-x64_oci_linux_2-docker/sas-certframe:3.51.0-20240313.1710330811841" already present on machine
19m         Normal    Created                           pod/sas-batch-server-93800272-a464-40de-a04c-26f6f92794fa-16761     Created container sas-certframe
19m         Normal    Started                           pod/sas-batch-server-93800272-a464-40de-a04c-26f6f92794fa-16761     Started container sas-certframe
19m         Normal    Pulled                            pod/sas-batch-server-93800272-a464-40de-a04c-26f6f92794fa-16761     Container image "668749497752.dkr.ecr.us-west-2.amazonaws.com/sasviya/viya-4-x64_oci_linux_2-docker/sas-config-init:1.21.1-20240305.1709656957059" already present on machine
19m         Normal    Created                           pod/sas-batch-server-93800272-a464-40de-a04c-26f6f92794fa-16761     Created container sas-config-init
19m         Normal    Started                           pod/sas-batch-server-93800272-a464-40de-a04c-26f6f92794fa-16761     Started container sas-config-init
19m         Normal    Pulled                            pod/sas-batch-server-93800272-a464-40de-a04c-26f6f92794fa-16761     Container image "668749497752.dkr.ecr.us-west-2.amazonaws.com/sasviya/viya-4-x64_oci_linux_2-docker/sas-programming-environment:1.53.31-20240613.1718295947845" already present on machine
19m         Normal    Created                           pod/sas-batch-server-93800272-a464-40de-a04c-26f6f92794fa-16761     Created container sas-programming-environment
19m         Normal    Started                           pod/sas-batch-server-93800272-a464-40de-a04c-26f6f92794fa-16761     Started container sas-programming-environment
19m         Normal    Pulled                            pod/sas-batch-server-93800272-a464-40de-a04c-26f6f92794fa-16761     Container image "668749497752.dkr.ecr.us-west-2.amazonaws.com/sasviya/viya-4-x64_oci_linux_2-docker/sas-process-exporter:1.9.1-20240306.1709732097762" already present on machine
19m         Normal    Created                           pod/sas-batch-server-93800272-a464-40de-a04c-26f6f92794fa-16761     Created container sas-process-exporter
19m         Normal    Started                           pod/sas-batch-server-93800272-a464-40de-a04c-26f6f92794fa-16761     Started container sas-process-exporter
6m17s       Normal    Killing                           pod/sas-batch-server-93800272-a464-40de-a04c-26f6f92794fa-16761     Stopping container sas-process-exporter
59m         Normal    Scheduled                         pod/sas-batch-server-93c3567a-6169-47c0-a29f-0f953dd86226-16637     Successfully assigned viya-dev/sas-batch-server-93c3567a-6169-47c0-a29f-0f953dd86226-16637 to ip-100-64-118-176.us-west-2.compute.internal
59m         Normal    Pulled                            pod/sas-batch-server-93c3567a-6169-47c0-a29f-0f953dd86226-16637     Container image "668749497752.dkr.ecr.us-west-2.amazonaws.com/sasviya/viya-4-x64_oci_linux_2-docker/sas-certframe:3.51.0-20240313.1710330811841" already present on machine
59m         Normal    Created                           pod/sas-batch-server-93c3567a-6169-47c0-a29f-0f953dd86226-16637     Created container sas-certframe
59m         Normal    Started                           pod/sas-batch-server-93c3567a-6169-47c0-a29f-0f953dd86226-16637     Started container sas-certframe
59m         Normal    Pulled                            pod/sas-batch-server-93c3567a-6169-47c0-a29f-0f953dd86226-16637     Container image "668749497752.dkr.ecr.us-west-2.amazonaws.com/sasviya/viya-4-x64_oci_linux_2-docker/sas-config-init:1.21.1-20240305.1709656957059" already present on machine
59m         Normal    Created                           pod/sas-batch-server-93c3567a-6169-47c0-a29f-0f953dd86226-16637     Created container sas-config-init
59m         Normal    Started                           pod/sas-batch-server-93c3567a-6169-47c0-a29f-0f953dd86226-16637     Started container sas-config-init
59m         Normal    Pulled                            pod/sas-batch-server-93c3567a-6169-47c0-a29f-0f953dd86226-16637     Container image "668749497752.dkr.ecr.us-west-2.amazonaws.com/sasviya/viya-4-x64_oci_linux_2-docker/sas-programming-environment:1.53.31-20240613.1718295947845" already present on machine
59m         Normal    Created                           pod/sas-batch-server-93c3567a-6169-47c0-a29f-0f953dd86226-16637     Created container sas-programming-environment
59m         Normal    Started                           pod/sas-batch-server-93c3567a-6169-47c0-a29f-0f953dd86226-16637     Started container sas-programming-environment
59m         Normal    Pulled                            pod/sas-batch-server-93c3567a-6169-47c0-a29f-0f953dd86226-16637     Container image "668749497752.dkr.ecr.us-west-2.amazonaws.com/sasviya/viya-4-x64_oci_linux_2-docker/sas-process-exporter:1.9.1-20240306.1709732097762" already present on machine
59m         Normal    Created                           pod/sas-batch-server-93c3567a-6169-47c0-a29f-0f953dd86226-16637     Created container sas-process-exporter
59m         Normal    Started                           pod/sas-batch-server-93c3567a-6169-47c0-a29f-0f953dd86226-16637     Started container sas-process-exporter
48m         Normal    Killing                           pod/sas-batch-server-93c3567a-6169-47c0-a29f-0f953dd86226-16637     Stopping container sas-process-exporter
20m         Normal    Scheduled                         pod/sas-batch-server-9566b0d0-7547-4f5d-903f-8fe8e1c6accb-16690     Successfully assigned viya-dev/sas-batch-server-9566b0d0-7547-4f5d-903f-8fe8e1c6accb-16690 to ip-100-64-118-98.us-west-2.compute.internal
20m         Normal    Pulled                            pod/sas-batch-server-9566b0d0-7547-4f5d-903f-8fe8e1c6accb-16690     Container image "668749497752.dkr.ecr.us-west-2.amazonaws.com/sasviya/viya-4-x64_oci_linux_2-docker/sas-certframe:3.51.0-20240313.1710330811841" already present on machine
20m         Normal    Created                           pod/sas-batch-server-9566b0d0-7547-4f5d-903f-8fe8e1c6accb-16690     Created container sas-certframe
20m         Normal    Started                           pod/sas-batch-server-9566b0d0-7547-4f5d-903f-8fe8e1c6accb-16690     Started container sas-certframe
20m         Normal    Pulled                            pod/sas-batch-server-9566b0d0-7547-4f5d-903f-8fe8e1c6accb-16690     Container image "668749497752.dkr.ecr.us-west-2.amazonaws.com/sasviya/viya-4-x64_oci_linux_2-docker/sas-config-init:1.21.1-20240305.1709656957059" already present on machine
20m         Normal    Created                           pod/sas-batch-server-9566b0d0-7547-4f5d-903f-8fe8e1c6accb-16690     Created container sas-config-init
20m         Normal    Started                           pod/sas-batch-server-9566b0d0-7547-4f5d-903f-8fe8e1c6accb-16690     Started container sas-config-init
20m         Normal    Pulled                            pod/sas-batch-server-9566b0d0-7547-4f5d-903f-8fe8e1c6accb-16690     Container image "668749497752.dkr.ecr.us-west-2.amazonaws.com/sasviya/viya-4-x64_oci_linux_2-docker/sas-programming-environment:1.53.31-20240613.1718295947845" already present on machine
20m         Normal    Created                           pod/sas-batch-server-9566b0d0-7547-4f5d-903f-8fe8e1c6accb-16690     Created container sas-programming-environment
20m         Normal    Started                           pod/sas-batch-server-9566b0d0-7547-4f5d-903f-8fe8e1c6accb-16690     Started container sas-programming-environment
20m         Normal    Pulled                            pod/sas-batch-server-9566b0d0-7547-4f5d-903f-8fe8e1c6accb-16690     Container image "668749497752.dkr.ecr.us-west-2.amazonaws.com/sasviya/viya-4-x64_oci_linux_2-docker/sas-process-exporter:1.9.1-20240306.1709732097762" already present on machine
20m         Normal    Created                           pod/sas-batch-server-9566b0d0-7547-4f5d-903f-8fe8e1c6accb-16690     Created container sas-process-exporter
20m         Normal    Started                           pod/sas-batch-server-9566b0d0-7547-4f5d-903f-8fe8e1c6accb-16690     Started container sas-process-exporter
12m         Normal    Killing                           pod/sas-batch-server-9566b0d0-7547-4f5d-903f-8fe8e1c6accb-16690     Stopping container sas-process-exporter
59m         Normal    Scheduled                         pod/sas-batch-server-957fad2a-feb0-47a0-b3ac-2d5ac6fe49eb-16609     Successfully assigned viya-dev/sas-batch-server-957fad2a-feb0-47a0-b3ac-2d5ac6fe49eb-16609 to ip-100-64-118-176.us-west-2.compute.internal
59m         Normal    Pulled                            pod/sas-batch-server-957fad2a-feb0-47a0-b3ac-2d5ac6fe49eb-16609     Container image "668749497752.dkr.ecr.us-west-2.amazonaws.com/sasviya/viya-4-x64_oci_linux_2-docker/sas-certframe:3.51.0-20240313.1710330811841" already present on machine
59m         Normal    Created                           pod/sas-batch-server-957fad2a-feb0-47a0-b3ac-2d5ac6fe49eb-16609     Created container sas-certframe
59m         Normal    Started                           pod/sas-batch-server-957fad2a-feb0-47a0-b3ac-2d5ac6fe49eb-16609     Started container sas-certframe
59m         Normal    Pulled                            pod/sas-batch-server-957fad2a-feb0-47a0-b3ac-2d5ac6fe49eb-16609     Container image "668749497752.dkr.ecr.us-west-2.amazonaws.com/sasviya/viya-4-x64_oci_linux_2-docker/sas-config-init:1.21.1-20240305.1709656957059" already present on machine
59m         Normal    Created                           pod/sas-batch-server-957fad2a-feb0-47a0-b3ac-2d5ac6fe49eb-16609     Created container sas-config-init
59m         Normal    Started                           pod/sas-batch-server-957fad2a-feb0-47a0-b3ac-2d5ac6fe49eb-16609     Started container sas-config-init
59m         Normal    Pulled                            pod/sas-batch-server-957fad2a-feb0-47a0-b3ac-2d5ac6fe49eb-16609     Container image "668749497752.dkr.ecr.us-west-2.amazonaws.com/sasviya/viya-4-x64_oci_linux_2-docker/sas-programming-environment:1.53.31-20240613.1718295947845" already present on machine
59m         Normal    Created                           pod/sas-batch-server-957fad2a-feb0-47a0-b3ac-2d5ac6fe49eb-16609     Created container sas-programming-environment
59m         Normal    Started                           pod/sas-batch-server-957fad2a-feb0-47a0-b3ac-2d5ac6fe49eb-16609     Started container sas-programming-environment
59m         Normal    Pulled                            pod/sas-batch-server-957fad2a-feb0-47a0-b3ac-2d5ac6fe49eb-16609     Container image "668749497752.dkr.ecr.us-west-2.amazonaws.com/sasviya/viya-4-x64_oci_linux_2-docker/sas-process-exporter:1.9.1-20240306.1709732097762" already present on machine
59m         Normal    Created                           pod/sas-batch-server-957fad2a-feb0-47a0-b3ac-2d5ac6fe49eb-16609     Created container sas-process-exporter
59m         Normal    Started                           pod/sas-batch-server-957fad2a-feb0-47a0-b3ac-2d5ac6fe49eb-16609     Started container sas-process-exporter
46m         Normal    Killing                           pod/sas-batch-server-957fad2a-feb0-47a0-b3ac-2d5ac6fe49eb-16609     Stopping container sas-process-exporter
19m         Normal    Scheduled                         pod/sas-batch-server-961cdbb6-0da7-49aa-a754-1f470dde1493-16757     Successfully assigned viya-dev/sas-batch-server-961cdbb6-0da7-49aa-a754-1f470dde1493-16757 to ip-100-64-118-176.us-west-2.compute.internal
19m         Normal    Pulled                            pod/sas-batch-server-961cdbb6-0da7-49aa-a754-1f470dde1493-16757     Container image "668749497752.dkr.ecr.us-west-2.amazonaws.com/sasviya/viya-4-x64_oci_linux_2-docker/sas-certframe:3.51.0-20240313.1710330811841" already present on machine
19m         Normal    Created                           pod/sas-batch-server-961cdbb6-0da7-49aa-a754-1f470dde1493-16757     Created container sas-certframe
19m         Normal    Started                           pod/sas-batch-server-961cdbb6-0da7-49aa-a754-1f470dde1493-16757     Started container sas-certframe
19m         Normal    Pulled                            pod/sas-batch-server-961cdbb6-0da7-49aa-a754-1f470dde1493-16757     Container image "668749497752.dkr.ecr.us-west-2.amazonaws.com/sasviya/viya-4-x64_oci_linux_2-docker/sas-config-init:1.21.1-20240305.1709656957059" already present on machine
19m         Normal    Created                           pod/sas-batch-server-961cdbb6-0da7-49aa-a754-1f470dde1493-16757     Created container sas-config-init
19m         Normal    Started                           pod/sas-batch-server-961cdbb6-0da7-49aa-a754-1f470dde1493-16757     Started container sas-config-init
19m         Normal    Pulled                            pod/sas-batch-server-961cdbb6-0da7-49aa-a754-1f470dde1493-16757     Container image "668749497752.dkr.ecr.us-west-2.amazonaws.com/sasviya/viya-4-x64_oci_linux_2-docker/sas-programming-environment:1.53.31-20240613.1718295947845" already present on machine
19m         Normal    Created                           pod/sas-batch-server-961cdbb6-0da7-49aa-a754-1f470dde1493-16757     Created container sas-programming-environment
19m         Normal    Started                           pod/sas-batch-server-961cdbb6-0da7-49aa-a754-1f470dde1493-16757     Started container sas-programming-environment
19m         Normal    Pulled                            pod/sas-batch-server-961cdbb6-0da7-49aa-a754-1f470dde1493-16757     Container image "668749497752.dkr.ecr.us-west-2.amazonaws.com/sasviya/viya-4-x64_oci_linux_2-docker/sas-process-exporter:1.9.1-20240306.1709732097762" already present on machine
19m         Normal    Created                           pod/sas-batch-server-961cdbb6-0da7-49aa-a754-1f470dde1493-16757     Created container sas-process-exporter
19m         Normal    Started                           pod/sas-batch-server-961cdbb6-0da7-49aa-a754-1f470dde1493-16757     Started container sas-process-exporter
9m31s       Normal    Killing                           pod/sas-batch-server-961cdbb6-0da7-49aa-a754-1f470dde1493-16757     Stopping container sas-process-exporter
13m         Warning   FailedScheduling                  pod/sas-batch-server-968bb195-d626-4444-8024-29139ec24ddd-16758     0/10 nodes are available: 1 Insufficient cpu, 1 node(s) had untolerated taint {workload.sas.com/class: cas}, 1 node(s) had untolerated taint {workload.sas.com/class: stateful}, 1 node(s) had untolerated taint {workload.sas.com/class: stateless}, 6 node(s) didn't match Pod's node affinity/selector. preemption: 0/10 nodes are available: 1 No preemption victims found for incoming pod, 9 Preemption is not helpful for scheduling..
13m         Normal    Scheduled                         pod/sas-batch-server-968bb195-d626-4444-8024-29139ec24ddd-16758     Successfully assigned viya-dev/sas-batch-server-968bb195-d626-4444-8024-29139ec24ddd-16758 to ip-100-64-98-232.us-west-2.compute.internal
13m         Normal    Pulled                            pod/sas-batch-server-968bb195-d626-4444-8024-29139ec24ddd-16758     Container image "668749497752.dkr.ecr.us-west-2.amazonaws.com/sasviya/viya-4-x64_oci_linux_2-docker/sas-certframe:3.51.0-20240313.1710330811841" already present on machine
13m         Normal    Created                           pod/sas-batch-server-968bb195-d626-4444-8024-29139ec24ddd-16758     Created container sas-certframe
13m         Normal    Started                           pod/sas-batch-server-968bb195-d626-4444-8024-29139ec24ddd-16758     Started container sas-certframe
13m         Normal    Pulled                            pod/sas-batch-server-968bb195-d626-4444-8024-29139ec24ddd-16758     Container image "668749497752.dkr.ecr.us-west-2.amazonaws.com/sasviya/viya-4-x64_oci_linux_2-docker/sas-config-init:1.21.1-20240305.1709656957059" already present on machine
13m         Normal    Created                           pod/sas-batch-server-968bb195-d626-4444-8024-29139ec24ddd-16758     Created container sas-config-init
13m         Normal    Started                           pod/sas-batch-server-968bb195-d626-4444-8024-29139ec24ddd-16758     Started container sas-config-init
13m         Normal    Pulled                            pod/sas-batch-server-968bb195-d626-4444-8024-29139ec24ddd-16758     Container image "668749497752.dkr.ecr.us-west-2.amazonaws.com/sasviya/viya-4-x64_oci_linux_2-docker/sas-programming-environment:1.53.31-20240613.1718295947845" already present on machine
13m         Normal    Created                           pod/sas-batch-server-968bb195-d626-4444-8024-29139ec24ddd-16758     Created container sas-programming-environment
13m         Normal    Started                           pod/sas-batch-server-968bb195-d626-4444-8024-29139ec24ddd-16758     Started container sas-programming-environment
13m         Normal    Pulled                            pod/sas-batch-server-968bb195-d626-4444-8024-29139ec24ddd-16758     Container image "668749497752.dkr.ecr.us-west-2.amazonaws.com/sasviya/viya-4-x64_oci_linux_2-docker/sas-process-exporter:1.9.1-20240306.1709732097762" already present on machine
13m         Normal    Created                           pod/sas-batch-server-968bb195-d626-4444-8024-29139ec24ddd-16758     Created container sas-process-exporter
13m         Normal    Started                           pod/sas-batch-server-968bb195-d626-4444-8024-29139ec24ddd-16758     Started container sas-process-exporter
3m46s       Normal    Killing                           pod/sas-batch-server-968bb195-d626-4444-8024-29139ec24ddd-16758     Stopping container sas-process-exporter
57m         Normal    Scheduled                         pod/sas-batch-server-97a152a5-a001-43e1-a840-546ea6cac6ec-16676     Successfully assigned viya-dev/sas-batch-server-97a152a5-a001-43e1-a840-546ea6cac6ec-16676 to ip-100-64-98-232.us-west-2.compute.internal
57m         Normal    Pulled                            pod/sas-batch-server-97a152a5-a001-43e1-a840-546ea6cac6ec-16676     Container image "668749497752.dkr.ecr.us-west-2.amazonaws.com/sasviya/viya-4-x64_oci_linux_2-docker/sas-certframe:3.51.0-20240313.1710330811841" already present on machine
57m         Normal    Created                           pod/sas-batch-server-97a152a5-a001-43e1-a840-546ea6cac6ec-16676     Created container sas-certframe
57m         Normal    Started                           pod/sas-batch-server-97a152a5-a001-43e1-a840-546ea6cac6ec-16676     Started container sas-certframe
57m         Normal    Pulling                           pod/sas-batch-server-97a152a5-a001-43e1-a840-546ea6cac6ec-16676     Pulling image "668749497752.dkr.ecr.us-west-2.amazonaws.com/sasviya/viya-4-x64_oci_linux_2-docker/sas-config-init:1.21.1-20240305.1709656957059"
56m         Normal    Pulled                            pod/sas-batch-server-97a152a5-a001-43e1-a840-546ea6cac6ec-16676     Successfully pulled image "668749497752.dkr.ecr.us-west-2.amazonaws.com/sasviya/viya-4-x64_oci_linux_2-docker/sas-config-init:1.21.1-20240305.1709656957059" in 24.985s (24.985s including waiting)
56m         Normal    Created                           pod/sas-batch-server-97a152a5-a001-43e1-a840-546ea6cac6ec-16676     Created container sas-config-init
56m         Normal    Started                           pod/sas-batch-server-97a152a5-a001-43e1-a840-546ea6cac6ec-16676     Started container sas-config-init
56m         Normal    Pulling                           pod/sas-batch-server-97a152a5-a001-43e1-a840-546ea6cac6ec-16676     Pulling image "668749497752.dkr.ecr.us-west-2.amazonaws.com/sasviya/viya-4-x64_oci_linux_2-docker/sas-programming-environment:1.53.31-20240613.1718295947845"
55m         Normal    Pulled                            pod/sas-batch-server-97a152a5-a001-43e1-a840-546ea6cac6ec-16676     Successfully pulled image "668749497752.dkr.ecr.us-west-2.amazonaws.com/sasviya/viya-4-x64_oci_linux_2-docker/sas-programming-environment:1.53.31-20240613.1718295947845" in 1m15.723s (1m15.723s including waiting)
55m         Normal    Created                           pod/sas-batch-server-97a152a5-a001-43e1-a840-546ea6cac6ec-16676     Created container sas-programming-environment
55m         Normal    Started                           pod/sas-batch-server-97a152a5-a001-43e1-a840-546ea6cac6ec-16676     Started container sas-programming-environment
55m         Normal    Pulled                            pod/sas-batch-server-97a152a5-a001-43e1-a840-546ea6cac6ec-16676     Container image "668749497752.dkr.ecr.us-west-2.amazonaws.com/sasviya/viya-4-x64_oci_linux_2-docker/sas-process-exporter:1.9.1-20240306.1709732097762" already present on machine
55m         Normal    Created                           pod/sas-batch-server-97a152a5-a001-43e1-a840-546ea6cac6ec-16676     Created container sas-process-exporter
55m         Normal    Started                           pod/sas-batch-server-97a152a5-a001-43e1-a840-546ea6cac6ec-16676     Started container sas-process-exporter
48m         Normal    Killing                           pod/sas-batch-server-97a152a5-a001-43e1-a840-546ea6cac6ec-16676     Stopping container sas-process-exporter
57m         Normal    Scheduled                         pod/sas-batch-server-98ca2512-d650-4a95-b8e4-742db40e8324-16677     Successfully assigned viya-dev/sas-batch-server-98ca2512-d650-4a95-b8e4-742db40e8324-16677 to ip-100-64-98-232.us-west-2.compute.internal
57m         Normal    Pulled                            pod/sas-batch-server-98ca2512-d650-4a95-b8e4-742db40e8324-16677     Container image "668749497752.dkr.ecr.us-west-2.amazonaws.com/sasviya/viya-4-x64_oci_linux_2-docker/sas-certframe:3.51.0-20240313.1710330811841" already present on machine
57m         Normal    Created                           pod/sas-batch-server-98ca2512-d650-4a95-b8e4-742db40e8324-16677     Created container sas-certframe
57m         Normal    Started                           pod/sas-batch-server-98ca2512-d650-4a95-b8e4-742db40e8324-16677     Started container sas-certframe
57m         Normal    Pulling                           pod/sas-batch-server-98ca2512-d650-4a95-b8e4-742db40e8324-16677     Pulling image "668749497752.dkr.ecr.us-west-2.amazonaws.com/sasviya/viya-4-x64_oci_linux_2-docker/sas-config-init:1.21.1-20240305.1709656957059"
56m         Normal    Pulled                            pod/sas-batch-server-98ca2512-d650-4a95-b8e4-742db40e8324-16677     Successfully pulled image "668749497752.dkr.ecr.us-west-2.amazonaws.com/sasviya/viya-4-x64_oci_linux_2-docker/sas-config-init:1.21.1-20240305.1709656957059" in 25.087s (25.087s including waiting)
56m         Normal    Created                           pod/sas-batch-server-98ca2512-d650-4a95-b8e4-742db40e8324-16677     Created container sas-config-init
56m         Normal    Started                           pod/sas-batch-server-98ca2512-d650-4a95-b8e4-742db40e8324-16677     Started container sas-config-init
56m         Normal    Pulling                           pod/sas-batch-server-98ca2512-d650-4a95-b8e4-742db40e8324-16677     Pulling image "668749497752.dkr.ecr.us-west-2.amazonaws.com/sasviya/viya-4-x64_oci_linux_2-docker/sas-programming-environment:1.53.31-20240613.1718295947845"
55m         Normal    Pulled                            pod/sas-batch-server-98ca2512-d650-4a95-b8e4-742db40e8324-16677     Successfully pulled image "668749497752.dkr.ecr.us-west-2.amazonaws.com/sasviya/viya-4-x64_oci_linux_2-docker/sas-programming-environment:1.53.31-20240613.1718295947845" in 1m15.645s (1m15.645s including waiting)
55m         Normal    Created                           pod/sas-batch-server-98ca2512-d650-4a95-b8e4-742db40e8324-16677     Created container sas-programming-environment
55m         Normal    Started                           pod/sas-batch-server-98ca2512-d650-4a95-b8e4-742db40e8324-16677     Started container sas-programming-environment
55m         Normal    Pulled                            pod/sas-batch-server-98ca2512-d650-4a95-b8e4-742db40e8324-16677     Container image "668749497752.dkr.ecr.us-west-2.amazonaws.com/sasviya/viya-4-x64_oci_linux_2-docker/sas-process-exporter:1.9.1-20240306.1709732097762" already present on machine
55m         Normal    Created                           pod/sas-batch-server-98ca2512-d650-4a95-b8e4-742db40e8324-16677     Created container sas-process-exporter
55m         Normal    Started                           pod/sas-batch-server-98ca2512-d650-4a95-b8e4-742db40e8324-16677     Started container sas-process-exporter
46m         Normal    Killing                           pod/sas-batch-server-98ca2512-d650-4a95-b8e4-742db40e8324-16677     Stopping container sas-process-exporter
59m         Normal    Scheduled                         pod/sas-batch-server-9b094d85-c670-4f04-8439-9b1309316560-16634     Successfully assigned viya-dev/sas-batch-server-9b094d85-c670-4f04-8439-9b1309316560-16634 to ip-100-64-118-98.us-west-2.compute.internal
59m         Normal    Pulled                            pod/sas-batch-server-9b094d85-c670-4f04-8439-9b1309316560-16634     Container image "668749497752.dkr.ecr.us-west-2.amazonaws.com/sasviya/viya-4-x64_oci_linux_2-docker/sas-certframe:3.51.0-20240313.1710330811841" already present on machine
59m         Normal    Created                           pod/sas-batch-server-9b094d85-c670-4f04-8439-9b1309316560-16634     Created container sas-certframe
59m         Normal    Started                           pod/sas-batch-server-9b094d85-c670-4f04-8439-9b1309316560-16634     Started container sas-certframe
59m         Normal    Pulled                            pod/sas-batch-server-9b094d85-c670-4f04-8439-9b1309316560-16634     Container image "668749497752.dkr.ecr.us-west-2.amazonaws.com/sasviya/viya-4-x64_oci_linux_2-docker/sas-config-init:1.21.1-20240305.1709656957059" already present on machine
59m         Normal    Created                           pod/sas-batch-server-9b094d85-c670-4f04-8439-9b1309316560-16634     Created container sas-config-init
59m         Normal    Started                           pod/sas-batch-server-9b094d85-c670-4f04-8439-9b1309316560-16634     Started container sas-config-init
59m         Normal    Pulled                            pod/sas-batch-server-9b094d85-c670-4f04-8439-9b1309316560-16634     Container image "668749497752.dkr.ecr.us-west-2.amazonaws.com/sasviya/viya-4-x64_oci_linux_2-docker/sas-programming-environment:1.53.31-20240613.1718295947845" already present on machine
59m         Normal    Created                           pod/sas-batch-server-9b094d85-c670-4f04-8439-9b1309316560-16634     Created container sas-programming-environment
59m         Normal    Started                           pod/sas-batch-server-9b094d85-c670-4f04-8439-9b1309316560-16634     Started container sas-programming-environment
59m         Normal    Pulled                            pod/sas-batch-server-9b094d85-c670-4f04-8439-9b1309316560-16634     Container image "668749497752.dkr.ecr.us-west-2.amazonaws.com/sasviya/viya-4-x64_oci_linux_2-docker/sas-process-exporter:1.9.1-20240306.1709732097762" already present on machine
59m         Normal    Created                           pod/sas-batch-server-9b094d85-c670-4f04-8439-9b1309316560-16634     Created container sas-process-exporter
59m         Normal    Started                           pod/sas-batch-server-9b094d85-c670-4f04-8439-9b1309316560-16634     Started container sas-process-exporter
47m         Normal    Killing                           pod/sas-batch-server-9b094d85-c670-4f04-8439-9b1309316560-16634     Stopping container sas-process-exporter
11m         Warning   FailedScheduling                  pod/sas-batch-server-9c96915a-ed56-454d-bbff-42f08a716f1b-16783     0/10 nodes are available: 1 Insufficient cpu, 1 node(s) had untolerated taint {workload.sas.com/class: cas}, 1 node(s) had untolerated taint {workload.sas.com/class: stateful}, 1 node(s) had untolerated taint {workload.sas.com/class: stateless}, 6 node(s) didn't match Pod's node affinity/selector. preemption: 0/10 nodes are available: 1 No preemption victims found for incoming pod, 9 Preemption is not helpful for scheduling..
10m         Normal    Scheduled                         pod/sas-batch-server-9c96915a-ed56-454d-bbff-42f08a716f1b-16783     Successfully assigned viya-dev/sas-batch-server-9c96915a-ed56-454d-bbff-42f08a716f1b-16783 to ip-100-64-98-232.us-west-2.compute.internal
10m         Normal    Pulled                            pod/sas-batch-server-9c96915a-ed56-454d-bbff-42f08a716f1b-16783     Container image "668749497752.dkr.ecr.us-west-2.amazonaws.com/sasviya/viya-4-x64_oci_linux_2-docker/sas-certframe:3.51.0-20240313.1710330811841" already present on machine
10m         Normal    Created                           pod/sas-batch-server-9c96915a-ed56-454d-bbff-42f08a716f1b-16783     Created container sas-certframe
10m         Normal    Started                           pod/sas-batch-server-9c96915a-ed56-454d-bbff-42f08a716f1b-16783     Started container sas-certframe
10m         Normal    Pulled                            pod/sas-batch-server-9c96915a-ed56-454d-bbff-42f08a716f1b-16783     Container image "668749497752.dkr.ecr.us-west-2.amazonaws.com/sasviya/viya-4-x64_oci_linux_2-docker/sas-config-init:1.21.1-20240305.1709656957059" already present on machine
10m         Normal    Created                           pod/sas-batch-server-9c96915a-ed56-454d-bbff-42f08a716f1b-16783     Created container sas-config-init
10m         Normal    Started                           pod/sas-batch-server-9c96915a-ed56-454d-bbff-42f08a716f1b-16783     Started container sas-config-init
10m         Normal    Pulled                            pod/sas-batch-server-9c96915a-ed56-454d-bbff-42f08a716f1b-16783     Container image "668749497752.dkr.ecr.us-west-2.amazonaws.com/sasviya/viya-4-x64_oci_linux_2-docker/sas-programming-environment:1.53.31-20240613.1718295947845" already present on machine
10m         Normal    Created                           pod/sas-batch-server-9c96915a-ed56-454d-bbff-42f08a716f1b-16783     Created container sas-programming-environment
10m         Normal    Started                           pod/sas-batch-server-9c96915a-ed56-454d-bbff-42f08a716f1b-16783     Started container sas-programming-environment
10m         Normal    Pulled                            pod/sas-batch-server-9c96915a-ed56-454d-bbff-42f08a716f1b-16783     Container image "668749497752.dkr.ecr.us-west-2.amazonaws.com/sasviya/viya-4-x64_oci_linux_2-docker/sas-process-exporter:1.9.1-20240306.1709732097762" already present on machine
10m         Normal    Created                           pod/sas-batch-server-9c96915a-ed56-454d-bbff-42f08a716f1b-16783     Created container sas-process-exporter
10m         Normal    Started                           pod/sas-batch-server-9c96915a-ed56-454d-bbff-42f08a716f1b-16783     Started container sas-process-exporter
3m57s       Normal    Killing                           pod/sas-batch-server-9c96915a-ed56-454d-bbff-42f08a716f1b-16783     Stopping container sas-process-exporter
59m         Normal    Killing                           pod/sas-batch-server-9cfdea6a-6dfd-48d0-9e60-473e9b42e6d7-16605     Stopping container sas-process-exporter
19m         Normal    Scheduled                         pod/sas-batch-server-9fb59c6c-14df-4fe8-aaa4-1435f7f6eb61-16725     Successfully assigned viya-dev/sas-batch-server-9fb59c6c-14df-4fe8-aaa4-1435f7f6eb61-16725 to ip-100-64-88-54.us-west-2.compute.internal
19m         Normal    Pulled                            pod/sas-batch-server-9fb59c6c-14df-4fe8-aaa4-1435f7f6eb61-16725     Container image "668749497752.dkr.ecr.us-west-2.amazonaws.com/sasviya/viya-4-x64_oci_linux_2-docker/sas-certframe:3.51.0-20240313.1710330811841" already present on machine
19m         Normal    Created                           pod/sas-batch-server-9fb59c6c-14df-4fe8-aaa4-1435f7f6eb61-16725     Created container sas-certframe
19m         Normal    Started                           pod/sas-batch-server-9fb59c6c-14df-4fe8-aaa4-1435f7f6eb61-16725     Started container sas-certframe
19m         Normal    Pulled                            pod/sas-batch-server-9fb59c6c-14df-4fe8-aaa4-1435f7f6eb61-16725     Container image "668749497752.dkr.ecr.us-west-2.amazonaws.com/sasviya/viya-4-x64_oci_linux_2-docker/sas-config-init:1.21.1-20240305.1709656957059" already present on machine
19m         Normal    Created                           pod/sas-batch-server-9fb59c6c-14df-4fe8-aaa4-1435f7f6eb61-16725     Created container sas-config-init
19m         Normal    Started                           pod/sas-batch-server-9fb59c6c-14df-4fe8-aaa4-1435f7f6eb61-16725     Started container sas-config-init
19m         Normal    Pulled                            pod/sas-batch-server-9fb59c6c-14df-4fe8-aaa4-1435f7f6eb61-16725     Container image "668749497752.dkr.ecr.us-west-2.amazonaws.com/sasviya/viya-4-x64_oci_linux_2-docker/sas-programming-environment:1.53.31-20240613.1718295947845" already present on machine
19m         Normal    Created                           pod/sas-batch-server-9fb59c6c-14df-4fe8-aaa4-1435f7f6eb61-16725     Created container sas-programming-environment
19m         Normal    Started                           pod/sas-batch-server-9fb59c6c-14df-4fe8-aaa4-1435f7f6eb61-16725     Started container sas-programming-environment
19m         Normal    Pulled                            pod/sas-batch-server-9fb59c6c-14df-4fe8-aaa4-1435f7f6eb61-16725     Container image "668749497752.dkr.ecr.us-west-2.amazonaws.com/sasviya/viya-4-x64_oci_linux_2-docker/sas-process-exporter:1.9.1-20240306.1709732097762" already present on machine
19m         Normal    Created                           pod/sas-batch-server-9fb59c6c-14df-4fe8-aaa4-1435f7f6eb61-16725     Created container sas-process-exporter
19m         Normal    Started                           pod/sas-batch-server-9fb59c6c-14df-4fe8-aaa4-1435f7f6eb61-16725     Started container sas-process-exporter
7m25s       Normal    Killing                           pod/sas-batch-server-9fb59c6c-14df-4fe8-aaa4-1435f7f6eb61-16725     Stopping container sas-process-exporter
19m         Normal    Scheduled                         pod/sas-batch-server-a2360b4c-1ff4-4268-b0c8-eac11f4197b2-16754     Successfully assigned viya-dev/sas-batch-server-a2360b4c-1ff4-4268-b0c8-eac11f4197b2-16754 to ip-100-64-88-54.us-west-2.compute.internal
19m         Normal    Pulled                            pod/sas-batch-server-a2360b4c-1ff4-4268-b0c8-eac11f4197b2-16754     Container image "668749497752.dkr.ecr.us-west-2.amazonaws.com/sasviya/viya-4-x64_oci_linux_2-docker/sas-certframe:3.51.0-20240313.1710330811841" already present on machine
19m         Normal    Created                           pod/sas-batch-server-a2360b4c-1ff4-4268-b0c8-eac11f4197b2-16754     Created container sas-certframe
19m         Normal    Started                           pod/sas-batch-server-a2360b4c-1ff4-4268-b0c8-eac11f4197b2-16754     Started container sas-certframe
19m         Normal    Pulled                            pod/sas-batch-server-a2360b4c-1ff4-4268-b0c8-eac11f4197b2-16754     Container image "668749497752.dkr.ecr.us-west-2.amazonaws.com/sasviya/viya-4-x64_oci_linux_2-docker/sas-config-init:1.21.1-20240305.1709656957059" already present on machine
19m         Normal    Created                           pod/sas-batch-server-a2360b4c-1ff4-4268-b0c8-eac11f4197b2-16754     Created container sas-config-init
19m         Normal    Started                           pod/sas-batch-server-a2360b4c-1ff4-4268-b0c8-eac11f4197b2-16754     Started container sas-config-init
19m         Normal    Pulled                            pod/sas-batch-server-a2360b4c-1ff4-4268-b0c8-eac11f4197b2-16754     Container image "668749497752.dkr.ecr.us-west-2.amazonaws.com/sasviya/viya-4-x64_oci_linux_2-docker/sas-programming-environment:1.53.31-20240613.1718295947845" already present on machine
19m         Normal    Created                           pod/sas-batch-server-a2360b4c-1ff4-4268-b0c8-eac11f4197b2-16754     Created container sas-programming-environment
19m         Normal    Started                           pod/sas-batch-server-a2360b4c-1ff4-4268-b0c8-eac11f4197b2-16754     Started container sas-programming-environment
19m         Normal    Pulled                            pod/sas-batch-server-a2360b4c-1ff4-4268-b0c8-eac11f4197b2-16754     Container image "668749497752.dkr.ecr.us-west-2.amazonaws.com/sasviya/viya-4-x64_oci_linux_2-docker/sas-process-exporter:1.9.1-20240306.1709732097762" already present on machine
19m         Normal    Created                           pod/sas-batch-server-a2360b4c-1ff4-4268-b0c8-eac11f4197b2-16754     Created container sas-process-exporter
19m         Normal    Started                           pod/sas-batch-server-a2360b4c-1ff4-4268-b0c8-eac11f4197b2-16754     Started container sas-process-exporter
5m13s       Normal    Killing                           pod/sas-batch-server-a2360b4c-1ff4-4268-b0c8-eac11f4197b2-16754     Stopping container sas-process-exporter
59m         Normal    Scheduled                         pod/sas-batch-server-a24c6d8d-f1d3-43ff-a4c2-a0f972821cbf-16622     Successfully assigned viya-dev/sas-batch-server-a24c6d8d-f1d3-43ff-a4c2-a0f972821cbf-16622 to ip-100-64-125-225.us-west-2.compute.internal
59m         Normal    Pulled                            pod/sas-batch-server-a24c6d8d-f1d3-43ff-a4c2-a0f972821cbf-16622     Container image "668749497752.dkr.ecr.us-west-2.amazonaws.com/sasviya/viya-4-x64_oci_linux_2-docker/sas-certframe:3.51.0-20240313.1710330811841" already present on machine
59m         Normal    Created                           pod/sas-batch-server-a24c6d8d-f1d3-43ff-a4c2-a0f972821cbf-16622     Created container sas-certframe
59m         Normal    Started                           pod/sas-batch-server-a24c6d8d-f1d3-43ff-a4c2-a0f972821cbf-16622     Started container sas-certframe
59m         Normal    Pulled                            pod/sas-batch-server-a24c6d8d-f1d3-43ff-a4c2-a0f972821cbf-16622     Container image "668749497752.dkr.ecr.us-west-2.amazonaws.com/sasviya/viya-4-x64_oci_linux_2-docker/sas-config-init:1.21.1-20240305.1709656957059" already present on machine
